Workbook
Name Instrumento: '[1]R-LAB-127 DENSIDAD AIRE'!#REF!
Name Instrumento: '[1]R-LAB-127 DENSIDAD AIRE'!#REF!
Name Instrumento.: '[1]R-LAB-127 DENSIDAD AIRE'!#REF!
Name Instrumento.: '[1]R-LAB-127 DENSIDAD AIRE'!#REF!
Name N: #REF!
Name N: #REF!

Sheet INFORMACIÓN
A1: Intrumento | B1: Marca | C1: Modelo | D1: Serie | E1: Ubicación | F1: Inventario | G1: Número de Certificado | H1: Fecha de Recepción
A2: BASCULA DE PISO | B2: HEALTH O METER | C2: 844KL | D2: 8440131906 | E2: UNIDAD MATERNA | F2: 1204002438 | G2: JD1741-24 | H2: 45465 | L2: En sitio (instalaciones del cliente)
L3: Laboratorio BTMC
A5: Datos de calibración | D5: Datos del cliente | L5: BUEN ESTADO
A6: Lugar de calibración: | B6: En sitio ( instalaciones del cliente) | D6: Solicitante: | E6: HOSPITAL DE ALTA COMPLEJIDAD DEL MAGDALENA CENTRO | L6: REGULAR ESTADO
A7: Estado Físico: | B7: BUEN ESTADO | D7: Nit: | E7: 901.532.463-8 | L7: MAL ESTADO
A8: Fecha de calibración: | B8: =H2 -> 45465 | D8: Telefono: | E8: 3007835072
A9: Fecha de emisión: | B9: =H2 -> 45465 | D9: Dirección: | E9: CARRERA 15 ENTRE CALLE 18 y 19
A10: Temperatura mínima: | B10: 24.1 | D10: Ciudad: | E10: LA DORADA - CALDAS
A11: Temperatura máxima: | B11: 24.5
A12: Humedad Mínima: | B12: 60
A13: Humedad Máxima: | B13: 63
A14: Calibración realiza por: | B14: ING. GABRIEL DURÁN

Sheet MEDIDA
J2: RESULTADOS DE CALIBRACIÓN DE MASA
A4: Unidad de medida: | F4: g
A5: Capacidad Máxima de item: | F5: 25000
R6: Valores Seleccionados | U6: EXACTITUD
B7: Valor Seleccionado | E7: REPETIBILIDAD | H7: Indicación sin carga | U7: =R8 -> g
K8: C | N8: D | R8: =F4 -> g | U8: ASCENDENTE
B9: =F4 -> g | E9: =B9 -> g | H9: =F4 -> g | L9: A | R9: 0 | S9: 0 | U9: 0
B10: =F5*50% -> 12500 | C10: =MROUND(B10,5) -> 12500 | E10: 11500 | K10: B | N10: E | R10: =F5/10 -> 2500 | S10: =MROUND(R10,5) -> 2500 | U10: 2300
B11: =B10 -> 12500 | C11: =MROUND(B11,5) -> 12500 | E11: 11500 | J11: Valor Seleccionado | M11: EXCENTRICIDAD | P11: Indicación sin carga | R11: =R10+R10 -> 5000 | S11: =MROUND(R11,5) -> 5000 | U11: 4600
B12: =B11 -> 12500 | C12: =MROUND(B12,5) -> 12500 | E12: 11500 | R12: =R10+R11 -> 7500 | S12: =MROUND(R12,5) -> 7500 | U12: 6900
B13: =B12 -> 12500 | C13: =MROUND(B13,5) -> 12500 | E13: 11500 | J13: =F5/3 -> 8333.3333 | K13: =MROUND(J13,100) -> 8300 | L13: =F4 -> g | M13: =J13 -> 8333.3333 | N13: =MROUND(M13,100) -> 8300 | O13: =L13 -> g | P13: =F4 -> g | R13: =$R$10+R12 -> 10000 | S13: =MROUND(R13,5) -> 10000 | U13: 9200
B14: =B13 -> 12500 | C14: =MROUND(B14,5) -> 12500 | E14: 11500 | J14: A | M14: 7700 | R14: =$R$10+R13 -> 12500 | S14: =MROUND(R14,5) -> 12500 | U14: 11500
J15: B | M15: 7700 | R15: =$R$10+R14 -> 15000 | S15: =MROUND(R15,5) -> 15000 | U15: 13800
J16: C | M16: 7700 | R16: =$R$10+R15 -> 17500 | S16: =MROUND(R16,5) -> 17500 | U16: 16100
J17: D | M17: 7700 | R17: =$R$10+R16 -> 20000 | S17: =MROUND(R17,5) -> 20000 | U17: 18400
B18: Montar | J18: E | M18: 7700 | R18: =$R$10+R17 -> 22500 | S18: =MROUND(R18,5) -> 22500 | U18: 20700
B19: -------- | R19: =$R$10+R18 -> 25000 | S19: =MROUND(R19,5) -> 25000 | U19: 23000
G23: DISTRIBUCIÓN DE MASAS
B25: ESCOGIDA | D25: MASA CONV
G26: 1 g | H26: 2 g | I26: 2 g punto | J26: 5 g | K26: 10 g | L26: 20 g | M26: 20 g punto | N26: 50 g | O26: 100 g | P26: 200 g | Q26: 200 g punto | R26: 500 g | S26: 1000 g | T26: 1000g * | U26: 2000 g | V26: 5 kg 001 | W26: 5 kg 002 | X26: 10 kg 001D | Y26: 10 kg 001C | Z26: 20 kg 001D | AA26: 20 kg 002D | AB26: 20 kg 003D | AC26: 20 kg 006 | AD26: 20 kg 005 | AE26: 20 kg 004 | AF26: 20 kg 003C | AG26: 20 kg 001C | AH26: 20 kg 002C
G28: -------- | H28: -------- | I28: -------- | J28: -------- | K28: -------- | L28: -------- | M28: -------- | N28: -------- | O28: Montar | P28: Montar | Q28: Montar | R28: -------- | S28: -------- | T28: -------- | U28: Montar | V28: -------- | W28: -------- | X28: -------- | Y28: -------- | Z28: -------- | AA28: -------- | AB28: -------- | AC28: -------- | AD28: -------- | AE28: -------- | AF28: -------- | AG28: -------- | AH28: --------
B29: =S10 -> 2500 | D29: =SUM(G29:AH29) -> 2500.0141 | G29: =IF(G28="Montar",1+G30,"") | H29: =IF(H28="Montar",2+H30,"") | I29: =IF(I28="Montar",2+I30,"") | J29: =IF(J28="Montar",5+J30,"") | K29: =IF(K28="Montar",10+K30,"") | L29: =IF(L28="Montar",20+L30,"") | M29: =IF(M28="Montar",20+M30,"") | N29: =IF(N28="Montar",50+N30,"") | O29: =IF(O28="Montar",100+O30,"") -> 100.0007 | P29: =IF(P28="Montar",200+P30,"") -> 200.0008 | Q29: =IF(Q28="Montar",200+Q30,"") -> 200.0016 | R29: =IF(R28="Montar",500+R30,"") | S29: =IF(S28="Montar",1000+S30,"") | T29: =IF(T28="Montar",1000+T30,"") | U29: =IF(U28="Montar",2000+U30,"") -> 2000.011 | V29: =IF(V28="Montar",5000+V30,"") | W29: =IF(W28="Montar",5000+W30,"") | X29: =IF(X28="Montar",10000+X30,"") | Y29: =IF(Y28="Montar",10000+Y30,"") | Z29: =IF(Z28="Montar",(20000+Z30),"") | AA29: =IF(AA28="Montar",(20000+AA30),"") | AB29: =IF(AB28="Montar",20000+AB30,"") | AC29: =IF(AC28="Montar",20000+AC30,"") | AD29: =IF(AD28="Montar",20000+AD30,"") | AE29: =IF(AE28="Montar",20000+AE30,"") | AF29: =IF(AF28="Montar",20000+AF30,"") | AG29: =IF(AG28="Montar",20000+AG30,"") | AH29: =IF(AH28="Montar",20000+AH30,"")
D30: =SUM(G30:AH30) -> 0.0141 | G30: =IF(G28="Montar",PATRÓN!$J$3,"") | H30: =IF(H28="Montar",PATRÓN!$J$4,"") | I30: =IF(I28="Montar",PATRÓN!$J$5,"") | J30: =IF(J28="Montar",PATRÓN!$J$6,"") | K30: =IF(K28="Montar",PATRÓN!$J$7,"") | L30: =IF(L28="Montar",PATRÓN!$J$8,"") | M30: =IF(M28="Montar",PATRÓN!$J$9,"") | N30: =IF(N28="Montar",PATRÓN!$J$10,"") | O30: =IF(O28="Montar",PATRÓN!$J$11,"") -> 0.0007 | P30: =IF(P28="Montar",PATRÓN!$J$12,"") -> 0.0008 | Q30: =IF(Q28="Montar",PATRÓN!$J$13,"") -> 0.0016 | R30: =IF(R28="Montar",PATRÓN!$J$14,"") | S30: =IF(S28="Montar",PATRÓN!$J$15,"") | T30: =IF(T28="Montar",PATRÓN!$J$16,"") | U30: =IF(U28="Montar",PATRÓN!$J$17,"") -> 0.011 | V30: =IF(V28="Montar",PATRÓN!$J$19,"") | W30: =IF(W28="Montar",PATRÓN!$J$20,"") | X30: =IF(X28="Montar",PATRÓN!$J$21,"") | Y30: =IF(Y28="Montar",PATRÓN!$J$22,"") | Z30: =IF(Z28="Montar",PATRÓN!$J$23,"") | AA30: =IF(AA28="Montar",PATRÓN!$J$24,"") | AB30: =IF(AB28="Montar",PATRÓN!$J$25,"") | AC30: =IF(AC28="Montar",PATRÓN!$J$26,"") | AD30: =IF(AD28="Montar",PATRÓN!$J$27,"") | AE30: =IF(AE28="Montar",PATRÓN!$J$28,"") | AF30: =IF(AF28="Montar",PATRÓN!$J$29,"") | AG30: =IF(AG28="Montar",PATRÓN!$J$30,"") | AH30: =IF(AH28="Montar",PATRÓN!$J$31,"")
D31: =SUM(G31:AH31) -> 0.0413 | G31: =IF(G28="Montar",PATRÓN!$M$3,"") | H31: =IF(H28="Montar",PATRÓN!$M$4,"") | I31: =IF(I28="Montar",PATRÓN!$M$5,"") | J31: =IF(J28="Montar",PATRÓN!$M$6,"") | K31: =IF(K28="Montar",PATRÓN!$M$7,"") | L31: =IF(L28="Montar",PATRÓN!$M$8,"") | M31: =IF(M28="Montar",PATRÓN!$M$9,"") | N31: =IF(N28="Montar",PATRÓN!$M$10,"") | O31: =IF(O28="Montar",PATRÓN!$M$11,"") -> 0.0017 | P31: =IF(P28="Montar",PATRÓN!$M$12,"") -> 0.0033 | Q31: =IF(Q28="Montar",PATRÓN!$M$13,"") -> 0.0033 | R31: =IF(R28="Montar",PATRÓN!$M$14,"") | S31: =IF(S28="Montar",PATRÓN!$M$15,"") | T31: =IF(T28="Montar",PATRÓN!$M$16,"") | U31: =IF(U28="Montar",PATRÓN!$M$17,"") -> 0.033 | V31: =IF(V28="Montar",PATRÓN!$M$19,"") | W31: =IF(W28="Montar",PATRÓN!$M$20,"") | X31: =IF(X28="Montar",PATRÓN!$M$21,"") | Y31: =IF(Y28="Montar",PATRÓN!$M$22,"") | Z31: =IF(Z28="Montar",PATRÓN!$M$23,"") | AA31: =IF(AA28="Montar",PATRÓN!$M$24,"") | AB31: =IF(AB28="Montar",PATRÓN!$M$25,"") | AC31: =IF(AC28="Montar",PATRÓN!$M$26,"") | AD31: =IF(AD28="Montar",PATRÓN!$M$27,"") | AE31: =IF(AE28="Montar",PATRÓN!$M$28,"") | AF31: =IF(AF28="Montar",PATRÓN!$M$29,"") | AG31: =IF(AG28="Montar",PATRÓN!$M$30,"") | AH31: =IF(AH28="Montar",PATRÓN!$M$31,"")
D32: =SUM(G32:AH32) -> 0.125 | G32: =IF(G28="Montar",PATRÓN!$K$3,"") | H32: =IF(H28="Montar",PATRÓN!$K$4,"") | I32: =IF(I28="Montar",PATRÓN!$K$5,"") | J32: =IF(J28="Montar",PATRÓN!$K$6,"") | K32: =IF(K28="Montar",PATRÓN!$K$7,"") | L32: =IF(L28="Montar",PATRÓN!$K$8,"") | M32: =IF(M28="Montar",PATRÓN!$K$9,"") | N32: =IF(N28="Montar",PATRÓN!$K$10,"") | O32: =IF(O28="Montar",PATRÓN!$K$11,"") -> 0.005 | P32: =IF(P28="Montar",PATRÓN!$K$12,"") -> 0.01 | Q32: =IF(Q28="Montar",PATRÓN!$K$13,"") -> 0.01 | R32: =IF(R28="Montar",PATRÓN!$K$14,"") | S32: =IF(S28="Montar",PATRÓN!$K$15,"") | T32: =IF(T28="Montar",PATRÓN!$K$16,"") | U32: =IF(U28="Montar",PATRÓN!$K$17,"") -> 0.1 | V32: =IF(V28="Montar",PATRÓN!$K$19,"") | W32: =IF(W28="Montar",PATRÓN!$K$20,"") | X32: =IF(X28="Montar",PATRÓN!$K$21,"") | Y32: =IF(Y28="Montar",PATRÓN!$K$22,"") | Z32: =IF(Z28="Montar",PATRÓN!$K$23,"") | AA32: =IF(AA28="Montar",PATRÓN!$K$24,"") | AB32: =IF(AB28="Montar",PATRÓN!$K$25,"") | AC32: =IF(AC28="Montar",PATRÓN!$K$26,"") | AD32: =IF(AD28="Montar",PATRÓN!$K$27,"") | AE32: =IF(AE28="Montar",PATRÓN!$K$28,"") | AF32: =IF(AF28="Montar",PATRÓN!$K$29,"") | AG32: =IF(AG28="Montar",PATRÓN!$K$30,"") | AH32: =IF(AH28="Montar",PATRÓN!$K$31,"")
G33: -------- | H33: -------- | I33: -------- | J33: -------- | K33: -------- | L33: -------- | M33: -------- | N33: -------- | O33: Montar | P33: Montar | Q33: Montar | R33: Montar | S33: Montar | T33: Montar | U33: Montar | V33: -------- | W33: -------- | X33: -------- | Y33: -------- | Z33: -------- | AA33: -------- | AB33: -------- | AC33: -------- | AD33: -------- | AE33: -------- | AF33: -------- | AG33: -------- | AH33: --------
B34: =S11 -> 5000 | D34: =SUM(G34:AH34) -> 5000.033 | G34: =IF(G33="Montar",1+G35,"") | H34: =IF(H33="Montar",2+H35,"") | I34: =IF(I33="Montar",2+I35,"") | J34: =IF(J33="Montar",5+J35,"") | K34: =IF(K33="Montar",10+K35,"") | L34: =IF(L33="Montar",20+L35,"") | M34: =IF(M33="Montar",20+M35,"") | N34: =IF(N33="Montar",50+N35,"") | O34: =IF(O33="Montar",100+O35,"") -> 100.0007 | P34: =IF(P33="Montar",200+P35,"") -> 200.0008 | Q34: =IF(Q33="Montar",200+Q35,"") -> 200.0016 | R34: =IF(R33="Montar",500+R35,"") -> 500.0029 | S34: =IF(S33="Montar",1000+S35,"") -> 1000.008 | T34: =IF(T33="Montar",1000+T35,"") -> 1000.008 | U34: =IF(U33="Montar",2000+U35,"") -> 2000.011 | V34: =IF(V33="Montar",5000+V35,"") | W34: =IF(W33="Montar",5000+W35,"") | X34: =IF(X33="Montar",10000+X35,"") | Y34: =IF(Y33="Montar",10000+Y35,"") | Z34: =IF(Z33="Montar",(20000+Z35),"") | AA34: =IF(AA33="Montar",(20000+AA35),"") | AB34: =IF(AB33="Montar",20000+AB35,"") | AC34: =IF(AC33="Montar",20000+AC35,"") | AD34: =IF(AD33="Montar",20000+AD35,"") | AE34: =IF(AE33="Montar",20000+AE35,"") | AF34: =IF(AF33="Montar",20000+AF35,"") | AG34: =IF(AG33="Montar",20000+AG35,"") | AH34: =IF(AH33="Montar",20000+AH35,"")
D35: =SUM(G35:AH35) -> 0.033 | G35: =IF(G33="Montar",PATRÓN!$J$3,"") | H35: =IF(H33="Montar",PATRÓN!$J$4,"") | I35: =IF(I33="Montar",PATRÓN!$J$5,"") | J35: =IF(J33="Montar",PATRÓN!$J$6,"") | K35: =IF(K33="Montar",PATRÓN!$J$7,"") | L35: =IF(L33="Montar",PATRÓN!$J$8,"") | M35: =IF(M33="Montar",PATRÓN!$J$9,"") | N35: =IF(N33="Montar",PATRÓN!$J$10,"") | O35: =IF(O33="Montar",PATRÓN!$J$11,"") -> 0.0007 | P35: =IF(P33="Montar",PATRÓN!$J$12,"") -> 0.0008 | Q35: =IF(Q33="Montar",PATRÓN!$J$13,"") -> 0.0016 | R35: =IF(R33="Montar",PATRÓN!$J$14,"") -> 0.0029 | S35: =IF(S33="Montar",PATRÓN!$J$15,"") -> 0.008 | T35: =IF(T33="Montar",PATRÓN!$J$16,"") -> 0.008 | U35: =IF(U33="Montar",PATRÓN!$J$17,"") -> 0.011 | V35: =IF(V33="Montar",PATRÓN!$J$19,"") | W35: =IF(W33="Montar",PATRÓN!$J$20,"") | X35: =IF(X33="Montar",PATRÓN!$J$21,"") | Y35: =IF(Y33="Montar",PATRÓN!$J$22,"") | Z35: =IF(Z33="Montar",PATRÓN!$J$23,"") | AA35: =IF(AA33="Montar",PATRÓN!$J$24,"") | AB35: =IF(AB33="Montar",PATRÓN!$J$25,"") | AC35: =IF(AC33="Montar",PATRÓN!$J$26,"") | AD35: =IF(AD33="Montar",PATRÓN!$J$27,"") | AE35: =IF(AE33="Montar",PATRÓN!$J$28,"") | AF35: =IF(AF33="Montar",PATRÓN!$J$29,"") | AG35: =IF(AG33="Montar",PATRÓN!$J$30,"") | AH35: =IF(AH33="Montar",PATRÓN!$J$31,"")
D36: =SUM(G36:AH36) -> 0.0996 | G36: =IF(G33="Montar",PATRÓN!$M$3,"") | H36: =IF(H33="Montar",PATRÓN!$M$4,"") | I36: =IF(I33="Montar",PATRÓN!$M$5,"") | J36: =IF(J33="Montar",PATRÓN!$M$6,"") | K36: =IF(K33="Montar",PATRÓN!$M$7,"") | L36: =IF(L33="Montar",PATRÓN!$M$8,"") | M36: =IF(M33="Montar",PATRÓN!$M$9,"") | N36: =IF(N33="Montar",PATRÓN!$M$10,"") | O36: =IF(O33="Montar",PATRÓN!$M$11,"") -> 0.0017 | P36: =IF(P33="Montar",PATRÓN!$M$12,"") -> 0.0033 | Q36: =IF(Q33="Montar",PATRÓN!$M$13,"") -> 0.0033 | R36: =IF(R33="Montar",PATRÓN!$M$14,"") -> 0.0083 | S36: =IF(S33="Montar",PATRÓN!$M$15,"") -> 0.017 | T36: =IF(T33="Montar",PATRÓN!$M$16,"") -> 0.033 | U36: =IF(U33="Montar",PATRÓN!$M$17,"") -> 0.033 | V36: =IF(V33="Montar",PATRÓN!$M$19,"") | W36: =IF(W33="Montar",PATRÓN!$M$20,"") | X36: =IF(X33="Montar",PATRÓN!$M$21,"") | Y36: =IF(Y33="Montar",PATRÓN!$M$22,"") | Z36: =IF(Z33="Montar",PATRÓN!$M$23,"") | AA36: =IF(AA33="Montar",PATRÓN!$M$24,"") | AB36: =IF(AB33="Montar",PATRÓN!$M$25,"") | AC36: =IF(AC33="Montar",PATRÓN!$M$26,"") | AD36: =IF(AD33="Montar",PATRÓN!$M$27,"") | AE36: =IF(AE33="Montar",PATRÓN!$M$28,"") | AF36: =IF(AF33="Montar",PATRÓN!$M$29,"") | AG36: =IF(AG33="Montar",PATRÓN!$M$30,"") | AH36: =IF(AH33="Montar",PATRÓN!$M$31,"")
D37: =SUM(G37:AH37) -> 0.3 | G37: =IF(G33="Montar",PATRÓN!$K$3,"") | H37: =IF(H33="Montar",PATRÓN!$K$4,"") | I37: =IF(I33="Montar",PATRÓN!$K$5,"") | J37: =IF(J33="Montar",PATRÓN!$K$6,"") | K37: =IF(K33="Montar",PATRÓN!$K$7,"") | L37: =IF(L33="Montar",PATRÓN!$K$8,"") | M37: =IF(M33="Montar",PATRÓN!$K$9,"") | N37: =IF(N33="Montar",PATRÓN!$K$10,"") | O37: =IF(O33="Montar",PATRÓN!$K$11,"") -> 0.005 | P37: =IF(P33="Montar",PATRÓN!$K$12,"") -> 0.01 | Q37: =IF(Q33="Montar",PATRÓN!$K$13,"") -> 0.01 | R37: =IF(R33="Montar",PATRÓN!$K$14,"") -> 0.025 | S37: =IF(S33="Montar",PATRÓN!$K$15,"") -> 0.05 | T37: =IF(T33="Montar",PATRÓN!$K$16,"") -> 0.1 | U37: =IF(U33="Montar",PATRÓN!$K$17,"") -> 0.1 | V37: =IF(V33="Montar",PATRÓN!$K$19,"") | W37: =IF(W33="Montar",PATRÓN!$K$20,"") | X37: =IF(X33="Montar",PATRÓN!$K$21,"") | Y37: =IF(Y33="Montar",PATRÓN!$K$22,"") | Z37: =IF(Z33="Montar",PATRÓN!$K$23,"") | AA37: =IF(AA33="Montar",PATRÓN!$K$24,"") | AB37: =IF(AB33="Montar",PATRÓN!$K$25,"") | AC37: =IF(AC33="Montar",PATRÓN!$K$26,"") | AD37: =IF(AD33="Montar",PATRÓN!$K$27,"") | AE37: =IF(AE33="Montar",PATRÓN!$K$28,"") | AF37: =IF(AF33="Montar",PATRÓN!$K$29,"") | AG37: =IF(AG33="Montar",PATRÓN!$K$30,"") | AH37: =IF(AH33="Montar",PATRÓN!$K$31,"")
G38: -------- | H38: -------- | I38: -------- | J38: -------- | K38: -------- | L38: -------- | M38: -------- | N38: -------- | O38: -------- | P38: -------- | Q38: -------- | R38: Montar | T38: Montar | U38: Montar | V38: Montar | W38: -------- | AE38: -------- | AF38: -------- | AG38: -------- | AH38: --------
B39: =S12 -> 7500 | D39: =SUM(G39:AH39) -> 7500.0879 | G39: =IF(G38="Montar",1+G40,"") | H39: =IF(H38="Montar",2+H40,"") | I39: =IF(I38="Montar",2+I40,"") | J39: =IF(J38="Montar",5+J40,"") | K39: =IF(K38="Montar",10+K40,"") | L39: =IF(L38="Montar",20+L40,"") | M39: =IF(M38="Montar",20+M40,"") | N39: =IF(N38="Montar",50+N40,"") | O39: =IF(O38="Montar",100+O40,"") | P39: =IF(P38="Montar",200+P40,"") | Q39: =IF(Q38="Montar",200+Q40,"") | R39: =IF(R38="Montar",500+R40,"") -> 500.0029 | S39: =IF(S38="Montar",1000+S40,"") | T39: =IF(T38="Montar",1000+T40,"") -> 1000.008 | U39: =IF(U38="Montar",1000+U40,"") -> 1000.008 | V39: =IF(V38="Montar",5000+V40,"") -> 5000.069 | W39: =IF(W38="Montar",5000+W40,"") | X39: =IF(X38="Montar",10000+X40,"") | Y39: =IF(Y38="Montar",10000+Y40,"") | Z39: =IF(Z38="Montar",(20000+Z40),"") | AA39: =IF(AA38="Montar",(20000+AA40),"") | AB39: =IF(AB38="Montar",20000+AB40,"") | AC39: =IF(AC38="Montar",20000+AC40,"") | AD39: =IF(AD38="Montar",20000+AD40,"") | AE39: =IF(AE38="Montar",20000+AE40,"") | AF39: =IF(AF38="Montar",20000+AF40,"") | AG39: =IF(AG38="Montar",20000+AG40,"") | AH39: =IF(AH38="Montar",20000+AH40,"")
D40: =SUM(G40:AH40) -> 0.0879 | G40: =IF(G38="Montar",PATRÓN!$J$3,"") | H40: =IF(H38="Montar",PATRÓN!$J$4,"") | I40: =IF(I38="Montar",PATRÓN!$J$5,"") | J40: =IF(J38="Montar",PATRÓN!$J$6,"") | K40: =IF(K38="Montar",PATRÓN!$J$7,"") | L40: =IF(L38="Montar",PATRÓN!$J$8,"") | M40: =IF(M38="Montar",PATRÓN!$J$9,"") | N40: =IF(N38="Montar",PATRÓN!$J$10,"") | O40: =IF(O38="Montar",PATRÓN!$J$11,"") | P40: =IF(P38="Montar",PATRÓN!$J$12,"") | Q40: =IF(Q38="Montar",PATRÓN!$J$13,"") | R40: =IF(R38="Montar",PATRÓN!$J$14,"") -> 0.0029 | S40: =IF(S38="Montar",PATRÓN!$J$15,"") | T40: =IF(T38="Montar",PATRÓN!$J$16,"") -> 0.008 | U40: =IF(U38="Montar",PATRÓN!$J$16,"") -> 0.008 | V40: =IF(V38="Montar",PATRÓN!$J$19,"") -> 0.069 | W40: =IF(W38="Montar",PATRÓN!$J$20,"") | X40: =IF(X38="Montar",PATRÓN!$J$21,"") | Y40: =IF(Y38="Montar",PATRÓN!$J$22,"") | Z40: =IF(Z38="Montar",PATRÓN!$J$23,"") | AA40: =IF(AA38="Montar",PATRÓN!$J$24,"") | AB40: =IF(AB38="Montar",PATRÓN!$J$25,"") | AC40: =IF(AC38="Montar",PATRÓN!$J$26,"") | AD40: =IF(AD38="Montar",PATRÓN!$J$27,"") | AE40: =IF(AE38="Montar",PATRÓN!$J$28,"") | AF40: =IF(AF38="Montar",PATRÓN!$J$29,"") | AG40: =IF(AG38="Montar",PATRÓN!$J$30,"") | AH40: =IF(AH38="Montar",PATRÓN!$J$31,"")
D41: =SUM(G41:AH41) -> 0.1573 | G41: =IF(G38="Montar",PATRÓN!$M$3,"") | H41: =IF(H38="Montar",PATRÓN!$M$4,"") | I41: =IF(I38="Montar",PATRÓN!$M$5,"") | J41: =IF(J38="Montar",PATRÓN!$M$6,"") | K41: =IF(K38="Montar",PATRÓN!$M$7,"") | L41: =IF(L38="Montar",PATRÓN!$M$8,"") | M41: =IF(M38="Montar",PATRÓN!$M$9,"") | N41: =IF(N38="Montar",PATRÓN!$M$10,"") | O41: =IF(O38="Montar",PATRÓN!$M$11,"") | P41: =IF(P38="Montar",PATRÓN!$M$12,"") | Q41: =IF(Q38="Montar",PATRÓN!$M$13,"") | R41: =IF(R38="Montar",PATRÓN!$M$14,"") -> 0.0083 | S41: =IF(S38="Montar",PATRÓN!$M$15,"") | T41: =IF(T38="Montar",PATRÓN!$M$16,"") -> 0.033 | U41: =IF(U38="Montar",PATRÓN!$M$16,"") -> 0.033 | V41: =IF(V38="Montar",PATRÓN!$M$19,"") -> 0.083 | W41: =IF(W38="Montar",PATRÓN!$M$20,"") | X41: =IF(X38="Montar",PATRÓN!$M$21,"") | Y41: =IF(Y38="Montar",PATRÓN!$M$22,"") | Z41: =IF(Z38="Montar",PATRÓN!$M$23,"") | AA41: =IF(AA38="Montar",PATRÓN!$M$24,"") | AB41: =IF(AB38="Montar",PATRÓN!$M$25,"") | AC41: =IF(AC38="Montar",PATRÓN!$M$26,"") | AD41: =IF(AD38="Montar",PATRÓN!$M$27,"") | AE41: =IF(AE38="Montar",PATRÓN!$M$28,"") | AF41: =IF(AF38="Montar",PATRÓN!$M$29,"") | AG41: =IF(AG38="Montar",PATRÓN!$M$30,"") | AH41: =IF(AH38="Montar",PATRÓN!$M$31,"")
D42: =SUM(G42:AH42) -> 0.475 | G42: =IF(G38="Montar",PATRÓN!$K$3,"") | H42: =IF(H38="Montar",PATRÓN!$K$4,"") | I42: =IF(I38="Montar",PATRÓN!$K$5,"") | J42: =IF(J38="Montar",PATRÓN!$K$6,"") | K42: =IF(K38="Montar",PATRÓN!$K$7,"") | L42: =IF(L38="Montar",PATRÓN!$K$8,"") | M42: =IF(M38="Montar",PATRÓN!$K$9,"") | N42: =IF(N38="Montar",PATRÓN!$K$10,"") | O42: =IF(O38="Montar",PATRÓN!$K$11,"") | P42: =IF(P38="Montar",PATRÓN!$K$12,"") | Q42: =IF(Q38="Montar",PATRÓN!$K$13,"") | R42: =IF(R38="Montar",PATRÓN!$K$14,"") -> 0.025 | S42: =IF(S38="Montar",PATRÓN!$K$15,"") | T42: =IF(T38="Montar",PATRÓN!$K$16,"") -> 0.1 | U42: =IF(U38="Montar",PATRÓN!$K$16,"") -> 0.1 | V42: =IF(V38="Montar",PATRÓN!$K$19,"") -> 0.25 | W42: =IF(W38="Montar",PATRÓN!$K$20,"") | X42: =IF(X38="Montar",PATRÓN!$K$21,"") | Y42: =IF(Y38="Montar",PATRÓN!$K$22,"") | Z42: =IF(Z38="Montar",PATRÓN!$K$23,"") | AA42: =IF(AA38="Montar",PATRÓN!$K$24,"") | AB42: =IF(AB38="Montar",PATRÓN!$K$25,"") | AC42: =IF(AC38="Montar",PATRÓN!$K$26,"") | AD42: =IF(AD38="Montar",PATRÓN!$K$27,"") | AE42: =IF(AE38="Montar",PATRÓN!$K$28,"") | AF42: =IF(AF38="Montar",PATRÓN!$K$29,"") | AG42: =IF(AG38="Montar",PATRÓN!$K$30,"") | AH42: =IF(AH38="Montar",PATRÓN!$K$31,"")
G43: -------- | H43: -------- | I43: -------- | J43: -------- | K43: -------- | L43: -------- | M43: -------- | N43: -------- | O43: -------- | P43: -------- | Q43: -------- | R43: -------- | S43: -------- | T43: -------- | U43: -------- | V43: Montar | W43: Montar | Y43: -------- | Z43: -------- | AA43: -------- | AB43: -------- | AC43: -------- | AD43: -------- | AE43: -------- | AF43: -------- | AG43: -------- | AH43: --------
B44: =S13 -> 10000 | D44: =SUM(G44:AH44) -> 10000.165 | G44: =IF(G43="Montar",1+G45,"") | H44: =IF(H43="Montar",2+H45,"") | I44: =IF(I43="Montar",2+I45,"") | J44: =IF(J43="Montar",5+J45,"") | K44: =IF(K43="Montar",10+K45,"") | L44: =IF(L43="Montar",20+L45,"") | M44: =IF(M43="Montar",20+M45,"") | N44: =IF(N43="Montar",50+N45,"") | O44: =IF(O43="Montar",100+O45,"") | P44: =IF(P43="Montar",200+P45,"") | Q44: =IF(Q43="Montar",200+Q45,"") | R44: =IF(R43="Montar",500+R45,"") | S44: =IF(S43="Montar",1000+S45,"") | T44: =IF(T43="Montar",1000+T45,"") | U44: =IF(U43="Montar",2000+U45,"") | V44: =IF(V43="Montar",5000+V45,"") -> 5000.069 | W44: =IF(W43="Montar",5000+W45,"") -> 5000.096 | X44: =IF(X43="Montar",10000+X45,"") | Y44: =IF(Y43="Montar",10000+Y45,"") | Z44: =IF(Z43="Montar",(20000+Z45),"") | AA44: =IF(AA43="Montar",(20000+AA45),"") | AB44: =IF(AB43="Montar",20000+AB45,"") | AC44: =IF(AC43="Montar",20000+AC45,"") | AD44: =IF(AD43="Montar",20000+AD45,"") | AE44: =IF(AE43="Montar",20000+AE45,"") | AF44: =IF(AF43="Montar",20000+AF45,"") | AG44: =IF(AG43="Montar",20000+AG45,"") | AH44: =IF(AH43="Montar",20000+AH45,"")
D45: =SUM(G45:AH45) -> 0.165 | G45: =IF(G43="Montar",PATRÓN!$J$3,"") | H45: =IF(H43="Montar",PATRÓN!$J$4,"") | I45: =IF(I43="Montar",PATRÓN!$J$5,"") | J45: =IF(J43="Montar",PATRÓN!$J$6,"") | K45: =IF(K43="Montar",PATRÓN!$J$7,"") | L45: =IF(L43="Montar",PATRÓN!$J$8,"") | M45: =IF(M43="Montar",PATRÓN!$J$9,"") | N45: =IF(N43="Montar",PATRÓN!$J$10,"") | O45: =IF(O43="Montar",PATRÓN!$J$11,"") | P45: =IF(P43="Montar",PATRÓN!$J$12,"") | Q45: =IF(Q43="Montar",PATRÓN!$J$13,"") | R45: =IF(R43="Montar",PATRÓN!$J$14,"") | S45: =IF(S43="Montar",PATRÓN!$J$15,"") | T45: =IF(T43="Montar",PATRÓN!$J$16,"") | U45: =IF(U43="Montar",PATRÓN!$J$17,"") | V45: =IF(V43="Montar",PATRÓN!$J$19,"") -> 0.069 | W45: =IF(W43="Montar",PATRÓN!$J$20,"") -> 0.096 | X45: =IF(X43="Montar",PATRÓN!$J$21,"") | Y45: =IF(Y43="Montar",PATRÓN!$J$22,"") | Z45: =IF(Z43="Montar",PATRÓN!$J$23,"") | AA45: =IF(AA43="Montar",PATRÓN!$J$24,"") | AB45: =IF(AB43="Montar",PATRÓN!$J$25,"") | AC45: =IF(AC43="Montar",PATRÓN!$J$26,"") | AD45: =IF(AD43="Montar",PATRÓN!$J$27,"") | AE45: =IF(AE43="Montar",PATRÓN!$J$28,"") | AF45: =IF(AF43="Montar",PATRÓN!$J$29,"") | AG45: =IF(AG43="Montar",PATRÓN!$J$30,"") | AH45: =IF(AH43="Montar",PATRÓN!$J$31,"")
D46: =SUM(G46:AH46) -> 0.166 | G46: =IF(G43="Montar",PATRÓN!$M$3,"") | H46: =IF(H43="Montar",PATRÓN!$M$4,"") | I46: =IF(I43="Montar",PATRÓN!$M$5,"") | J46: =IF(J43="Montar",PATRÓN!$M$6,"") | K46: =IF(K43="Montar",PATRÓN!$M$7,"") | L46: =IF(L43="Montar",PATRÓN!$M$8,"") | M46: =IF(M43="Montar",PATRÓN!$M$9,"") | N46: =IF(N43="Montar",PATRÓN!$M$10,"") | O46: =IF(O43="Montar",PATRÓN!$M$11,"") | P46: =IF(P43="Montar",PATRÓN!$M$12,"") | Q46: =IF(Q43="Montar",PATRÓN!$M$13,"") | R46: =IF(R43="Montar",PATRÓN!$M$14,"") | S46: =IF(S43="Montar",PATRÓN!$M$15,"") | T46: =IF(T43="Montar",PATRÓN!$M$16,"") | U46: =IF(U43="Montar",PATRÓN!$M$17,"") | V46: =IF(V43="Montar",PATRÓN!$M$19,"") -> 0.083 | W46: =IF(W43="Montar",PATRÓN!$M$20,"") -> 0.083 | X46: =IF(X43="Montar",PATRÓN!$M$21,"") | Y46: =IF(Y43="Montar",PATRÓN!$M$22,"") | Z46: =IF(Z43="Montar",PATRÓN!$M$23,"") | AA46: =IF(AA43="Montar",PATRÓN!$M$24,"") | AB46: =IF(AB43="Montar",PATRÓN!$M$25,"") | AC46: =IF(AC43="Montar",PATRÓN!$M$26,"") | AD46: =IF(AD43="Montar",PATRÓN!$M$27,"") | AE46: =IF(AE43="Montar",PATRÓN!$M$28,"") | AF46: =IF(AF43="Montar",PATRÓN!$M$29,"") | AG46: =IF(AG43="Montar",PATRÓN!$M$30,"") | AH46: =IF(AH43="Montar",PATRÓN!$M$31,"")
D47: =SUM(G47:AH47) -> 0.5 | G47: =IF(G43="Montar",PATRÓN!$K$3,"") | H47: =IF(H43="Montar",PATRÓN!$K$4,"") | I47: =IF(I43="Montar",PATRÓN!$K$5,"") | J47: =IF(J43="Montar",PATRÓN!$K$6,"") | K47: =IF(K43="Montar",PATRÓN!$K$7,"") | L47: =IF(L43="Montar",PATRÓN!$K$8,"") | M47: =IF(M43="Montar",PATRÓN!$K$9,"") | N47: =IF(N43="Montar",PATRÓN!$K$10,"") | O47: =IF(O43="Montar",PATRÓN!$K$11,"") | P47: =IF(P43="Montar",PATRÓN!$K$12,"") | Q47: =IF(Q43="Montar",PATRÓN!$K$13,"") | R47: =IF(R43="Montar",PATRÓN!$K$14,"") | S47: =IF(S43="Montar",PATRÓN!$K$15,"") | T47: =IF(T43="Montar",PATRÓN!$K$16,"") | U47: =IF(U43="Montar",PATRÓN!$K$17,"") | V47: =IF(V43="Montar",PATRÓN!$K$19,"") -> 0.25 | W47: =IF(W43="Montar",PATRÓN!$K$20,"") -> 0.25 | X47: =IF(X43="Montar",PATRÓN!$K$21,"") | Y47: =IF(Y43="Montar",PATRÓN!$K$22,"") | Z47: =IF(Z43="Montar",PATRÓN!$K$23,"") | AA47: =IF(AA43="Montar",PATRÓN!$K$24,"") | AB47: =IF(AB43="Montar",PATRÓN!$K$25,"") | AC47: =IF(AC43="Montar",PATRÓN!$K$26,"") | AD47: =IF(AD43="Montar",PATRÓN!$K$27,"") | AE47: =IF(AE43="Montar",PATRÓN!$K$28,"") | AF47: =IF(AF43="Montar",PATRÓN!$K$29,"") | AG47: =IF(AG43="Montar",PATRÓN!$K$30,"") | AH47: =IF(AH43="Montar",PATRÓN!$K$31,"")
...

Sheet PATRÓN
C2: PLACA | D2: EQUIPO | E2: MARCA | F2: MODELO | G2: SERIE | H2: FECHA CALIBRACIÓN | I2: CERTIFICADO | J2: ERROR (g) | K2: EMP (g) | L2: CLASE | M2: INCERT(g)
D3: MASA 1 g | E3: YANTAI JIA JIA | F3: CILÍNDRICAS | G3: 1 | H3: 44257 | I3: CAP-184-21 | J3: =0.07/1000 -> 7e-05 | K3: =1/1000 -> 0.001 | L3: M1 | M3: =0.33/1000 -> 0.00033
D4: MASA 2 g | E4: YANTAI JIA JIA | F4: CILÍNDRICAS | G4: 2 | H4: 44257 | I4: CAP-184-21 | J4: =0.05/1000 -> 5e-05 | K4: =1.2/1000 -> 0.0012 | L4: M1 | M4: =0.4/1000 -> 0.0004
D5: MASA 2 g punto | E5: YANTAI JIA JIA | F5: CILÍNDRICAS | G5: 2 PUNTO | H5: 44257 | I5: CAP-184-21 | J5: =0.06/1000 -> 6e-05 | K5: =1.2/1000 -> 0.0012 | L5: M1 | M5: =0.4/1000 -> 0.0004
D6: MASA 5 g | E6: YANTAI JIA JIA | F6: CILÍNDRICAS | G6: 5 | H6: 44257 | I6: CAP-184-21 | J6: =0.08/1000 -> 8e-05 | K6: =1.6/1000 -> 0.0016 | L6: M1 | M6: =0.53/1000 -> 0.00053
D7: MASA 10 g | E7: YANTAI JIA JIA | F7: CILÍNDRICAS | G7: 10 | H7: 44257 | I7: CAP-184-21 | J7: =0.12/1000 -> 0.00012 | K7: =2/1000 -> 0.002 | L7: M1 | M7: =0.67/1000 -> 0.00067
D8: MASA 20 g | E8: YANTAI JIA JIA | F8: CILÍNDRICAS | G8: 20 | H8: 44257 | I8: CAP-184-21 | J8: =0.13/1000 -> 0.00013 | K8: =2.5/1000 -> 0.0025 | L8: M1 | M8: =0.83/1000 -> 0.00083
D9: MASA 20 g punto | E9: YANTAI JIA JIA | F9: CILÍNDRICAS | G9: 20 PUNTO | H9: 44257 | I9: CAP-184-21 | J9: =0.13/1000 -> 0.00013 | K9: =2.5/1000 -> 0.0025 | L9: M1 | M9: =0.83/1000 -> 0.00083
D10: MASA 50 g | E10: YANTAI JIA JIA | F10: CILÍNDRICAS | G10: 50 | H10: 44257 | I10: CAP-184-21 | J10: =0.7/1000 -> 0.0007 | K10: =3/1000 -> 0.003 | L10: M1 | M10: =1/1000 -> 0.001
D11: MASA 100 g | E11: YANTAI JIA JIA | F11: CILÍNDRICAS | G11: 100 | H11: 44257 | I11: CAP-184-21 | J11: =0.7/1000 -> 0.0007 | K11: =5/1000 -> 0.005 | L11: M1 | M11: =1.7/1000 -> 0.0017
D12: MASA 200 g | E12: YANTAI JIA JIA | F12: CILÍNDRICAS | G12: 200 | H12: 44257 | I12: CAP-184-21 | J12: =0.8/1000 -> 0.0008 | K12: =10/1000 -> 0.01 | L12: M1 | M12: =3.3/1000 -> 0.0033
D13: MASA 200 g punto | E13: YANTAI JIA JIA | F13: CILÍNDRICAS | G13: 200 PUNTO | H13: 44257 | I13: CAP-184-21 | J13: =1.6/1000 -> 0.0016 | K13: =10/1000 -> 0.01 | L13: M1 | M13: =3.3/1000 -> 0.0033
D14: MASA 500 g | E14: YANTAI JIA JIA | F14: CILÍNDRICAS | G14: 500 | H14: 44257 | I14: CAP-184-21 | J14: =2.9/1000 -> 0.0029 | K14: =25/1000 -> 0.025 | L14: M1 | M14: =8.3/1000 -> 0.0083
D15: MASA 1000 g | E15: YANTAI JIA JIA | F15: CILÍNDRICAS | G15: 1 | H15: 44257 | I15: CAP-184-21 | J15: =8/1000 -> 0.008 | K15: =50/1000 -> 0.05 | L15: M1 | M15: =17/1000 -> 0.017
D16: MASA 2000 g | E16: YANTAI JIA JIA | F16: CILÍNDRICAS | G16: 2 | H16: 44257 | I16: CAP-184-21 | J16: 0.008 | K16: =100/1000 -> 0.1 | L16: M1 | M16: =33/1000 -> 0.033
D17: MASA 2000 g * | E17: YANTAI JIA JIA | F17: CILÍNDRICAS | G17: 2 punto | H17: 44257 | I17: CAP-184-21 | J17: =11/1000 -> 0.011 | K17: =100/1000 -> 0.1 | L17: M1 | M17: =33/1000 -> 0.033
D18: MASA 5000 g | E18: YANTAI JIA JIA | F18: CILÍNDRICAS | G18: 5 | H18: 44257 | I18: CAP-184-21 | J18: =8/1000 -> 0.008 | K18: =250/1000 -> 0.25 | L18: M1 | M18: =83/1000 -> 0.083
A19: Montar | C19: 000065 | D19: MASA PATRÓN 5 kg 001 | E19: CONAMET | F19: PARALELEPIPEDO | G19: 001 | H19: 43987 | I19: CAP-387-20 | J19: 0.069 | K19: 0.25 | L19: M1 | M19: 0.083 | P19: Conformidad | Q19: Si | R19: Buen estado
A20: -------- | C20: 000066 | D20: MASA PATRÓN 5 kg 002 | E20: CONAMET | F20: PARALELEPIPEDO | G20: 002 | H20: 43987 | I20: CAP-386-20 | J20: 0.096 | K20: 0.25 | L20: M1 | M20: 0.083 | Q20: No | R20: Mal estado
C21: 000036 | D21: MASA PATRÓN 10 kg 001D | E21: DETECTO | F21: PARALELEPIPEDO | G21: 001D | H21: 43987 | I21: CAP-385-20 | J21: 0.05 | K21: 0.5 | L21: M1 | M21: 0.17
C22: 000064 | D22: MASA PATRÓN 10 kg 001C | E22: CONAMET | F22: PARALELEPIPEDO | G22: 001C | H22: 43987 | I22: CAP-384-20 | J22: 0.05 | K22: 0.5 | L22: M1 | M22: 0.17
C23: 000033 | D23: MASA PATRÓN 20 kg 001D | E23: DETECTO | F23: PARALELEPIPEDO | G23: 001D | H23: 43987 | I23: CAP-375-20 | J23: 0.21 | K23: 1 | L23: M1 | M23: 0.33
C24: 000034 | D24: MASA PATRÓN 20 kg 002D | E24: DETECTO | F24: PARALELEPIPEDO | G24: 002D | H24: 43987 | I24: CAP-383-20 | J24: 0.09 | K24: 1 | L24: M1 | M24: 0.33
C25: 000035 | D25: MASA PATRÓN 20 kg 003D | E25: DETECTO | F25: PARALELEPIPEDO | G25: 003D | H25: 43987 | I25: CAP-379-20 | J25: 0.09 | K25: 1 | L25: M1 | M25: 0.33
C26: 000063 | D26: MASA PATRÓN 20 kg 006 | E26: CONAMET | F26: PARALELEPIPEDO | G26: 006 | H26: 43987 | I26: CAP-376-20 | J26: 0.27 | K26: 1 | L26: M1 | M26: 0.33
C27: 000062 | D27: MASA PATRÓN 20 kg 005 | E27: CONAMET | F27: PARALELEPIPEDO | G27: 005 | H27: 43987 | I27: CAP-381-20 | J27: 0.03 | K27: 1 | L27: M1 | M27: 0.33
C28: 000061 | D28: MASA PATRÓN 20 kg 004 | E28: CONAMET | F28: PARALELEPIPEDO | G28: 004 | H28: 43987 | I28: CAP-382-20 | J28: 0.08 | K28: 1 | L28: M1 | M28: 0.33
C29: 000060 | D29: MASA PATRÓN 20 kg 003C | E29: CONAMET | F29: PARALELEPIPEDO | G29: 003C | H29: 43987 | I29: CAP-380-20 | J29: 0.15 | K29: 1 | L29: M1 | M29: 0.33
C30: 000058 | D30: MASA PATRÓN 20 kg 001C | E30: CONAMET | F30: PARALELEPIPEDO | G30: 001C | H30: 43987 | I30: CAP-378-20 | J30: 0.21 | K30: 1 | L30: M1 | M30: 0.33
C31: 000059 | D31: MASA PATRÓN 20 kg 002C | E31: CONAMET | F31: PARALELEPIPEDO | G31: 002C | H31: 43987 | I31: CAP-377-20 | J31: 0.25 | K31: 1 | L31: M1 | M31: 0.33
B38: EQUIPO PATRÓN 1
B39: Equipo patrón: | G39: Juego de Masas Cilíndricas
B40: Marca: | G40: Truemass
B41: Modelo: | G41: Cilíndricas
B42: Serie: | G42: No tiene
B43: Fecha de Calibración: | G43: 43990
B44: No. Certificado: | G44: CAP388-20
B45: Factor de cobertura K: | G45: 2
B47: EQUIPO PATRÓN 2
B48: Equipo patrón: | G48: Masa de 5 kg
...

Sheet INCERTIDUMBRE
B3: FUENTES DE INCERTIDUMBRE
B4: Valor Referencia | C4: Promedio | D4: Error | E4: Repetibilidad | F4: Indicación sin carga | G4: Indicación con carga | H4: Excentricidad | I4: Certificado de Calibración | J4: Deriva | K4: Veff | L4: Factor de cobertura (k) | M4: Incertidumbre Combinada | N4: Incertidumbre Expandida
B5: =G24 -> 0 | C5: =I24 -> 0 | D5: =K24 -> 0 | E5: =STDEVA(MEDIDA!E$10:G$14)/SQRT(COUNT(MEDIDA!E$10:G$14)) -> 0 | F5: =5/SQRT(12) -> 1.4433757 | G5: =5/SQRT(12) -> 1.4433757 | H5: =(C$30*B5)/(2*MEDIDA!K$13)*SQRT(3) -> 0 | I5: 0 | J5: 0 | K5: =M5^4/(E5^4/4+F5^4/200+G5^4/200+H5^4/200+I5^4/200+J5^4/200) -> 400 | L5: =TINV(0.0455,K5) -> 2.0062874 | M5: =SQRT(SUMSQ(E5,F5,G5,H5,I5,J5)) -> 2.0412415 | N5: =M5*L5 -> 4.095317
B6: =G25 -> 2500.0141 | C6: =I25 -> 2300 | D6: =K25 -> -200.0141 | E6: =STDEVA(MEDIDA!E$10:G$14)/SQRT(COUNT(MEDIDA!E$10:G$14)) -> 0 | F6: =5/SQRT(12) -> 1.4433757 | G6: =5/SQRT(12) -> 1.4433757 | H6: =(C$30*B6)/(2*MEDIDA!K$13)*SQRT(3) -> 0 | I6: =MEDIDA!D31/2 -> 0.02065 | J6: =MEDIDA!D32/SQRT(3) -> 0.072168784 | K6: =M6^4/(E6^4/4+F6^4/200+G6^4/200+H6^4/200+I6^4/200+J6^4/200) -> 401.08134 | L6: =TINV(0.0455,K6) -> 2.006256 | M6: =SQRT(SUMSQ(E6,F6,G6,H6,I6,J6)) -> 2.0426212 | N6: =M6*L6 -> 4.098021
B7: =G26 -> 5000.033 | C7: =I26 -> 4600 | D7: =K26 -> -400.033 | E7: =STDEVA(MEDIDA!E$10:G$14)/SQRT(COUNT(MEDIDA!E$10:G$14)) -> 0 | F7: =5/SQRT(12) -> 1.4433757 | G7: =5/SQRT(12) -> 1.4433757 | H7: =(C$30*B7)/(2*MEDIDA!K$13)*SQRT(3) -> 0 | I7: =MEDIDA!D36/2 -> 0.0498 | J7: =MEDIDA!D37/SQRT(3) -> 0.17320508 | K7: =M7^4/(E7^4/4+F7^4/200+G7^4/200+H7^4/200+I7^4/200+J7^4/200) -> 406.21807 | L7: =TINV(0.0455,K7) -> 2.0061787 | M7: =SQRT(SUMSQ(E7,F7,G7,H7,I7,J7)) -> 2.049182 | N7: =M7*L7 -> 4.1110252
B8: =G27 -> 7500.0879 | C8: =I27 -> 6900 | D8: =K27 -> -600.0879 | E8: =STDEVA(MEDIDA!E$10:G$14)/SQRT(COUNT(MEDIDA!E$10:G$14)) -> 0 | F8: =5/SQRT(12) -> 1.4433757 | G8: =5/SQRT(12) -> 1.4433757 | H8: =(C$30*B8)/(2*MEDIDA!K$13)*SQRT(3) -> 0 | I8: =MEDIDA!D41/2 -> 0.07865 | J8: =MEDIDA!D42/SQRT(3) -> 0.27424138 | K8: =M8^4/(E8^4/4+F8^4/200+G8^4/200+H8^4/200+I8^4/200+J8^4/200) -> 415.50774 | L8: =TINV(0.0455,K8) -> 2.0060444 | M8: =SQRT(SUMSQ(E8,F8,G8,H8,I8,J8)) -> 2.0610824 | N8: =M8*L8 -> 4.1346228
B9: =G28 -> 10000.165 | C9: =I28 -> 9200 | D9: =K28 -> -800.165 | E9: =STDEVA(MEDIDA!E$10:G$14)/SQRT(COUNT(MEDIDA!E$10:G$14)) -> 0 | F9: =5/SQRT(12) -> 1.4433757 | G9: =5/SQRT(12) -> 1.4433757 | H9: =(C$30*B9)/(2*MEDIDA!K$13)*SQRT(3) -> 0 | I9: =MEDIDA!D46/2 -> 0.083 | J9: =MEDIDA!D47/SQRT(3) -> 0.28867513 | K9: =M9^4/(E9^4/4+F9^4/200+G9^4/200+H9^4/200+I9^4/200+J9^4/200) -> 417.17422 | L9: =TINV(0.0455,K9) -> 2.0060153 | M9: =SQRT(SUMSQ(E9,F9,G9,H9,I9,J9)) -> 2.063223 | N9: =M9*L9 -> 4.1388569
B10: =G29 -> 12500.184 | C10: =I29 -> 11500 | D10: =K29 -> -1000.1841 | E10: =STDEVA(MEDIDA!E$10:G$14)/SQRT(COUNT(MEDIDA!E$10:G$14)) -> 0 | F10: =10/SQRT(12) -> 2.8867513 | G10: =10/SQRT(12) -> 2.8867513 | H10: =(C$30*B10)/(2*MEDIDA!K$13)*SQRT(3) -> 0 | I10: =MEDIDA!D51/2 -> 0.11215 | J10: =MEDIDA!D52/SQRT(3) -> 0.38971143 | K10: =M10^4/(E10^4/4+F10^4/200+G10^4/200+H10^4/200+I10^4/200+J10^4/200) -> 407.86447 | L10: =TINV(0.0455,K10) -> 2.0061635 | M10: =SQRT(SUMSQ(E10,F10,G10,H10,I10,J10)) -> 4.1025747 | N10: =M10*L10 -> 8.2304356
B11: =G30 -> 15000.119 | C11: =I30 -> 13800 | D11: =K30 -> -1200.119 | E11: =STDEVA(MEDIDA!E$10:G$14)/SQRT(COUNT(MEDIDA!E$10:G$14)) -> 0 | F11: =10/SQRT(12) -> 2.8867513 | G11: =10/SQRT(12) -> 2.8867513 | H11: =(C$30*B11)/(2*MEDIDA!K$13)*SQRT(3) -> 0 | I11: =MEDIDA!D56/2 -> 0.1265 | J11: =MEDIDA!D57/SQRT(3) -> 0.4330127 | K11: =M11^4/(E11^4/4+F11^4/200+G11^4/200+H11^4/200+I11^4/200+J11^4/200) -> 409.72328 | L11: =TINV(0.0455,K11) -> 2.0061333 | M11: =SQRT(SUMSQ(E11,F11,G11,H11,I11,J11)) -> 4.1073311 | N11: =M11*L11 -> 8.2398537
B12: =G31 -> 17500.133 | C12: =I31 -> 16100 | D12: =K31 -> -1400.1329 | E12: =STDEVA(MEDIDA!E$10:G$14)/SQRT(COUNT(MEDIDA!E$10:G$14)) -> 0 | F12: =10/SQRT(12) -> 2.8867513 | G12: =10/SQRT(12) -> 2.8867513 | H12: =(C$30*B12)/(2*MEDIDA!K$13)*SQRT(3) -> 0 | I12: =MEDIDA!D61/2 -> 0.14715 | J12: =MEDIDA!D62/SQRT(3) -> 0.50518149 | K12: =M12^4/(E12^4/4+F12^4/200+G12^4/200+H12^4/200+I12^4/200+J12^4/200) -> 413.20456 | L12: =TINV(0.0455,K12) -> 2.0060737 | M12: =SQRT(SUMSQ(E12,F12,G12,H12,I12,J12)) -> 4.1162517 | N12: =M12*L12 -> 8.2575044
B13: =G32 -> 20000.21 | C13: =I32 -> 18400 | D13: =K32 -> -1600.21 | E13: =STDEVA(MEDIDA!E$10:G$14)/SQRT(COUNT(MEDIDA!E$10:G$14)) -> 0 | F13: =10/SQRT(12) -> 2.8867513 | G13: =10/SQRT(12) -> 2.8867513 | H13: =(C$30*B13)/(2*MEDIDA!K$13)*SQRT(3) -> 0 | I13: =MEDIDA!D66/2 -> 0.165 | J13: =MEDIDA!D67/SQRT(3) -> 0.57735027 | K13: =M13^4/(E13^4/4+F13^4/200+G13^4/200+H13^4/200+I13^4/200+J13^4/200) -> 417.15805 | L13: =TINV(0.0455,K13) -> 2.0060153 | M13: =SQRT(SUMSQ(E13,F13,G13,H13,I13,J13)) -> 4.1264058 | N13: =M13*L13 -> 8.2776333
B14: =G33 -> 22500.224 | C14: =I33 -> 20700 | D14: =K33 -> -1800.2239 | E14: =STDEVA(MEDIDA!E$10:G$14)/SQRT(COUNT(MEDIDA!E$10:G$14)) -> 0 | F14: =10/SQRT(12) -> 2.8867513 | G14: =10/SQRT(12) -> 2.8867513 | H14: =(C$30*B14)/(2*MEDIDA!K$13)*SQRT(3) -> 0 | I14: =MEDIDA!D71/2 -> 0.18565 | J14: =MEDIDA!D72/SQRT(3) -> 0.64951905 | K14: =M14^4/(E14^4/4+F14^4/200+G14^4/200+H14^4/200+I14^4/200+J14^4/200) -> 421.6603 | L14: =TINV(0.0455,K14) -> 2.005958 | M14: =SQRT(SUMSQ(E14,F14,G14,H14,I14,J14)) -> 4.1379956 | N14: =M14*L14 -> 8.3006455
B15: =G34 -> 25000.279 | C15: =I34 -> 23000 | D15: =K34 -> -2000.279 | E15: =STDEVA(MEDIDA!E$10:G$14)/SQRT(COUNT(MEDIDA!E$10:G$14)) -> 0 | F15: =10/SQRT(12) -> 2.8867513 | G15: =10/SQRT(12) -> 2.8867513 | H15: =(C$30*B15)/(2*MEDIDA!K$13)*SQRT(3) -> 0 | I15: =MEDIDA!D76/2 -> 0.2065 | J15: =MEDIDA!D77/SQRT(3) -> 0.72168784 | K15: =M15^4/(E15^4/4+F15^4/200+G15^4/200+H15^4/200+I15^4/200+J15^4/200) -> 426.66512 | L15: =TINV(0.0455,K15) -> 2.0058879 | M15: =SQRT(SUMSQ(E15,F15,G15,H15,I15,J15)) -> 4.1509207 | N15: =M15*L15 -> 8.3262816
C23: Excentricidad | G23: Selección | I23: Medición | K23: Error
C24: =ABS(MEDIDA!M14-MEDIDA!M14) -> 0 | G24: =MEDIDA!S9 -> 0 | I24: =MEDIDA!U9 -> 0 | K24: =I24-G24 -> 0
C25: =ABS(MEDIDA!M$14-MEDIDA!M15) -> 0 | G25: =MEDIDA!D29 -> 2500.0141 | I25: =MEDIDA!U10 -> 2300 | K25: =I25-G25 -> -200.0141
C26: =ABS(MEDIDA!M$14-MEDIDA!M16) -> 0 | G26: =MEDIDA!D34 -> 5000.033 | I26: =MEDIDA!U11 -> 4600 | K26: =I26-G26 -> -400.033
C27: =ABS(MEDIDA!M$14-MEDIDA!M17) -> 0 | G27: =MEDIDA!D39 -> 7500.0879 | I27: =MEDIDA!U12 -> 6900 | K27: =I27-G27 -> -600.0879
C28: =ABS(MEDIDA!M$14-MEDIDA!M18) -> 0 | G28: =MEDIDA!D44 -> 10000.165 | I28: =MEDIDA!U13 -> 9200 | K28: =I28-G28 -> -800.165
G29: =MEDIDA!D49 -> 12500.184 | I29: =MEDIDA!U14 -> 11500 | K29: =I29-G29 -> -1000.1841
C30: =MAX(C24:C28) -> 0 | G30: =MEDIDA!D54 -> 15000.119 | I30: =MEDIDA!U15 -> 13800 | K30: =I30-G30 -> -1200.119
G31: =MEDIDA!D59 -> 17500.133 | I31: =MEDIDA!U16 -> 16100 | K31: =I31-G31 -> -1400.1329
G32: =MEDIDA!D64 -> 20000.21 | I32: =MEDIDA!U17 -> 18400 | K32: =I32-G32 -> -1600.21
G33: =MEDIDA!D69 -> 22500.224 | I33: =MEDIDA!U18 -> 20700 | K33: =I33-G33 -> -1800.2239
G34: =MEDIDA!D74 -> 25000.279 | I34: =MEDIDA!U19 -> 23000 | K34: =I34-G34 -> -2000.279

Sheet CERTIFICADO 
O1: CERTIFICADO N°: | R1: =INFORMACIÓN!G2 -> JD1741-24
C3: 1. EQUIPO BAJO PRUEBA
C5: INSTRUMENTO: | I5: =INFORMACIÓN!A2 -> BASCULA DE PISO
C6: MARCA: | I6: =INFORMACIÓN!B2 -> HEALTH O METER
C7: MODELO: | I7: =INFORMACIÓN!C2 -> 844KL
C8: SERIE: | I8: =INFORMACIÓN!D2 -> 8440131906
C9: CÓDIGO INTERNO: | I9: =INFORMACIÓN!F2 -> 1204002438
C10: UBICACIÓN: | I10: =INFORMACIÓN!E2 -> UNIDAD MATERNA
C11: ESTADO FÍSICO: | I11: =INFORMACIÓN!B7 -> BUEN ESTADO
C12: FECHA DE RECEPCIÓN: | I12: =INFORMACIÓN!H2 -> 45465
C13: FECHA DE CALIBRACIÓN: | I13: =INFORMACIÓN!B8 -> 45465
C15: 2. DATOS DEL CLIENTE
C17: NOMBRE: | I17: =INFORMACIÓN!E6 -> HOSPITAL DE ALTA COMPLEJIDAD DEL MAGDALENA CENTRO
C18: NIT: | I18: =INFORMACIÓN!E7 -> 901.532.463-8
C19: TELÉFONO: | I19: =INFORMACIÓN!E8 -> 3007835072
C20: DIRECCIÓN: | I20: =INFORMACIÓN!E9 -> CARRERA 15 ENTRE CALLE 18 y 19
C21: CIUDAD: | I21: =INFORMACIÓN!E10 -> LA DORADA - CALDAS
C23: Este certificado expresa fielmente el resultado de las mediciones realizadas; no podrá ser reproducido total o parcialmente excepto cuando se haya obtenido permiso por escrito de BTM COLOMBIA ZOMAC S.A.S y se debe reproducir en su totalidad, para proporcionar seguridad de que el certificado no sea sacado de contexto. Los resultados que se encuentran en este certificado se refieren al momento y condiciones en que se realizaron las mediciones, BTM COLOMBIA ZOMAC S.A.S no se responsabiliza de los daños que puedan ser causados por el uso inadecuado de los equipos calibrados. El usuario es responsable de la calibración de sus instrumentos a intervalos apropiados. El laboratorio no se hace responsable por cómo la información suministrada por el cliente afecte los resultados de medición.
C31: REVISÓ Y AUTORIZÓ: | I31: CALIBRADO POR: | M31: =INFORMACIÓN!B14 -> ING. GABRIEL DURÁN
I32: FECHA DE EMISIÓN: | M32: =INFORMACIÓN!B9 -> 45465
I33: NÚMERO DE PÁGINAS: | M33: 4
C36: ING. JOHAN SEBASTIÁN PÉREZ
C37: DIRECTOR DE LABORATORIO
O38: =O1 -> CERTIFICADO N°: | R38: =R1 -> JD1741-24
B40: 3. CONDICIONES AMBIENTALES
B41: El laboratorio de metrología BTM COLOMBIA ZOMAC S.A.S registra las condiciones ambientales (Humedad y Temperatura) tomando los máximos y mínimos alcanzados durante el tiempo en que se ejecuta la calibración. A continuación se presenta el promedio y la variación resultante.
F45: TEMPERATURA AMBIENTE (°C) | K45: HUMEDAD RELATIVA (%HR)
F46: =AVERAGE(INFORMACIÓN!B10:B11) -> 24.3 | H46: ± | I46: =ABS(INFORMACIÓN!B10-INFORMACIÓN!B11) -> 0.4 | K46: =AVERAGE(INFORMACIÓN!B12:B13) -> 61.5 | M46: ± | N46: =ABS(INFORMACIÓN!B12-INFORMACIÓN!B13) -> 3
F48: La calibración fue realizada en: | K48: En sitio (instalaciones del cliente)
B50: 4. INCERTIDUMBRE DE MEDICIÓN
B51: La incertidumbre expandida de la medición reportada se establece como la incertidumbre estándar de medición multiplicada por el factor de cobertura “k” y la probabilidad de cobertura, la cual debe ser aproximada al 95% y no menor a este valor. La incertidumbre de medición ha sido estimada con un nivel de confianza del 95,45% empleando una distribución t de student. Cuando se hace declaración de cumplimiento, el laboratorio hace referencia a las especificaciones del fabricante, norma o requisitos declarados por el cliente. La regla de decisión aplicada en estos casos será |Error| +U ≤ EMP según la ASME B89 7.3.1, si cumple la anterior condición la medición se toma como conforme y registrará un pasa, en caso contrario se registrará falla. La probabilidad de dar una aceptación falsa o un rechazo falso no lo determina el laboratorio, sin embargo se puede calcular de acuerdo a la guía JCGM 106:2012 según su numeral 8.
B60: 5. PROCEDIMIENTO DE CALIBRACIÓN
B61: La calibración se ejecutó mediante el método de comparación directa con patrón de referencia de acuerdo con el procedimiento interno para Básculas BTM-P-001.
B64: 6. TRAZABILIDAD
B65: El laboratorio BTM COLOMBIA ZOMAC S.A.S establece la trazabilidad metrológica de sus mediciones al sistema internacional de unidades (SI), por medio de una cadena documentada de calibraciones, las cuales se encuentran referenciadas a patrones de medidas primarios. Esta vinculación se logra a través del uso de patrones calibrados por institutos nacionales de metrología (INM) y por laboratorios acreditados por parte de un organismo de acreditación.
B70: PATRÓN | H70: SERIE | M70: CALIBRACIÓN | P70: CERTIFICADO
B71: Masa de 5 Kg | H71: 01-02 | M71: 46041 | P71: CBC-0007-004-26
B72: Masa de 10 Kg | H72: 10 KG SB 01 - 10 KG SB 02 - SB 10KG 01 - M1 10 KG 02 - SB 10 KG 03 | M72: 2026-01-05 2026-01-19 2025-12-29 | P72: CBC-0547-004-25 CBC-0567-003-25 CBC-0007-003-26
B73: Masa de 20 Kg | H73: 01-02-03-04-05-06 | M73: 2026-01-05 2025-12-29 | P73: CBC-0547-001-25 CBC-0547-002-25 CBC-0547-003-25 CBC-0567-001-25 CBC-0567-002-25 CBC-0567-003-25
B74: Juego de Pesas (1 mg a 500 g) | H74: No registra | M74: 46038 | P74: CBC-0007-001-26
...
