Workbook
Name Instrumento: '[1]R-LAB-127 DENSIDAD AIRE'!#REF!
Name Instrumento: '[1]R-LAB-127 DENSIDAD AIRE'!#REF!
Name Instrumento.: '[1]R-LAB-127 DENSIDAD AIRE'!#REF!
Name Instrumento.: '[1]R-LAB-127 DENSIDAD AIRE'!#REF!
Name N: #REF!
Name N: #REF!

Sheet INFORMACIÓN
A1: Datos del item | J1: En sitio ( instalaciones del cliente)
A2: Intrumento | B2: Marca | C2: Modelo | D2: Serie | E2: Ubicación | F2: Inventario | G2: Número de Certificado | H2: Fecha de Recepción | J2: Laboratorio BTMC
A3: BASCULA DE PISO | B3: HEALTH O METER | C3: 844KL | D3: 8440131906 | E3: UNIDAD MATERNA | F3: 1204002438 | G3: JD1741-24 | H3: 45465
J4: BUEN ESTADO
J5: REGULAR ESTADO
A6: Datos de calibración | D6: Datos del cliente | J6: MAL ESTADO
A7: Lugar de calibración: | B7: En sitio ( instalaciones del cliente) | D7: Solicitante: | E7: HOSPITAL DE ALTA COMPLEJIDAD DEL MAGDALENA CENTRO
A8: Estado Físico: | B8: BUEN ESTADO | D8: Nit: | E8: 901.532.463-8
A9: Fecha de calibración: | B9: =H3 -> 45465 | D9: Telefono: | E9: 3007835072
A10: Fecha de emisión: | B10: =H3 -> 45465 | D10: Dirección: | E10: CARRERA 15 ENTRE CALLE 18 y 19
A11: Temperatura mínima: | B11: 24.1 | D11: Ciudad: | E11: LA DORADA - CALDAS
A12: Temperatura máxima: | B12: 24.5
A13: Humedad Mínima: | B13: 60
A14: Humedad Máxima: | B14: 63
A15: Calibración realiza por: | B15: ING. GABRIEL DURÁN

Sheet MEDIDA
J2: RESULTADOS DE CALIBRACIÓN DE MASA
A4: Unidad de medida: | F4: kg
A5: Capacidad Máxima de item: | F5: 150
R6: Valores Seleccionados | U6: EXACTITUD
B7: Valor Seleccionado | E7: REPETIBILIDAD | H7: Indicación sin carga | U7: =R8 -> kg
K8: C | N8: D | R8: =F4 -> kg | U8: ASCENDENTE
B9: =F4 -> kg | E9: =B9 -> kg | H9: =F4 -> kg | L9: A | R9: 0 | S9: 0 | U9: 0
B10: =F5*50% -> 75 | C10: =MROUND(B10,5) -> 75 | E10: =U14 -> 75 | H10: 0 | K10: B | N10: E | R10: =F5/10 -> 15 | S10: =MROUND(R10,5) -> 15 | U10: 15
B11: =B10 -> 75 | C11: =MROUND(B11,5) -> 75 | E11: =E10 -> 75 | H11: 0 | J11: Valor Seleccionado | M11: EXCENTRICIDAD | P11: Indicación sin carga | R11: =R10+R10 -> 30 | S11: =MROUND(R11,5) -> 30 | U11: =U10+15 -> 30
B12: =B11 -> 75 | C12: =MROUND(B12,5) -> 75 | E12: =E11 -> 75 | H12: 0 | R12: =R10+R11 -> 45 | S12: =MROUND(R12,5) -> 45 | U12: =U11+15 -> 45
B13: =B12 -> 75 | C13: =MROUND(B13,5) -> 75 | E13: =E12 -> 75 | H13: 0 | J13: =F5/3 -> 50 | K13: 60 | L13: =F4 -> kg | M13: =J13 -> 50 | N13: 60 | O13: =L13 -> kg | P13: =F4 -> kg | R13: =$R$10+R12 -> 60 | S13: =MROUND(R13,5) -> 60 | U13: =U12+15 -> 60
B14: =B13 -> 75 | C14: =MROUND(B14,5) -> 75 | E14: =E13 -> 75 | H14: 0 | J14: A | M14: =U13 -> 60 | P14: 0 | R14: =$R$10+R13 -> 75 | S14: =MROUND(R14,5) -> 75 | U14: =U13+15 -> 75
J15: B | M15: =M14 -> 60 | P15: 0 | R15: =$R$10+R14 -> 90 | S15: =MROUND(R15,5) -> 90 | U15: =U14+15 -> 90
J16: C | M16: =M15 -> 60 | P16: 0 | R16: =$R$10+R15 -> 105 | S16: =MROUND(R16,5) -> 105 | U16: =U15+15 -> 105
J17: D | M17: =M16 -> 60 | P17: 0 | R17: =$R$10+R16 -> 120 | S17: =MROUND(R17,5) -> 120 | U17: =U16+15 -> 120
B18: Montar | J18: E | M18: =M17 -> 60 | P18: 0 | R18: =$R$10+R17 -> 135 | S18: =MROUND(R18,5) -> 135 | U18: =U17+15 -> 135
B19: -------- | R19: =$R$10+R18 -> 150 | S19: =MROUND(R19,5) -> 150 | U19: =U18+15 -> 150
B24: DISTRIBUCIÓN DE MASAS
B25: ESCOGIDA | D25: MASA CONV
G26: 5 kg 01 | H26: 5 kg 02 | I26: 10 kg 01 | J26: 10 kg 02 | K26: 10 kg 03 | L26: 10 kg 04 | M26: 10 kg 05 | N26: 10 kg 06 | O26: 20 kg 01 | P26: 20 kg 02 | Q26: 20 kg 03 | R26: 20 kg 04 | S26: 20 kg 05
G28: -------- | H28: Montar | I28: Montar | K28: -------- | L28: -------- | M28: -------- | N28: -------- | O28: -------- | P28: -------- | Q28: -------- | R28: -------- | S28: --------
B29: =S10 -> 15 | D29: =SUM(G29:S29) -> 15.000068 | G29: =IF(G28="Montar",5+G30,"") | H29: =IF(H28="Montar",5+H30,"") -> 4.999918 | I29: =IF(I28="Montar",10+I30,"") -> 10.00015 | J29: =IF(J28="Montar",10+J30,"") | K29: =IF(K28="Montar",10+K30,"") | L29: =IF(L28="Montar",10+L30,"") | M29: =IF(M28="Montar",10+M30,"") | N29: =IF(N28="Montar",10+N30,"") | O29: =IF(O28="Montar",20+O30,"") | P29: =IF(P28="Montar",20+P30,"") | Q29: =IF(Q28="Montar",20+Q30,"") | R29: =IF(R28="Montar",20+R30,"") | S29: =IF(S28="Montar",20+S30,"")
D30: =SUM(G30:S30) -> 6.8e-05 | G30: =IF(G28="Montar",PATRÓN!$J$3/1000,"") | H30: =IF(H28="Montar",PATRÓN!$J$4/1000,"") -> -8.2e-05 | I30: =IF(I28="Montar",PATRÓN!$J$5/1000,"") -> 0.00015 | J30: =IF(J28="Montar",PATRÓN!$J$6/1000,"") | K30: =IF(K28="Montar",PATRÓN!$J$7/1000,"") | L30: =IF(L28="Montar",PATRÓN!$J$8/1000,"") | M30: =IF(M28="Montar",PATRÓN!$J$9/1000,"") | N30: =IF(N28="Montar",PATRÓN!$J$10/1000,"") | O30: =IF(O28="Montar",PATRÓN!$J$11/1000,"") | P30: =IF(P28="Montar",PATRÓN!$J$12/1000,"") | Q30: =IF(Q28="Montar",PATRÓN!$J$13/1000,"") | R30: =IF(R28="Montar",PATRÓN!$J$14/1000,"") | S30: =IF(S28="Montar",PATRÓN!$J$15/1000,"")
D31: =SUM(G31:S31) -> 0.000253 | G31: =IF(G28="Montar",PATRÓN!$M$3/1000,"") | H31: =IF(H28="Montar",PATRÓN!$M$4/1000,"") -> 8.3e-05 | I31: =IF(I28="Montar",PATRÓN!$M$5/1000,"") -> 0.00017 | J31: =IF(J28="Montar",PATRÓN!$M$6/1000,"") | K31: =IF(K28="Montar",PATRÓN!$M$7/1000,"") | L31: =IF(L28="Montar",PATRÓN!$M$8/1000,"") | M31: =IF(M28="Montar",PATRÓN!$M$9/1000,"") | N31: =IF(N28="Montar",PATRÓN!$M$10/1000,"") | O31: =IF(O28="Montar",PATRÓN!$M$11/1000,"") | P31: =IF(P28="Montar",PATRÓN!$M$12/1000,"") | Q31: =IF(Q28="Montar",PATRÓN!$M$13/1000,"") | R31: =IF(R28="Montar",PATRÓN!$M$14/1000,"") | S31: =IF(S28="Montar",PATRÓN!$M$15/1000,"")
G32: -------- | I32: Montar | J32: -------- | K32: -------- | L32: -------- | M32: -------- | N32: -------- | O32: Montar | P32: -------- | Q32: -------- | R32: -------- | S32: --------
B33: =S11 -> 30 | D33: =SUM(G33:S33) -> 30.00001 | G33: =IF(G32="Montar",5+G34,"") | H33: =IF(H32="Montar",5+H34,"") | I33: =IF(I32="Montar",10+I34,"") -> 10.00015 | J33: =IF(J32="Montar",10+J34,"") | K33: =IF(K32="Montar",10+K34,"") | L33: =IF(L32="Montar",10+L34,"") | M33: =IF(M32="Montar",10+M34,"") | N33: =IF(N32="Montar",10+N34,"") | O33: =IF(O32="Montar",20+O34,"") -> 19.99986 | P33: =IF(P32="Montar",20+P34,"") | Q33: =IF(Q32="Montar",20+Q34,"") | R33: =IF(R32="Montar",20+R34,"") | S33: =IF(S32="Montar",20+S34,"")
D34: =SUM(G34:S34) -> 1e-05 | G34: =IF(G32="Montar",PATRÓN!$J$3/1000,"") | H34: =IF(H32="Montar",PATRÓN!$J$4/1000,"") | I34: =IF(I32="Montar",PATRÓN!$J$5/1000,"") -> 0.00015 | J34: =IF(J32="Montar",PATRÓN!$J$6/1000,"") | K34: =IF(K32="Montar",PATRÓN!$J$7/1000,"") | L34: =IF(L32="Montar",PATRÓN!$J$8/1000,"") | M34: =IF(M32="Montar",PATRÓN!$J$9/1000,"") | N34: =IF(N32="Montar",PATRÓN!$J$10/1000,"") | O34: =IF(O32="Montar",PATRÓN!$J$11/1000,"") -> -0.00014 | P34: =IF(P32="Montar",PATRÓN!$J$12/1000,"") | Q34: =IF(Q32="Montar",PATRÓN!$J$13/1000,"") | R34: =IF(R32="Montar",PATRÓN!$J$14/1000,"") | S34: =IF(S32="Montar",PATRÓN!$J$15/1000,"")
D35: =SUM(G35:S35) -> 0.0005 | G35: =IF(G32="Montar",PATRÓN!$M$3/1000,"") | H35: =IF(H32="Montar",PATRÓN!$M$4/1000,"") | I35: =IF(I32="Montar",PATRÓN!$M$5/1000,"") -> 0.00017 | J35: =IF(J32="Montar",PATRÓN!$M$6/1000,"") | K35: =IF(K32="Montar",PATRÓN!$M$7/1000,"") | L35: =IF(L32="Montar",PATRÓN!$M$8/1000,"") | M35: =IF(M32="Montar",PATRÓN!$M$9/1000,"") | N35: =IF(N32="Montar",PATRÓN!$M$10/1000,"") | O35: =IF(O32="Montar",PATRÓN!$M$11/1000,"") -> 0.00033 | P35: =IF(P32="Montar",PATRÓN!$M$12/1000,"") | Q35: =IF(Q32="Montar",PATRÓN!$M$13/1000,"") | R35: =IF(R32="Montar",PATRÓN!$M$14/1000,"") | S35: =IF(S32="Montar",PATRÓN!$M$15/1000,"")
G36: -------- | H36: Montar | I36: -------- | J36: -------- | L36: -------- | M36: -------- | N36: -------- | O36: Montar | P36: Montar | Q36: -------- | R36: -------- | S36: --------
B37: =S12 -> 45 | D37: =SUM(G37:S37) -> 44.999838 | G37: =IF(G36="Montar",5+G38,"") | H37: =IF(H36="Montar",5+H38,"") -> 4.999918 | I37: =IF(I36="Montar",10+I38,"") | J37: =IF(J36="Montar",10+J38,"") | K37: =IF(K36="Montar",10+K38,"") | L37: =IF(L36="Montar",10+L38,"") | M37: =IF(M36="Montar",10+M38,"") | N37: =IF(N36="Montar",10+N38,"") | O37: =IF(O36="Montar",20+O38,"") -> 19.99986 | P37: =IF(P36="Montar",20+P38,"") -> 20.00006 | Q37: =IF(Q36="Montar",20+Q38,"") | R37: =IF(R36="Montar",20+R38,"") | S37: =IF(S36="Montar",20+S38,"")
D38: =SUM(G38:S38) -> -0.000162 | G38: =IF(G36="Montar",PATRÓN!$J$3/1000,"") | H38: =IF(H36="Montar",PATRÓN!$J$4/1000,"") -> -8.2e-05 | I38: =IF(I36="Montar",PATRÓN!$J$5/1000,"") | J38: =IF(J36="Montar",PATRÓN!$J$6/1000,"") | K38: =IF(K36="Montar",PATRÓN!$J$7/1000,"") | L38: =IF(L36="Montar",PATRÓN!$J$8/1000,"") | M38: =IF(M36="Montar",PATRÓN!$J$9/1000,"") | N38: =IF(N36="Montar",PATRÓN!$J$10/1000,"") | O38: =IF(O36="Montar",PATRÓN!$J$11/1000,"") -> -0.00014 | P38: =IF(P36="Montar",PATRÓN!$J$12/1000,"") -> 6e-05 | Q38: =IF(Q36="Montar",PATRÓN!$J$13/1000,"") | R38: =IF(R36="Montar",PATRÓN!$J$14/1000,"") | S38: =IF(S36="Montar",PATRÓN!$J$15/1000,"")
D39: =SUM(G39:S39) -> 0.000743 | G39: =IF(G36="Montar",PATRÓN!$M$3/1000,"") | H39: =IF(H36="Montar",PATRÓN!$M$4/1000,"") -> 8.3e-05 | I39: =IF(I36="Montar",PATRÓN!$M$5/1000,"") | J39: =IF(J36="Montar",PATRÓN!$M$6/1000,"") | K39: =IF(K36="Montar",PATRÓN!$M$7/1000,"") | L39: =IF(L36="Montar",PATRÓN!$M$8/1000,"") | M39: =IF(M36="Montar",PATRÓN!$M$9/1000,"") | N39: =IF(N36="Montar",PATRÓN!$M$10/1000,"") | O39: =IF(O36="Montar",PATRÓN!$M$11/1000,"") -> 0.00033 | P39: =IF(P36="Montar",PATRÓN!$M$12/1000,"") -> 0.00033 | Q39: =IF(Q36="Montar",PATRÓN!$M$13/1000,"") | R39: =IF(R36="Montar",PATRÓN!$M$14/1000,"") | S39: =IF(S36="Montar",PATRÓN!$M$15/1000,"")
G40: -------- | H40: -------- | I40: -------- | J40: -------- | L40: -------- | M40: -------- | N40: -------- | O40: Montar | P40: Montar | Q40: Montar | R40: -------- | S40: --------
B41: =S13 -> 60 | D41: =SUM(G41:S41) -> 59.99968 | G41: =IF(G40="Montar",5+G42,"") | H41: =IF(H40="Montar",5+H42,"") | I41: =IF(I40="Montar",10+I42,"") | J41: =IF(J40="Montar",10+J42,"") | K41: =IF(K40="Montar",10+K42,"") | L41: =IF(L40="Montar",10+L42,"") | M41: =IF(M40="Montar",10+M42,"") | N41: =IF(N40="Montar",10+N42,"") | O41: =IF(O40="Montar",20+O42,"") -> 19.99986 | P41: =IF(P40="Montar",20+P42,"") -> 20.00006 | Q41: =IF(Q40="Montar",20+Q42,"") -> 19.99976 | R41: =IF(R40="Montar",20+R42,"") | S41: =IF(S40="Montar",20+S42,"")
D42: =SUM(G42:S42) -> -0.00032 | G42: =IF(G40="Montar",PATRÓN!$J$3/1000,"") | H42: =IF(H40="Montar",PATRÓN!$J$4/1000,"") | I42: =IF(I40="Montar",PATRÓN!$J$5/1000,"") | J42: =IF(J40="Montar",PATRÓN!$J$6/1000,"") | K42: =IF(K40="Montar",PATRÓN!$J$7/1000,"") | L42: =IF(L40="Montar",PATRÓN!$J$8/1000,"") | M42: =IF(M40="Montar",PATRÓN!$J$9/1000,"") | N42: =IF(N40="Montar",PATRÓN!$J$10/1000,"") | O42: =IF(O40="Montar",PATRÓN!$J$11/1000,"") -> -0.00014 | P42: =IF(P40="Montar",PATRÓN!$J$12/1000,"") -> 6e-05 | Q42: =IF(Q40="Montar",PATRÓN!$J$13/1000,"") -> -0.00024 | R42: =IF(R40="Montar",PATRÓN!$J$14/1000,"") | S42: =IF(S40="Montar",PATRÓN!$J$15/1000,"")
D43: =SUM(G43:S43) -> 0.00099 | G43: =IF(G40="Montar",PATRÓN!$M$3/1000,"") | H43: =IF(H40="Montar",PATRÓN!$M$4/1000,"") | I43: =IF(I40="Montar",PATRÓN!$M$5/1000,"") | J43: =IF(J40="Montar",PATRÓN!$M$6/1000,"") | K43: =IF(K40="Montar",PATRÓN!$M$7/1000,"") | L43: =IF(L40="Montar",PATRÓN!$M$8/1000,"") | M43: =IF(M40="Montar",PATRÓN!$M$9/1000,"") | N43: =IF(N40="Montar",PATRÓN!$M$10/1000,"") | O43: =IF(O40="Montar",PATRÓN!$M$11/1000,"") -> 0.00033 | P43: =IF(P40="Montar",PATRÓN!$M$12/1000,"") -> 0.00033 | Q43: =IF(Q40="Montar",PATRÓN!$M$13/1000,"") -> 0.00033 | R43: =IF(R40="Montar",PATRÓN!$M$14/1000,"") | S43: =IF(S40="Montar",PATRÓN!$M$15/1000,"")
G44: -------- | H44: Montar | I44: Montar | J44: -------- | K44: -------- | L44: -------- | M44: -------- | N44: -------- | P44: Montar | Q44: Montar | R44: Montar | S44: --------
B45: =S14 -> 75 | D45: =SUM(G45:S45) -> 74.999948 | G45: =IF(G44="Montar",5+G46,"") | H45: =IF(H44="Montar",5+H46,"") -> 4.999918 | I45: =IF(I44="Montar",10+I46,"") -> 10.00015 | J45: =IF(J44="Montar",10+J46,"") | K45: =IF(K44="Montar",10+K46,"") | L45: =IF(L44="Montar",10+L46,"") | M45: =IF(M44="Montar",10+M46,"") | N45: =IF(N44="Montar",10+N46,"") | O45: =IF(O44="Montar",20+O46,"") | P45: =IF(P44="Montar",20+P46,"") -> 20.00006 | Q45: =IF(Q44="Montar",20+Q46,"") -> 19.99976 | R45: =IF(R44="Montar",20+R46,"") -> 20.00006 | S45: =IF(S44="Montar",20+S46,"")
D46: =SUM(G46:S46) -> -5.2e-05 | G46: =IF(G44="Montar",PATRÓN!$J$3/1000,"") | H46: =IF(H44="Montar",PATRÓN!$J$4/1000,"") -> -8.2e-05 | I46: =IF(I44="Montar",PATRÓN!$J$5/1000,"") -> 0.00015 | J46: =IF(J44="Montar",PATRÓN!$J$6/1000,"") | K46: =IF(K44="Montar",PATRÓN!$J$7/1000,"") | L46: =IF(L44="Montar",PATRÓN!$J$8/1000,"") | M46: =IF(M44="Montar",PATRÓN!$J$9/1000,"") | N46: =IF(N44="Montar",PATRÓN!$J$10/1000,"") | O46: =IF(O44="Montar",PATRÓN!$J$11/1000,"") | P46: =IF(P44="Montar",PATRÓN!$J$12/1000,"") -> 6e-05 | Q46: =IF(Q44="Montar",PATRÓN!$J$13/1000,"") -> -0.00024 | R46: =IF(R44="Montar",PATRÓN!$J$14/1000,"") -> 6e-05 | S46: =IF(S44="Montar",PATRÓN!$J$15/1000,"")
D47: =SUM(G47:S47) -> 0.001243 | G47: =IF(G44="Montar",PATRÓN!$M$3/1000,"") | H47: =IF(H44="Montar",PATRÓN!$M$4/1000,"") -> 8.3e-05 | I47: =IF(I44="Montar",PATRÓN!$M$5/1000,"") -> 0.00017 | J47: =IF(J44="Montar",PATRÓN!$M$6/1000,"") | K47: =IF(K44="Montar",PATRÓN!$M$7/1000,"") | L47: =IF(L44="Montar",PATRÓN!$M$8/1000,"") | M47: =IF(M44="Montar",PATRÓN!$M$9/1000,"") | N47: =IF(N44="Montar",PATRÓN!$M$10/1000,"") | O47: =IF(O44="Montar",PATRÓN!$M$11/1000,"") | P47: =IF(P44="Montar",PATRÓN!$M$12/1000,"") -> 0.00033 | Q47: =IF(Q44="Montar",PATRÓN!$M$13/1000,"") -> 0.00033 | R47: =IF(R44="Montar",PATRÓN!$M$14/1000,"") -> 0.00033 | S47: =IF(S44="Montar",PATRÓN!$M$15/1000,"")
...

Sheet PATRÓN
C2: PLACA | D2: EQUIPO | E2: MARCA | F2: MODELO | G2: SERIE | H2: FECHA CALIBRACIÓN | I2: CERTIFICADO | J2: ERROR (g) | K2: EMP (g) | L2: CLASE | M2: INCERT(g)
A3: Montar | D3: MASA PATRÓN 5 kg 01 | E3: SIGMA | F3: PARALELEPIPEDO | G3: 01 | H3: 44232 | I3: M-5646-1 | J3: -0.032 | K3: 0.25 | L3: M1 | M3: 0.083 | P3: Conformidad | Q3: Si | R3: BUEN ESTADO
A4: -------- | D4: MASA PATRÓN 5 kg 02 | E4: SIGMA | F4: PARALELEPIPEDO | G4: 02 | H4: 43987 | I4: M-5646-1 | J4: -0.082 | K4: 0.25 | L4: M1 | M4: 0.083 | Q4: No | R4: MAL ESTADO
D5: MASA PATRÓN 10 kg 01 | E5: SIGMA | F5: PARALELEPIPEDO | G5: 01 | H5: 43987 | I5: M-5646-1 | J5: 0.15 | K5: 0.5 | L5: M1 | M5: 0.17
D6: MASA PATRÓN 10 kg 02 | E6: SIGMA | F6: PARALELEPIPEDO | G6: 02 | H6: 43987 | I6: M-5646-1 | J6: -0.1 | K6: 0.5 | L6: M1 | M6: 0.17
D7: MASA PATRÓN 10 kg 03 | E7: SIGMA | F7: PARALELEPIPEDO | G7: 03 | H7: 43987 | I7: M-5646-1 | J7: 0 | K7: 0.5 | L7: M1 | M7: 0.17 | Q7: Conformidad | R7: EMP
D8: MASA PATRÓN 10 kg 04 | E8: SIGMA | F8: PARALELEPIPEDO | G8: 04 | H8: 43987 | I8: M-5646-1 | J8: 0 | K8: 0.5 | L8: M1 | M8: 0.17 | Q8: #DIV/0! | R8: 0
D9: MASA PATRÓN 10 kg 05 | E9: SIGMA | F9: PARALELEPIPEDO | G9: 05 | H9: 43987 | I9: M-5646-1 | J9: 0.05 | K9: 0.5 | L9: M1 | M9: 0.17 | Q9: #DIV/0! | R9: 0
D10: MASA PATRÓN 10 kg 06 | E10: SIGMA | F10: PARALELEPIPEDO | G10: 06 | H10: 43987 | I10: M-5646-1 | J10: 0.1 | K10: 0.5 | L10: M1 | M10: 0.17 | Q10: #DIV/0! | R10: 0
D11: MASA PATRÓN 20 kg 01 | E11: SIGMA | F11: PARALELEPIPEDO | G11: 01 | H11: 43987 | I11: M-5646-1 | J11: -0.14 | K11: 1 | L11: M1 | M11: 0.33 | Q11: #DIV/0! | R11: 0
D12: MASA PATRÓN 20 kg 02 | E12: SIGMA | F12: PARALELEPIPEDO | G12: 02 | H12: 43987 | I12: M-5646-1 | J12: 0.06 | K12: 1 | L12: M1 | M12: 0.33 | Q12: #DIV/0! | R12: 0
D13: MASA PATRÓN 20 kg 03 | E13: SIGMA | F13: PARALELEPIPEDO | G13: 03 | H13: 43987 | I13: M-5646-1 | J13: -0.24 | K13: 1 | L13: M1 | M13: 0.33 | Q13: #DIV/0! | R13: 0
D14: MASA PATRÓN 20 kg 04 | E14: SIGMA | F14: PARALELEPIPEDO | G14: 04 | H14: 43987 | I14: M-5646-1 | J14: 0.06 | K14: 1 | L14: M1 | M14: 0.33 | Q14: #DIV/0! | R14: 0
D15: MASA PATRÓN 20 kg 05 | E15: SIGMA | F15: PARALELEPIPEDO | G15: 05 | H15: 43987 | I15: M-5646-1 | J15: 0.01 | K15: 1 | L15: M1 | M15: 0.33 | Q15: #DIV/0! | R15: 0
Q16: #DIV/0! | R16: 0
Q17: #DIV/0! | R17: 0
Q18: #DIV/0! | R18: 0
B22: EQUIPO PATRÓN 1
B23: Equipo patrón: | G23: Juego de Masas Cilíndricas
B24: Marca: | G24: Truemass
B25: Modelo: | G25: Cilíndricas
B26: Serie: | G26: No tiene
B27: Fecha de Calibración: | G27: 43990
B28: No. Certificado: | G28: CAP388-20
B29: Factor de cobertura K: | G29: 2
B31: EQUIPO PATRÓN 2
B32: Equipo patrón: | G32: Masa de 5 kg
B33: Marca: | G33: Sigma
B34: Modelo: | G34: Paralelepípedo
B35: Serie: | G35: 01-02
B36: Fecha de Calibración: | G36: 44232
B37: No. Certificado: | G37: M-5646-1
B38: Factor de cobertura K: | G38: 2
B40: EQUIPO PATRÓN 3
B41: Equipo patrón: | G41: Masa de 10 kg
B42: Marca: | G42: Sigma
B43: Modelo: | G43: Paralelepípedo
B44: Serie: | G44: 01-02-03-04-05-06
B45: Fecha de Calibración: | G45: 44232
B46: No. Certificado: | G46: M-5646-1
...

Sheet INCERTIDUMBRE
B3: FUENTES DE INCERTIDUMBRE
B4: Valor Referencia | C4: Promedio | D4: Error | E4: Repetibilidad | F4: Indicación sin carga | G4: Indicación con carga | H4: Excentricidad | I4: Certificado de Calibración | J4: Deriva | K4: Veff | L4: Factor de cobertura (k) | M4: Incertidumbre Combinada | N4: Incertidumbre Expandida
B5: =G24 -> 0 | C5: =I24 -> 0 | D5: =K24 -> 0 | E5: =STDEVA(MEDIDA!E$10:G$14)/SQRT(COUNT(MEDIDA!E$10:G$14)) -> 0 | F5: =0.05/SQRT(12) -> 0.014433757 | G5: =0.05/SQRT(12) -> 0.014433757 | H5: =(C$30*B5)/(2*MEDIDA!K$13)*SQRT(3) -> 0 | I5: 0 | J5: 0 | K5: =M5^4/(E5^4/4+F5^4/200+G5^4/200+H5^4/200+I5^4/200+J5^4/200) -> 400 | L5: =TINV(0.0455,K5) -> 2.0062716 | M5: =SQRT(SUMSQ(E5,F5,G5,H5,I5,J5)) -> 0.020412415 | N5: =M5*L5 -> 0.040952849
B6: =G25 -> 15.000068 | C6: =I25 -> 15 | D6: =K25 -> -6.8e-05 | E6: =STDEVA(MEDIDA!E$10:G$14)/SQRT(COUNT(MEDIDA!E$10:G$14)) -> 0 | F6: =0.05/SQRT(12) -> 0.014433757 | G6: =0.05/SQRT(12) -> 0.014433757 | H6: =(C$30*B6)/(2*MEDIDA!K$13)*SQRT(3) -> 0 | I6: =MEDIDA!D31/2 -> 0.0001265 | J6: =((VLOOKUP(MEDIDA!S10,PATRÓN!B82:C121,2,FALSE))/(1000)/SQRT(3)) -> 0.0004330127 | K6: =M6^4/(E6^4/4+F6^4/200+G6^4/200+H6^4/200+I6^4/200+J6^4/200) -> 400.39066 | L6: =TINV(0.0455,K6) -> 2.0062716 | M6: =SQRT(SUMSQ(E6,F6,G6,H6,I6,J6)) -> 0.020417399 | N6: =M6*L6 -> 0.040962848
B7: =G26 -> 30.00001 | C7: =I26 -> 30 | D7: =K26 -> -1e-05 | E7: =STDEVA(MEDIDA!E$10:G$14)/SQRT(COUNT(MEDIDA!E$10:G$14)) -> 0 | F7: =0.05/SQRT(12) -> 0.014433757 | G7: =0.05/SQRT(12) -> 0.014433757 | H7: =(C$30*B7)/(2*MEDIDA!K$13)*SQRT(3) -> 0 | I7: =MEDIDA!D35/2 -> 0.00025 | J7: =((VLOOKUP(MEDIDA!S11,PATRÓN!B83:C122,2,FALSE))/(1000)/SQRT(3)) -> 0.0008660254 | K7: =M7^4/(E7^4/4+F7^4/200+G7^4/200+H7^4/200+I7^4/200+J7^4/200) -> 401.5589 | L7: =TINV(0.0455,K7) -> 2.006256 | M7: =SQRT(SUMSQ(E7,F7,G7,H7,I7,J7)) -> 0.020432307 | N7: =M7*L7 -> 0.040992438
B8: =G27 -> 44.999838 | C8: =I27 -> 45 | D8: =K27 -> 0.000162 | E8: =STDEVA(MEDIDA!E$10:G$14)/SQRT(COUNT(MEDIDA!E$10:G$14)) -> 0 | F8: =0.05/SQRT(12) -> 0.014433757 | G8: =0.05/SQRT(12) -> 0.014433757 | H8: =(C$30*B8)/(2*MEDIDA!K$13)*SQRT(3) -> 0 | I8: =MEDIDA!D39/2 -> 0.0003715 | J8: =((VLOOKUP(MEDIDA!S12,PATRÓN!B84:C123,2,FALSE))/(1000)/SQRT(3)) -> 0.0012990381 | K8: =M8^4/(E8^4/4+F8^4/200+G8^4/200+H8^4/200+I8^4/200+J8^4/200) -> 403.49934 | L8: =TINV(0.0455,K8) -> 2.0062248 | M8: =SQRT(SUMSQ(E8,F8,G8,H8,I8,J8)) -> 0.020457081 | N8: =M8*L8 -> 0.041041505
B9: =G28 -> 59.99968 | C9: =I28 -> 60 | D9: =K28 -> 0.00032 | E9: =STDEVA(MEDIDA!E$10:G$14)/SQRT(COUNT(MEDIDA!E$10:G$14)) -> 0 | F9: =0.05/SQRT(12) -> 0.014433757 | G9: =0.05/SQRT(12) -> 0.014433757 | H9: =(C$30*B9)/(2*MEDIDA!K$13)*SQRT(3) -> 0 | I9: =MEDIDA!D43/2 -> 0.000495 | J9: =((VLOOKUP(MEDIDA!S13,PATRÓN!B85:C124,2,FALSE))/(1000)/SQRT(3)) -> 0.0017320508 | K9: =M9^4/(E9^4/4+F9^4/200+G9^4/200+H9^4/200+I9^4/200+J9^4/200) -> 406.21231 | L9: =TINV(0.0455,K9) -> 2.0061787 | M9: =SQRT(SUMSQ(E9,F9,G9,H9,I9,J9)) -> 0.020491747 | N9: =M9*L9 -> 0.041110107
B10: =G29 -> 74.999948 | C10: =I29 -> 75 | D10: =K29 -> 5.2e-05 | E10: =STDEVA(MEDIDA!E$10:G$14)/SQRT(COUNT(MEDIDA!E$10:G$14)) -> 0 | F10: =0.05/SQRT(12) -> 0.014433757 | G10: =0.05/SQRT(12) -> 0.014433757 | H10: =(C$30*B10)/(2*MEDIDA!K$13)*SQRT(3) -> 0 | I10: =MEDIDA!D47/2 -> 0.0006215 | J10: =((VLOOKUP(MEDIDA!S14,PATRÓN!B86:C125,2,FALSE))/(1000)/SQRT(3)) -> 0.0021650635 | K10: =M10^4/(E10^4/4+F10^4/200+G10^4/200+H10^4/200+I10^4/200+J10^4/200) -> 409.69653 | L10: =TINV(0.0455,K10) -> 2.0061333 | M10: =SQRT(SUMSQ(E10,F10,G10,H10,I10,J10)) -> 0.02053632 | N10: =M10*L10 -> 0.041198595
B11: =G30 -> 90.00004 | C11: =I30 -> 90 | D11: =K30 -> -4e-05 | E11: =STDEVA(MEDIDA!E$10:G$14)/SQRT(COUNT(MEDIDA!E$10:G$14)) -> 0 | F11: =0.05/SQRT(12) -> 0.014433757 | G11: =0.05/SQRT(12) -> 0.014433757 | H11: =(C$30*B11)/(2*MEDIDA!K$13)*SQRT(3) -> 0 | I11: =MEDIDA!D51/2 -> 0.000745 | J11: =((VLOOKUP(MEDIDA!S15,PATRÓN!B87:C126,2,FALSE))/(1000)/SQRT(3)) -> 0.0025980762 | K11: =M11^4/(E11^4/4+F11^4/200+G11^4/200+H11^4/200+I11^4/200+J11^4/200) -> 413.92986 | L11: =TINV(0.0455,K11) -> 2.0060737 | M11: =SQRT(SUMSQ(E11,F11,G11,H11,I11,J11)) -> 0.020590573 | N11: =M11*L11 -> 0.041306207
B12: =G31 -> 104.99981 | C12: =I31 -> 105 | D12: =K31 -> 0.000192 | E12: =STDEVA(MEDIDA!E$10:G$14)/SQRT(COUNT(MEDIDA!E$10:G$14)) -> 0 | F12: =0.05/SQRT(12) -> 0.014433757 | G12: =0.05/SQRT(12) -> 0.014433757 | H12: =(C$30*B12)/(2*MEDIDA!K$13)*SQRT(3) -> 0 | I12: =MEDIDA!D55/2 -> 0.0008715 | J12: =((VLOOKUP(MEDIDA!S16,PATRÓN!B88:C127,2,FALSE))/(1000)/SQRT(3)) -> 0.0030310889 | K12: =M12^4/(E12^4/4+F12^4/200+G12^4/200+H12^4/200+I12^4/200+J12^4/200) -> 418.91609 | L12: =TINV(0.0455,K12) -> 2.0060009 | M12: =SQRT(SUMSQ(E12,F12,G12,H12,I12,J12)) -> 0.020654629 | N12: =M12*L12 -> 0.041433203
B13: =G32 -> 120.00009 | C13: =I32 -> 120 | D13: =K32 -> -9e-05 | E13: =STDEVA(MEDIDA!E$10:G$14)/SQRT(COUNT(MEDIDA!E$10:G$14)) -> 0 | F13: =0.05/SQRT(12) -> 0.014433757 | G13: =0.05/SQRT(12) -> 0.014433757 | H13: =(C$30*B13)/(2*MEDIDA!K$13)*SQRT(3) -> 0 | I13: =MEDIDA!D59/2 -> 0.001 | J13: =((VLOOKUP(MEDIDA!S17,PATRÓN!B89:C128,2,FALSE))/(1000)/SQRT(3)) -> 0.0034641016 | K13: =M13^4/(E13^4/4+F13^4/200+G13^4/200+H13^4/200+I13^4/200+J13^4/200) -> 424.64006 | L13: =TINV(0.0455,K13) -> 2.0059158 | M13: =SQRT(SUMSQ(E13,F13,G13,H13,I13,J13)) -> 0.020728402 | N13: =M13*L13 -> 0.041579429
B14: =G33 -> 134.99991 | C14: =I33 -> 135 | D14: =K33 -> 9.2e-05 | E14: =STDEVA(MEDIDA!E$10:G$14)/SQRT(COUNT(MEDIDA!E$10:G$14)) -> 0 | F14: =0.05/SQRT(12) -> 0.014433757 | G14: =0.05/SQRT(12) -> 0.014433757 | H14: =(C$30*B14)/(2*MEDIDA!K$13)*SQRT(3) -> 0 | I14: =MEDIDA!D63/2 -> 0.0011265 | J14: =((VLOOKUP(MEDIDA!S18,PATRÓN!B90:C129,2,FALSE))/(1000)/SQRT(3)) -> 0.0038971143 | K14: =M14^4/(E14^4/4+F14^4/200+G14^4/200+H14^4/200+I14^4/200+J14^4/200) -> 431.06702 | L14: =TINV(0.0455,K14) -> 2.0058194 | M14: =SQRT(SUMSQ(E14,F14,G14,H14,I14,J14)) -> 0.020811611 | N14: =M14*L14 -> 0.041744335
B15: =G34 -> 149.99974 | C15: =I34 -> 150 | D15: =K34 -> 0.000264 | E15: =STDEVA(MEDIDA!E$10:G$14)/SQRT(COUNT(MEDIDA!E$10:G$14)) -> 0 | F15: =0.05/SQRT(12) -> 0.014433757 | G15: =0.05/SQRT(12) -> 0.014433757 | H15: =(C$30*B15)/(2*MEDIDA!K$13)*SQRT(3) -> 0 | I15: =MEDIDA!D67/2 -> 0.001083 | J15: =((VLOOKUP(MEDIDA!S19,PATRÓN!B91:C130,2,FALSE))/(1000)/SQRT(3)) -> 0.004330127 | K15: =M15^4/(E15^4/4+F15^4/200+G15^4/200+H15^4/200+I15^4/200+J15^4/200) -> 437.3881 | L15: =TINV(0.0455,K15) -> 2.0057394 | M15: =SQRT(SUMSQ(E15,F15,G15,H15,I15,J15)) -> 0.020894726 | N15: =M15*L15 -> 0.041909373
C23: Excentricidad | G23: Selección | I23: Medición | K23: Error
C24: =ABS(MEDIDA!M14-MEDIDA!M14) -> 0 | G24: =MEDIDA!S9 -> 0 | I24: =MEDIDA!U9 -> 0 | K24: =I24-G24 -> 0
C25: =ABS(MEDIDA!M$14-MEDIDA!M15) -> 0 | G25: =MEDIDA!D29 -> 15.000068 | I25: =MEDIDA!U10 -> 15 | K25: =I25-G25 -> -6.8e-05
C26: =ABS(MEDIDA!M$14-MEDIDA!M16) -> 0 | G26: =MEDIDA!D33 -> 30.00001 | I26: =MEDIDA!U11 -> 30 | K26: =I26-G26 -> -1e-05
C27: =ABS(MEDIDA!M$14-MEDIDA!M17) -> 0 | G27: =MEDIDA!D37 -> 44.999838 | I27: =MEDIDA!U12 -> 45 | K27: =I27-G27 -> 0.000162
C28: =ABS(MEDIDA!M$14-MEDIDA!M18) -> 0 | G28: =MEDIDA!D41 -> 59.99968 | I28: =MEDIDA!U13 -> 60 | K28: =I28-G28 -> 0.00032
G29: =MEDIDA!D45 -> 74.999948 | I29: =MEDIDA!U14 -> 75 | K29: =I29-G29 -> 5.2e-05
C30: =MAX(C24:C28) -> 0 | G30: =MEDIDA!D49 -> 90.00004 | I30: =MEDIDA!U15 -> 90 | K30: =I30-G30 -> -4e-05
G31: =MEDIDA!D53 -> 104.99981 | I31: =MEDIDA!U16 -> 105 | K31: =I31-G31 -> 0.000192
G32: =MEDIDA!D57 -> 120.00009 | I32: =MEDIDA!U17 -> 120 | K32: =I32-G32 -> -9e-05
G33: =MEDIDA!D61 -> 134.99991 | I33: =MEDIDA!U18 -> 135 | K33: =I33-G33 -> 9.2e-05
G34: =MEDIDA!D65 -> 149.99974 | I34: =MEDIDA!U19 -> 150 | K34: =I34-G34 -> 0.000264

Sheet CERTIFICADO 
O1: CERTIFICADO N°: | R1: =INFORMACIÓN!G3 -> JD1741-24
C3: 1. EQUIPO BAJO PRUEBA
C5: INSTRUMENTO: | I5: =INFORMACIÓN!A3 -> BASCULA DE PISO
C6: MARCA: | I6: =INFORMACIÓN!B3 -> HEALTH O METER
C7: MODELO: | I7: =INFORMACIÓN!C3 -> 844KL
C8: SERIE: | I8: =INFORMACIÓN!D3 -> 8440131906
C9: CÓDIGO INTERNO: | I9: =INFORMACIÓN!F3 -> 1204002438
C10: UBICACIÓN: | I10: =INFORMACIÓN!E3 -> UNIDAD MATERNA
C11: ESTADO FÍSICO: | I11: =INFORMACIÓN!B8 -> BUEN ESTADO
C12: FECHA DE RECEPCIÓN: | I12: =INFORMACIÓN!H3 -> 45465
C13: FECHA DE CALIBRACIÓN: | I13: =INFORMACIÓN!B9 -> 45465
C15: 2. DATOS DEL CLIENTE
C17: NOMBRE: | I17: =INFORMACIÓN!E7 -> HOSPITAL DE ALTA COMPLEJIDAD DEL MAGDALENA CENTRO
C18: NIT: | I18: =INFORMACIÓN!E8 -> 901.532.463-8
C19: TELÉFONO: | I19: =INFORMACIÓN!E9 -> 3007835072
C20: DIRECCIÓN: | I20: =INFORMACIÓN!E10 -> CARRERA 15 ENTRE CALLE 18 y 19
C21: CIUDAD: | I21: =INFORMACIÓN!E11 -> LA DORADA - CALDAS
C23: Este certificado expresa fielmente el resultado de las mediciones realizadas; no podrá ser reproducido total o parcialmente excepto cuando se haya obtenido permiso por escrito de BTM COLOMBIA ZOMAC S.A.S y se debe reproducir en su totalidad, para proporcionar seguridad de que el certificado no sea sacado de contexto. Los resultados que se encuentran en este certificado se refieren al momento y condiciones en que se realizaron las mediciones, BTM COLOMBIA ZOMAC S.A.S no se responsabiliza de los daños que puedan ser causados por el uso inadecuado de los equipos calibrados. El usuario es responsable de la calibración de sus instrumentos a intervalos apropiados. El laboratorio no se hace responsable por cómo la información suministrada por el cliente afecte los resultados de medición.
C31: REVISÓ Y AUTORIZÓ: | I31: CALIBRADO POR: | M31: =INFORMACIÓN!B15 -> ING. GABRIEL DURÁN
I32: FECHA DE EMISIÓN: | M32: =INFORMACIÓN!B10 -> 45465
I33: NÚMERO DE PÁGINAS: | M33: 4
C36: ING. JOHAN SEBASTIÁN PÉREZ
C37: DIRECTOR DE LABORATORIO
O38: =O1 -> CERTIFICADO N°: | R38: =R1 -> JD1741-24
B40: 3. CONDICIONES AMBIENTALES
B41: El laboratorio de metrología BTM COLOMBIA ZOMAC S.A.S registra las condiciones ambientales (Humedad y Temperatura) tomando los máximos y mínimos alcanzados durante el tiempo en que se ejecuta la calibración. A continuación se presenta el promedio y la variación resultante.
F45: TEMPERATURA AMBIENTE (°C) | K45: HUMEDAD RELATIVA (%HR)
F46: =AVERAGE(INFORMACIÓN!B11:B12) -> 24.3 | H46: ± | I46: =ABS(INFORMACIÓN!B11-INFORMACIÓN!B12) -> 0.4 | K46: =AVERAGE(INFORMACIÓN!B13:B14) -> 61.5 | M46: ± | N46: =ABS(INFORMACIÓN!B13-INFORMACIÓN!B14) -> 3
F48: La calibración fue realizada en: | K48: En sitio (instalaciones del cliente)
B50: 4. INCERTIDUMBRE DE MEDICIÓN
B51: La incertidumbre expandida de la medición reportada se establece como la incertidumbre estándar de medición multiplicada por el factor de cobertura “k” y la probabilidad de cobertura, la cual debe ser aproximada al 95% y no menor a este valor. La incertidumbre de medición ha sido estimada con un nivel de confianza del 95,45% empleando una distribución t de student. Cuando se hace declaración de cumplimiento, el laboratorio hace referencia a las especificaciones del fabricante, norma o requisitos declarados por el cliente. La regla de decisión aplicada en estos casos será |Error| +U ≤ EMP según la ASME B89 7.3.1, si cumple la anterior condición la medición se toma como conforme y registrará un pasa, en caso contrario se registrará falla. La probabilidad de dar una aceptación falsa o un rechazo falso no lo determina el laboratorio, sin embargo se puede calcular de acuerdo a la guía JCGM 106:2012 según su numeral 8.
B60: 5. PROCEDIMIENTO DE CALIBRACIÓN
B61: La calibración se ejecutó mediante el método de comparación directa con patrón de referencia de acuerdo con el procedimiento interno para Básculas BTM-P-001.
B64: 6. TRAZABILIDAD
B65: El laboratorio BTM COLOMBIA ZOMAC S.A.S establece la trazabilidad metrológica de sus mediciones al sistema internacional de unidades (SI), por medio de una cadena documentada de calibraciones, las cuales se encuentran referenciadas a patrones de medidas primarios. Esta vinculación se logra a través del uso de patrones calibrados por institutos nacionales de metrología (INM) y por laboratorios acreditados por parte de un organismo de acreditación.
B70: PATRÓN | H70: SERIE | M70: CALIBRACIÓN | P70: CERTIFICADO
B71: Masa de 5 Kg | H71: 01-02 | M71: 46041 | P71: CBC-0007-004-26
B72: Masa de 10 Kg | H72: 10 KG SB 01 - 10 KG SB 02 - SB 10KG 01 - M1 10 KG 02 - SB 10 KG 03 | M72: 2026-01-05 2026-01-19 2025-12-29 | P72: CBC-0547-004-25 CBC-0567-003-25 CBC-0007-003-26
B73: Masa de 20 Kg | H73: 01-02-03-04-05-06 | M73: 2026-01-05 2025-12-29 | P73: CBC-0547-001-25 CBC-0547-002-25 CBC-0547-003-25 CBC-0567-001-25 CBC-0567-002-25 CBC-0567-003-25
O74: =O1 -> CERTIFICADO N°: | R74: =R1 -> JD1741-24
...
