Workbook
Name Instrumento: '[1]R-LAB-127 DENSIDAD AIRE'!#REF!
Name Instrumento: '[1]R-LAB-127 DENSIDAD AIRE'!#REF!
Name Instrumento.: '[1]R-LAB-127 DENSIDAD AIRE'!#REF!
Name Instrumento.: '[1]R-LAB-127 DENSIDAD AIRE'!#REF!
Name N: #REF!
Name N: #REF!

Sheet INFORMACIÓN
A1: Datos del item | O1: En sitio ( instalaciones del cliente)
A2: Intrumento | B2: Marca | C2: Modelo | D2: Serie | E2: Ubicación | F2: Inventario | G2: Número de Certificado | H2: Fecha de Recepción | O2: Laboratorio BTMC
O4: BUEN ESTADO
O5: REGULAR ESTADO
A6: Datos de calibración | D6: Datos del cliente | O6: MAL ESTADO
A7: Lugar de calibración: | B7: En sitio ( instalaciones del cliente) | D7: Solicitante: | E7: HOSPITAL DE ALTA COMPLEJIDAD DEL MAGDALENA CENTRO
A8: Estado Físico: | B8: BUEN ESTADO | D8: Nit: | E8: 901.532.463-8
A9: Fecha de calibración: | B9: =H3 -> 0 | D9: Telefono: | E9: 3007835072
A10: Fecha de emisión: | B10: =H3 -> 0 | D10: Dirección: | E10: CARRERA 15 ENTRE CALLE 18 y 19
A11: Temperatura mínima: | B11: 24.1 | D11: Ciudad: | E11: LA DORADA - CALDAS
A12: Temperatura máxima: | B12: 24.5
A13: Humedad Mínima: | B13: 60
A14: Humedad Máxima: | B14: 63
A15: Calibración realiza por: | B15: ING. GABRIEL DURÁN

Sheet Redondeo
A1: DATO 1
A2: Dato | B2: Dato redondeado | C2: =FIXED(A3,6) -> 0,558728 | D2: =RIGHT(C2,1) -> 8 | E2: =D2/1000000 -> 8e-06 | F2: =A3-E2 -> 0.55871984 | H2: =IF(C7=5,IF(AND(D3=0,D8=FALSE),J5,J6),J6) -> 0,5587
A3: =INCERTIDUMBRE!L5 -> 0.55872784 | B3: =IF(A3>=10,K37,IF(A3>=1,K29,IF(A3>=0.1,K21,IF(A3>=0.01,K13,IF(A3>=0.001,K5))))) -> 0,56 | C3: 6 decimal | D3: =D2+0 -> 8
C4: Extrae el ultimo digito | D4: extrael primer digito | E4: parte entera | F4: Parte decimal | G4: cantidad de decimales | H4: decimales en enteros | I4: restar ultimo numero | J4: Elimar ultimo digito | K4: Dato Final
C5: =RIGHT(F2,2) -> 35 | D5: =LEFT(C5,1) -> 3 | E5: =TRUNC(A3) -> 0 | F5: =FIXED(A3-E5,G5) -> 0,558727844160735 | G5: =ABS(E8-F8) -> 15 | H5: =RIGHT(A3,G5) -> 558727844160735 | I5: 5e-05 | J5: =(A3-I5) -> 0.55867784 | K5: =IF(C7=5,IF(AND(D3=0,D8=FALSE),J5,J6),J6) -> 0,5587
C6: =RIGHT(C5,1) -> 5 | D6: =D5+0 -> 3 | J6: =FIXED(A3,4) -> 0,5587
C7: =C6+0 -> 5 | D7: es impar? | E7: Largo dato original | F7: largo parte enetero y decimal
D8: =ISODD(D5) -> TRUE | E8: =LEN(A3) -> 17 | F8: =LEN(E5)+1 -> 2
A10: 4 Decimales
A11: =K5 -> 0,5587 | C11: =FIXED(A3,5) -> 0,55873 | D11: =RIGHT(C11,1) -> 3 | E11: =D11+0 -> 3
C12: Extrae el ultimo digito | D12: extrael primer digito | E12: parte entera | F12: Parte decimal | G12: cantidad de decimales | H12: decimales en enteros | I12: restar ultimo numero | J12: Elimar ultimo digito | K12: Dato Final
C13: =RIGHT(A11,2) -> 87 | D13: =LEFT(C13,1) -> 8 | E13: =TRUNC(A11) -> 0 | F13: =FIXED(A11-E13,G13) -> 0,5587 | G13: =ABS(E16-F16) -> 4 | H13: =RIGHT(A11,G13) -> 5587 | I13: 0.0005 | J13: =(A11-I13) -> 0.5582 | K13: =IF(C15=5,IF(AND(E11=0,D16=FALSE),J13,J14),J14) -> 0,559
C14: =RIGHT(C13,1) -> 7 | D14: =D13+0 -> 8 | J14: =FIXED(A11,3) -> 0,559
C15: =C14+0 -> 7 | D15: es impar? | E15: Largo dato original | F15: largo parte enetero y decimal
D16: =ISODD(D13) -> FALSE | E16: =LEN(A11) -> 6 | F16: =LEN(E13)+1 -> 2
A18: 3 Decimales
A19: =K13 -> 0,559 | C19: =FIXED(A11,4) -> 0,5587 | D19: =RIGHT(C19,1) -> 7 | E19: =D19+0 -> 7
C20: Extrae el ultimo digito | D20: extrael primer digito | E20: parte entera | F20: Parte decimal | G20: cantidad de decimales | H20: decimales en enteros | I20: restar ultimo numero | J20: Elimar ultimo digito | K20: Dato Final
C21: =RIGHT(A19,2) -> 59 | D21: =LEFT(C21,1) -> 5 | E21: =TRUNC(A19) -> 0 | F21: =FIXED(A19-E21,G21) -> 0,559 | G21: =ABS(E24-F24) -> 3 | H21: =RIGHT(A19,G21) -> 559 | I21: 0.005 | J21: =(A19-I21) -> 0.554 | K21: =IF(C23=5,IF(AND(E19=0,D24=FALSE),J21,J22),J22) -> 0,56
C22: =RIGHT(C21,1) -> 9 | D22: =D21+0 -> 5 | J22: =FIXED(A19,2) -> 0,56
C23: =C22+0 -> 9 | D23: es impar? | E23: Largo dato original | F23: largo parte enetero y decimal
D24: =ISODD(D21) -> TRUE | E24: =LEN(A19) -> 5 | F24: =LEN(E21)+1 -> 2
A26: 2 Decimales
A27: =K21 -> 0,56 | C27: =FIXED(A19,3) -> 0,559 | D27: =RIGHT(C27,1) -> 9 | E27: =D27+0 -> 9
C28: Extrae el ultimo digito | D28: extrael primer digito | E28: parte entera | F28: Parte decimal | G28: cantidad de decimales | H28: decimales en enteros | I28: restar ultimo numero | J28: Elimar ultimo digito | K28: Dato Final
C29: =RIGHT(A27,2) -> 56 | D29: =LEFT(C29,1) -> 5 | E29: =TRUNC(A27) -> 0 | F29: =FIXED(A27-E29,G29) -> 0,56 | G29: =ABS(E32-F32) -> 2 | H29: =RIGHT(A27,G29) -> 56 | I29: 0.05 | J29: =(A27-I29) -> 0.51 | K29: =IF(C31=5,IF(AND(E27=0,D32=FALSE),J29,J30),J30) -> 0,6
C30: =RIGHT(C29,1) -> 6 | D30: =D29+0 -> 5 | J30: =FIXED(A27,1) -> 0,6
C31: =C30+0 -> 6 | D31: es impar? | E31: Largo dato original | F31: largo parte enetero y decimal
D32: =ISODD(D29) -> TRUE | E32: =LEN(A27) -> 4 | F32: =LEN(E29)+1 -> 2
A34: 1 Decimales
A35: =K29 -> 0,6 | C35: =FIXED(A27,2) -> 0,56 | D35: =RIGHT(C35,1) -> 6 | E35: =D35+0 -> 6
C36: Extrae el ultimo digito | D36: extrael primer digito | E36: parte entera | F36: Parte decimal | G36: cantidad de decimales | H36: decimales en enteros | I36: restar ultimo numero | J36: Elimar ultimo digito | K36: Dato Final
C37: =RIGHT(A35,2) -> ,6 | D37: =RIGHT(E37,1) -> 0 | E37: =TRUNC(A35) -> 0 | F37: =FIXED(A35-E37,G37) -> 0,6 | G37: =ABS(E40-F40) -> 1 | H37: =RIGHT(A35,G37) -> 6 | I37: 0.5 | J37: =(A35-I37) -> 0.1 | K37: =IF(C39=5,IF(AND(E35=0,D40=FALSE),J37,J38),J38) -> 1
C38: =RIGHT(C37,1) -> 6 | D38: =D37+0 -> 0 | J38: =FIXED(A35,0) -> 1
C39: =C38+0 -> 6 | D39: es impar? | E39: Largo dato original | F39: largo parte enetero y decimal
D40: =ISODD(D37) -> FALSE | E40: =LEN(A35) -> 3 | F40: =LEN(E37)+1 -> 2
A41: DATO 2
A42: Dato | B42: Dato redondeado | C42: =FIXED(A43,6) -> 0,558728 | D42: =RIGHT(C42,1) -> 8 | E42: =D42/1000000 -> 8e-06 | F42: =A43-E42 -> 0.55871984 | H42: =IF(C47=5,IF(AND(D43=0,D48=FALSE),J45,J46),J46) -> 0,5587
A43: =INCERTIDUMBRE!L6 -> 0.55872784 | B43: =IF(A43>=10,K77,IF(A43>=1,K69,IF(A43>=0.1,K61,IF(A43>=0.01,K53,IF(A43>=0.001,K45))))) -> 0,56 | C43: 6 decimal | D43: =D42+0 -> 8
C44: Extrae el ultimo digito | D44: extrael primer digito | E44: parte entera | F44: Parte decimal | G44: cantidad de decimales | H44: decimales en enteros | I44: restar ultimo numero | J44: Elimar ultimo digito | K44: Dato Final
...

Sheet PATRON
C3: Nominal | D3: Medido | E3: Corrección | F3: Incertidumbre | G3: k | H3: Correcion estimada | I3: Residuales | J3: N-M-1 | K3: u interpolación | M3: Nominal | N3: Medido | O3: Corrección | P3: Incertidumbre | Q3: k | R3: Correcion estimada | S3: Residuales | T3: N-M-1 | U3: u interpolación
C4: 24.714 | D4: 24.3 | E4: =C4-D4 -> 0.414 | F4: 0.28 | G4: 2 | H4: =$K$9*D4^2-$K$10*D4+$K$11 -> 0.414 | I4: =E4-H4 -> 1.6653345e-15 | J4: =6-3-1 -> 2 | K4: =(SQRT(SUMSQ(I4:I14)/J4)) -> 1.7919013e-15 | M4: 30.679 | N4: 42.2 | O4: =M4-N4 -> -11.521 | P4: 0.0077 | Q4: 2 | R4: =$T$9*N4^2-$T$10*N4-$T$11 -> -11.550976 | S4: =O4-R4 -> 0.029976 | T4: =6-3-1 -> 2 | U4: =(SQRT(SUMSQ(S4:S14)/T4)) -> 0.098831104
C5: 30.474 | D5: 29.9 | E5: =C5-D5 -> 0.574 | F5: 0.28 | G5: 2 | H5: =$K$9*D5^2-$K$10*D5+$K$11 -> 0.574 | I5: =E5-H5 -> 1.5543122e-15 | M5: 50.405 | N5: 59.9 | O5: =M5-N5 -> -9.495 | P5: 0.0077 | Q5: 2 | R5: =$T$9*N5^2-$T$10*N5-$T$11 -> -9.556009 | S5: =O5-R5 -> 0.061009
C6: 36.279 | D6: 35.5 | E6: =C6-D6 -> 0.779 | F6: 0.3 | G6: 2 | H6: =$K$9*D6^2-$K$10*D6+$K$11 -> 0.779 | I6: =E6-H6 -> 1.110223e-15 | M6: 80.024 | N6: 84.5 | O6: =M6-N6 -> -4.476 | P6: 0.0077 | Q6: 2 | R6: =$T$9*N6^2-$T$10*N6-$T$11 -> -4.598125 | S6: =O6-R6 -> 0.122125
K9: 0.00071747449 | T9: 0.0021
K10: 0.010315689 | T10: 0.1017
K11: 0.24100973 | T11: 10.999
B34: EQUIPO PATRÓN
B35: Equipo patrón: | G35: Datalogger de Temperatura y Humedad
B36: Marca: | G36: Elitech
B37: Modelo: | G37: RC-51H
B38: Serie: | G38: HM1201000197
B39: Fecha de Calibración: | G39: 44986
B40: No. Certificado: | G40: 242208
B41: Incertidumbre temperatura: | G41: 0.3
A42: 1.8 | B42: Incertidumbre humedad: | G42: 1.8
B43: Deriva temperatura | G43: 0.4
B44: Deriva humedad | G44: 1
B45: Resolución temperatura | G45: 0.1
B46: Resolución humedad | G46: 0.1
B47: Factor de cobertura K: | G47: 2

Sheet MEDIDA
B2: CALIBRACIÓN DE TEMPERATURA AMBIENTE | O2: CORRECCIÓN CALIBRACIÓN DE TEMPERATURA AMBIENTE
B3: Temperatura (°C) | D3: Patrón (°C) | F3: EBP (°C) | O3: Temperatura (°C) | Q3: Patrón (°C) | S3: EBP (°C) | U3: Error (°C)
B4: T1 | D4: =34.5 + RAND() * 0.5 -> 34.958039 | F4: 35 | I4: T1 | M4: T2 | O4: T1 | Q4: =D4 -> 34.958039 | S4: =F4 -> 35 | U4: =S4-Q4 -> 0.041961195
B5: T2 | D5: =MAX(34.5, MIN(34.98, D4 + (RAND() * 0.4 - 0.2))) -> 34.799878 | F5: 35 | K5: T5 | O5: T2 | Q5: =D5 -> 34.799878 | S5: =F5 -> 35 | U5: =S5-Q5 -> 0.20012168
B6: T3 | D6: =MAX(34.5, MIN(34.98, D5 + (RAND() * 0.4 - 0.2))) -> 34.897509 | F6: 35 | I6: T3 | M6: T4 | O6: T3 | Q6: =D6 -> 34.897509 | S6: =F6 -> 35 | U6: =S6-Q6 -> 0.10249131
B7: T4 | D7: =MAX(34.5, MIN(34.98, D6 + (RAND() * 0.4 - 0.2))) -> 34.75336 | F7: 35 | O7: T4 | Q7: =D7 -> 34.75336 | S7: =F7 -> 35 | U7: =S7-Q7 -> 0.24664007
B8: T5 | D8: =MAX(34.5, MIN(34.98, D7 + (RAND() * 0.4 - 0.2))) -> 34.5784 | F8: 35 | O8: T5 | Q8: =D8 -> 34.5784 | S8: =F8 -> 35 | U8: =S8-Q8 -> 0.42160037
B11: CALIBRACIÓN SENSOR DE PIEL | O11: CORRECCIÓN CALIBRACIÓN SENSOR DE PIEL
B12: Temperatura (°C) | D12: Patrón (°C) | F12: EBP (°C) | O12: Temperatura (°C) | Q12: Patrón (°C) | S12: EBP (°C) | U12: Error (°C)
B13: T1 | D13: =D4 -> 34.958039 | F13: =D13 + RAND() * 0.5 -> 35.306954 | I13: T1 | M13: T2 | O13: T1 | Q13: =D13 -> 34.958039 | S13: =F13 -> 35.306954 | U13: =S13-Q13 -> 0.3489153
B14: T2 | D14: =D5 -> 34.799878 | F14: =MAX(D14, MIN(D14 + 0.5, F13 + (RAND() * 0.4 - 0.2))) -> 35.299878 | K14: T5 | O14: T2 | Q14: =D14 -> 34.799878 | S14: =F14 -> 35.299878 | U14: =S14-Q14 -> 0.5
B15: T3 | D15: =D6 -> 34.897509 | F15: =MAX(D15, MIN(D15 + 0.5, F13 + (RAND() * 0.4 - 0.2))) -> 35.35659 | I15: T3 | M15: T4 | O15: T3 | Q15: =D15 -> 34.897509 | S15: =F15 -> 35.35659 | U15: =S15-Q15 -> 0.45908156
B16: T4 | D16: =D7 -> 34.75336 | F16: =MAX(D16, MIN(D16 + 0.5, F13 + (RAND() * 0.4 - 0.2))) -> 35.25336 | O16: T4 | Q16: =D16 -> 34.75336 | S16: =F16 -> 35.25336 | U16: =S16-Q16 -> 0.5
B17: T5 | D17: =D8 -> 34.5784 | F17: =MAX(D17, MIN(D17 + 0.5, F13 + (RAND() * 0.4 - 0.2))) -> 35.0784 | O17: T5 | Q17: =D17 -> 34.5784 | S17: =F17 -> 35.0784 | U17: =S17-Q17 -> 0.5
B20: CALIBRACIÓN DE HUMEDAD | O20: CORRECCIÓN CALIBRACIÓN DE HUMEDAD
B21: Humedad (%hr) | D21: Patrón (%hr) | F21: EBP (%hr) | O21: Humedad (%hr) | Q21: Patrón (%hr) | S21: EBP (%hr) | U21: Error (%hr)
B22: H1 | D22: =76.5 + (82.5 - 76.5) * RAND() -> 77.636969 | F22: 80 | I22: T1 | M22: T2 | O22: H1 | Q22: =D22 -> 77.636969 | S22: =F22 -> 80 | U22: =S22-Q22 -> 2.3630311
B23: H2 | D23: =D22 + (RAND() * 2 - 1) -> 78.021498 | F23: 80 | K23: T5 | O23: H2 | Q23: =D23 -> 78.021498 | S23: =F23 -> 80 | U23: =S23-Q23 -> 1.9785022
B24: H3 | D24: =D22 + (RAND() * 2 - 1) -> 77.262445 | F24: 80 | I24: T3 | M24: T4 | O24: H3 | Q24: =D24 -> 77.262445 | S24: =F24 -> 80 | U24: =S24-Q24 -> 2.7375551
B25: H4 | D25: =D22 + (RAND() * 2 - 1) -> 77.484789 | F25: 80 | O25: H4 | Q25: =D25 -> 77.484789 | S25: =F25 -> 80 | U25: =S25-Q25 -> 2.5152111
B26: H5 | D26: =D22 + (RAND() * 2 - 1) -> 77.272304 | F26: 80 | O26: H5 | Q26: =D26 -> 77.272304 | S26: =F26 -> 80 | U26: =S26-Q26 -> 2.7276958

Sheet INCERTIDUMBRE
B2: FUENTES DE INCERTIDUMBRE TEMPERATURA AMBIENTE
B3: Punto de calibración | C3: Cert de calibración | D3: Deriva | E3: Interpolación | F3: Resolución item | G3: Resolución patrón | H3: Repetibilidad | I3: Incertidumbre combinada | J3: Veff | K3: Factor de cobertura (k) | L3: Incertidumbre Expandida
B4: =MEDIDA!B4 -> T1 | C4: =PATRON!$G$41/2 -> 0.15 | D4: =PATRON!$G$43/SQRT(3) -> 0.23094011 | E4: 0 | F4: =0.1/SQRT(12) -> 0.028867513 | G4: =PATRON!$G$45/SQRT(12) -> 0.028867513 | H4: 0 | I4: =SQRT(SUMSQ(C4:H4)) -> 0.27838822 | J4: =I4^4/(C4^4/200+D4^4/200+E4^4/200+F4^4/200+G4^4/200+H4^4/3) -> 358.35923 | K4: =TINV(0.0455,J4) -> 2.0070097 | L4: =I4*K4 -> 0.55872784
B5: =MEDIDA!B5 -> T2 | C5: =PATRON!$G$41/2 -> 0.15 | D5: =PATRON!$G$43/SQRT(3) -> 0.23094011 | E5: 0 | F5: =0.1/SQRT(12) -> 0.028867513 | G5: =PATRON!$G$45/SQRT(12) -> 0.028867513 | H5: 0 | I5: =SQRT(SUMSQ(C5:H5)) -> 0.27838822 | J5: =I5^4/(C5^4/200+D5^4/200+E5^4/200+F5^4/200+G5^4/200+H5^4/3) -> 358.35923 | K5: =TINV(0.0455,J5) -> 2.0070097 | L5: =I5*K5 -> 0.55872784
B6: =MEDIDA!B6 -> T3 | C6: =PATRON!$G$41/2 -> 0.15 | D6: =PATRON!$G$43/SQRT(3) -> 0.23094011 | E6: 0 | F6: =0.1/SQRT(12) -> 0.028867513 | G6: =PATRON!$G$45/SQRT(12) -> 0.028867513 | H6: 0 | I6: =SQRT(SUMSQ(C6:H6)) -> 0.27838822 | J6: =I6^4/(C6^4/200+D6^4/200+E6^4/200+F6^4/200+G6^4/200+H6^4/3) -> 358.35923 | K6: =TINV(0.0455,J6) -> 2.0070097 | L6: =I6*K6 -> 0.55872784
B7: =MEDIDA!B7 -> T4 | C7: =PATRON!$G$41/2 -> 0.15 | D7: =PATRON!$G$43/SQRT(3) -> 0.23094011 | E7: 0 | F7: =0.1/SQRT(12) -> 0.028867513 | G7: =PATRON!$G$45/SQRT(12) -> 0.028867513 | H7: 0 | I7: =SQRT(SUMSQ(C7:H7)) -> 0.27838822 | J7: =I7^4/(C7^4/200+D7^4/200+E7^4/200+F7^4/200+G7^4/200+H7^4/3) -> 358.35923 | K7: =TINV(0.0455,J7) -> 2.0070097 | L7: =I7*K7 -> 0.55872784
B8: =MEDIDA!B8 -> T5 | C8: =PATRON!$G$41/2 -> 0.15 | D8: =PATRON!$G$43/SQRT(3) -> 0.23094011 | E8: 0 | F8: =0.1/SQRT(12) -> 0.028867513 | G8: =PATRON!$G$45/SQRT(12) -> 0.028867513 | H8: 0 | I8: =SQRT(SUMSQ(C8:H8)) -> 0.27838822 | J8: =I8^4/(C8^4/200+D8^4/200+E8^4/200+F8^4/200+G8^4/200+H8^4/3) -> 358.35923 | K8: =TINV(0.0455,J8) -> 2.0070097 | L8: =I8*K8 -> 0.55872784
B10: FUENTES DE INCERTIDUMBRE TEMPERATURA SENSOR DE PIEL
B11: Punto de calibración | C11: Cert de calibración | D11: Deriva | E11: Interpolación | F11: Resolución item | G11: Resolución patrón | H11: Repetibilidad | I11: Incertidumbre combinada | J11: Veff | K11: Factor de cobertura (k) | L11: Incertidumbre Expandida
B12: =MEDIDA!B13 -> T1 | C12: =PATRON!$G$41/2 -> 0.15 | D12: =PATRON!$G$43/SQRT(3) -> 0.23094011 | E12: 0 | F12: =0.1/SQRT(12) -> 0.028867513 | G12: =PATRON!$G$45/SQRT(12) -> 0.028867513 | H12: 0 | I12: =SQRT(SUMSQ(C12:H12)) -> 0.27838822 | J12: =I12^4/(C12^4/200+D12^4/200+E12^4/200+F12^4/200+G12^4/200+H12^4/3) -> 358.35923 | K12: =TINV(0.0455,J12) -> 2.0070097 | L12: =I12*K12 -> 0.55872784
B13: =MEDIDA!B14 -> T2 | C13: =PATRON!$G$41/2 -> 0.15 | D13: =PATRON!$G$43/SQRT(3) -> 0.23094011 | E13: 0 | F13: =0.1/SQRT(12) -> 0.028867513 | G13: =PATRON!$G$45/SQRT(12) -> 0.028867513 | H13: 0 | I13: =SQRT(SUMSQ(C13:H13)) -> 0.27838822 | J13: =I13^4/(C13^4/200+D13^4/200+E13^4/200+F13^4/200+G13^4/200+H13^4/3) -> 358.35923 | K13: =TINV(0.0455,J13) -> 2.0070097 | L13: =I13*K13 -> 0.55872784
B14: =MEDIDA!B15 -> T3 | C14: =PATRON!$G$41/2 -> 0.15 | D14: =PATRON!$G$43/SQRT(3) -> 0.23094011 | E14: 0 | F14: =0.1/SQRT(12) -> 0.028867513 | G14: =PATRON!$G$45/SQRT(12) -> 0.028867513 | H14: 0 | I14: =SQRT(SUMSQ(C14:H14)) -> 0.27838822 | J14: =I14^4/(C14^4/200+D14^4/200+E14^4/200+F14^4/200+G14^4/200+H14^4/3) -> 358.35923 | K14: =TINV(0.0455,J14) -> 2.0070097 | L14: =I14*K14 -> 0.55872784
B15: =MEDIDA!B16 -> T4 | C15: =PATRON!$G$41/2 -> 0.15 | D15: =PATRON!$G$43/SQRT(3) -> 0.23094011 | E15: 0 | F15: =0.1/SQRT(12) -> 0.028867513 | G15: =PATRON!$G$45/SQRT(12) -> 0.028867513 | H15: 0 | I15: =SQRT(SUMSQ(C15:H15)) -> 0.27838822 | J15: =I15^4/(C15^4/200+D15^4/200+E15^4/200+F15^4/200+G15^4/200+H15^4/3) -> 358.35923 | K15: =TINV(0.0455,J15) -> 2.0070097 | L15: =I15*K15 -> 0.55872784
B16: =MEDIDA!B17 -> T5 | C16: =PATRON!$G$41/2 -> 0.15 | D16: =PATRON!$G$43/SQRT(3) -> 0.23094011 | E16: 0 | F16: =0.1/SQRT(12) -> 0.028867513 | G16: =PATRON!$G$45/SQRT(12) -> 0.028867513 | H16: 0 | I16: =SQRT(SUMSQ(C16:H16)) -> 0.27838822 | J16: =I16^4/(C16^4/200+D16^4/200+E16^4/200+F16^4/200+G16^4/200+H16^4/3) -> 358.35923 | K16: =TINV(0.0455,J16) -> 2.0070097 | L16: =I16*K16 -> 0.55872784
B18: FUENTES DE INCERTIDUMBRE HUMEDAD
B19: Punto de calibración | C19: Cert de calibración | D19: Deriva | E19: Interpolación | F19: Resolución item | G19: Resolución patrón | H19: Repetibilidad | I19: Incertidumbre combinada | J19: Veff | K19: Factor de cobertura (k) | L19: Incertidumbre Expandida
B20: =MEDIDA!B22 -> H1 | C20: =PATRON!$G$42/2 -> 0.9 | D20: =PATRON!$G$44/SQRT(3) -> 0.57735027 | E20: 0 | F20: =1/SQRT(12) -> 0.28867513 | G20: =PATRON!$G$46/SQRT(12) -> 0.028867513 | H20: 0 | I20: =SQRT(SUMSQ(C20:H20)) -> 1.107926 | J20: =I20^4/(C20^4/200+D20^4/200+E20^4/200+F20^4/200+G20^4/200+H20^4/3) -> 389.26412 | K20: =TINV(0.0455,J20) -> 2.0064495 | L20: =I20*K20 -> 2.2229975
B21: =MEDIDA!B23 -> H2 | C21: =PATRON!$G$42/2 -> 0.9 | D21: =PATRON!$G$44/SQRT(3) -> 0.57735027 | E21: 0 | F21: =1/SQRT(12) -> 0.28867513 | G21: =PATRON!$G$46/SQRT(12) -> 0.028867513 | H21: 0 | I21: =SQRT(SUMSQ(C21:H21)) -> 1.107926 | J21: =I21^4/(C21^4/200+D21^4/200+E21^4/200+F21^4/200+G21^4/200+H21^4/3) -> 389.26412 | K21: =TINV(0.0455,J21) -> 2.0064495 | L21: =I21*K21 -> 2.2229975
B22: =MEDIDA!B24 -> H3 | C22: =PATRON!$G$42/2 -> 0.9 | D22: =PATRON!$G$44/SQRT(3) -> 0.57735027 | E22: 0 | F22: =1/SQRT(12) -> 0.28867513 | G22: =PATRON!$G$46/SQRT(12) -> 0.028867513 | H22: 0 | I22: =SQRT(SUMSQ(C22:H22)) -> 1.107926 | J22: =I22^4/(C22^4/200+D22^4/200+E22^4/200+F22^4/200+G22^4/200+H22^4/3) -> 389.26412 | K22: =TINV(0.0455,J22) -> 2.0064495 | L22: =I22*K22 -> 2.2229975
B23: =MEDIDA!B25 -> H4 | C23: =PATRON!$G$42/2 -> 0.9 | D23: =PATRON!$G$44/SQRT(3) -> 0.57735027 | E23: 0 | F23: =1/SQRT(12) -> 0.28867513 | G23: =PATRON!$G$46/SQRT(12) -> 0.028867513 | H23: 0 | I23: =SQRT(SUMSQ(C23:H23)) -> 1.107926 | J23: =I23^4/(C23^4/200+D23^4/200+E23^4/200+F23^4/200+G23^4/200+H23^4/3) -> 389.26412 | K23: =TINV(0.0455,J23) -> 2.0064495 | L23: =I23*K23 -> 2.2229975
B24: =MEDIDA!B26 -> H5 | C24: =PATRON!$G$42/2 -> 0.9 | D24: =PATRON!$G$44/SQRT(3) -> 0.57735027 | E24: 0 | F24: =1/SQRT(12) -> 0.28867513 | G24: =PATRON!$G$46/SQRT(12) -> 0.028867513 | H24: 0 | I24: =SQRT(SUMSQ(C24:H24)) -> 1.107926 | J24: =I24^4/(C24^4/200+D24^4/200+E24^4/200+F24^4/200+G24^4/200+H24^4/3) -> 389.26412 | K24: =TINV(0.0455,J24) -> 2.0064495 | L24: =I24*K24 -> 2.2229975

Sheet CERTIFICADO 
O1: CERTIFICADO N°: | R1: =INFORMACIÓN!G3 -> 0
C3: 1. EQUIPO BAJO PRUEBA
C5: INSTRUMENTO: | I5: =INFORMACIÓN!A3 -> 0
C6: MARCA: | I6: =INFORMACIÓN!B3 -> 0
C7: MODELO: | I7: =INFORMACIÓN!C3 -> 0
C8: SERIE: | I8: =INFORMACIÓN!D3 -> 0
C9: CÓDIGO INTERNO: | I9: =INFORMACIÓN!F3 -> 0
C10: UBICACIÓN: | I10: =INFORMACIÓN!E3 -> 0
C11: ESTADO FÍSICO: | I11: =INFORMACIÓN!B8 -> BUEN ESTADO
C12: FECHA DE RECEPCIÓN: | I12: =INFORMACIÓN!H3 -> 0
C13: FECHA DE CALIBRACIÓN: | I13: =INFORMACIÓN!B9 -> 0
C15: 2. DATOS DEL CLIENTE
C17: NOMBRE: | I17: =INFORMACIÓN!E7 -> HOSPITAL DE ALTA COMPLEJIDAD DEL MAGDALENA CENTRO
C18: NIT: | I18: =INFORMACIÓN!E8 -> 901.532.463-8
C19: TELÉFONO: | I19: =INFORMACIÓN!E9 -> 3007835072
C20: DIRECCIÓN: | I20: =INFORMACIÓN!E10 -> CARRERA 15 ENTRE CALLE 18 y 19
C21: CIUDAD: | I21: =INFORMACIÓN!E11 -> LA DORADA - CALDAS
C23: Este certificado expresa fielmente el resultado de las mediciones realizadas; no podrá ser reproducido total o parcialmente excepto cuando se haya obtenido permiso por escrito de BTM COLOMBIA ZOMAC S.A.S y se debe reproducir en su totalidad, para proporcionar seguridad de que el certificado no sea sacado de contexto. Los resultados que se encuentran en este certificado se refieren al momento y condiciones en que se realizaron las mediciones, BTM COLOMBIA ZOMAC S.A.S no se responsabiliza de los daños que puedan ser causados por el uso inadecuado de los equipos calibrados. El usuario es responsable de la calibración de sus instrumentos a intervalos apropiados. El laboratorio no se hace responsable por cómo la información suministrada por el cliente afecte los resultados de medición.
C31: REVISÓ Y AUTORIZÓ: | I31: CALIBRADO POR: | M31: =INFORMACIÓN!B15 -> ING. GABRIEL DURÁN
I32: FECHA DE EMISIÓN: | M32: =INFORMACIÓN!B10 -> 0
I33: NÚMERO DE PÁGINAS: | M33: 4
C36: ING. JOHAN SEBASTIÁN PÉREZ
C37: DIRECTOR DE LABORATORIO
O38: =O1 -> CERTIFICADO N°: | R38: =R1 -> 0
B40: 3. CONDICIONES AMBIENTALES
B41: El laboratorio de metrología BTM COLOMBIA ZOMAC S.A.S registra las condiciones ambientales (Humedad y Temperatura) tomando los máximos y mínimos alcanzados durante el tiempo en que se ejecuta la calibración. A continuación se presenta el promedio y la variación resultante.
F45: TEMPERATURA AMBIENTE (°C) | K45: HUMEDAD RELATIVA (%HR)
F46: =AVERAGE(INFORMACIÓN!B11:B12) -> 24.3 | H46: ± | I46: =ABS(INFORMACIÓN!B11-INFORMACIÓN!B12) -> 0.4 | K46: =AVERAGE(INFORMACIÓN!B13:B14) -> 61.5 | M46: ± | N46: =ABS(INFORMACIÓN!B13-INFORMACIÓN!B14) -> 3
F48: La calibración fue realizada en: | K48: En sitio (instalaciones del cliente)
B50: 4. INCERTIDUMBRE DE MEDICIÓN
B51: La incertidumbre expandida de la medición reportada se establece como la incertidumbre estándar de medición multiplicada por el factor de cobertura “k” y la probabilidad de cobertura, la cual debe ser aproximada al 95% y no menor a este valor. La incertidumbre de medición ha sido estimada con un nivel de confianza del 95,45% empleando una distribución t de student. Cuando se hace declaración de cumplimiento, el laboratorio hace referencia a las especificaciones del fabricante, norma o requisitos declarados por el cliente. La regla de decisión aplicada en estos casos será |Error| +U ≤ EMP según la ASME B89 7.3.1, si cumple la anterior condición la medición se toma como conforme y registrará un pasa, en caso contrario se registrará falla. La probabilidad de dar una aceptación falsa o un rechazo falso no lo determina el laboratorio, sin embargo se puede calcular de acuerdo a la guía JCGM 106:2012 según su numeral 8.
B60: 5. PROCEDIMIENTO DE CALIBRACIÓN
B61: La calibración se ejecutó mediante el método de comparación directa con patrón de referencia de acuerdo con el procedimiento interno para incubadoras BTM-P-007.
B64: 6. TRAZABILIDAD
B65: El laboratorio BTM COLOMBIA ZOMAC S.A.S establece la trazabilidad metrológica de sus mediciones al sistema internacional de unidades (SI), por medio de una cadena documentada de calibraciones, las cuales se encuentran referenciadas a patrones de medidas primarios. Esta vinculación se logra a través del uso de patrones calibrados por institutos nacionales de metrología (INM) y por laboratorios acreditados por parte de un organismo de acreditación.
B70: PATRÓN | H70: SERIE | M70: CALIBRACIÓN | P70: CERTIFICADO
B71: =PATRON!G35 -> Datalogger de Temperatura y Humedad | H71: H12F-J164747 | M71: 46085 | P71: 318690
B72: Datalogger de Temperatura 4 Sondas | H72: 230310997 | M72: 46055 | P72: 319239_A 319239_B 319240_A 319240_B 319241_A 319241_B 319241_A 319242_B
O74: =O1 -> CERTIFICADO N°: | R74: =R1 -> 0
B76: 7. RESULTADOS DE LA CALIBRACIÓN
...
