Workbook
Name Instrumento: '[1]R-LAB-127 DENSIDAD AIRE'!#REF!
Name Instrumento: '[1]R-LAB-127 DENSIDAD AIRE'!#REF!
Name Instrumento.: '[1]R-LAB-127 DENSIDAD AIRE'!#REF!
Name Instrumento.: '[1]R-LAB-127 DENSIDAD AIRE'!#REF!
Name N: #REF!
Name N: #REF!

Sheet INFORMACIÓN
A1: Datos del item | M1: En sitio ( instalaciones del cliente)
A2: Código interno | B2: Intrumento | C2: Marca | D2: Modelo | E2: Serie | F2: Ubicación | G2: Número de Certificado | H2: Fecha de Recepción | M2: Laboratorio BTMC
P4: BUEN ESTADO
A6: Datos de calibración | D6: Datos del cliente
A7: Lugar de calibración: | B7: En sitio ( instalaciones del cliente) | D7: Solicitante:
A8: Estado Físico: | B8: BUEN ESTADO | D8: Nit:
A9: Fecha de calibración: | B9: =H3 -> 0 | D9: Telefono:
A10: Fecha de emisión: | B10: =H3 -> 0 | D10: Dirección:
A11: Temperatura mínima: | B11: 24.1 | D11: Ciudad:
A12: Temperatura máxima: | B12: 24.5
A13: Humedad Mínima: | B13: 60
A14: Humedad Máxima: | B14: 63
A15: Calibración realiza por: | B15: ING. GABRIEL DURÁN

Sheet Redondeo
A1: DATO 1
A2: Dato | B2: Dato redondeado | C2: =FIXED(A3,6) -> 0,828372 | D2: =RIGHT(C2,1) -> 2 | E2: =D2/1000000 -> 2e-06 | F2: =A3-E2 -> 0.8283695 | H2: =IF(C7=5,IF(AND(D3=0,D8=FALSE),J5,J6),J6) -> 0,8284
A3: =INCERTIDUMBRE!L5 -> 0.8283715 | B3: =IF(A3>=10,K37,IF(A3>=1,K29,IF(A3>=0.1,K21,IF(A3>=0.01,K13,IF(A3>=0.001,K5))))) -> 0,83 | C3: 6 decimal | D3: =D2+0 -> 2
C4: Extrae el ultimo digito | D4: extrael primer digito | E4: parte entera | F4: Parte decimal | G4: cantidad de decimales | H4: decimales en enteros | I4: restar ultimo numero | J4: Elimar ultimo digito | K4: Dato Final
C5: =RIGHT(F2,2) -> 85 | D5: =LEFT(C5,1) -> 8 | E5: =TRUNC(A3) -> 0 | F5: =FIXED(A3-E5,G5) -> 0,828371503936585 | G5: =ABS(E8-F8) -> 15 | H5: =RIGHT(A3,G5) -> 828371503936585 | I5: 5e-05 | J5: =(A3-I5) -> 0.8283215 | K5: =IF(C7=5,IF(AND(D3=0,D8=FALSE),J5,J6),J6) -> 0,8284
C6: =RIGHT(C5,1) -> 5 | D6: =D5+0 -> 8 | J6: =FIXED(A3,4) -> 0,8284
C7: =C6+0 -> 5 | D7: es impar? | E7: Largo dato original | F7: largo parte enetero y decimal
D8: =ISODD(D5) -> FALSE | E8: =LEN(A3) -> 17 | F8: =LEN(E5)+1 -> 2
A10: 4 Decimales
A11: =K5 -> 0,8284 | C11: =FIXED(A3,5) -> 0,82837 | D11: =RIGHT(C11,1) -> 7 | E11: =D11+0 -> 7
C12: Extrae el ultimo digito | D12: extrael primer digito | E12: parte entera | F12: Parte decimal | G12: cantidad de decimales | H12: decimales en enteros | I12: restar ultimo numero | J12: Elimar ultimo digito | K12: Dato Final
C13: =RIGHT(A11,2) -> 84 | D13: =LEFT(C13,1) -> 8 | E13: =TRUNC(A11) -> 0 | F13: =FIXED(A11-E13,G13) -> 0,8284 | G13: =ABS(E16-F16) -> 4 | H13: =RIGHT(A11,G13) -> 8284 | I13: 0.0005 | J13: =(A11-I13) -> 0.8279 | K13: =IF(C15=5,IF(AND(E11=0,D16=FALSE),J13,J14),J14) -> 0,828
C14: =RIGHT(C13,1) -> 4 | D14: =D13+0 -> 8 | J14: =FIXED(A11,3) -> 0,828
C15: =C14+0 -> 4 | D15: es impar? | E15: Largo dato original | F15: largo parte enetero y decimal
D16: =ISODD(D13) -> FALSE | E16: =LEN(A11) -> 6 | F16: =LEN(E13)+1 -> 2
A18: 3 Decimales
A19: =K13 -> 0,828 | C19: =FIXED(A11,4) -> 0,8284 | D19: =RIGHT(C19,1) -> 4 | E19: =D19+0 -> 4
C20: Extrae el ultimo digito | D20: extrael primer digito | E20: parte entera | F20: Parte decimal | G20: cantidad de decimales | H20: decimales en enteros | I20: restar ultimo numero | J20: Elimar ultimo digito | K20: Dato Final
C21: =RIGHT(A19,2) -> 28 | D21: =LEFT(C21,1) -> 2 | E21: =TRUNC(A19) -> 0 | F21: =FIXED(A19-E21,G21) -> 0,828 | G21: =ABS(E24-F24) -> 3 | H21: =RIGHT(A19,G21) -> 828 | I21: 0.005 | J21: =(A19-I21) -> 0.823 | K21: =IF(C23=5,IF(AND(E19=0,D24=FALSE),J21,J22),J22) -> 0,83
C22: =RIGHT(C21,1) -> 8 | D22: =D21+0 -> 2 | J22: =FIXED(A19,2) -> 0,83
C23: =C22+0 -> 8 | D23: es impar? | E23: Largo dato original | F23: largo parte enetero y decimal
D24: =ISODD(D21) -> FALSE | E24: =LEN(A19) -> 5 | F24: =LEN(E21)+1 -> 2
A26: 2 Decimales
A27: =K21 -> 0,83 | C27: =FIXED(A19,3) -> 0,828 | D27: =RIGHT(C27,1) -> 8 | E27: =D27+0 -> 8
C28: Extrae el ultimo digito | D28: extrael primer digito | E28: parte entera | F28: Parte decimal | G28: cantidad de decimales | H28: decimales en enteros | I28: restar ultimo numero | J28: Elimar ultimo digito | K28: Dato Final
C29: =RIGHT(A27,2) -> 83 | D29: =LEFT(C29,1) -> 8 | E29: =TRUNC(A27) -> 0 | F29: =FIXED(A27-E29,G29) -> 0,83 | G29: =ABS(E32-F32) -> 2 | H29: =RIGHT(A27,G29) -> 83 | I29: 0.05 | J29: =(A27-I29) -> 0.78 | K29: =IF(C31=5,IF(AND(E27=0,D32=FALSE),J29,J30),J30) -> 0,8
C30: =RIGHT(C29,1) -> 3 | D30: =D29+0 -> 8 | J30: =FIXED(A27,1) -> 0,8
C31: =C30+0 -> 3 | D31: es impar? | E31: Largo dato original | F31: largo parte enetero y decimal
D32: =ISODD(D29) -> FALSE | E32: =LEN(A27) -> 4 | F32: =LEN(E29)+1 -> 2
A34: 1 Decimales
A35: =K29 -> 0,8 | C35: =FIXED(A27,2) -> 0,83 | D35: =RIGHT(C35,1) -> 3 | E35: =D35+0 -> 3
C36: Extrae el ultimo digito | D36: extrael primer digito | E36: parte entera | F36: Parte decimal | G36: cantidad de decimales | H36: decimales en enteros | I36: restar ultimo numero | J36: Elimar ultimo digito | K36: Dato Final
C37: =RIGHT(A35,2) -> ,8 | D37: =RIGHT(E37,1) -> 0 | E37: =TRUNC(A35) -> 0 | F37: =FIXED(A35-E37,G37) -> 0,8 | G37: =ABS(E40-F40) -> 1 | H37: =RIGHT(A35,G37) -> 8 | I37: 0.5 | J37: =(A35-I37) -> 0.3 | K37: =IF(C39=5,IF(AND(E35=0,D40=FALSE),J37,J38),J38) -> 1
C38: =RIGHT(C37,1) -> 8 | D38: =D37+0 -> 0 | J38: =FIXED(A35,0) -> 1
C39: =C38+0 -> 8 | D39: es impar? | E39: Largo dato original | F39: largo parte enetero y decimal
D40: =ISODD(D37) -> FALSE | E40: =LEN(A35) -> 3 | F40: =LEN(E37)+1 -> 2
A41: DATO 2
A42: Dato | B42: Dato redondeado | C42: =FIXED(A43,6) -> 0,828372 | D42: =RIGHT(C42,1) -> 2 | E42: =D42/1000000 -> 2e-06 | F42: =A43-E42 -> 0.8283695 | H42: =IF(C47=5,IF(AND(D43=0,D48=FALSE),J45,J46),J46) -> 0,8284
A43: =INCERTIDUMBRE!L6 -> 0.8283715 | B43: =IF(A43>=10,K77,IF(A43>=1,K69,IF(A43>=0.1,K61,IF(A43>=0.01,K53,IF(A43>=0.001,K45))))) -> 0,83 | C43: 6 decimal | D43: =D42+0 -> 2
C44: Extrae el ultimo digito | D44: extrael primer digito | E44: parte entera | F44: Parte decimal | G44: cantidad de decimales | H44: decimales en enteros | I44: restar ultimo numero | J44: Elimar ultimo digito | K44: Dato Final
...

Sheet MEDIDA
B1: NIBP | R1: ECG
D2: Medidas del equipo bajo prueba | T2: Medidas del equipo bajo prueba
B3: Patrón (mmHg) | D3: Lectura 1 (mmHg) | F3: Lectura 2 (mmHg) | H3: Lectura 3 (mmHg) | J3: Lectura 4 (mmHg) | L3: Promedio (mmHg) | N3: Error (mmHg) | R3: Patrón (Lat/min) | T3: Lectura 1 (Lat/min) | V3: Lectura 2 (Lat/min) | X3: Lectura 3 (Lat/min) | Z3: Lectura 4 (Lat/min) | AB3: Promedio (Lat/min) | AD3: Error (Lat/min)
B4: 50 | D4: =RANDBETWEEN(49, 50) -> 49 | F4: =D4 -> 49 | H4: =D4 -> 49 | J4: =D4 -> 49 | L4: =AVERAGE(D4:K4) -> 49 | N4: =L4-B4 -> -1 | R4: 30 | T4: 30 | V4: =T4 -> 30 | X4: =V4 -> 30 | Z4: =X4 -> 30 | AB4: =AVERAGE(T4:AA4) -> 30 | AD4: =AB4-R4 -> 0
B5: 100 | D5: =IF((D4 - B4) = 0, IF(RAND() < 0.5, B5, B5 - 1), IF((D4 - B4) = -1, B5 - 1, "Condición no especificada")) -> 99 | F5: =D5 -> 99 | H5: =D5 -> 99 | J5: =D5 -> 99 | L5: =AVERAGE(D5:K5) -> 99 | N5: =L5-B5 -> -1 | R5: 60 | T5: 60 | V5: =T5 -> 60 | X5: =V5 -> 60 | Z5: =X5 -> 60 | AB5: =AVERAGE(T5:AA5) -> 60 | AD5: =AB5-R5 -> 0
B6: 150 | D6: =IF((D5 - B5) = 0, INT(IF(RAND() < 0.5, B6, B6 - 1)), IF((D5 - B5) = -1, B6 - 1, "Condición no especificada")) -> 149 | F6: =D6 -> 149 | H6: =D6 -> 149 | J6: =D6 -> 149 | L6: =AVERAGE(D6:K6) -> 149 | N6: =L6-B6 -> -1 | R6: 120 | T6: 120 | V6: =T6 -> 120 | X6: =V6 -> 120 | Z6: =X6 -> 120 | AB6: =AVERAGE(T6:AA6) -> 120 | AD6: =AB6-R6 -> 0
B7: 200 | D7: =IF((D6 - B6) = 0, INT(IF(RAND() < 0.5, B7, B7 - 1)), IF((D6 - B6) = -1, INT(IF(RAND() < 0.5, B7 - 1, B7 - 2)), B7)) -> 199 | F7: =D7 -> 199 | H7: =D7 -> 199 | J7: =D7 -> 199 | L7: =AVERAGE(D7:K7) -> 199 | N7: =L7-B7 -> -1 | R7: 240 | T7: 240 | V7: =T7 -> 240 | X7: =V7 -> 240 | Z7: =X7 -> 240 | AB7: =AVERAGE(T7:AA7) -> 240 | AD7: =AB7-R7 -> 0
B8: 250 | D8: =IF((D7 - B7) = 0, INT(IF(RAND() < 0.5, B8, B8 - 1)), IF((D7 - B7) = -1, INT(IF(RAND() < 0.5, B8 - 1, B8 - 2)), IF((D7 - B7) = -2, B8 - 2, "Condición no especificada"))) -> 248 | F8: =D8 -> 248 | H8: =D8 -> 248 | J8: =D8 -> 248 | L8: =AVERAGE(D8:K8) -> 248 | N8: =L8-B8 -> -2
B10: IBP 1 | R10: SPO2
D11: Medidas del equipo bajo prueba | T11: Medidas del equipo bajo prueba
B12: Patrón (mmHg) | D12: Lectura 1 (mmHg) | F12: Lectura 2 (mmHg) | H12: Lectura 3 (mmHg) | J12: Lectura 4 (mmHg) | L12: Promedio (mmHg) | N12: Error (mmHg) | R12: Patrón (%) | T12: Lectura 1 (%) | V12: Lectura 2 (%) | X12: Lectura 3 (%) | Z12: Lectura 4 (%) | AB12: Promedio (%) | AD12: Error (%)
B13: 50 | D13: =RANDBETWEEN(49, 50) -> 49 | F13: =D13 -> 49 | H13: =D13 -> 49 | J13: =D13 -> 49 | L13: =AVERAGE(D13:K13) -> 49 | N13: =L13-B13 -> -1 | R13: 80 | T13: =IF(RAND() < 0.7, 80, IF(RAND() < 0.5, 79.5, 80.5)) -> 80.5 | V13: =T13 -> 80.5 | X13: =V13 -> 80.5 | Z13: =X13 -> 80.5 | AB13: =AVERAGE(T13:AA13) -> 80.5 | AD13: =AB13-R13 -> 0.5
B14: 100 | D14: =IF((D13 - B13) = 0, IF(RAND() < 0.5, B14, B14 - 1), IF((D13 - B13) = -1, B14 - 1, "Condición no especificada")) -> 99 | F14: =D14 -> 99 | H14: =D14 -> 99 | J14: =D14 -> 99 | L14: =AVERAGE(D14:K14) -> 99 | N14: =L14-B14 -> -1 | R14: 85 | T14: =IF(RAND() < 0.7, 85, IF(RAND() < 0.5, 84.5, 85.5)) -> 84.5 | V14: =T14 -> 84.5 | X14: =V14 -> 84.5 | Z14: =X14 -> 84.5 | AB14: =AVERAGE(T14:AA14) -> 84.5 | AD14: =AB14-R14 -> -0.5
B15: 150 | D15: =IF((D14 - B14) = 0, INT(IF(RAND() < 0.5, B15, B15 - 1)), IF((D14 - B14) = -1, B15 - 1, "Condición no especificada")) -> 149 | F15: =D15 -> 149 | H15: =D15 -> 149 | J15: =D15 -> 149 | L15: =AVERAGE(D15:K15) -> 149 | N15: =L15-B15 -> -1 | R15: 90 | T15: =IF(RAND() < 0.7, 90, IF(RAND() < 0.5, 89.5, 90.5)) -> 90 | V15: =T15 -> 90 | X15: =V15 -> 90 | Z15: =X15 -> 90 | AB15: =AVERAGE(T15:AA15) -> 90 | AD15: =AB15-R15 -> 0
B16: 200 | D16: =IF((D15 - B15) = 0, INT(IF(RAND() < 0.5, B16, B16 - 1)), IF((D15 - B15) = -1, INT(IF(RAND() < 0.5, B16 - 1, B16 - 2)), B16)) -> 199 | F16: =D16 -> 199 | H16: =D16 -> 199 | J16: =D16 -> 199 | L16: =AVERAGE(D16:K16) -> 199 | N16: =L16-B16 -> -1 | R16: 95 | T16: =IF(RAND() < 0.7, 95, IF(RAND() < 0.5, 94.5, 95.5)) -> 95 | V16: =T16 -> 95 | X16: =V16 -> 95 | Z16: =X16 -> 95 | AB16: =AVERAGE(T16:AA16) -> 95 | AD16: =AB16-R16 -> 0
B17: 250 | D17: =IF((D16 - B16) = 0, INT(IF(RAND() < 0.5, B17, B17 - 1)), IF((D16 - B16) = -1, INT(IF(RAND() < 0.5, B17 - 1, B17 - 2)), IF((D16 - B16) = -2, B17 - 2, "Condición no especificada"))) -> 249 | F17: =D17 -> 249 | H17: =D17 -> 249 | J17: =D17 -> 249 | L17: =AVERAGE(D17:K17) -> 249 | N17: =L17-B17 -> -1 | R17: 99 | T17: =ROUNDUP(RANDBETWEEN(196, 200)/2, 1) -> 98 | V17: =T17 -> 98 | X17: =V17 -> 98 | Z17: =X17 -> 98 | AB17: =AVERAGE(T17:AA17) -> 98 | AD17: =AB17-R17 -> -1
B20: IBP 2 | R20: ECG (SPO2)
D21: Medidas del equipo bajo prueba | T21: Medidas del equipo bajo prueba
B22: Patrón (mmHg) | D22: Lectura 1 (mmHg) | F22: Lectura 2 (mmHg) | H22: Lectura 3 (mmHg) | J22: Lectura 4 (mmHg) | L22: Promedio (mmHg) | N22: Error (mmHg) | R22: Patrón (Lat/min) | T22: Lectura 1 (Lat/min) | V22: Lectura 2 (Lat/min) | X22: Lectura 3 (Lat/min) | Z22: Lectura 4 (Lat/min) | AB22: Promedio (Lat/min) | AD22: Error (Lat/min)
B23: 50 | D23: =RANDBETWEEN(49, 50) -> 50 | F23: =D23 -> 50 | H23: =D23 -> 50 | J23: =D23 -> 50 | L23: =AVERAGE(D23:K23) -> 50 | N23: =L23-B23 -> 0 | R23: 30 | T23: 30 | V23: =T23 -> 30 | X23: =V23 -> 30 | Z23: =X23 -> 30 | AB23: =AVERAGE(T23:AA23) -> 30 | AD23: =AB23-R23 -> 0
B24: 100 | D24: =IF((D23 - B23) = 0, IF(RAND() < 0.5, B24, B24 - 1), IF((D23 - B23) = -1, B24 - 1, "Condición no especificada")) -> 100 | F24: =D24 -> 100 | H24: =D24 -> 100 | J24: =D24 -> 100 | L24: =AVERAGE(D24:K24) -> 100 | N24: =L24-B24 -> 0 | R24: 60 | T24: 60 | V24: =T24 -> 60 | X24: =V24 -> 60 | Z24: =X24 -> 60 | AB24: =AVERAGE(T24:AA24) -> 60 | AD24: =AB24-R24 -> 0
B25: 150 | D25: =IF((D24 - B24) = 0, INT(IF(RAND() < 0.5, B25, B25 - 1)), IF((D24 - B24) = -1, B25 - 1, "Condición no especificada")) -> 150 | F25: =D25 -> 150 | H25: =D25 -> 150 | J25: =D25 -> 150 | L25: =AVERAGE(D25:K25) -> 150 | N25: =L25-B25 -> 0 | R25: 120 | T25: 120 | V25: =T25 -> 120 | X25: =V25 -> 120 | Z25: =X25 -> 120 | AB25: =AVERAGE(T25:AA25) -> 120 | AD25: =AB25-R25 -> 0
B26: 200 | D26: =IF((D25 - B25) = 0, INT(IF(RAND() < 0.5, B26, B26 - 1)), IF((D25 - B25) = -1, INT(IF(RAND() < 0.5, B26 - 1, B26 - 2)), B26)) -> 199 | F26: =D26 -> 199 | H26: =D26 -> 199 | J26: =D26 -> 199 | L26: =AVERAGE(D26:K26) -> 199 | N26: =L26-B26 -> -1 | R26: 246 | T26: 246 | V26: =T26 -> 246 | X26: =V26 -> 246 | Z26: =X26 -> 246 | AB26: =AVERAGE(T26:AA26) -> 246 | AD26: =AB26-R26 -> 0
B27: 250 | D27: =IF((D26 - B26) = 0, INT(IF(RAND() < 0.5, B27, B27 - 1)), IF((D26 - B26) = -1, INT(IF(RAND() < 0.5, B27 - 1, B27 - 2)), IF((D26 - B26) = -2, B27 - 2, "Condición no especificada"))) -> 248 | F27: =D27 -> 248 | H27: =D27 -> 248 | J27: =D27 -> 248 | L27: =AVERAGE(D27:K27) -> 248 | N27: =L27-B27 -> -2
B29: TEMPERATURA 1
B30: Patrón (°C) | D30: EBP (°C) | F30: Error (°C)
B31: 33 | D31: 33.1 | F31: =D31-B31 -> 0.1
B32: 35 | D32: 35.1 | F32: =D32-B32 -> 0.1
B33: 37 | D33: 37.2 | F33: =D33-B33 -> 0.2

Sheet PATRON
C2: NIBP
C3: Nominal | D3: Medido | E3: Corrección | F3: k | G3: Correcion estimada | H3: Residuales | I3: N-M-1 | J3: u interpolación
C4: -24.99 | D4: -25.2 | E4: =C4-D4 -> 0.21 | F4: 2 | G4: =_xlfn.IFS($C$2="PSI",(K$18*D4^4-K$19*D4^3+K$20*D4^2-K$21*D4-K$22),$C$2="kPa",(N$18*D4^4-N$19*D4^3+N$20*D4^2-N$21*D4-N$22),$C$2="inHg",(M$18*D4^4-M$19*D4^3+M$20*D4^2-M$21*D4-M$22),$C$2="mmHg",(L$18*D4^4-L$19*D4^3+L$20*D4^2-L$21*D4-L$22)) -> #N/A | H4: =E4-G4 -> #N/A | I4: =11-4-1 -> 6 | J4: =(SQRT(SUMSQ(I4:I14)/I4)) -> 2.4494897
C5: 9.99 | D5: 10.4 | E5: =C5-D5 -> -0.41 | F5: 2 | G5: =_xlfn.IFS($C$2="PSI",(K$18*D5^4-K$19*D5^3+K$20*D5^2-K$21*D5-K$22),$C$2="kPa",(N$18*D5^4-N$19*D5^3+N$20*D5^2-N$21*D5-N$22),$C$2="inHg",(M$18*D5^4-M$19*D5^3+M$20*D5^2-M$21*D5-M$22),$C$2="mmHg",(L$18*D5^4-L$19*D5^3+L$20*D5^2-L$21*D5-L$22)) -> #N/A | H5: =E5-G5 -> #N/A
C6: 29.99 | D6: 30.2 | E6: =C6-D6 -> -0.21 | F6: 2 | G6: =_xlfn.IFS($C$2="PSI",(K$18*D6^4-K$19*D6^3+K$20*D6^2-K$21*D6-K$22),$C$2="kPa",(N$18*D6^4-N$19*D6^3+N$20*D6^2-N$21*D6-N$22),$C$2="inHg",(M$18*D6^4-M$19*D6^3+M$20*D6^2-M$21*D6-M$22),$C$2="mmHg",(L$18*D6^4-L$19*D6^3+L$20*D6^2-L$21*D6-L$22)) -> #N/A | H6: =E6-G6 -> #N/A
C7: 49.99 | D7: 50.2 | E7: =C7-D7 -> -0.21 | F7: 2 | G7: =_xlfn.IFS($C$2="PSI",(K$18*D7^4-K$19*D7^3+K$20*D7^2-K$21*D7-K$22),$C$2="kPa",(N$18*D7^4-N$19*D7^3+N$20*D7^2-N$21*D7-N$22),$C$2="inHg",(M$18*D7^4-M$19*D7^3+M$20*D7^2-M$21*D7-M$22),$C$2="mmHg",(L$18*D7^4-L$19*D7^3+L$20*D7^2-L$21*D7-L$22)) -> #N/A | H7: =E7-G7 -> #N/A
C8: 79.99 | D8: 80.1 | E8: =C8-D8 -> -0.11 | F8: 2 | G8: =_xlfn.IFS($C$2="PSI",(K$18*D8^4-K$19*D8^3+K$20*D8^2-K$21*D8-K$22),$C$2="kPa",(N$18*D8^4-N$19*D8^3+N$20*D8^2-N$21*D8-N$22),$C$2="inHg",(M$18*D8^4-M$19*D8^3+M$20*D8^2-M$21*D8-M$22),$C$2="mmHg",(L$18*D8^4-L$19*D8^3+L$20*D8^2-L$21*D8-L$22)) -> #N/A | H8: =E8-G8 -> #N/A
B34: EQUIPO PATRÓN
B35: Equipo patrón: | G35: Simulador de signos vitales
B36: Marca: | G36: BC Biomedical
B37: Modelo: | G37: NIBP-1020
B38: Serie: | G38: 73581403 Rev AH
B39: Fecha de Calibración: | G39: 44971
B40: No. Certificado: | G40: L4015
B41: Incertidumbre NIBP: | G41: 0.11
B42: Incertidumbre ECG: | G42: 0.48
B43: Deriva NIBP | G43: 0.5
B44: Deriva ECG | G44: 0
B45: Resolución NIBP | G45: 0.1
B46: Resolución ECG | G46: 1
B47: Factor de cobertura K: | G47: 2
B49: EQUIPO PATRÓN
B50: Equipo patrón: | G50: Termómetro
B51: Marca: | G51: No registra
B52: Modelo: | G52: No registra
B53: Serie: | G53: No registra
B54: Fecha de Calibración: | G54: 45048
B55: No. Certificado: | G55: CA00305-23
B56: Incertidumbre Temperatura | G56: 0.52
B57: Deriva Temperatura: | G57: 0.2
B58: Resolución Temperatura: | G58: 0.1
B59: Factor de cobertura K: | G59: 2
B61: EQUIPO PATRÓN
B62: Equipo patrón: | G62: Simulador de SPO2
B63: Marca: | G63: BC Biomedical
B64: Modelo: | G64: FSX-1101
B65: Serie: | G65: 73021035
B66: Fecha de Calibración: | G66: 44970
B67: No. Certificado: | G67: L4013
B68: Incertidumbre SPO2: | G68: 2.3
...

Sheet INCERTIDUMBRE
B2: FUENTES DE INCERTIDUMBRE PRESIÓN NO INVASIVA
B3: Punto de calibración | C3: Cert de calibración | D3: Deriva | E3: Interpolación | F3: Resolución item | G3: Resolución patrón | H3: Repetibilidad | I3: Incertidumbre combinada | J3: Veff | K3: Factor de cobertura (k) | L3: Incertidumbre Expandida
B4: =MEDIDA!B4 -> 50 | C4: =0.11/2 -> 0.055 | D4: =PATRON!G$43/SQRT(3) -> 0.28867513 | E4: 0 | F4: =1/SQRT(12) -> 0.28867513 | G4: =PATRON!G$45/SQRT(12) -> 0.028867513 | H4: =STDEVA(MEDIDA!D4:K4)/SQRT(4) -> 0 | I4: =SQRT(SUMSQ(C4:H4)) -> 0.41294673 | J4: =I4^4/(C4^4/200+D4^4/200+E4^4/200+F4^4/200+G4^4/200+H4^4/3) -> 418.43776 | K4: =TINV(0.0455,J4) -> 2.0060009 | L4: =I4*K4 -> 0.8283715
B5: =MEDIDA!B5 -> 100 | C5: =0.11/2 -> 0.055 | D5: =PATRON!G$43/SQRT(3) -> 0.28867513 | E5: 0 | F5: =1/SQRT(12) -> 0.28867513 | G5: =PATRON!G$45/SQRT(12) -> 0.028867513 | H5: =STDEVA(MEDIDA!D5:K5)/SQRT(4) -> 0 | I5: =SQRT(SUMSQ(C5:H5)) -> 0.41294673 | J5: =I5^4/(C5^4/200+D5^4/200+E5^4/200+F5^4/200+G5^4/200+H5^4/3) -> 418.43776 | K5: =TINV(0.0455,J5) -> 2.0060009 | L5: =I5*K5 -> 0.8283715
B6: =MEDIDA!B6 -> 150 | C6: =0.11/2 -> 0.055 | D6: =PATRON!G$43/SQRT(3) -> 0.28867513 | E6: 0 | F6: =1/SQRT(12) -> 0.28867513 | G6: =PATRON!G$45/SQRT(12) -> 0.028867513 | H6: =STDEVA(MEDIDA!D6:K6)/SQRT(4) -> 0 | I6: =SQRT(SUMSQ(C6:H6)) -> 0.41294673 | J6: =I6^4/(C6^4/200+D6^4/200+E6^4/200+F6^4/200+G6^4/200+H6^4/3) -> 418.43776 | K6: =TINV(0.0455,J6) -> 2.0060009 | L6: =I6*K6 -> 0.8283715
B7: =MEDIDA!B7 -> 200 | C7: =0.11/2 -> 0.055 | D7: =PATRON!G$43/SQRT(3) -> 0.28867513 | E7: 0 | F7: =1/SQRT(12) -> 0.28867513 | G7: =PATRON!G$45/SQRT(12) -> 0.028867513 | H7: =STDEVA(MEDIDA!D7:K7)/SQRT(4) -> 0 | I7: =SQRT(SUMSQ(C7:H7)) -> 0.41294673 | J7: =I7^4/(C7^4/200+D7^4/200+E7^4/200+F7^4/200+G7^4/200+H7^4/3) -> 418.43776 | K7: =TINV(0.0455,J7) -> 2.0060009 | L7: =I7*K7 -> 0.8283715
B8: =MEDIDA!B8 -> 250 | C8: =0.11/2 -> 0.055 | D8: =PATRON!G$43/SQRT(3) -> 0.28867513 | E8: 0 | F8: =1/SQRT(12) -> 0.28867513 | G8: =PATRON!G$45/SQRT(12) -> 0.028867513 | H8: =STDEVA(MEDIDA!D8:K8)/SQRT(4) -> 0 | I8: =SQRT(SUMSQ(C8:H8)) -> 0.41294673 | J8: =I8^4/(C8^4/200+D8^4/200+E8^4/200+F8^4/200+G8^4/200+H8^4/3) -> 418.43776 | K8: =TINV(0.0455,J8) -> 2.0060009 | L8: =I8*K8 -> 0.8283715
B10: FUENTES DE INCERTIDUMBRE PRESIÓN INVASIVA 1
B11: Punto de calibración | C11: Cert de calibración | D11: Deriva | E11: Interpolación | F11: Resolución item | G11: Resolución patrón | H11: Repetibilidad | I11: Incertidumbre combinada | J11: Veff | K11: Factor de cobertura (k) | L11: Incertidumbre Expandida
B12: =MEDIDA!B13 -> 50 | C12: =0.11/2 -> 0.055 | D12: =PATRON!G$43/SQRT(3) -> 0.28867513 | E12: 0 | F12: =1/SQRT(12) -> 0.28867513 | G12: =PATRON!G$45/SQRT(12) -> 0.028867513 | H12: {=STDEVA(MEDIDA!D13:K13/SQRT(4))} -> 13.095801 | I12: =SQRT(SUMSQ(C12:H12)) -> 13.10231 | J12: =I12^4/(C12^4/200+D12^4/200+E12^4/200+F12^4/200+G12^4/200+H12^4/3) -> 3.0059688 | K12: =TINV(0.0455,J12) -> 3.3068299 | L12: =I12*K12 -> 43.32711
B13: =MEDIDA!B14 -> 100 | C13: =0.11/2 -> 0.055 | D13: =PATRON!G$43/SQRT(3) -> 0.28867513 | E13: 0 | F13: =1/SQRT(12) -> 0.28867513 | G13: =PATRON!G$45/SQRT(12) -> 0.028867513 | H13: =STDEVA(MEDIDA!#REF!)/SQRT(4) -> #REF! | I13: =SQRT(SUMSQ(C13:H13)) -> #REF! | J13: =I13^4/(C13^4/200+D13^4/200+E13^4/200+F13^4/200+G13^4/200+H13^4/3) -> #REF! | K13: =TINV(0.0455,J13) -> #REF! | L13: =I13*K13 -> #REF!
B14: =MEDIDA!B15 -> 150 | C14: =0.11/2 -> 0.055 | D14: =PATRON!G$43/SQRT(3) -> 0.28867513 | E14: 0 | F14: =1/SQRT(12) -> 0.28867513 | G14: =PATRON!G$45/SQRT(12) -> 0.028867513 | H14: =STDEVA(MEDIDA!#REF!)/SQRT(4) -> #REF! | I14: =SQRT(SUMSQ(C14:H14)) -> #REF! | J14: =I14^4/(C14^4/200+D14^4/200+E14^4/200+F14^4/200+G14^4/200+H14^4/3) -> #REF! | K14: =TINV(0.0455,J14) -> #REF! | L14: =I14*K14 -> #REF!
B15: =MEDIDA!B16 -> 200 | C15: =0.11/2 -> 0.055 | D15: =PATRON!G$43/SQRT(3) -> 0.28867513 | E15: 0 | F15: =1/SQRT(12) -> 0.28867513 | G15: =PATRON!G$45/SQRT(12) -> 0.028867513 | H15: =STDEVA(MEDIDA!#REF!)/SQRT(4) -> #REF! | I15: =SQRT(SUMSQ(C15:H15)) -> #REF! | J15: =I15^4/(C15^4/200+D15^4/200+E15^4/200+F15^4/200+G15^4/200+H15^4/3) -> #REF! | K15: =TINV(0.0455,J15) -> #REF! | L15: =I15*K15 -> #REF!
B16: =MEDIDA!B17 -> 250 | C16: =0.11/2 -> 0.055 | D16: =PATRON!G$43/SQRT(3) -> 0.28867513 | E16: 0 | F16: =1/SQRT(12) -> 0.28867513 | G16: =PATRON!G$45/SQRT(12) -> 0.028867513 | H16: =STDEVA(MEDIDA!#REF!)/SQRT(4) -> #REF! | I16: =SQRT(SUMSQ(C16:H16)) -> #REF! | J16: =I16^4/(C16^4/200+D16^4/200+E16^4/200+F16^4/200+G16^4/200+H16^4/3) -> #REF! | K16: =TINV(0.0455,J16) -> #REF! | L16: =I16*K16 -> #REF!
B18: FUENTES DE INCERTIDUMBRE PRESIÓN INVASIVA 2
B19: Punto de calibración | C19: Cert de calibración | D19: Deriva | E19: Interpolación | F19: Resolución item | G19: Resolución patrón | H19: Repetibilidad | I19: Incertidumbre combinada | J19: Veff | K19: Factor de cobertura (k) | L19: Incertidumbre Expandida
B20: =MEDIDA!#REF! -> #REF! | C20: =0.11/2 -> 0.055 | D20: =PATRON!G$43/SQRT(3) -> 0.28867513 | E20: 0 | F20: =1/SQRT(12) -> 0.28867513 | G20: =PATRON!G$45/SQRT(12) -> 0.028867513 | H20: =STDEVA(MEDIDA!D13:K13)/SQRT(4) -> 0 | I20: =SQRT(SUMSQ(C20:H20)) -> 0.41294673 | J20: =I20^4/(C20^4/200+D20^4/200+E20^4/200+F20^4/200+G20^4/200+H20^4/3) -> 418.43776 | K20: =TINV(0.0455,J20) -> 2.0060009 | L20: =I20*K20 -> 0.8283715
B21: =MEDIDA!#REF! -> #REF! | C21: =0.11/2 -> 0.055 | D21: =PATRON!G$43/SQRT(3) -> 0.28867513 | E21: 0 | F21: =1/SQRT(12) -> 0.28867513 | G21: =PATRON!G$45/SQRT(12) -> 0.028867513 | H21: =STDEVA(MEDIDA!D14:K14)/SQRT(4) -> 0 | I21: =SQRT(SUMSQ(C21:H21)) -> 0.41294673 | J21: =I21^4/(C21^4/200+D21^4/200+E21^4/200+F21^4/200+G21^4/200+H21^4/3) -> 418.43776 | K21: =TINV(0.0455,J21) -> 2.0060009 | L21: =I21*K21 -> 0.8283715
B22: =MEDIDA!B33 -> 37 | C22: =0.11/2 -> 0.055 | D22: =PATRON!G$43/SQRT(3) -> 0.28867513 | E22: 0 | F22: =1/SQRT(12) -> 0.28867513 | G22: =PATRON!G$45/SQRT(12) -> 0.028867513 | H22: =STDEVA(MEDIDA!D15:K15)/SQRT(4) -> 0 | I22: =SQRT(SUMSQ(C22:H22)) -> 0.41294673 | J22: =I22^4/(C22^4/200+D22^4/200+E22^4/200+F22^4/200+G22^4/200+H22^4/3) -> 418.43776 | K22: =TINV(0.0455,J22) -> 2.0060009 | L22: =I22*K22 -> 0.8283715
B23: =MEDIDA!B34 -> 0 | C23: =0.11/2 -> 0.055 | D23: =PATRON!G$43/SQRT(3) -> 0.28867513 | E23: 0 | F23: =1/SQRT(12) -> 0.28867513 | G23: =PATRON!G$45/SQRT(12) -> 0.028867513 | H23: =STDEVA(MEDIDA!D16:K16)/SQRT(4) -> 0 | I23: =SQRT(SUMSQ(C23:H23)) -> 0.41294673 | J23: =I23^4/(C23^4/200+D23^4/200+E23^4/200+F23^4/200+G23^4/200+H23^4/3) -> 418.43776 | K23: =TINV(0.0455,J23) -> 2.0060009 | L23: =I23*K23 -> 0.8283715
B24: =MEDIDA!B35 -> 0 | C24: =0.11/2 -> 0.055 | D24: =PATRON!G$43/SQRT(3) -> 0.28867513 | E24: 0 | F24: =1/SQRT(12) -> 0.28867513 | G24: =PATRON!G$45/SQRT(12) -> 0.028867513 | H24: =STDEVA(MEDIDA!D17:K17)/SQRT(4) -> 0 | I24: =SQRT(SUMSQ(C24:H24)) -> 0.41294673 | J24: =I24^4/(C24^4/200+D24^4/200+E24^4/200+F24^4/200+G24^4/200+H24^4/3) -> 418.43776 | K24: =TINV(0.0455,J24) -> 2.0060009 | L24: =I24*K24 -> 0.8283715
B26: FUENTES DE INCERTIDUMBRE ECG
B27: Punto de calibración | C27: Cert de calibración | D27: Deriva | E27: Interpolación | F27: Resolución item | G27: Resolución patrón | H27: Repetibilidad | I27: Incertidumbre combinada | J27: Veff | K27: Factor de cobertura (k) | L27: Incertidumbre Expandida
B28: =MEDIDA!R4 -> 30 | C28: =PATRON!G$42/2 -> 0.24 | D28: =PATRON!G$44 -> 0 | E28: 0 | F28: =1/SQRT(12) -> 0.28867513 | G28: =1/SQRT(12) -> 0.28867513 | H28: =STDEVA(MEDIDA!T4:AA4)/SQRT(4) -> 0 | I28: =SQRT(SUMSQ(C28:H28)) -> 0.47356802 | J28: =I28^4/(C28^4/200+D28^4/200+E28^4/200+F28^4/200+G28^4/200+H28^4/3) -> 584.60585 | K28: =TINV(0.0455,J28) -> 2.0042923 | L28: =I28*K28 -> 0.94916872
B29: =MEDIDA!R5 -> 60 | C29: =PATRON!G$42/2 -> 0.24 | D29: =PATRON!G$44 -> 0 | E29: 0 | F29: =1/SQRT(12) -> 0.28867513 | G29: =1/SQRT(12) -> 0.28867513 | H29: =STDEVA(MEDIDA!T5:AA5)/SQRT(4) -> 0 | I29: =SQRT(SUMSQ(C29:H29)) -> 0.47356802 | J29: =I29^4/(C29^4/200+D29^4/200+E29^4/200+F29^4/200+G29^4/200+H29^4/3) -> 584.60585 | K29: =TINV(0.0455,J29) -> 2.0042923 | L29: =I29*K29 -> 0.94916872
B30: =MEDIDA!R6 -> 120 | C30: =PATRON!G$42/2 -> 0.24 | D30: =PATRON!G$44 -> 0 | E30: 0 | F30: =1/SQRT(12) -> 0.28867513 | G30: =1/SQRT(12) -> 0.28867513 | H30: =STDEVA(MEDIDA!T6:AA6)/SQRT(4) -> 0 | I30: =SQRT(SUMSQ(C30:H30)) -> 0.47356802 | J30: =I30^4/(C30^4/200+D30^4/200+E30^4/200+F30^4/200+G30^4/200+H30^4/3) -> 584.60585 | K30: =TINV(0.0455,J30) -> 2.0042923 | L30: =I30*K30 -> 0.94916872
B31: =MEDIDA!R7 -> 240 | C31: =PATRON!G$42/2 -> 0.24 | D31: =PATRON!G$44 -> 0 | E31: 0 | F31: =1/SQRT(12) -> 0.28867513 | G31: =1/SQRT(12) -> 0.28867513 | H31: =STDEVA(MEDIDA!T7:AA7)/SQRT(4) -> 0 | I31: =SQRT(SUMSQ(C31:H31)) -> 0.47356802 | J31: =I31^4/(C31^4/200+D31^4/200+E31^4/200+F31^4/200+G31^4/200+H31^4/3) -> 584.60585 | K31: =TINV(0.0455,J31) -> 2.0042923 | L31: =I31*K31 -> 0.94916872
B33: FUENTES DE INCERTIDUMBRE ECG (SPO2)
B34: Punto de calibración | C34: Cert de calibración | D34: Deriva | E34: Interpolación | F34: Resolución item | G34: Resolución patrón | H34: Repetibilidad | I34: Incertidumbre combinada | J34: Veff | K34: Factor de cobertura (k) | L34: Incertidumbre Expandida
B35: =MEDIDA!R23 -> 30 | C35: =PATRON!G$69/2 -> 0.85 | D35: =PATRON!G$71/SQRT(3) -> 0.57735027 | E35: 0 | F35: =1/SQRT(12) -> 0.28867513 | G35: =1/SQRT(12) -> 0.28867513 | H35: =STDEVA(MEDIDA!T23:AA23)/SQRT(4) -> 0 | I35: =SQRT(SUMSQ(C35:H35)) -> 1.1056672 | J35: =I35^4/(C35^4/200+D35^4/200+E35^4/200+F35^4/200+G35^4/200+H35^4/3) -> 461.97583 | K35: =TINV(0.0455,J35) -> 2.0054399 | L35: =I35*K35 -> 2.2173492
B36: =MEDIDA!R24 -> 60 | C36: =PATRON!G$69/2 -> 0.85 | D36: =PATRON!G$71/SQRT(3) -> 0.57735027 | E36: 0 | F36: =1/SQRT(12) -> 0.28867513 | G36: =1/SQRT(12) -> 0.28867513 | H36: =STDEVA(MEDIDA!T24:AA24)/SQRT(4) -> 0 | I36: =SQRT(SUMSQ(C36:H36)) -> 1.1056672 | J36: =I36^4/(C36^4/200+D36^4/200+E36^4/200+F36^4/200+G36^4/200+H36^4/3) -> 461.97583 | K36: =TINV(0.0455,J36) -> 2.0054399 | L36: =I36*K36 -> 2.2173492
B37: =MEDIDA!R25 -> 120 | C37: =PATRON!G$69/2 -> 0.85 | D37: =PATRON!G$71/SQRT(3) -> 0.57735027 | E37: 0 | F37: =1/SQRT(12) -> 0.28867513 | G37: =1/SQRT(12) -> 0.28867513 | H37: =STDEVA(MEDIDA!T25:AA25)/SQRT(4) -> 0 | I37: =SQRT(SUMSQ(C37:H37)) -> 1.1056672 | J37: =I37^4/(C37^4/200+D37^4/200+E37^4/200+F37^4/200+G37^4/200+H37^4/3) -> 461.97583 | K37: =TINV(0.0455,J37) -> 2.0054399 | L37: =I37*K37 -> 2.2173492
B38: =MEDIDA!R26 -> 246 | C38: =PATRON!G$69/2 -> 0.85 | D38: =PATRON!G$71/SQRT(3) -> 0.57735027 | E38: 0 | F38: =1/SQRT(12) -> 0.28867513 | G38: =1/SQRT(12) -> 0.28867513 | H38: =STDEVA(MEDIDA!T26:AA26)/SQRT(4) -> 0 | I38: =SQRT(SUMSQ(C38:H38)) -> 1.1056672 | J38: =I38^4/(C38^4/200+D38^4/200+E38^4/200+F38^4/200+G38^4/200+H38^4/3) -> 461.97583 | K38: =TINV(0.0455,J38) -> 2.0054399 | L38: =I38*K38 -> 2.2173492
B40: FUENTES DE INCERTIDUMBRE SPO2
B41: Punto de calibración | C41: Cert de calibración | D41: Deriva | E41: Interpolación | F41: Resolución item | G41: Resolución patrón | H41: Repetibilidad | I41: Incertidumbre combinada | J41: Veff | K41: Factor de cobertura (k) | L41: Incertidumbre Expandida
B42: =MEDIDA!R13 -> 80 | C42: =PATRON!G$68/2 -> 1.15 | D42: =PATRON!G$70/SQRT(3) -> 0.46188022 | E42: 0 | F42: =1/SQRT(12) -> 0.28867513 | G42: =1/SQRT(12) -> 0.28867513 | H42: =STDEVA(MEDIDA!T13:AA13)/SQRT(4) -> 0 | I42: =SQRT(SUMSQ(C42:H42)) -> 1.3047988 | J42: =I42^4/(C42^4/200+D42^4/200+E42^4/200+F42^4/200+G42^4/200+H42^4/3) -> 320.55919 | K42: =TINV(0.0455,J42) -> 2.007845 | L42: =I42*K42 -> 2.6198338
B43: =MEDIDA!R14 -> 85 | C43: =PATRON!G$68/2 -> 1.15 | D43: =PATRON!G$70/SQRT(3) -> 0.46188022 | E43: 0 | F43: =1/SQRT(12) -> 0.28867513 | G43: =1/SQRT(12) -> 0.28867513 | H43: =STDEVA(MEDIDA!T14:AA14)/SQRT(4) -> 0 | I43: =SQRT(SUMSQ(C43:H43)) -> 1.3047988 | J43: =I43^4/(C43^4/200+D43^4/200+E43^4/200+F43^4/200+G43^4/200+H43^4/3) -> 320.55919 | K43: =TINV(0.0455,J43) -> 2.007845 | L43: =I43*K43 -> 2.6198338
B44: =MEDIDA!R15 -> 90 | C44: =PATRON!G$68/2 -> 1.15 | D44: =PATRON!G$70/SQRT(3) -> 0.46188022 | E44: 0 | F44: =1/SQRT(12) -> 0.28867513 | G44: =1/SQRT(12) -> 0.28867513 | H44: =STDEVA(MEDIDA!T15:AA15)/SQRT(4) -> 0 | I44: =SQRT(SUMSQ(C44:H44)) -> 1.3047988 | J44: =I44^4/(C44^4/200+D44^4/200+E44^4/200+F44^4/200+G44^4/200+H44^4/3) -> 320.55919 | K44: =TINV(0.0455,J44) -> 2.007845 | L44: =I44*K44 -> 2.6198338
B45: =MEDIDA!R16 -> 95 | C45: =PATRON!G$68/2 -> 1.15 | D45: =PATRON!G$70/SQRT(3) -> 0.46188022 | E45: 0 | F45: =1/SQRT(12) -> 0.28867513 | G45: =1/SQRT(12) -> 0.28867513 | H45: =STDEVA(MEDIDA!T16:AA16)/SQRT(4) -> 0 | I45: =SQRT(SUMSQ(C45:H45)) -> 1.3047988 | J45: =I45^4/(C45^4/200+D45^4/200+E45^4/200+F45^4/200+G45^4/200+H45^4/3) -> 320.55919 | K45: =TINV(0.0455,J45) -> 2.007845 | L45: =I45*K45 -> 2.6198338
B46: =MEDIDA!R17 -> 99 | C46: =PATRON!G$68/2 -> 1.15 | D46: =PATRON!G$70/SQRT(3) -> 0.46188022 | E46: 0 | F46: =1/SQRT(12) -> 0.28867513 | G46: =1/SQRT(12) -> 0.28867513 | H46: =STDEVA(MEDIDA!T17:AA17)/SQRT(4) -> 0 | I46: =SQRT(SUMSQ(C46:H46)) -> 1.3047988 | J46: =I46^4/(C46^4/200+D46^4/200+E46^4/200+F46^4/200+G46^4/200+H46^4/3) -> 320.55919 | K46: =TINV(0.0455,J46) -> 2.007845 | L46: =I46*K46 -> 2.6198338
...

Sheet CERTIFICADO
O1: CERTIFICADO N°: | R1: =INFORMACIÓN!G3 -> 0
C3: 1. EQUIPO BAJO PRUEBA
C5: INSTRUMENTO: | I5: =INFORMACIÓN!B3 -> 0
C6: MARCA: | I6: =INFORMACIÓN!C3 -> 0
C7: MODELO: | I7: =INFORMACIÓN!D3 -> 0
C8: SERIE: | I8: =INFORMACIÓN!E3 -> 0
C9: CÓDIGO INTERNO: | I9: =INFORMACIÓN!A3 -> 0
C10: UBICACIÓN: | I10: =INFORMACIÓN!F3 -> 0
C11: ESTADO FÍSICO: | I11: =INFORMACIÓN!B8 -> BUEN ESTADO
C12: FECHA DE RECEPCIÓN: | I12: =INFORMACIÓN!H3 -> 0
C13: FECHA DE CALIBRACIÓN: | I13: =INFORMACIÓN!B9 -> 0
C15: 2. DATOS DEL CLIENTE
C17: NOMBRE: | I17: =INFORMACIÓN!E7 -> 0
C18: NIT: | I18: =INFORMACIÓN!E8 -> 0
C19: TELÉFONO: | I19: =INFORMACIÓN!E9 -> 0
C20: DIRECCIÓN: | I20: =INFORMACIÓN!E10 -> 0
C21: CIUDAD: | I21: =INFORMACIÓN!E11 -> 0
C23: Este certificado expresa fielmente el resultado de las mediciones realizadas; no podrá ser reproducido total o parcialmente excepto cuando se haya obtenido permiso por escrito de BTM COLOMBIA ZOMAC S.A.S y se debe reproducir en su totalidad, para proporcionar seguridad de que el certificado no sea sacado de contexto. Los resultados que se encuentran en este certificado se refieren al momento y condiciones en que se realizaron las mediciones, BTM COLOMBIA ZOMAC S.A.S no se responsabiliza de los daños que puedan ser causados por el uso inadecuado de los equipos calibrados. El usuario es responsable de la calibración de sus instrumentos a intervalos apropiados. El laboratorio no se hace responsable por cómo la información suministrada por el cliente afecte los resultados de medición.
C31: REVISÓ Y AUTORIZÓ: | I31: CALIBRADO POR: | M31: =INFORMACIÓN!B15 -> ING. GABRIEL DURÁN
I32: FECHA DE EMISIÓN: | M32: =INFORMACIÓN!B10 -> 0
I33: NÚMERO DE PÁGINAS: | M33: 4
C36: ING. JOHAN SEBASTIÁN PÉREZ
C37: DIRECTOR DE LABORATORIO
O38: =O1 -> CERTIFICADO N°: | R38: =R1 -> 0
B40: 3. CONDICIONES AMBIENTALES
B41: El laboratorio de metrología BTM COLOMBIA ZOMAC S.A.S registra las condiciones ambientales (Humedad y Temperatura) tomando los máximos y mínimos alcanzados durante el tiempo en que se ejecuta la calibración. A continuación se presenta el promedio y la variación resultante.
F45: TEMPERATURA AMBIENTE (°C) | K45: HUMEDAD RELATIVA (%HR)
F46: =AVERAGE(INFORMACIÓN!B11:B12) -> 24.3 | H46: ± | I46: =ABS(INFORMACIÓN!B11-INFORMACIÓN!B12) -> 0.4 | K46: =AVERAGE(INFORMACIÓN!B13:B14) -> 61.5 | M46: ± | N46: =ABS(INFORMACIÓN!B13-INFORMACIÓN!B14) -> 3
F48: La calibración fue realizada en: | K48: En sitio (instalaciones del cliente)
B50: 4. INCERTIDUMBRE DE MEDICIÓN
B51: La incertidumbre expandida de la medición reportada se establece como la incertidumbre estándar de medición multiplicada por el factor de cobertura “k” y la probabilidad de cobertura, la cual debe ser aproximada al 95% y no menor a este valor. La incertidumbre de medición ha sido estimada con un nivel de confianza del 95,45% empleando una distribución t de Student. Cuando se hace declaración de cumplimiento, el laboratorio hace referencia a las especificaciones del fabricante, norma o requisitos declarados por el cliente. La regla de decisión aplicada en estos casos será |Error| +U ≤ EMP según la ASME B89 7.3.1, si cumple la anterior condición la medición se toma como conforme y registrará un pasa, en caso contrario se registrará falla. La probabilidad de dar una aceptación falsa o un rechazo falso no lo determina el laboratorio, sin embargo se puede calcular de acuerdo a la guía JCGM 106:2012 según su numeral 8.
B60: 5. PROCEDIMIENTO DE CALIBRACIÓN
B61: La calibración se ejecutó mediante el método de comparación directa con patrón de referencia de acuerdo con el procedimiento interno para monitores de signos vitales BTM-P-004.
B64: 6. TRAZABILIDAD
B65: El laboratorio BTM COLOMBIA ZOMAC S.A.S establece la trazabilidad metrológica de sus mediciones al sistema internacional de unidades (SI), por medio de una cadena documentada de calibraciones, las cuales se encuentran referenciadas a patrones de medidas primarios. Esta vinculación se logra a través del uso de patrones calibrados por institutos nacionales de metrología (INM) y por laboratorios acreditados por parte de un organismo de acreditación.
B70: PATRÓN | H70: SERIE | M70: CALIBRACIÓN | P70: CERTIFICADO
B71: Simulador de signos vitales | H71: 73581403 | M71: 46065 | P71: L5555
B72: Simulador de SPO2 | H72: 73021035 | M72: 46064 | P72: L5548
B73: Termómetro | H73: 230310997 | M73: 46055 | P73: 319239_A 319239_B
O76: =O1 -> CERTIFICADO N°: | R76: =R1 -> 0
...
