Workbook
Name Instrumento: '[1]R-LAB-127 DENSIDAD AIRE'!#REF!
Name Instrumento: '[1]R-LAB-127 DENSIDAD AIRE'!#REF!
Name Instrumento.: '[1]R-LAB-127 DENSIDAD AIRE'!#REF!
Name Instrumento.: '[1]R-LAB-127 DENSIDAD AIRE'!#REF!
Name N: #REF!
Name N: #REF!

Sheet INFORMACIÓN
A1: Datos del item | O1: En sitio (instalaciones del cliente)
A2: Intrumento | B2: Marca | C2: Modelo | D2: Serie | E2: Ubicación | F2: Inventario | G2: Número de Certificado | H2: Fecha de Recepción | O2: Laboratorio BTMC
O4: BUEN ESTADO
O5: REGULAR ESTADO
A6: Datos de calibración | D6: Datos del cliente | O6: MAL ESTADO
A7: Lugar de calibración: | B7: En sitio (instalaciones del cliente) | D7: Solicitante:
A8: Estado Físico: | B8: BUEN ESTADO | D8: Nit:
A9: Fecha de calibración: | B9: =H3 -> 0 | D9: Telefono:
A10: Fecha de emisión: | B10: =H3 -> 0 | D10: Dirección:
A11: Temperatura mínima: | B11: 24.1 | D11: Ciudad:
A12: Temperatura máxima: | B12: 24.5
A13: Humedad Mínima: | B13: 60
A14: Humedad Máxima: | B14: 63
A15: Calibración realiza por: | B15: ING. GABRIEL DURÁN

Sheet Redondeo
A1: DATO 1
A2: Dato | B2: Dato redondeado | C2: =FIXED(A3,6) -> 1,884242 | D2: =RIGHT(C2,1) -> 2 | E2: =D2/1000000 -> 2e-06 | F2: =A3-E2 -> 1.8842395 | H2: =IF(C7=5,IF(AND(D3=0,D8=FALSE),J5,J6),J6) -> 1,8842
A3: =INCERTIDUMBRE!L5 -> 1.8842415 | B3: =IF(A3>=10,K37,IF(A3>=1,K29,IF(A3>=0.1,K21,IF(A3>=0.01,K13,IF(A3>=0.001,K5))))) -> 1,9 | C3: 6 decimal | D3: =D2+0 -> 2
C4: Extrae el ultimo digito | D4: extrael primer digito | E4: parte entera | F4: Parte decimal | G4: cantidad de decimales | H4: decimales en enteros | I4: restar ultimo numero | J4: Elimar ultimo digito | K4: Dato Final
C5: =RIGHT(F2,2) -> 72 | D5: =LEFT(C5,1) -> 7 | E5: =TRUNC(A3) -> 1 | F5: =FIXED(A3-E5,G5) -> 0,88424151982872 | G5: =ABS(E8-F8) -> 14 | H5: =RIGHT(A3,G5) -> 88424151982872 | I5: 5e-05 | J5: =(A3-I5) -> 1.8841915 | K5: =IF(C7=5,IF(AND(D3=0,D8=FALSE),J5,J6),J6) -> 1,8842
C6: =RIGHT(C5,1) -> 2 | D6: =D5+0 -> 7 | J6: =FIXED(A3,4) -> 1,8842
C7: =C6+0 -> 2 | D7: es impar? | E7: Largo dato original | F7: largo parte enetero y decimal
D8: =ISODD(D5) -> TRUE | E8: =LEN(A3) -> 16 | F8: =LEN(E5)+1 -> 2
A10: 4 Decimales
A11: =K5 -> 1,8842 | C11: =FIXED(A3,5) -> 1,88424 | D11: =RIGHT(C11,1) -> 4 | E11: =D11+0 -> 4
C12: Extrae el ultimo digito | D12: extrael primer digito | E12: parte entera | F12: Parte decimal | G12: cantidad de decimales | H12: decimales en enteros | I12: restar ultimo numero | J12: Elimar ultimo digito | K12: Dato Final
C13: =RIGHT(A11,2) -> 42 | D13: =LEFT(C13,1) -> 4 | E13: =TRUNC(A11) -> 1 | F13: =FIXED(A11-E13,G13) -> 0,8842 | G13: =ABS(E16-F16) -> 4 | H13: =RIGHT(A11,G13) -> 8842 | I13: 0.0005 | J13: =(A11-I13) -> 1.8837 | K13: =IF(C15=5,IF(AND(E11=0,D16=FALSE),J13,J14),J14) -> 1,884
C14: =RIGHT(C13,1) -> 2 | D14: =D13+0 -> 4 | J14: =FIXED(A11,3) -> 1,884
C15: =C14+0 -> 2 | D15: es impar? | E15: Largo dato original | F15: largo parte enetero y decimal
D16: =ISODD(D13) -> FALSE | E16: =LEN(A11) -> 6 | F16: =LEN(E13)+1 -> 2
A18: 3 Decimales
A19: =K13 -> 1,884 | C19: =FIXED(A11,4) -> 1,8842 | D19: =RIGHT(C19,1) -> 2 | E19: =D19+0 -> 2
C20: Extrae el ultimo digito | D20: extrael primer digito | E20: parte entera | F20: Parte decimal | G20: cantidad de decimales | H20: decimales en enteros | I20: restar ultimo numero | J20: Elimar ultimo digito | K20: Dato Final
C21: =RIGHT(A19,2) -> 84 | D21: =LEFT(C21,1) -> 8 | E21: =TRUNC(A19) -> 1 | F21: =FIXED(A19-E21,G21) -> 0,884 | G21: =ABS(E24-F24) -> 3 | H21: =RIGHT(A19,G21) -> 884 | I21: 0.005 | J21: =(A19-I21) -> 1.879 | K21: =IF(C23=5,IF(AND(E19=0,D24=FALSE),J21,J22),J22) -> 1,88
C22: =RIGHT(C21,1) -> 4 | D22: =D21+0 -> 8 | J22: =FIXED(A19,2) -> 1,88
C23: =C22+0 -> 4 | D23: es impar? | E23: Largo dato original | F23: largo parte enetero y decimal
D24: =ISODD(D21) -> FALSE | E24: =LEN(A19) -> 5 | F24: =LEN(E21)+1 -> 2
A26: 2 Decimales
A27: =K21 -> 1,88 | C27: =FIXED(A19,3) -> 1,884 | D27: =RIGHT(C27,1) -> 4 | E27: =D27+0 -> 4
C28: Extrae el ultimo digito | D28: extrael primer digito | E28: parte entera | F28: Parte decimal | G28: cantidad de decimales | H28: decimales en enteros | I28: restar ultimo numero | J28: Elimar ultimo digito | K28: Dato Final
C29: =RIGHT(A27,2) -> 88 | D29: =LEFT(C29,1) -> 8 | E29: =TRUNC(A27) -> 1 | F29: =FIXED(A27-E29,G29) -> 0,88 | G29: =ABS(E32-F32) -> 2 | H29: =RIGHT(A27,G29) -> 88 | I29: 0.05 | J29: =(A27-I29) -> 1.83 | K29: =IF(C31=5,IF(AND(E27=0,D32=FALSE),J29,J30),J30) -> 1,9
C30: =RIGHT(C29,1) -> 8 | D30: =D29+0 -> 8 | J30: =FIXED(A27,1) -> 1,9
C31: =C30+0 -> 8 | D31: es impar? | E31: Largo dato original | F31: largo parte enetero y decimal
D32: =ISODD(D29) -> FALSE | E32: =LEN(A27) -> 4 | F32: =LEN(E29)+1 -> 2
A34: 1 Decimales
A35: =K29 -> 1,9 | C35: =FIXED(A27,2) -> 1,88 | D35: =RIGHT(C35,1) -> 8 | E35: =D35+0 -> 8
C36: Extrae el ultimo digito | D36: extrael primer digito | E36: parte entera | F36: Parte decimal | G36: cantidad de decimales | H36: decimales en enteros | I36: restar ultimo numero | J36: Elimar ultimo digito | K36: Dato Final
C37: =RIGHT(A35,2) -> ,9 | D37: =RIGHT(E37,1) -> 1 | E37: =TRUNC(A35) -> 1 | F37: =FIXED(A35-E37,G37) -> 0,9 | G37: =ABS(E40-F40) -> 1 | H37: =RIGHT(A35,G37) -> 9 | I37: 0.5 | J37: =(A35-I37) -> 1.4 | K37: =IF(C39=5,IF(AND(E35=0,D40=FALSE),J37,J38),J38) -> 2
C38: =RIGHT(C37,1) -> 9 | D38: =D37+0 -> 1 | J38: =FIXED(A35,0) -> 2
C39: =C38+0 -> 9 | D39: es impar? | E39: Largo dato original | F39: largo parte enetero y decimal
D40: =ISODD(D37) -> TRUE | E40: =LEN(A35) -> 3 | F40: =LEN(E37)+1 -> 2
A41: DATO 2
A42: Dato | B42: Dato redondeado | C42: =FIXED(A43,6) -> 1,830369 | D42: =RIGHT(C42,1) -> 9 | E42: =D42/1000000 -> 9e-06 | F42: =A43-E42 -> 1.8303596 | H42: =IF(C47=5,IF(AND(D43=0,D48=FALSE),J45,J46),J46) -> 1,8304
A43: =INCERTIDUMBRE!L6 -> 1.8303686 | B43: =IF(A43>=10,K77,IF(A43>=1,K69,IF(A43>=0.1,K61,IF(A43>=0.01,K53,IF(A43>=0.001,K45))))) -> 1,8 | C43: 6 decimal | D43: =D42+0 -> 9
C44: Extrae el ultimo digito | D44: extrael primer digito | E44: parte entera | F44: Parte decimal | G44: cantidad de decimales | H44: decimales en enteros | I44: restar ultimo numero | J44: Elimar ultimo digito | K44: Dato Final
...

Sheet PATRON
C2: =INFORMACIÓN!#REF! -> #REF!
A3: Deriva | C3: Nominal | D3: Medido | E3: Corrección | F3: Incertidumbre | G3: k | H3: Correcion estimada | I3: Residuales | J3: N-M-1 | K3: u interpolación
A4: =_xlfn.IFS($C$2="PSI",0.8,$C$2="kPa",0.8*6.894757,$C$2="inHg",(0.8*6.894757)/3.386389,$C$2="mmHg",(0.8*6.894757)/0.1333224) -> #REF! | C4: 60 | D4: 60.1 | E4: =C4-D4 -> -0.1 | F4: 0 | G4: 2 | H4: =$K$16*D4^3-$K$17*D4^2+$K$18*D4-$K$19 -> -0.18573684 | I4: =E4-H4 -> 0.085736836 | J4: =6-3-1 -> 2 | K4: =(SQRT(SUMSQ(I4:I8)/J4)) -> 1.6754153
C5: 120 | D5: 120 | E5: =C5-D5 -> 0 | F5: 0.3 | G5: 2 | H5: =$K$16*D5^3-$K$17*D5^2+$K$18*D5-$K$19 -> -0.93035315 | I5: =E5-H5 -> 0.93035315
C6: 140 | D6: 140.3 | E6: =C6-D6 -> -0.3 | F6: 0.4 | G6: 2 | H6: =$K$16*D6^3-$K$17*D6^2+$K$18*D6-$K$19 -> -1.2253364 | I6: =E6-H6 -> 0.92533638
C7: 180 | D7: 180.5 | E7: =C7-D7 -> -0.5 | F7: 2 | G7: 2 | H7: =$K$16*D7^3-$K$17*D7^2+$K$18*D7-$K$19 -> -1.6138233 | I7: =E7-H7 -> 1.1138233
C8: 200 | D8: 200 | E8: =C8-D8 -> 0 | F8: 0 | G8: 2 | H8: =$K$16*D8^3-$K$17*D8^2+$K$18*D8-$K$19 -> -1.6261228 | I8: =E8-H8 -> 1.6261228
K16: 8.8570577e-07
K17: 0.0003099672
K18: 0.021053052
K19: 0.52369123
B34: EQUIPO PATRÓN
B35: Equipo patrón: | G35: Simulador Fetal
B36: Marca: | G36: Novamedical
B37: Modelo: | G37: SFNM
B38: Serie: | G38: SF0094
B39: Fecha de Calibración: | G39: 44729
B40: No. Certificado: | G40: L3620
B41: Incertidumbre frecuencia: | G41: 1.5
B42: Deriva frecuencia: | G42: 0.5
B43: Resolución frecuencia: | G43: 1
B44: Factor de cobertura K: | G44: 2

Sheet MEDIDA
B3: CALIBRACIÓN DE FETOCARDIA | K3: CORRECCIÓN CALIBRACIÓN DE FETOCARDIA
B4: Valor nominal | C4: Lectura 1 | D4: Lectura 2 | E4: Lectura 3 | F4: Lectura 4 | K4: Valor nominal | L4: Lectura 1 | M4: Lectura 2 | N4: Lectura 3 | O4: Lectura 4 | P4: Promedio | Q4: Error
B5: 60 | C5: 60 | D5: =C5+((RAND()*(0.9-0.1)+0.1)*RANDBETWEEN(-1,1)) -> 60 | E5: =C5+((RAND()*(0.9-0.1)+0.1)*RANDBETWEEN(-1,1)) -> 59.841267 | F5: =C5+((RAND()*(0.9-0.1)+0.1)*RANDBETWEEN(-1,1)) -> 60 | K5: =B5 -> 60 | L5: =C5-0.1 -> 59.9 | M5: =D5-0.1 -> 59.9 | N5: =E5-0.1 -> 59.741267 | O5: =F5-0.1 -> 59.9 | P5: =AVERAGE(L5:O5) -> 59.860317 | Q5: =K5-P5 -> 0.13968334
B6: 120 | C6: 120 | D6: =C6+((RAND()*(0.9-0.1)+0.1)*RANDBETWEEN(-1,1)) -> 119.22678 | E6: =C6+((RAND()*(0.9-0.1)+0.1)*RANDBETWEEN(-1,1)) -> 120 | F6: =C6+((RAND()*(0.9-0.1)+0.1)*RANDBETWEEN(-1,1)) -> 120.46715 | K6: =B6 -> 120 | L6: =C6 -> 120 | M6: =D6 -> 119.22678 | N6: =E6 -> 120 | O6: =F6 -> 120.46715 | P6: =AVERAGE(L6:O6) -> 119.92348 | Q6: =K6-P6 -> 0.076516841
B7: 180 | C7: 179 | D7: =C7+((RAND()*(0.9-0.1)+0.1)*RANDBETWEEN(-1,1)) -> 178.44037 | E7: =C7+((RAND()*(0.9-0.1)+0.1)*RANDBETWEEN(-1,1)) -> 179 | F7: =C7+((RAND()*(0.9-0.1)+0.1)*RANDBETWEEN(-1,1)) -> 179 | K7: =B7 -> 180 | L7: =C7-0.5 -> 178.5 | M7: =D7-0.5 -> 177.94037 | N7: =E7-0.5 -> 178.5 | O7: =F7-0.5 -> 178.5 | P7: =AVERAGE(L7:O7) -> 178.36009 | Q7: =K7-P7 -> 1.6399066
B8: 200 | C8: 200 | D8: =C8+((RAND()*(0.9-0.1)+0.1)*RANDBETWEEN(-1,1)) -> 200 | E8: =C8+((RAND()*(0.9-0.1)+0.1)*RANDBETWEEN(-1,1)) -> 199.73175 | F8: =C8+((RAND()*(0.9-0.1)+0.1)*RANDBETWEEN(-1,1)) -> 200.75554 | K8: =B8 -> 200 | L8: =C8 -> 200 | M8: =D8 -> 200 | N8: =E8 -> 199.73175 | O8: =F8 -> 200.75554 | P8: =AVERAGE(L8:O8) -> 200.12182 | Q8: =K8-P8 -> -0.12182395
B11: CALIBRACIÓN DE ACTIVIDAD UTERINA
B12: Valor nominal | C12: Lectura 1 | D12: Lectura 2 | E12: Lectura 3 | F12: Lectura 4
B13: 20 | C13: =19 + (21 - 19) * RAND() -> 20.838139 | D13: =C13+((RAND()*(0.9-0.1)+0.1)*RANDBETWEEN(-1,1)) -> 20.303566 | E13: =C13+((RAND()*(0.9-0.1)+0.1)*RANDBETWEEN(-1,1)) -> 20.838139 | F13: =C13+((RAND()*(0.9-0.1)+0.1)*RANDBETWEEN(-1,1)) -> 20.322818
B14: 60 | C14: =59 + (61 - 59) * RAND() -> 60.817861 | D14: =C14+((RAND()*(0.9-0.1)+0.1)*RANDBETWEEN(-1,1)) -> 60.430512 | E14: =C14+((RAND()*(0.9-0.1)+0.1)*RANDBETWEEN(-1,1)) -> 60.817861 | F14: =C14+((RAND()*(0.9-0.1)+0.1)*RANDBETWEEN(-1,1)) -> 61.691673
B15: 80 | C15: =79 + (81 - 79) * RAND() -> 79.555966 | D15: =C15+((RAND()*(0.9-0.1)+0.1)*RANDBETWEEN(-1,1)) -> 78.742194 | E15: =C15+((RAND()*(0.9-0.1)+0.1)*RANDBETWEEN(-1,1)) -> 79.555966 | F15: =C15+((RAND()*(0.9-0.1)+0.1)*RANDBETWEEN(-1,1)) -> 79.555966
B16: 100 | C16: =99 + (101 - 99) * RAND() -> 100.8565 | D16: =C16+((RAND()*(0.9-0.1)+0.1)*RANDBETWEEN(-1,1)) -> 100.8565 | E16: =C16+((RAND()*(0.9-0.1)+0.1)*RANDBETWEEN(-1,1)) -> 100.8565 | F16: =C16+((RAND()*(0.9-0.1)+0.1)*RANDBETWEEN(-1,1)) -> 100.8565

Sheet INCERTIDUMBRE
B2: FUENTES DE INCERTIDUMBRE FETOCARDIA
B3: Punto de calibración | C3: Cert de calibración | D3: Deriva | E3: Interpolación | F3: Resolución item | G3: Resolución patrón | H3: Repetibilidad | I3: Incertidumbre combinada | J3: Veff | K3: Factor de cobertura (k) | L3: Incertidumbre Expandida
B4: =MEDIDA!B5 -> 60 | C4: =PATRON!$G$41/2 -> 0.75 | D4: =PATRON!$G$42/SQRT(3) -> 0.28867513 | E4: 0 | F4: =1/SQRT(12) -> 0.28867513 | G4: =PATRON!$G$43/SQRT(12) -> 0.28867513 | H4: =STDEVA(MEDIDA!L5:O5)/SQRT(4) -> 0.039683339 | I4: =SQRT(SUMSQ(C4:H4)) -> 0.90226092 | J4: =I4^4/(C4^4/200+D4^4/200+E4^4/200+F4^4/200+G4^4/200+H4^4/3) -> 392.8323 | K4: =TINV(0.0455,J4) -> 2.0064 | L4: =I4*K4 -> 1.8102963
B5: =MEDIDA!B6 -> 120 | C5: =PATRON!$G$41/2 -> 0.75 | D5: =PATRON!$G$42/SQRT(3) -> 0.28867513 | E5: 0 | F5: =1/SQRT(12) -> 0.28867513 | G5: =PATRON!$G$43/SQRT(12) -> 0.28867513 | H5: =STDEVA(MEDIDA!L6:O6)/SQRT(4) -> 0.25701436 | I5: =SQRT(SUMSQ(C5:H5)) -> 0.93731339 | J5: =I5^4/(C5^4/200+D5^4/200+E5^4/200+F5^4/200+G5^4/200+H5^4/3) -> 245.7625 | K5: =TINV(0.0455,J5) -> 2.0102578 | L5: =I5*K5 -> 1.8842415
B6: =MEDIDA!B7 -> 180 | C6: =PATRON!$G$41/2 -> 0.75 | D6: =PATRON!$G$42/SQRT(3) -> 0.28867513 | E6: 0 | F6: =1/SQRT(12) -> 0.28867513 | G6: =PATRON!$G$43/SQRT(12) -> 0.28867513 | H6: =STDEVA(MEDIDA!L7:O7)/SQRT(4) -> 0.13990663 | I6: =SQRT(SUMSQ(C6:H6)) -> 0.91218083 | J6: =I6^4/(C6^4/200+D6^4/200+E6^4/200+F6^4/200+G6^4/200+H6^4/3) -> 381.68758 | K6: =TINV(0.0455,J6) -> 2.0065853 | L6: =I6*K6 -> 1.8303686
B7: =MEDIDA!B8 -> 200 | C7: =PATRON!$G$41/2 -> 0.75 | D7: =PATRON!$G$42/SQRT(3) -> 0.28867513 | E7: 0 | F7: =1/SQRT(12) -> 0.28867513 | G7: =PATRON!$G$43/SQRT(12) -> 0.28867513 | H7: =STDEVA(MEDIDA!L8:O8)/SQRT(4) -> 0.2204986 | I7: =SQRT(SUMSQ(C7:H7)) -> 0.92796532 | J7: =I7^4/(C7^4/200+D7^4/200+E7^4/200+F7^4/200+G7^4/200+H7^4/3) -> 299.70931 | K7: =TINV(0.0455,J7) -> 2.008398 | L7: =I7*K7 -> 1.8637237
B10: FUENTES DE INCERTIDUMBRE ACTIVIDAD UTERINA
B11: Punto de calibración | C11: Cert de calibración | D11: Deriva | E11: Interpolación | F11: Resolución item | G11: Resolución patrón | H11: Repetibilidad | I11: Incertidumbre combinada | J11: Veff | K11: Factor de cobertura (k) | L11: Incertidumbre Expandida
B12: =MEDIDA!B13 -> 20 | C12: =PATRON!$G$41/2 -> 0.75 | D12: =PATRON!$G$42/SQRT(3) -> 0.28867513 | E12: 0 | F12: =1/SQRT(12) -> 0.28867513 | G12: =PATRON!$G$43/SQRT(12) -> 0.28867513 | H12: =STDEVA(MEDIDA!C13:F13)/SQRT(4) -> 0.15159027 | I12: =SQRT(SUMSQ(C12:H12)) -> 0.91404574 | J12: =I12^4/(C12^4/200+D12^4/200+E12^4/200+F12^4/200+G12^4/200+H12^4/3) -> 374.83576 | K12: =TINV(0.0455,J12) -> 2.0067089 | L12: =I12*K12 -> 1.8342237
B13: =MEDIDA!B14 -> 60 | C13: =PATRON!$G$41/2 -> 0.75 | D13: =PATRON!$G$42/SQRT(3) -> 0.28867513 | E13: 0 | F13: =1/SQRT(12) -> 0.28867513 | G13: =PATRON!$G$43/SQRT(12) -> 0.28867513 | H13: =STDEVA(MEDIDA!C14:F14)/SQRT(4) -> 0.26683723 | I13: =SQRT(SUMSQ(C13:H13)) -> 0.94005431 | J13: =I13^4/(C13^4/200+D13^4/200+E13^4/200+F13^4/200+G13^4/200+H13^4/3) -> 231.31034 | K13: =TINV(0.0455,J13) -> 2.0108826 | L13: =I13*K13 -> 1.8903389
B14: =MEDIDA!B15 -> 80 | C14: =PATRON!$G$41/2 -> 0.75 | D14: =PATRON!$G$42/SQRT(3) -> 0.28867513 | E14: 0 | F14: =1/SQRT(12) -> 0.28867513 | G14: =PATRON!$G$43/SQRT(12) -> 0.28867513 | H14: =STDEVA(MEDIDA!C15:F15)/SQRT(4) -> 0.20344321 | I14: =SQRT(SUMSQ(C14:H14)) -> 0.92406122 | J14: =I14^4/(C14^4/200+D14^4/200+E14^4/200+F14^4/200+G14^4/200+H14^4/3) -> 323.02002 | K14: =TINV(0.0455,J14) -> 2.0077718 | L14: =I14*K14 -> 1.8553041
B15: =MEDIDA!B16 -> 100 | C15: =PATRON!$G$41/2 -> 0.75 | D15: =PATRON!$G$42/SQRT(3) -> 0.28867513 | E15: 0 | F15: =1/SQRT(12) -> 0.28867513 | G15: =PATRON!$G$43/SQRT(12) -> 0.28867513 | H15: =STDEVA(MEDIDA!C16:F16)/SQRT(4) -> 0 | I15: =SQRT(SUMSQ(C15:H15)) -> 0.90138782 | J15: =I15^4/(C15^4/200+D15^4/200+E15^4/200+F15^4/200+G15^4/200+H15^4/3) -> 391.50579 | K15: =TINV(0.0455,J15) -> 2.0064164 | L15: =I15*K15 -> 1.8085593

Sheet CERTIFICADO
O1: CERTIFICADO N°: | R1: =INFORMACIÓN!G3 -> 0
C3: 1. EQUIPO BAJO PRUEBA
C5: INSTRUMENTO: | I5: =INFORMACIÓN!A3 -> 0
C6: MARCA: | I6: =INFORMACIÓN!B3 -> 0
C7: MODELO: | I7: =INFORMACIÓN!C3 -> 0
C8: SERIE: | I8: =INFORMACIÓN!D3 -> 0
C9: CÓDIGO INTERNO: | I9: =INFORMACIÓN!F3 -> 0
C10: UBICACIÓN: | I10: =INFORMACIÓN!E3 -> 0
C11: ESTADO FÍSICO: | I11: =INFORMACIÓN!B8 -> BUEN ESTADO
C12: FECHA DE RECEPCIÓN: | I12: =INFORMACIÓN!H3 -> 0
C13: FECHA DE CALIBRACIÓN: | I13: =INFORMACIÓN!B9 -> 0
C15: 2. DATOS DEL CLIENTE
C17: NOMBRE: | I17: =INFORMACIÓN!E7 -> 0
C18: NIT: | I18: =INFORMACIÓN!E8 -> 0
C19: TELÉFONO: | I19: =INFORMACIÓN!E9 -> 0
C20: DIRECCIÓN: | I20: =INFORMACIÓN!E10 -> 0
C21: CIUDAD: | I21: =INFORMACIÓN!E11 -> 0
C23: Este certificado expresa fielmente el resultado de las mediciones realizadas; no podrá ser reproducido total o parcialmente excepto cuando se haya obtenido permiso por escrito de BTM COLOMBIA ZOMAC S.A.S y se debe reproducir en su totalidad, para proporcionar seguridad de que el certificado no sea sacado de contexto. Los resultados que se encuentran en este certificado se refieren al momento y condiciones en que se realizaron las mediciones, BTM COLOMBIA ZOMAC S.A.S no se responsabiliza de los daños que puedan ser causados por el uso inadecuado de los equipos calibrados. El usuario es responsable de la calibración de sus instrumentos a intervalos apropiados. El laboratorio no se hace responsable por cómo la información suministrada por el cliente afecte los resultados de medición.
C31: REVISÓ Y AUTORIZÓ: | I31: CALIBRADO POR: | M31: =INFORMACIÓN!B15 -> ING. GABRIEL DURÁN
I32: FECHA DE EMISIÓN: | M32: =INFORMACIÓN!B10 -> 0
I33: NÚMERO DE PÁGINAS: | M33: 3
C36: ING. JOHAN SEBASTIÁN PÉREZ
C37: DIRECTOR DE LABORATORIO
O38: =O1 -> CERTIFICADO N°: | R38: =R1 -> 0
B40: 3. CONDICIONES AMBIENTALES
B41: El laboratorio de metrología BTM COLOMBIA ZOMAC S.A.S registra las condiciones ambientales (Humedad y Temperatura) tomando los máximos y mínimos alcanzados durante el tiempo en que se ejecuta la calibración. A continuación se presenta el promedio y la variación resultante.
F45: TEMPERATURA AMBIENTE (°C) | K45: HUMEDAD RELATIVA (%HR)
F46: =AVERAGE(INFORMACIÓN!B11:B12) -> 24.3 | H46: ± | I46: =ABS(INFORMACIÓN!B11-INFORMACIÓN!B12) -> 0.4 | K46: =AVERAGE(INFORMACIÓN!B13:B14) -> 61.5 | M46: ± | N46: =ABS(INFORMACIÓN!B13-INFORMACIÓN!B14) -> 3
F48: La calibración fue realizada en: | K48: =INFORMACIÓN!B7 -> En sitio (instalaciones del cliente)
B50: 4. INCERTIDUMBRE DE MEDICIÓN
B51: La incertidumbre expandida de la medición reportada se establece como la incertidumbre estándar de medición multiplicada por el factor de cobertura “k” y la probabilidad de cobertura, la cual debe ser aproximada al 95% y no menor a este valor. La incertidumbre de medición ha sido estimada con un nivel de confianza del 95,45% empleando una distribución t de Student. Cuando se hace declaración de cumplimiento, el laboratorio hace referencia a las especificaciones del fabricante, norma o requisitos declarados por el cliente. La regla de decisión aplicada en estos casos será |Error| +U ≤ EMP según la ASME B89 7.3.1, si cumple la anterior condición la medición se toma como conforme y registrará un pasa, en caso contrario se registrará falla. La probabilidad de dar una aceptación falsa o un rechazo falso no lo determina el laboratorio, sin embargo se puede calcular de acuerdo a la guía JCGM 106:2012 según su numeral 8.
B60: 5. PROCEDIMIENTO DE CALIBRACIÓN
B61: La calibración se ejecutó mediante el método de comparación directa con patrón de referencia de acuerdo con el procedimiento interno para monitor fetal BTM-P-009.
B64: 6. TRAZABILIDAD
B65: El laboratorio BTM COLOMBIA ZOMAC S.A.S establece la trazabilidad metrológica de sus mediciones al sistema internacional de unidades (SI), por medio de una cadena documentada de calibraciones, las cuales se encuentran referenciadas a patrones de medidas primarios. Esta vinculación se logra a través del uso de patrones calibrados por institutos nacionales de metrología (INM) y por laboratorios acreditados por parte de un organismo de acreditación.
B70: PATRÓN | H70: SERIE | M70: CALIBRACIÓN | P70: CERTIFICADO
B71: Simulador fetal | H71: SF0094 | M71: 46069 | P71: L5566
B72: Juego de Pesas (1 mg a 500 g) | H72: No registra | M72: 46038 | P72: CBC-0007-001-26
B73: Juego de Pesas (1 kg a 5 kg) | H73: No registra | M73: 46038 | P73: CBC-0007-002-26
O76: =O1 -> CERTIFICADO N°: | R76: =R1 -> 0
...
