Workbook
Name Instrumento: '[1]R-LAB-127 DENSIDAD AIRE'!#REF!
Name Instrumento: '[1]R-LAB-127 DENSIDAD AIRE'!#REF!
Name Instrumento.: '[1]R-LAB-127 DENSIDAD AIRE'!#REF!
Name Instrumento.: '[1]R-LAB-127 DENSIDAD AIRE'!#REF!
Name N: #REF!
Name N: #REF!

Sheet INFORMACIÓN
A1: Datos del item | O1: En sitio ( instalaciones del cliente)
A2: Intrumento | B2: Marca | C2: Modelo | D2: Serie | E2: Ubicación | F2: Inventario | G2: Número de Certificado | H2: Fecha de Recepción | O2: Laboratorio BTMC
O4: BUEN ESTADO
O5: REGULAR ESTADO
A6: Datos de calibración | D6: Datos del cliente | O6: MAL ESTADO
A7: Lugar de calibración: | B7: En sitio ( instalaciones del cliente) | D7: Solicitante: | E7: HOSPITAL DE ALTA COMPLEJIDAD DEL MAGDALENA CENTRO
A8: Estado Físico: | B8: BUEN ESTADO | D8: Nit: | E8: 901.532.463-8
A9: Fecha de calibración: | B9: =H3 -> 0 | D9: Telefono: | E9: 3007835072
A10: Fecha de emisión: | B10: =H3 -> 0 | D10: Dirección: | E10: CARRERA 15 ENTRE CALLE 18 y 19
A11: Temperatura mínima: | B11: 24.1 | D11: Ciudad: | E11: LA DORADA - CALDAS
A12: Temperatura máxima: | B12: 24.5
A13: Humedad Mínima: | B13: 60
A14: Humedad Máxima: | B14: 63
A15: Calibración realiza por: | B15: ING. GABRIEL DURÁN

Sheet Redondeo
A1: DATO 1
A2: Dato | B2: Dato redondeado | C2: =FIXED(A3,6) -> 0,630920 | D2: =RIGHT(C2,1) -> 0 | E2: =D2/1000000 -> 0 | F2: =A3-E2 -> 0.63091998 | H2: =IF(C7=5,IF(AND(D3=0,D8=FALSE),J5,J6),J6) -> 0,6309
A3: =INCERTIDUMBRE!L5 -> 0.63091998 | B3: =IF(A3>=10,K37,IF(A3>=1,K29,IF(A3>=0.1,K21,IF(A3>=0.01,K13,IF(A3>=0.001,K5))))) -> 0,63 | C3: 6 decimal | D3: =D2+0 -> 0
C4: Extrae el ultimo digito | D4: extrael primer digito | E4: parte entera | F4: Parte decimal | G4: cantidad de decimales | H4: decimales en enteros | I4: restar ultimo numero | J4: Elimar ultimo digito | K4: Dato Final
C5: =RIGHT(F2,2) -> 94 | D5: =LEFT(C5,1) -> 9 | E5: =TRUNC(A3) -> 0 | F5: =FIXED(A3-E5,G5) -> 0,63091998228594 | G5: =ABS(E8-F8) -> 14 | H5: =RIGHT(A3,G5) -> 63091998228594 | I5: 5e-05 | J5: =(A3-I5) -> 0.63086998 | K5: =IF(C7=5,IF(AND(D3=0,D8=FALSE),J5,J6),J6) -> 0,6309
C6: =RIGHT(C5,1) -> 4 | D6: =D5+0 -> 9 | J6: =FIXED(A3,4) -> 0,6309
C7: =C6+0 -> 4 | D7: es impar? | E7: Largo dato original | F7: largo parte enetero y decimal
D8: =ISODD(D5) -> TRUE | E8: =LEN(A3) -> 16 | F8: =LEN(E5)+1 -> 2
A10: 4 Decimales
A11: =K5 -> 0,6309 | C11: =FIXED(A3,5) -> 0,63092 | D11: =RIGHT(C11,1) -> 2 | E11: =D11+0 -> 2
C12: Extrae el ultimo digito | D12: extrael primer digito | E12: parte entera | F12: Parte decimal | G12: cantidad de decimales | H12: decimales en enteros | I12: restar ultimo numero | J12: Elimar ultimo digito | K12: Dato Final
C13: =RIGHT(A11,2) -> 09 | D13: =LEFT(C13,1) -> 0 | E13: =TRUNC(A11) -> 0 | F13: =FIXED(A11-E13,G13) -> 0,6309 | G13: =ABS(E16-F16) -> 4 | H13: =RIGHT(A11,G13) -> 6309 | I13: 0.0005 | J13: =(A11-I13) -> 0.6304 | K13: =IF(C15=5,IF(AND(E11=0,D16=FALSE),J13,J14),J14) -> 0,631
C14: =RIGHT(C13,1) -> 9 | D14: =D13+0 -> 0 | J14: =FIXED(A11,3) -> 0,631
C15: =C14+0 -> 9 | D15: es impar? | E15: Largo dato original | F15: largo parte enetero y decimal
D16: =ISODD(D13) -> FALSE | E16: =LEN(A11) -> 6 | F16: =LEN(E13)+1 -> 2
A18: 3 Decimales
A19: =K13 -> 0,631 | C19: =FIXED(A11,4) -> 0,6309 | D19: =RIGHT(C19,1) -> 9 | E19: =D19+0 -> 9
C20: Extrae el ultimo digito | D20: extrael primer digito | E20: parte entera | F20: Parte decimal | G20: cantidad de decimales | H20: decimales en enteros | I20: restar ultimo numero | J20: Elimar ultimo digito | K20: Dato Final
C21: =RIGHT(A19,2) -> 31 | D21: =LEFT(C21,1) -> 3 | E21: =TRUNC(A19) -> 0 | F21: =FIXED(A19-E21,G21) -> 0,631 | G21: =ABS(E24-F24) -> 3 | H21: =RIGHT(A19,G21) -> 631 | I21: 0.005 | J21: =(A19-I21) -> 0.626 | K21: =IF(C23=5,IF(AND(E19=0,D24=FALSE),J21,J22),J22) -> 0,63
C22: =RIGHT(C21,1) -> 1 | D22: =D21+0 -> 3 | J22: =FIXED(A19,2) -> 0,63
C23: =C22+0 -> 1 | D23: es impar? | E23: Largo dato original | F23: largo parte enetero y decimal
D24: =ISODD(D21) -> TRUE | E24: =LEN(A19) -> 5 | F24: =LEN(E21)+1 -> 2
A26: 2 Decimales
A27: =K21 -> 0,63 | C27: =FIXED(A19,3) -> 0,631 | D27: =RIGHT(C27,1) -> 1 | E27: =D27+0 -> 1
C28: Extrae el ultimo digito | D28: extrael primer digito | E28: parte entera | F28: Parte decimal | G28: cantidad de decimales | H28: decimales en enteros | I28: restar ultimo numero | J28: Elimar ultimo digito | K28: Dato Final
C29: =RIGHT(A27,2) -> 63 | D29: =LEFT(C29,1) -> 6 | E29: =TRUNC(A27) -> 0 | F29: =FIXED(A27-E29,G29) -> 0,63 | G29: =ABS(E32-F32) -> 2 | H29: =RIGHT(A27,G29) -> 63 | I29: 0.05 | J29: =(A27-I29) -> 0.58 | K29: =IF(C31=5,IF(AND(E27=0,D32=FALSE),J29,J30),J30) -> 0,6
C30: =RIGHT(C29,1) -> 3 | D30: =D29+0 -> 6 | J30: =FIXED(A27,1) -> 0,6
C31: =C30+0 -> 3 | D31: es impar? | E31: Largo dato original | F31: largo parte enetero y decimal
D32: =ISODD(D29) -> FALSE | E32: =LEN(A27) -> 4 | F32: =LEN(E29)+1 -> 2
A34: 1 Decimales
A35: =K29 -> 0,6 | C35: =FIXED(A27,2) -> 0,63 | D35: =RIGHT(C35,1) -> 3 | E35: =D35+0 -> 3
C36: Extrae el ultimo digito | D36: extrael primer digito | E36: parte entera | F36: Parte decimal | G36: cantidad de decimales | H36: decimales en enteros | I36: restar ultimo numero | J36: Elimar ultimo digito | K36: Dato Final
C37: =RIGHT(A35,2) -> ,6 | D37: =RIGHT(E37,1) -> 0 | E37: =TRUNC(A35) -> 0 | F37: =FIXED(A35-E37,G37) -> 0,6 | G37: =ABS(E40-F40) -> 1 | H37: =RIGHT(A35,G37) -> 6 | I37: 0.5 | J37: =(A35-I37) -> 0.1 | K37: =IF(C39=5,IF(AND(E35=0,D40=FALSE),J37,J38),J38) -> 1
C38: =RIGHT(C37,1) -> 6 | D38: =D37+0 -> 0 | J38: =FIXED(A35,0) -> 1
C39: =C38+0 -> 6 | D39: es impar? | E39: Largo dato original | F39: largo parte enetero y decimal
D40: =ISODD(D37) -> FALSE | E40: =LEN(A35) -> 3 | F40: =LEN(E37)+1 -> 2
A41: DATO 2
A42: Dato | B42: Dato redondeado | C42: =FIXED(A43,6) -> #REF! | D42: =RIGHT(C42,1) -> #REF! | E42: =D42/1000000 -> #REF! | F42: =A43-E42 -> #REF! | H42: =IF(C47=5,IF(AND(D43=0,D48=FALSE),J45,J46),J46) -> #REF!
A43: =INCERTIDUMBRE!#REF! -> #REF! | B43: =IF(A43>=10,K77,IF(A43>=1,K69,IF(A43>=0.1,K61,IF(A43>=0.01,K53,IF(A43>=0.001,K45))))) -> #REF! | C43: 6 decimal | D43: =D42+0 -> #REF!
C44: Extrae el ultimo digito | D44: extrael primer digito | E44: parte entera | F44: Parte decimal | G44: cantidad de decimales | H44: decimales en enteros | I44: restar ultimo numero | J44: Elimar ultimo digito | K44: Dato Final
...

Sheet MEDIDA
B3: CALIBRACIÓN DE VOLTAJE | T3: TIEMPO DE EXPOSICIÓN
B4: Equipo bajo prueba | D4: Medidas del equipo patrón | T4: Equipo bajo prueba | V4: Medidas del equipo patrón
D5: Lectura 1 | F5: Lectura 2 | H5: Lectura 3 | J5: Lectura 4 | L5: Promedio | N5: Error | V5: Lectura 1 | X5: Lectura 2 | Z5: Lectura 3 | AB5: Lectura 4 | AD5: Promedio
B6: 50 | D6: 51 | F6: =D6+((RAND()*(0.3-0.1)+0.1)*RANDBETWEEN(-1,1)) -> 51.231122 | H6: =D6+((RAND()*(0.3-0.1)+0.1)*RANDBETWEEN(-1,1)) -> 51 | J6: =D6+((RAND()*(0.3-0.1)+0.1)*RANDBETWEEN(-1,1)) -> 51 | L6: =AVERAGE(D6:K6) -> 51.057781 | N6: =B6-L6 -> -1.0577806 | T6: 50 | V6: 19 | X6: =V6+((RAND()*(0.9-0.1)+0.7)*RANDBETWEEN(-1,1)) -> 19.786881 | Z6: =V6+((RAND()*(0.9-0.1)+0.7)*RANDBETWEEN(-1,1)) -> 19.798918 | AB6: =V6+((RAND()*(0.9-0.1)+0.7)*RANDBETWEEN(-1,1)) -> 19.976287 | AD6: =AVERAGE(V6:AC6) -> 19.640522
B7: 100 | D7: 100.3 | F7: =D7+((RAND()*(0.3-0.1)+0.1)*RANDBETWEEN(-1,1)) -> 100.3 | H7: =D7+((RAND()*(0.3-0.1)+0.1)*RANDBETWEEN(-1,1)) -> 100.46652 | J7: =D7+((RAND()*(0.3-0.1)+0.1)*RANDBETWEEN(-1,1)) -> 100.41047 | L7: =AVERAGE(D7:K7) -> 100.36925 | N7: =B7-L7 -> -0.36924695 | T7: 100 | V7: 102 | X7: =V7+((RAND()*(0.9-0.1)+0.7)*RANDBETWEEN(-1,1)) -> 101.18074 | Z7: =V7+((RAND()*(0.9-0.1)+0.7)*RANDBETWEEN(-1,1)) -> 103.27739 | AB7: =V7+((RAND()*(0.9-0.1)+0.7)*RANDBETWEEN(-1,1)) -> 100.86051 | AD7: =AVERAGE(V7:AC7) -> 101.82966
B8: 125 | D8: 123.5 | F8: =D8+((RAND()*(0.3-0.1)+0.1)*RANDBETWEEN(-1,1)) -> 123.5 | H8: =D8+((RAND()*(0.3-0.1)+0.1)*RANDBETWEEN(-1,1)) -> 123.26094 | J8: =D8+((RAND()*(0.3-0.1)+0.1)*RANDBETWEEN(-1,1)) -> 123.77932 | L8: =AVERAGE(D8:K8) -> 123.51007 | N8: =B8-L8 -> 1.4899349 | T8: 125 | V8: 343 | X8: =V8+((RAND()*(0.9-0.1)+0.7)*RANDBETWEEN(-1,1)) -> 341.63066 | Z8: =V8+((RAND()*(0.9-0.1)+0.7)*RANDBETWEEN(-1,1)) -> 341.73412 | AB8: =V8+((RAND()*(0.9-0.1)+0.7)*RANDBETWEEN(-1,1)) -> 342.1648 | AD8: =AVERAGE(V8:AC8) -> 342.1324
B11: CALIBRACIÓN DE DOSIMETRÍA | T11: HVL
B12: Equipo bajo prueba | D12: Medidas del equipo patrón | T12: Equipo bajo prueba | V12: Medidas del equipo patrón
D13: Lectura 1 | F13: Lectura 2 | H13: Lectura 3 | J13: Lectura 4 | L13: Promedio | V13: Lectura 1 | X13: Lectura 2 | Z13: Lectura 3 | AB13: Lectura 4 | AD13: Promedio
B14: 50 | D14: 1.54 | F14: =D14+((RAND()*(0.3-0.1)+0.1)*RANDBETWEEN(-1,1)) -> 1.6951216 | H14: =D14+((RAND()*(0.3-0.1)+0.1)*RANDBETWEEN(-1,1)) -> 1.3925603 | J14: =D14+((RAND()*(0.3-0.1)+0.1)*RANDBETWEEN(-1,1)) -> 1.8274477 | L14: =AVERAGE(D14:K14) -> 1.6137824 | T14: 50 | V14: 2.3 | X14: =V14+((RAND()*(0.2-0.1)+0.1)*RANDBETWEEN(-1,1)) -> 2.4677066 | Z14: =V14+((RAND()*(0.2-0.1)+0.1)*RANDBETWEEN(-1,1)) -> 2.4394102 | AB14: =V14+((RAND()*(0.2-0.1)+0.1)*RANDBETWEEN(-1,1)) -> 2.4733624 | AD14: =AVERAGE(V14:AC14) -> 2.4201198
B15: 100 | D15: 16.76 | F15: =D15+((RAND()*(0.3-0.1)+0.1)*RANDBETWEEN(-1,1)) -> 16.478976 | H15: =D15+((RAND()*(0.3-0.1)+0.1)*RANDBETWEEN(-1,1)) -> 16.541168 | J15: =D15+((RAND()*(0.3-0.1)+0.1)*RANDBETWEEN(-1,1)) -> 16.932756 | L15: =AVERAGE(D15:K15) -> 16.678225 | T15: 100 | V15: 4.6 | X15: =V15+((RAND()*(0.2-0.1)+0.1)*RANDBETWEEN(-1,1)) -> 4.4856779 | Z15: =V15+((RAND()*(0.2-0.1)+0.1)*RANDBETWEEN(-1,1)) -> 4.7849559 | AB15: =V15+((RAND()*(0.2-0.1)+0.1)*RANDBETWEEN(-1,1)) -> 4.7022447 | AD15: =AVERAGE(V15:AC15) -> 4.6432196
B16: 125 | D16: 23.21 | F16: =D16+((RAND()*(0.3-0.1)+0.1)*RANDBETWEEN(-1,1)) -> 22.939979 | H16: =D16+((RAND()*(0.3-0.1)+0.1)*RANDBETWEEN(-1,1)) -> 23.21 | J16: =D16+((RAND()*(0.3-0.1)+0.1)*RANDBETWEEN(-1,1)) -> 23.384549 | L16: =AVERAGE(D16:K16) -> 23.186132 | T16: 125 | V16: 6 | X16: =V16+((RAND()*(0.2-0.1)+0.1)*RANDBETWEEN(-1,1)) -> 6 | Z16: =V16+((RAND()*(0.2-0.1)+0.1)*RANDBETWEEN(-1,1)) -> 5.8948781 | AB16: =V16+((RAND()*(0.2-0.1)+0.1)*RANDBETWEEN(-1,1)) -> 6 | AD16: =AVERAGE(V16:AC16) -> 5.9737195
B19: TASA DE DOSIMETRIA
B20: Equipo bajo prueba | D20: Medidas del equipo patrón
D21: Lectura 1 | F21: Lectura 2 | H21: Lectura 3 | J21: Lectura 4 | L21: Promedio
B22: 50 | D22: 23.2 | F22: =D22+((RAND()*(0.3-0.1)+0.1)*RANDBETWEEN(-1,1)) -> 23.2 | H22: =D22+((RAND()*(0.3-0.1)+0.1)*RANDBETWEEN(-1,1)) -> 23.383456 | J22: =D22+((RAND()*(0.3-0.1)+0.1)*RANDBETWEEN(-1,1)) -> 23.2 | L22: =AVERAGE(D22:K22) -> 23.245864
B23: 100 | D23: 67.8 | F23: =D23+((RAND()*(0.3-0.1)+0.1)*RANDBETWEEN(-1,1)) -> 68.035045 | H23: =D23+((RAND()*(0.3-0.1)+0.1)*RANDBETWEEN(-1,1)) -> 67.613521 | J23: =D23+((RAND()*(0.3-0.1)+0.1)*RANDBETWEEN(-1,1)) -> 67.673581 | L23: =AVERAGE(D23:K23) -> 67.780537
B24: 125 | D24: 31.2 | F24: =D24+((RAND()*(0.3-0.1)+0.1)*RANDBETWEEN(-1,1)) -> 31.475956 | H24: =D24+((RAND()*(0.3-0.1)+0.1)*RANDBETWEEN(-1,1)) -> 31.329094 | J24: =D24+((RAND()*(0.3-0.1)+0.1)*RANDBETWEEN(-1,1)) -> 31.494714 | L24: =AVERAGE(D24:K24) -> 31.374941

Sheet PATRON
C2: Volumen
C3: Nominal | D3: Medido | E3: Corrección | F3: k | G3: Correcion estimada | H3: Residuales | I3: N-M-1 | J3: u interpolación
C4: 99.6 | D4: 106.2 | E4: =C4-D4 -> -6.6 | F4: 2 | G4: =J$13*D4-J$14 -> -6.6 | H4: =E4-G4 -> 0 | I4: =2-2-1 -> -1 | J4: 0
C5: 1000 | D5: 1042 | E5: =C5-D5 -> -42 | F5: 2 | G5: =J$13*D5-J$14 -> -42 | H5: =E5-G5 -> 0
J13: -0.037828596
J14: 2.5826031
B34: EQUIPO PATRÓN
B35: Equipo patrón: | G35: Analizador de flujo de gases
B36: Marca: | G36: TSI
B37: Modelo: | G37: 4070
B38: Serie: | G38: 40712037006
B39: Fecha de Calibración: | G39: 44970
B40: No. Certificado: | G40: L4012
B41: Incertidumbre flujo: | G41: 0.027
B42: Deriva flujo | G42: 0.2
B43: Resolución flujo | G43: 0.001
B44: Factor de cobertura K: | G44: 2

Sheet INCERTIDUMBRE
B2: FUENTES DE INCERTIDUMBRE VOLUMEN
B3: Punto de calibración | C3: Cert de calibración | D3: Deriva | E3: Interpolación | F3: Resolución item | G3: Resolución patrón | H3: Repetibilidad | I3: Incertidumbre combinada | J3: Veff | K3: Factor de cobertura (k) | L3: Incertidumbre Expandida
B4: =MEDIDA!B6 -> 50 | C4: =PATRON!G$41/2 -> 0.0135 | D4: =PATRON!G$42/SQRT(3) -> 0.11547005 | E4: 0 | F4: =1/SQRT(12) -> 0.28867513 | G4: =PATRON!G$43/SQRT(12) -> 0.00028867513 | H4: =STDEVA(MEDIDA!D6:K6)/SQRT(4) -> 0.057780611 | I4: =SQRT(SUMSQ(C4:H4)) -> 0.31652425 | J4: =I4^4/(C4^4/200+D4^4/200+E4^4/200+F4^4/200+G4^4/200+H4^4/3) -> 255.23517 | K4: =TINV(0.0455,J4) -> 2.0098537 | L4: =I4*K4 -> 0.63616742
B5: =MEDIDA!B7 -> 100 | C5: =PATRON!G$41/2 -> 0.0135 | D5: =PATRON!G$42/SQRT(3) -> 0.11547005 | E5: 0 | F5: =1/SQRT(12) -> 0.28867513 | G5: =PATRON!G$43/SQRT(12) -> 0.00028867513 | H5: =STDEVA(MEDIDA!D7:K7)/SQRT(4) -> 0.041584247 | I5: =SQRT(SUMSQ(C5:H5)) -> 0.31397173 | J5: =I5^4/(C5^4/200+D5^4/200+E5^4/200+F5^4/200+G5^4/200+H5^4/3) -> 265.45179 | K5: =TINV(0.0455,J5) -> 2.0094802 | L5: =I5*K5 -> 0.63091998
B6: =MEDIDA!B8 -> 125 | C6: =PATRON!G$41/2 -> 0.0135 | D6: =PATRON!G$42/SQRT(3) -> 0.11547005 | E6: 0 | F6: =1/SQRT(12) -> 0.28867513 | G6: =PATRON!G$43/SQRT(12) -> 0.00028867513 | H6: =STDEVA(MEDIDA!D8:K8)/SQRT(4) -> 0.10597454 | I6: =SQRT(SUMSQ(C6:H6)) -> 0.32875462 | J6: =I6^4/(C6^4/200+D6^4/200+E6^4/200+F6^4/200+G6^4/200+H6^4/3) -> 150.42738 | K6: =TINV(0.0455,J6) -> 2.0168061 | L6: =I6*K6 -> 0.66303434
B7: =MEDIDA!#REF! -> #REF! | C7: =PATRON!G$41/2 -> 0.0135 | D7: =PATRON!G$42/SQRT(3) -> 0.11547005 | E7: 0 | F7: =1/SQRT(12) -> 0.28867513 | G7: =PATRON!G$43/SQRT(12) -> 0.00028867513 | H7: =STDEVA(MEDIDA!#REF!)/SQRT(4) -> #REF! | I7: =SQRT(SUMSQ(C7:H7)) -> #REF! | J7: =I7^4/(C7^4/200+D7^4/200+E7^4/200+F7^4/200+G7^4/200+H7^4/3) -> #REF! | K7: =TINV(0.0455,J7) -> #REF! | L7: =I7*K7 -> #REF!
B8: =MEDIDA!#REF! -> #REF! | C8: =PATRON!G$41/2 -> 0.0135 | D8: =PATRON!G$42/SQRT(3) -> 0.11547005 | E8: 0 | F8: =1/SQRT(12) -> 0.28867513 | G8: =PATRON!G$43/SQRT(12) -> 0.00028867513 | H8: =STDEVA(MEDIDA!#REF!)/SQRT(4) -> #REF! | I8: =SQRT(SUMSQ(C8:H8)) -> #REF! | J8: =I8^4/(C8^4/200+D8^4/200+E8^4/200+F8^4/200+G8^4/200+H8^4/3) -> #REF! | K8: =TINV(0.0455,J8) -> #REF! | L8: =I8*K8 -> #REF!

Sheet CERTIFICADO 
O1: CERTIFICADO N°: | R1: =INFORMACIÓN!G3 -> 0
C3: 1. EQUIPO BAJO PRUEBA
C5: INSTRUMENTO: | I5: =INFORMACIÓN!A3 -> 0
C6: MARCA: | I6: =INFORMACIÓN!B3 -> 0
C7: MODELO: | I7: =INFORMACIÓN!C3 -> 0
C8: SERIE: | I8: =INFORMACIÓN!D3 -> 0
C9: CÓDIGO INTERNO: | I9: =INFORMACIÓN!F3 -> 0
C10: UBICACIÓN: | I10: =INFORMACIÓN!E3 -> 0
C11: ESTADO FÍSICO: | I11: =INFORMACIÓN!B8 -> BUEN ESTADO
C12: FECHA DE RECEPCIÓN: | I12: =INFORMACIÓN!H3 -> 0
C13: FECHA DE CALIBRACIÓN: | I13: =INFORMACIÓN!B9 -> 0
C15: 2. DATOS DEL CLIENTE
C17: NOMBRE: | I17: =INFORMACIÓN!E7 -> HOSPITAL DE ALTA COMPLEJIDAD DEL MAGDALENA CENTRO
C18: NIT: | I18: =INFORMACIÓN!E8 -> 901.532.463-8
C19: TELÉFONO: | I19: =INFORMACIÓN!E9 -> 3007835072
C20: DIRECCIÓN: | I20: =INFORMACIÓN!E10 -> CARRERA 15 ENTRE CALLE 18 y 19
C21: CIUDAD: | I21: =INFORMACIÓN!E11 -> LA DORADA - CALDAS
C23: Este certificado expresa fielmente el resultado de las mediciones realizadas; no podrá ser reproducido total o parcialmente excepto cuando se haya obtenido permiso por escrito de BTM COLOMBIA ZOMAC S.A.S y se debe reproducir en su totalidad, para proporcionar seguridad de que el certificado no sea sacado de contexto. Los resultados que se encuentran en este certificado se refieren al momento y condiciones en que se realizaron las mediciones, BTM COLOMBIA ZOMAC S.A.S no se responsabiliza de los daños que puedan ser causados por el uso inadecuado de los equipos calibrados. El usuario es responsable de la calibración de sus instrumentos a intervalos apropiados. El laboratorio no se hace responsable por cómo la información suministrada por el cliente afecte los resultados de medición.
C31: REVISÓ Y AUTORIZÓ: | I31: CALIBRADO POR: | M31: =INFORMACIÓN!B15 -> ING. GABRIEL DURÁN
I32: FECHA DE EMISIÓN: | M32: =INFORMACIÓN!B10 -> 0
I33: NÚMERO DE PÁGINAS: | M33: 4
C36: ING. JOHAN SEBASTIÁN PÉREZ
C37: DIRECTOR DE LABORATORIO
O38: =O1 -> CERTIFICADO N°: | R38: =R1 -> 0
B40: 3. CONDICIONES AMBIENTALES
B41: El laboratorio de metrología BTM COLOMBIA ZOMAC S.A.S registra las condiciones ambientales (Humedad y Temperatura) tomando los máximos y mínimos alcanzados durante el tiempo en que se ejecuta la calibración. A continuación se presenta el promedio y la variación resultante.
F45: TEMPERATURA AMBIENTE (°C) | K45: HUMEDAD RELATIVA (%HR)
F46: =AVERAGE(INFORMACIÓN!B11:B12) -> 24.3 | H46: ± | I46: =ABS(INFORMACIÓN!B11-INFORMACIÓN!B12) -> 0.4 | K46: =AVERAGE(INFORMACIÓN!B13:B14) -> 61.5 | M46: ± | N46: =ABS(INFORMACIÓN!B13-INFORMACIÓN!B14) -> 3
F48: La calibración fue realizada en: | K48: En sitio (instalaciones del cliente)
B50: 4. INCERTIDUMBRE DE MEDICIÓN
B51: La incertidumbre expandida de la medición reportada se establece como la incertidumbre estándar de medición multiplicada por el factor de cobertura “k” y la probabilidad de cobertura, la cual debe ser aproximada al 95% y no menor a este valor. La incertidumbre de medición ha sido estimada con un nivel de confianza del 95,45% empleando una distribución t de student. Cuando se hace declaración de cumplimiento, el laboratorio hace referencia a las especificaciones del fabricante, norma o requisitos declarados por el cliente. La regla de decisión aplicada en estos casos será |Error| +U ≤ EMP según la ASME B89 7.3.1, si cumple la anterior condición la medición se toma como conforme y registrará un pasa, en caso contrario se registrará falla. La probabilidad de dar una aceptación falsa o un rechazo falso no lo determina el laboratorio, sin embargo se puede calcular de acuerdo a la guía JCGM 106:2012 según su numeral 8.
B60: 5. PROCEDIMIENTO DE CALIBRACIÓN
B61: La calibración se ejecutó mediante el método de comparación directa con patrón de referencia de acuerdo con el procedimiento interno para Rayos X BTM-P-060.
B64: 6. TRAZABILIDAD
B65: El laboratorio BTM COLOMBIA ZOMAC S.A.S establece la trazabilidad metrológica de sus mediciones al sistema internacional de unidades (SI), por medio de una cadena documentada de calibraciones, las cuales se encuentran referenciadas a patrones de medidas primarios. Esta vinculación se logra a través del uso de patrones calibrados por institutos nacionales de metrología (INM) y por laboratorios acreditados por parte de un organismo de acreditación.
B70: PATRÓN | H70: SERIE | M70: CALIBRACIÓN | P70: CERTIFICADO
B71: Analizador de rayos X | H71: 30007226 | M71: 45808 | P71: o10203823i30007226-A-1
O76: =O1 -> CERTIFICADO N°: | R76: =R1 -> 0
B78: 7. RESULTADOS DE LA CALIBRACIÓN
B80: Calibración de voltaje | I80: Intervalo de medición (kVp): | N80: 50 a 125 | P80: Resolución (kVp): | S80: 1
...
