Workbook
Name Instrumento: '[1]R-LAB-127 DENSIDAD AIRE'!#REF!
Name Instrumento: '[1]R-LAB-127 DENSIDAD AIRE'!#REF!
Name Instrumento.: '[1]R-LAB-127 DENSIDAD AIRE'!#REF!
Name Instrumento.: '[1]R-LAB-127 DENSIDAD AIRE'!#REF!
Name N: #REF!
Name N: #REF!

Sheet INFORMACIÓN
A1: Datos del item | O1: En sitio ( instalaciones del cliente)
A2: Intrumento | B2: Marca | C2: Modelo | D2: Serie | E2: Ubicación | F2: Inventario | G2: Número de Certificado | H2: Fecha de Recepción | O2: Laboratorio BTMC
O4: BUEN ESTADO
O5: REGULAR ESTADO
A6: Datos de calibración | D6: Datos del cliente | O6: MAL ESTADO
A7: Lugar de calibración: | B7: En sitio ( instalaciones del cliente) | D7: Solicitante: | E7: HOSPITAL DE ALTA COMPLEJIDAD DEL MAGDALENA CENTRO
A8: Estado Físico: | B8: BUEN ESTADO | D8: Nit: | E8: 901.532.463-8
A9: Fecha de calibración: | B9: =H3 -> 0 | D9: Telefono: | E9: 3007835072
A10: Fecha de emisión: | B10: =H3 -> 0 | D10: Dirección: | E10: CARRERA 15 ENTRE CALLE 18 y 19
A11: Temperatura mínima: | B11: 24.1 | D11: Ciudad: | E11: LA DORADA - CALDAS
A12: Temperatura máxima: | B12: 24.5
A13: Humedad Mínima: | B13: 60
A14: Humedad Máxima: | B14: 63
A15: Calibración realiza por: | B15: ING. GABRIEL DURÁN

Sheet Redondeo
A1: DATO 1
A2: Dato | B2: Dato redondeado | C2: =FIXED(A3,6) -> #REF! | D2: =RIGHT(C2,1) -> #REF! | E2: =D2/1000000 -> #REF! | F2: =A3-E2 -> #REF! | H2: =IF(C7=5,IF(AND(D3=0,D8=FALSE),J5,J6),J6) -> #REF!
A3: =#REF! -> #REF! | B3: =IF(A3>=10,K37,IF(A3>=1,K29,IF(A3>=0.1,K21,IF(A3>=0.01,K13,IF(A3>=0.001,K5))))) -> #REF! | C3: 6 decimal | D3: =D2+0 -> #REF!
C4: Extrae el ultimo digito | D4: extrael primer digito | E4: parte entera | F4: Parte decimal | G4: cantidad de decimales | H4: decimales en enteros | I4: restar ultimo numero | J4: Elimar ultimo digito | K4: Dato Final
C5: =RIGHT(F2,2) -> #REF! | D5: =LEFT(C5,1) -> #REF! | E5: =TRUNC(A3) -> #REF! | F5: =FIXED(A3-E5,G5) -> #REF! | G5: =ABS(E8-F8) -> #REF! | H5: =RIGHT(A3,G5) -> #REF! | I5: 5e-05 | J5: =(A3-I5) -> #REF! | K5: =IF(C7=5,IF(AND(D3=0,D8=FALSE),J5,J6),J6) -> #REF!
C6: =RIGHT(C5,1) -> #REF! | D6: =D5+0 -> #REF! | J6: =FIXED(A3,4) -> #REF!
C7: =C6+0 -> #REF! | D7: es impar? | E7: Largo dato original | F7: largo parte enetero y decimal
D8: =ISODD(D5) -> #REF! | E8: =LEN(A3) -> #REF! | F8: =LEN(E5)+1 -> #REF!
A10: 4 Decimales
A11: =K5 -> #REF! | C11: =FIXED(A3,5) -> #REF! | D11: =RIGHT(C11,1) -> #REF! | E11: =D11+0 -> #REF!
C12: Extrae el ultimo digito | D12: extrael primer digito | E12: parte entera | F12: Parte decimal | G12: cantidad de decimales | H12: decimales en enteros | I12: restar ultimo numero | J12: Elimar ultimo digito | K12: Dato Final
C13: =RIGHT(A11,2) -> #REF! | D13: =LEFT(C13,1) -> #REF! | E13: =TRUNC(A11) -> #REF! | F13: =FIXED(A11-E13,G13) -> #REF! | G13: =ABS(E16-F16) -> #REF! | H13: =RIGHT(A11,G13) -> #REF! | I13: 0.0005 | J13: =(A11-I13) -> #REF! | K13: =IF(C15=5,IF(AND(E11=0,D16=FALSE),J13,J14),J14) -> #REF!
C14: =RIGHT(C13,1) -> #REF! | D14: =D13+0 -> #REF! | J14: =FIXED(A11,3) -> #REF!
C15: =C14+0 -> #REF! | D15: es impar? | E15: Largo dato original | F15: largo parte enetero y decimal
D16: =ISODD(D13) -> #REF! | E16: =LEN(A11) -> #REF! | F16: =LEN(E13)+1 -> #REF!
A18: 3 Decimales
A19: =K13 -> #REF! | C19: =FIXED(A11,4) -> #REF! | D19: =RIGHT(C19,1) -> #REF! | E19: =D19+0 -> #REF!
C20: Extrae el ultimo digito | D20: extrael primer digito | E20: parte entera | F20: Parte decimal | G20: cantidad de decimales | H20: decimales en enteros | I20: restar ultimo numero | J20: Elimar ultimo digito | K20: Dato Final
C21: =RIGHT(A19,2) -> #REF! | D21: =LEFT(C21,1) -> #REF! | E21: =TRUNC(A19) -> #REF! | F21: =FIXED(A19-E21,G21) -> #REF! | G21: =ABS(E24-F24) -> #REF! | H21: =RIGHT(A19,G21) -> #REF! | I21: 0.005 | J21: =(A19-I21) -> #REF! | K21: =IF(C23=5,IF(AND(E19=0,D24=FALSE),J21,J22),J22) -> #REF!
C22: =RIGHT(C21,1) -> #REF! | D22: =D21+0 -> #REF! | J22: =FIXED(A19,2) -> #REF!
C23: =C22+0 -> #REF! | D23: es impar? | E23: Largo dato original | F23: largo parte enetero y decimal
D24: =ISODD(D21) -> #REF! | E24: =LEN(A19) -> #REF! | F24: =LEN(E21)+1 -> #REF!
A26: 2 Decimales
A27: =K21 -> #REF! | C27: =FIXED(A19,3) -> #REF! | D27: =RIGHT(C27,1) -> #REF! | E27: =D27+0 -> #REF!
C28: Extrae el ultimo digito | D28: extrael primer digito | E28: parte entera | F28: Parte decimal | G28: cantidad de decimales | H28: decimales en enteros | I28: restar ultimo numero | J28: Elimar ultimo digito | K28: Dato Final
C29: =RIGHT(A27,2) -> #REF! | D29: =LEFT(C29,1) -> #REF! | E29: =TRUNC(A27) -> #REF! | F29: =FIXED(A27-E29,G29) -> #REF! | G29: =ABS(E32-F32) -> #REF! | H29: =RIGHT(A27,G29) -> #REF! | I29: 0.05 | J29: =(A27-I29) -> #REF! | K29: =IF(C31=5,IF(AND(E27=0,D32=FALSE),J29,J30),J30) -> #REF!
C30: =RIGHT(C29,1) -> #REF! | D30: =D29+0 -> #REF! | J30: =FIXED(A27,1) -> #REF!
C31: =C30+0 -> #REF! | D31: es impar? | E31: Largo dato original | F31: largo parte enetero y decimal
D32: =ISODD(D29) -> #REF! | E32: =LEN(A27) -> #REF! | F32: =LEN(E29)+1 -> #REF!
A34: 1 Decimales
A35: =K29 -> #REF! | C35: =FIXED(A27,2) -> #REF! | D35: =RIGHT(C35,1) -> #REF! | E35: =D35+0 -> #REF!
C36: Extrae el ultimo digito | D36: extrael primer digito | E36: parte entera | F36: Parte decimal | G36: cantidad de decimales | H36: decimales en enteros | I36: restar ultimo numero | J36: Elimar ultimo digito | K36: Dato Final
C37: =RIGHT(A35,2) -> #REF! | D37: =RIGHT(E37,1) -> #REF! | E37: =TRUNC(A35) -> #REF! | F37: =FIXED(A35-E37,G37) -> #REF! | G37: =ABS(E40-F40) -> #REF! | H37: =RIGHT(A35,G37) -> #REF! | I37: 0.5 | J37: =(A35-I37) -> #REF! | K37: =IF(C39=5,IF(AND(E35=0,D40=FALSE),J37,J38),J38) -> #REF!
C38: =RIGHT(C37,1) -> #REF! | D38: =D37+0 -> #REF! | J38: =FIXED(A35,0) -> #REF!
C39: =C38+0 -> #REF! | D39: es impar? | E39: Largo dato original | F39: largo parte enetero y decimal
D40: =ISODD(D37) -> #REF! | E40: =LEN(A35) -> #REF! | F40: =LEN(E37)+1 -> #REF!
A41: DATO 2
A42: Dato | B42: Dato redondeado | C42: =FIXED(A43,6) -> #REF! | D42: =RIGHT(C42,1) -> #REF! | E42: =D42/1000000 -> #REF! | F42: =A43-E42 -> #REF! | H42: =IF(C47=5,IF(AND(D43=0,D48=FALSE),J45,J46),J46) -> #REF!
A43: =#REF! -> #REF! | B43: =IF(A43>=10,K77,IF(A43>=1,K69,IF(A43>=0.1,K61,IF(A43>=0.01,K53,IF(A43>=0.001,K45))))) -> #REF! | C43: 6 decimal | D43: =D42+0 -> #REF!
C44: Extrae el ultimo digito | D44: extrael primer digito | E44: parte entera | F44: Parte decimal | G44: cantidad de decimales | H44: decimales en enteros | I44: restar ultimo numero | J44: Elimar ultimo digito | K44: Dato Final
...

Sheet CERTIFICADO
O1: CERTIFICADO N°: | R1: =INFORMACIÓN!G3 -> 0
C3: 1. EQUIPO BAJO PRUEBA
C5: INSTRUMENTO: | I5: =INFORMACIÓN!A3 -> 0
C6: MARCA: | I6: =INFORMACIÓN!B3 -> 0
C7: MODELO: | I7: =INFORMACIÓN!C3 -> 0
C8: SERIE: | I8: =INFORMACIÓN!D3 -> 0
C9: CÓDIGO INTERNO: | I9: =INFORMACIÓN!F3 -> 0
C10: UBICACIÓN: | I10: =INFORMACIÓN!E3 -> 0
C11: ESTADO FÍSICO: | I11: =INFORMACIÓN!B8 -> BUEN ESTADO
C12: FECHA DE RECEPCIÓN: | I12: =INFORMACIÓN!H3 -> 0
C13: FECHA DE CALIBRACIÓN: | I13: =INFORMACIÓN!B9 -> 0
C15: 2. DATOS DEL CLIENTE
C17: NOMBRE: | I17: HOSPITAL DE ALTA COMPLEJIDAD DEL MAGDALENA CENTRO
C18: NIT: | I18: =INFORMACIÓN!E8 -> 901.532.463-8
C19: TELÉFONO: | I19: =INFORMACIÓN!E9 -> 3007835072
C20: DIRECCIÓN: | I20: =INFORMACIÓN!E10 -> CARRERA 15 ENTRE CALLE 18 y 19
C21: CIUDAD: | I21: =INFORMACIÓN!E11 -> LA DORADA - CALDAS
C23: Este certificado expresa fielmente el resultado de las mediciones realizadas; no podrá ser reproducido total o parcialmente excepto cuando se haya obtenido permiso por escrito de BTM COLOMBIA ZOMAC S.A.S y se debe reproducir en su totalidad, para proporcionar seguridad de que el certificado no sea sacado de contexto. Los resultados que se encuentran en este certificado se refieren al momento y condiciones en que se realizaron las mediciones, BTM COLOMBIA ZOMAC S.A.S no se responsabiliza de los daños que puedan ser causados por el uso inadecuado de los equipos calibrados. El usuario es responsable de la calibración de sus instrumentos a intervalos apropiados. El laboratorio no se hace responsable por cómo la información suministrada por el cliente afecte los resultados de medición.
C31: REVISÓ Y AUTORIZÓ: | I31: CALIBRADO POR: | M31: =INFORMACIÓN!B15 -> ING. GABRIEL DURÁN
I32: FECHA DE EMISIÓN: | M32: =INFORMACIÓN!B10 -> 0
I33: NÚMERO DE PÁGINAS: | M33: 4
C36: ING. JOHAN SEBASTIÁN PÉREZ
C37: DIRECTOR DE LABORATORIO
O38: =O1 -> CERTIFICADO N°: | R38: =R1 -> 0
B40: 3. CONDICIONES AMBIENTALES
B41: El laboratorio de metrología BTM COLOMBIA ZOMAC S.A.S registra las condiciones ambientales (Humedad y Temperatura) tomando los máximos y mínimos alcanzados durante el tiempo en que se ejecuta la calibración. A continuación se presenta el promedio y la variación resultante.
F45: TEMPERATURA AMBIENTE (°C) | K45: HUMEDAD RELATIVA (%HR)
F46: =AVERAGE(INFORMACIÓN!B11:B12) -> 24.3 | H46: ± | I46: =ABS(INFORMACIÓN!B11-INFORMACIÓN!B12) -> 0.4 | K46: =AVERAGE(INFORMACIÓN!B13:B14) -> 61.5 | M46: ± | N46: =ABS(INFORMACIÓN!B13-INFORMACIÓN!B14) -> 3
F48: La calibración fue realizada en: | K48: En sitio (instalaciones del cliente)
B50: 4. INCERTIDUMBRE DE MEDICIÓN
B51: La incertidumbre expandida de la medición reportada se establece como la incertidumbre estándar de medición multiplicada por el factor de cobertura “k” y la probabilidad de cobertura, la cual debe ser aproximada al 95% y no menor a este valor. La incertidumbre de medición ha sido estimada con un nivel de confianza del 95,45% empleando una distribución t de Student. Cuando se hace declaración de cumplimiento, el laboratorio hace referencia a las especificaciones del fabricante, norma o requisitos declarados por el cliente. La regla de decisión aplicada en estos casos será |Error| +U ≤ EMP según la ASME B89 7.3.1, si cumple la anterior condición la medición se toma como conforme y registrará un pasa, en caso contrario se registrará falla. La probabilidad de dar una aceptación falsa o un rechazo falso no lo determina el laboratorio, sin embargo se puede calcular de acuerdo a la guía JCGM 106:2012 según su numeral 8.
B60: 5. PROCEDIMIENTO DE CALIBRACIÓN
B61: La calibración se ejecutó mediante el método de comparación directa con patrón de referencia de acuerdo con el procedimiento interno seguridad eléctrica BTM-P-061.
B64: 6. TRAZABILIDAD
B65: El laboratorio BTM COLOMBIA ZOMAC S.A.S establece la trazabilidad metrológica de sus mediciones al sistema internacional de unidades (SI), por medio de una cadena documentada de calibraciones, las cuales se encuentran referenciadas a patrones de medidas primarios. Esta vinculación se logra a través del uso de patrones calibrados por institutos nacionales de metrología (INM) y por laboratorios acreditados por parte de un organismo de acreditación.
B71: PATRÓN | H71: SERIE | M71: CALIBRACIÓN | P71: CERTIFICADO
B72: Analizador de Seguridad Eléctrica | H72: 953401 | M72: 45777 | P72: J20404-25
O76: =O1 -> CERTIFICADO N°: | R76: =R1 -> 0
B78: 7. RESULTADOS DE LA CALIBRACIÓN
B80: Consumo de Corriente (A): | F80: =RAND()*0.3+ 0.4 -> 0.64550395 | H80: Toma corriente: | K80: Buen estado | N80: Etiquetado: | Q80: Buen estado
...
