Workbook
Name Instrumento: '[1]R-LAB-127 DENSIDAD AIRE'!#REF!
Name Instrumento: '[1]R-LAB-127 DENSIDAD AIRE'!#REF!
Name Instrumento.: '[1]R-LAB-127 DENSIDAD AIRE'!#REF!
Name Instrumento.: '[1]R-LAB-127 DENSIDAD AIRE'!#REF!
Name N: #REF!
Name N: #REF!

Sheet INFORMACIÓN
A1: Datos del item | O1: En sitio ( instalaciones del cliente)
A2: Intrumento | B2: Marca | C2: Modelo | D2: Serie | E2: Ubicación | F2: Inventario | G2: Número de Certificado | H2: Fecha de Recepción | O2: Laboratorio BTMC
A3: TERMOHIGRÓMETRO | B3: HTC | C3: HTC-2 | D3: NO REGISTRA | E3: EN SITIO | F3: NO REGISTRA | G3: JD6576-25 | H3: 45911
O4: BUEN ESTADO
O5: REGULAR ESTADO
A6: Datos de calibración | D6: Datos del cliente | O6: MAL ESTADO
A7: Lugar de calibración: | B7: En sitio ( instalaciones del cliente) | D7: Solicitante: | E7: ECOOTRANSVIAS LTDA
A8: Estado Físico: | B8: BUEN ESTADO | D8: Nit: | E8: 900300213-4
A9: Fecha de calibración: | B9: =H3 -> 45911 | D9: Telefono: | E9: 3138023656
A10: Fecha de emisión: | B10: =H3 -> 45911 | D10: Dirección: | E10: CR 18 # 13-62, BRR LAS AMERICAS
A11: Temperatura mínima: | B11: 24.1 | D11: Ciudad: | E11: PUERTO ASIS
A12: Temperatura máxima: | B12: 24.5
A13: Humedad Mínima: | B13: 60
A14: Humedad Máxima: | B14: 63
A15: Calibración realiza por: | B15: ING. GABRIEL DURÁN

Sheet Redondeo
A1: DATO 1
A2: Dato | B2: Dato redondeado | C2: =FIXED(A3,6) -> 0,388483 | D2: =RIGHT(C2,1) -> 3 | E2: =D2/1000000 -> 3e-06 | F2: =A3-E2 -> 0.38848014 | H2: =IF(C7=5,IF(AND(D3=0,D8=FALSE),J5,J6),J6) -> 0,3885
A3: =INCERTIDUMBRE!L5 -> 0.38848314 | B3: =IF(A3>=10,K37,IF(A3>=1,K29,IF(A3>=0.1,K21,IF(A3>=0.01,K13,IF(A3>=0.001,K5))))) -> 0,39 | C3: 6 decimal | D3: =D2+0 -> 3
C4: Extrae el ultimo digito | D4: extrael primer digito | E4: parte entera | F4: Parte decimal | G4: cantidad de decimales | H4: decimales en enteros | I4: restar ultimo numero | J4: Elimar ultimo digito | K4: Dato Final
C5: =RIGHT(F2,2) -> 05 | D5: =LEFT(C5,1) -> 0 | E5: =TRUNC(A3) -> 0 | F5: =FIXED(A3-E5,G5) -> 0,38848313526405 | G5: =ABS(E8-F8) -> 14 | H5: =RIGHT(A3,G5) -> 38848313526405 | I5: 5e-05 | J5: =(A3-I5) -> 0.38843314 | K5: =IF(C7=5,IF(AND(D3=0,D8=FALSE),J5,J6),J6) -> 0,3885
C6: =RIGHT(C5,1) -> 5 | D6: =D5+0 -> 0 | J6: =FIXED(A3,4) -> 0,3885
C7: =C6+0 -> 5 | D7: es impar? | E7: Largo dato original | F7: largo parte enetero y decimal
D8: =ISODD(D5) -> FALSE | E8: =LEN(A3) -> 16 | F8: =LEN(E5)+1 -> 2
A10: 4 Decimales
A11: =K5 -> 0,3885 | C11: =FIXED(A3,5) -> 0,38848 | D11: =RIGHT(C11,1) -> 8 | E11: =D11+0 -> 8
C12: Extrae el ultimo digito | D12: extrael primer digito | E12: parte entera | F12: Parte decimal | G12: cantidad de decimales | H12: decimales en enteros | I12: restar ultimo numero | J12: Elimar ultimo digito | K12: Dato Final
C13: =RIGHT(A11,2) -> 85 | D13: =LEFT(C13,1) -> 8 | E13: =TRUNC(A11) -> 0 | F13: =FIXED(A11-E13,G13) -> 0,3885 | G13: =ABS(E16-F16) -> 4 | H13: =RIGHT(A11,G13) -> 3885 | I13: 0.0005 | J13: =(A11-I13) -> 0.388 | K13: =IF(C15=5,IF(AND(E11=0,D16=FALSE),J13,J14),J14) -> 0,389
C14: =RIGHT(C13,1) -> 5 | D14: =D13+0 -> 8 | J14: =FIXED(A11,3) -> 0,389
C15: =C14+0 -> 5 | D15: es impar? | E15: Largo dato original | F15: largo parte enetero y decimal
D16: =ISODD(D13) -> FALSE | E16: =LEN(A11) -> 6 | F16: =LEN(E13)+1 -> 2
A18: 3 Decimales
A19: =K13 -> 0,389 | C19: =FIXED(A11,4) -> 0,3885 | D19: =RIGHT(C19,1) -> 5 | E19: =D19+0 -> 5
C20: Extrae el ultimo digito | D20: extrael primer digito | E20: parte entera | F20: Parte decimal | G20: cantidad de decimales | H20: decimales en enteros | I20: restar ultimo numero | J20: Elimar ultimo digito | K20: Dato Final
C21: =RIGHT(A19,2) -> 89 | D21: =LEFT(C21,1) -> 8 | E21: =TRUNC(A19) -> 0 | F21: =FIXED(A19-E21,G21) -> 0,389 | G21: =ABS(E24-F24) -> 3 | H21: =RIGHT(A19,G21) -> 389 | I21: 0.005 | J21: =(A19-I21) -> 0.384 | K21: =IF(C23=5,IF(AND(E19=0,D24=FALSE),J21,J22),J22) -> 0,39
C22: =RIGHT(C21,1) -> 9 | D22: =D21+0 -> 8 | J22: =FIXED(A19,2) -> 0,39
C23: =C22+0 -> 9 | D23: es impar? | E23: Largo dato original | F23: largo parte enetero y decimal
D24: =ISODD(D21) -> FALSE | E24: =LEN(A19) -> 5 | F24: =LEN(E21)+1 -> 2
A26: 2 Decimales
A27: =K21 -> 0,39 | C27: =FIXED(A19,3) -> 0,389 | D27: =RIGHT(C27,1) -> 9 | E27: =D27+0 -> 9
C28: Extrae el ultimo digito | D28: extrael primer digito | E28: parte entera | F28: Parte decimal | G28: cantidad de decimales | H28: decimales en enteros | I28: restar ultimo numero | J28: Elimar ultimo digito | K28: Dato Final
C29: =RIGHT(A27,2) -> 39 | D29: =LEFT(C29,1) -> 3 | E29: =TRUNC(A27) -> 0 | F29: =FIXED(A27-E29,G29) -> 0,39 | G29: =ABS(E32-F32) -> 2 | H29: =RIGHT(A27,G29) -> 39 | I29: 0.05 | J29: =(A27-I29) -> 0.34 | K29: =IF(C31=5,IF(AND(E27=0,D32=FALSE),J29,J30),J30) -> 0,4
C30: =RIGHT(C29,1) -> 9 | D30: =D29+0 -> 3 | J30: =FIXED(A27,1) -> 0,4
C31: =C30+0 -> 9 | D31: es impar? | E31: Largo dato original | F31: largo parte enetero y decimal
D32: =ISODD(D29) -> TRUE | E32: =LEN(A27) -> 4 | F32: =LEN(E29)+1 -> 2
A34: 1 Decimales
A35: =K29 -> 0,4 | C35: =FIXED(A27,2) -> 0,39 | D35: =RIGHT(C35,1) -> 9 | E35: =D35+0 -> 9
C36: Extrae el ultimo digito | D36: extrael primer digito | E36: parte entera | F36: Parte decimal | G36: cantidad de decimales | H36: decimales en enteros | I36: restar ultimo numero | J36: Elimar ultimo digito | K36: Dato Final
C37: =RIGHT(A35,2) -> ,4 | D37: =RIGHT(E37,1) -> 0 | E37: =TRUNC(A35) -> 0 | F37: =FIXED(A35-E37,G37) -> 0,4 | G37: =ABS(E40-F40) -> 1 | H37: =RIGHT(A35,G37) -> 4 | I37: 0.5 | J37: =(A35-I37) -> -0.1 | K37: =IF(C39=5,IF(AND(E35=0,D40=FALSE),J37,J38),J38) -> 0
C38: =RIGHT(C37,1) -> 4 | D38: =D37+0 -> 0 | J38: =FIXED(A35,0) -> 0
C39: =C38+0 -> 4 | D39: es impar? | E39: Largo dato original | F39: largo parte enetero y decimal
D40: =ISODD(D37) -> FALSE | E40: =LEN(A35) -> 3 | F40: =LEN(E37)+1 -> 2
A41: DATO 2
A42: Dato | B42: Dato redondeado | C42: =FIXED(A43,6) -> 0,388483 | D42: =RIGHT(C42,1) -> 3 | E42: =D42/1000000 -> 3e-06 | F42: =A43-E42 -> 0.38848014 | H42: =IF(C47=5,IF(AND(D43=0,D48=FALSE),J45,J46),J46) -> 0,3885
A43: =INCERTIDUMBRE!L6 -> 0.38848314 | B43: =IF(A43>=10,K77,IF(A43>=1,K69,IF(A43>=0.1,K61,IF(A43>=0.01,K53,IF(A43>=0.001,K45))))) -> 0,39 | C43: 6 decimal | D43: =D42+0 -> 3
C44: Extrae el ultimo digito | D44: extrael primer digito | E44: parte entera | F44: Parte decimal | G44: cantidad de decimales | H44: decimales en enteros | I44: restar ultimo numero | J44: Elimar ultimo digito | K44: Dato Final
...

Sheet PATRON
X2: Temperatura sonda
C3: Nominal | D3: Medido | E3: Corrección | F3: Incertidumbre | G3: k | H3: Correcion estimada | I3: Residuales | J3: N-M-1 | K3: u interpolación | M3: Nominal | N3: Medido | O3: Corrección | P3: Incertidumbre | Q3: k | R3: Correcion estimada | S3: Residuales | T3: N-M-1 | U3: u interpolación | X3: Nominal | Y3: Medido | Z3: Corrección | AA3: Incertidumbre | AB3: k | AC3: Correcion estimada | AD3: Residuales | AE3: N-M-1 | AF3: u interpolación
C4: 24.714 | D4: 24.3 | E4: =C4-D4 -> 0.414 | F4: 0.28 | G4: 2 | H4: =$K$9*D4^2-$K$10*D4+$K$11 -> 0.414 | I4: =E4-H4 -> 1.6653345e-15 | J4: =6-3-1 -> 2 | K4: =(SQRT(SUMSQ(I4:I14)/J4)) -> 1.7919013e-15 | M4: 30.679 | N4: 42.2 | O4: =M4-N4 -> -11.521 | P4: 0.0077 | Q4: 2 | R4: =$T$9*N4^2-$T$10*N4-$T$11 -> -11.550976 | S4: =O4-R4 -> 0.029976 | T4: =6-3-1 -> 2 | U4: =(SQRT(SUMSQ(S4:S14)/T4)) -> 0.098831104 | X4: -24.99 | Y4: -25.2 | Z4: =X4-Y4 -> 0.21 | AA4: 0.0077 | AB4: 2 | AC4: =AD$11*Y4^4-AD$12*Y4^3+AD$13*Y4^2+AD$14*Y4-AD$15 -> 0.21068662 | AD4: =Z4-AC4 -> -0.00068662358 | AE4: =6-3-1 -> 2 | AF4: =(SQRT(SUMSQ(AD4:AD14)/AE4)) -> 0.052653479
C5: 30.474 | D5: 29.9 | E5: =C5-D5 -> 0.574 | F5: 0.28 | G5: 2 | H5: =$K$9*D5^2-$K$10*D5+$K$11 -> 0.574 | I5: =E5-H5 -> 1.5543122e-15 | M5: 50.405 | N5: 59.9 | O5: =M5-N5 -> -9.495 | P5: 0.0077 | Q5: 2 | R5: =$T$9*N5^2-$T$10*N5-$T$11 -> -9.556009 | S5: =O5-R5 -> 0.061009 | X5: 9.99 | Y5: 10.4 | Z5: =X5-Y5 -> -0.41 | AA5: 0.0077 | AB5: 2 | AC5: =AD$11*Y5^4-AD$12*Y5^3+AD$13*Y5^2+AD$14*Y5-AD$15 -> -0.40997719 | AD5: =Z5-AC5 -> -2.2809504e-05
C6: 36.279 | D6: 35.5 | E6: =C6-D6 -> 0.779 | F6: 0.3 | G6: 2 | H6: =$K$9*D6^2-$K$10*D6+$K$11 -> 0.779 | I6: =E6-H6 -> 1.110223e-15 | M6: 80.024 | N6: 84.5 | O6: =M6-N6 -> -4.476 | P6: 0.0077 | Q6: 2 | R6: =$T$9*N6^2-$T$10*N6-$T$11 -> -4.598125 | S6: =O6-R6 -> 0.122125 | X6: 29.99 | Y6: 30.2 | Z6: =X6-Y6 -> -0.21 | AA6: 0.0077 | AB6: 2 | AC6: =AD$11*Y6^4-AD$12*Y6^3+AD$13*Y6^2+AD$14*Y6-AD$15 -> -0.20848389 | AD6: =Z6-AC6 -> -0.0015161077
X7: 49.99 | Y7: 50.2 | Z7: =X7-Y7 -> -0.21 | AC7: =AD$11*Y7^4-AD$12*Y7^3+AD$13*Y7^2+AD$14*Y7-AD$15 -> -0.19857785 | AD7: =Z7-AC7 -> -0.011422149
X8: 79.99 | Y8: 80.1 | Z8: =X8-Y8 -> -0.11 | AC8: =AD$11*Y8^4-AD$12*Y8^3+AD$13*Y8^2+AD$14*Y8-AD$15 -> -0.036501262 | AD8: =Z8-AC8 -> -0.073498738
K9: 0.00071747449 | T9: 0.0021
K10: 0.010315689 | T10: 0.1017
K11: 0.24100973 | T11: 10.999 | AD11: 1.4e-07
AD12: 1.902e-05
AD13: 0.00065883
AD14: 0.00300712
AD15: 0.49275318
B34: EQUIPO PATRÓN
B35: Equipo patrón: | G35: Datalogger de Temperatura y Humedad
B36: Marca: | G36: Elitech
B37: Modelo: | G37: RC-51H
B38: Serie: | G38: HM1201000197
B39: Fecha de Calibración: | G39: 44986
B40: No. Certificado: | G40: 242208
B41: Incertidumbre temperatura: | G41: 0.3
B42: Incertidumbre humedad: | G42: 2
B43: Deriva temperatura | G43: 0.2
B44: Deriva humedad | G44: 1
B45: Resolución temperatura | G45: 0.1
B46: Resolución humedad | G46: 0.1
B47: Factor de cobertura K: | G47: 2

Sheet MEDIDA
B2: TEMPERATURA AMBIENTE | O2: TEMPERATURA AMBIENTE
B3: Temperatura (°C) | D3: Patrón (°C) | F3: EBP (°C) | O3: Temperatura (°C) | Q3: Patrón (°C) | S3: EBP (°C) | U3: Error (°C)
B4: 15 | D4: 14.9 | F4: =MAX(0.06, RAND() + (D4 - 0.5)) -> 14.514586 | O4: =B4 -> 15 | Q4: =D4 -> 14.9 | S4: =F4 -> 14.514586 | U4: =S4-Q4 -> -0.38541411
B5: 23 | D5: 22.8 | F5: =MAX(0.06, RAND() + (D5 - 0.5)) -> 23.282138 | O5: =B5 -> 23 | Q5: =D5 -> 22.8 | S5: =F5 -> 23.282138 | U5: =S5-Q5 -> 0.48213823
B6: 31 | D6: 30.3 | F6: =MAX(0.06, RAND() + (D6 - 0.5)) -> 29.894924 | O6: =B6 -> 31 | Q6: =D6 -> 30.3 | S6: =F6 -> 29.894924 | U6: =S6-Q6 -> -0.40507619
B13: CALIBRACIÓN DE HUMEDAD | O13: CALIBRACIÓN DE HUMEDAD
B14: Humedad (%hr) | D14: Patrón (%hr) | F14: EBP (%hr) | O14: Humedad (%hr) | Q14: Patrón (%hr) | S14: EBP (%hr) | U14: Error (%hr)
B15: 50 | D15: 49.7 | F15: =ROUNDDOWN(RAND()*5 + (D15 - 2), 0) -> 49 | O15: =B15 -> 50 | Q15: =D15 -> 49.7 | S15: =F15 -> 49 | U15: =S15-Q15 -> -0.7
B16: 58 | D16: 57.6 | F16: =ROUNDDOWN(RAND()*5 + (D16 - 2), 0) -> 60 | O16: =B16 -> 58 | Q16: =D16 -> 57.6 | S16: =F16 -> 60 | U16: =S16-Q16 -> 2.4
B17: 65 | D17: 64.3 | F17: =ROUNDDOWN(RAND()*5 + (D17 - 2), 0) -> 65 | O17: =B17 -> 65 | Q17: =D17 -> 64.3 | S17: =F17 -> 65 | U17: =S17-Q17 -> 0.7

Sheet INCERTIDUMBRE
B2: FUENTES DE INCERTIDUMBRE TEMPERATURA AMBIENTE
B3: Punto de calibración | C3: Cert de calibración | D3: Deriva | E3: Interpolación | F3: Resolución item | G3: Resolución patrón | H3: Repetibilidad | I3: Incertidumbre combinada | J3: Veff | K3: Factor de cobertura (k) | L3: Incertidumbre Expandida
B4: =MEDIDA!B4 -> 15 | C4: =PATRON!$G$41/2 -> 0.15 | D4: =PATRON!$G$43/SQRT(3) -> 0.11547005 | E4: 0 | F4: =0.1/SQRT(12) -> 0.028867513 | G4: =PATRON!$G$45/SQRT(12) -> 0.028867513 | H4: 0 | I4: =SQRT(SUMSQ(C4:H4)) -> 0.19364917 | J4: =I4^4/(C4^4/200+D4^4/200+E4^4/200+F4^4/200+G4^4/200+H4^4/3) -> 410.33435 | K4: =TINV(0.0455,J4) -> 2.0061183 | L4: =I4*K4 -> 0.38848314
B5: =MEDIDA!B5 -> 23 | C5: =PATRON!$G$41/2 -> 0.15 | D5: =PATRON!$G$43/SQRT(3) -> 0.11547005 | E5: 0 | F5: =0.1/SQRT(12) -> 0.028867513 | G5: =PATRON!$G$45/SQRT(12) -> 0.028867513 | H5: 0 | I5: =SQRT(SUMSQ(C5:H5)) -> 0.19364917 | J5: =I5^4/(C5^4/200+D5^4/200+E5^4/200+F5^4/200+G5^4/200+H5^4/3) -> 410.33435 | K5: =TINV(0.0455,J5) -> 2.0061183 | L5: =I5*K5 -> 0.38848314
B6: =MEDIDA!B6 -> 31 | C6: =PATRON!$G$41/2 -> 0.15 | D6: =PATRON!$G$43/SQRT(3) -> 0.11547005 | E6: 0 | F6: =0.1/SQRT(12) -> 0.028867513 | G6: =PATRON!$G$45/SQRT(12) -> 0.028867513 | H6: 0 | I6: =SQRT(SUMSQ(C6:H6)) -> 0.19364917 | J6: =I6^4/(C6^4/200+D6^4/200+E6^4/200+F6^4/200+G6^4/200+H6^4/3) -> 410.33435 | K6: =TINV(0.0455,J6) -> 2.0061183 | L6: =I6*K6 -> 0.38848314
B10: FUENTES DE INCERTIDUMBRE TEMPERATURA SONDA
B11: Punto de calibración | C11: Cert de calibración | D11: Deriva | E11: Interpolación | F11: Resolución item | G11: Resolución patrón | H11: Repetibilidad | I11: Incertidumbre combinada | J11: Veff | K11: Factor de cobertura (k) | L11: Incertidumbre Expandida
B12: =MEDIDA!#REF! -> #REF! | C12: =0.59/2 -> 0.295 | D12: =PATRON!$G$43/SQRT(3) -> 0.11547005 | E12: 0 | F12: =0.1/SQRT(12) -> 0.028867513 | G12: =PATRON!$G$45/SQRT(12) -> 0.028867513 | H12: 0 | I12: =SQRT(SUMSQ(C12:H12)) -> 0.31941353 | J12: =I12^4/(C12^4/200+D12^4/200+E12^4/200+F12^4/200+G12^4/200+H12^4/3) -> 268.53473 | K12: =TINV(0.0455,J12) -> 2.0093736 | L12: =I12*K12 -> 0.64182111
B13: =MEDIDA!#REF! -> #REF! | C13: =0.59/2 -> 0.295 | D13: =PATRON!$G$43/SQRT(3) -> 0.11547005 | E13: 0 | F13: =0.1/SQRT(12) -> 0.028867513 | G13: =PATRON!$G$45/SQRT(12) -> 0.028867513 | H13: 0 | I13: =SQRT(SUMSQ(C13:H13)) -> 0.31941353 | J13: =I13^4/(C13^4/200+D13^4/200+E13^4/200+F13^4/200+G13^4/200+H13^4/3) -> 268.53473 | K13: =TINV(0.0455,J13) -> 2.0093736 | L13: =I13*K13 -> 0.64182111
B14: =MEDIDA!#REF! -> #REF! | C14: =0.59/2 -> 0.295 | D14: =PATRON!$G$43/SQRT(3) -> 0.11547005 | E14: 0 | F14: =0.1/SQRT(12) -> 0.028867513 | G14: =PATRON!$G$45/SQRT(12) -> 0.028867513 | H14: 0 | I14: =SQRT(SUMSQ(C14:H14)) -> 0.31941353 | J14: =I14^4/(C14^4/200+D14^4/200+E14^4/200+F14^4/200+G14^4/200+H14^4/3) -> 268.53473 | K14: =TINV(0.0455,J14) -> 2.0093736 | L14: =I14*K14 -> 0.64182111
B18: FUENTES DE INCERTIDUMBRE HUMEDAD
B19: Punto de calibración | C19: Cert de calibración | D19: Deriva | E19: Interpolación | F19: Resolución item | G19: Resolución patrón | H19: Repetibilidad | I19: Incertidumbre combinada | J19: Veff | K19: Factor de cobertura (k) | L19: Incertidumbre Expandida
B20: =MEDIDA!B15 -> 50 | C20: =PATRON!$G$42/2 -> 1 | D20: =PATRON!$G$44/SQRT(3) -> 0.57735027 | E20: 0 | F20: =1/SQRT(12) -> 0.28867513 | G20: =PATRON!$G$46/SQRT(12) -> 0.028867513 | H20: 0 | I20: =SQRT(SUMSQ(C20:H20)) -> 1.1905881 | J20: =I20^4/(C20^4/200+D20^4/200+E20^4/200+F20^4/200+G20^4/200+H20^4/3) -> 359.42847 | K20: =TINV(0.0455,J20) -> 2.0069901 | L20: =I20*K20 -> 2.3894985
B21: =MEDIDA!B16 -> 58 | C21: =PATRON!$G$42/2 -> 1 | D21: =PATRON!$G$44/SQRT(3) -> 0.57735027 | E21: 0 | F21: =1/SQRT(12) -> 0.28867513 | G21: =PATRON!$G$46/SQRT(12) -> 0.028867513 | H21: 0 | I21: =SQRT(SUMSQ(C21:H21)) -> 1.1905881 | J21: =I21^4/(C21^4/200+D21^4/200+E21^4/200+F21^4/200+G21^4/200+H21^4/3) -> 359.42847 | K21: =TINV(0.0455,J21) -> 2.0069901 | L21: =I21*K21 -> 2.3894985
B22: =MEDIDA!B17 -> 65 | C22: =PATRON!$G$42/2 -> 1 | D22: =PATRON!$G$44/SQRT(3) -> 0.57735027 | E22: 0 | F22: =1/SQRT(12) -> 0.28867513 | G22: =PATRON!$G$46/SQRT(12) -> 0.028867513 | H22: 0 | I22: =SQRT(SUMSQ(C22:H22)) -> 1.1905881 | J22: =I22^4/(C22^4/200+D22^4/200+E22^4/200+F22^4/200+G22^4/200+H22^4/3) -> 359.42847 | K22: =TINV(0.0455,J22) -> 2.0069901 | L22: =I22*K22 -> 2.3894985

Sheet CERTIFICADO 
O1: CERTIFICADO N°: | R1: =INFORMACIÓN!G3 -> JD6576-25
C3: 1. EQUIPO BAJO PRUEBA
C5: INSTRUMENTO: | I5: =INFORMACIÓN!A3 -> TERMOHIGRÓMETRO
C6: MARCA: | I6: =INFORMACIÓN!B3 -> HTC
C7: MODELO: | I7: =INFORMACIÓN!C3 -> HTC-2
C8: SERIE: | I8: =INFORMACIÓN!D3 -> NO REGISTRA
C9: CÓDIGO INTERNO: | I9: =INFORMACIÓN!F3 -> NO REGISTRA
C10: UBICACIÓN: | I10: =INFORMACIÓN!E3 -> EN SITIO
C11: ESTADO FÍSICO: | I11: =INFORMACIÓN!B8 -> BUEN ESTADO
C12: FECHA DE RECEPCIÓN: | I12: =INFORMACIÓN!H3 -> 45911
C13: FECHA DE CALIBRACIÓN: | I13: =INFORMACIÓN!B9 -> 45911
C15: 2. DATOS DEL CLIENTE
C17: NOMBRE: | I17: =INFORMACIÓN!E7 -> ECOOTRANSVIAS LTDA
C18: NIT: | I18: =INFORMACIÓN!E8 -> 900300213-4
C19: TELÉFONO: | I19: =INFORMACIÓN!E9 -> 3138023656
C20: DIRECCIÓN: | I20: =INFORMACIÓN!E10 -> CR 18 # 13-62, BRR LAS AMERICAS
C21: CIUDAD: | I21: =INFORMACIÓN!E11 -> PUERTO ASIS
C23: Este certificado expresa fielmente el resultado de las mediciones realizadas; no podrá ser reproducido total o parcialmente excepto cuando se haya obtenido permiso por escrito de BTM COLOMBIA ZOMAC S.A.S y se debe reproducir en su totalidad, para proporcionar seguridad de que el certificado no sea sacado de contexto. Los resultados que se encuentran en este certificado se refieren al momento y condiciones en que se realizaron las mediciones, BTM COLOMBIA ZOMAC S.A.S no se responsabiliza de los daños que puedan ser causados por el uso inadecuado de los equipos calibrados. El usuario es responsable de la calibración de sus instrumentos a intervalos apropiados. El laboratorio no se hace responsable por cómo la información suministrada por el cliente afecte los resultados de medición.
C31: REVISÓ Y AUTORIZÓ: | I31: CALIBRADO POR: | M31: =INFORMACIÓN!B15 -> ING. GABRIEL DURÁN
I32: FECHA DE EMISIÓN: | M32: =INFORMACIÓN!B10 -> 45911
I33: NÚMERO DE PÁGINAS: | M33: 4
C36: ING. JOHAN SEBASTIÁN PÉREZ
C37: DIRECTOR DE LABORATORIO
O38: =O1 -> CERTIFICADO N°: | R38: =R1 -> JD6576-25
B40: 3. CONDICIONES AMBIENTALES
B41: El laboratorio de metrología BTM COLOMBIA ZOMAC S.A.S registra las condiciones ambientales (Humedad y Temperatura) tomando los máximos y mínimos alcanzados durante el tiempo en que se ejecuta la calibración. A continuación se presenta el promedio y la variación resultante.
F45: TEMPERATURA AMBIENTE (°C) | K45: HUMEDAD RELATIVA (%HR)
F46: =AVERAGE(INFORMACIÓN!B11:B12) -> 24.3 | H46: ± | I46: =ABS(INFORMACIÓN!B11-INFORMACIÓN!B12) -> 0.4 | K46: =AVERAGE(INFORMACIÓN!B13:B14) -> 61.5 | M46: ± | N46: =ABS(INFORMACIÓN!B13-INFORMACIÓN!B14) -> 3
F48: La calibración fue realizada en: | K48: En sitio (instalaciones del cliente)
B50: 4. INCERTIDUMBRE DE MEDICIÓN
B51: La incertidumbre expandida de la medición reportada se establece como la incertidumbre estándar de medición multiplicada por el factor de cobertura “k” y la probabilidad de cobertura, la cual debe ser aproximada al 95% y no menor a este valor. La incertidumbre de medición ha sido estimada con un nivel de confianza del 95,45% empleando una distribución t de student. Cuando se hace declaración de cumplimiento, el laboratorio hace referencia a las especificaciones del fabricante, norma o requisitos declarados por el cliente. La regla de decisión aplicada en estos casos será |Error| +U ≤ EMP según la ASME B89 7.3.1, si cumple la anterior condición la medición se toma como conforme y registrará un pasa, en caso contrario se registrará falla. La probabilidad de dar una aceptación falsa o un rechazo falso no lo determina el laboratorio, sin embargo se puede calcular de acuerdo a la guía JCGM 106:2012 según su numeral 8.
B60: 5. PROCEDIMIENTO DE CALIBRACIÓN
B61: La calibración se ejecutó mediante el método de comparación directa con patrón de referencia de acuerdo con el procedimiento interno para termohigrómetros BTM-P-014.
B64: 6. TRAZABILIDAD
B65: El laboratorio BTM COLOMBIA ZOMAC S.A.S establece la trazabilidad metrológica de sus mediciones al sistema internacional de unidades (SI), por medio de una cadena documentada de calibraciones, las cuales se encuentran referenciadas a patrones de medidas primarios. Esta vinculación se logra a través del uso de patrones calibrados por institutos nacionales de metrología (INM) y por laboratorios acreditados por parte de un organismo de acreditación.
B70: PATRÓN | H70: SERIE | M70: CALIBRACIÓN | P70: CERTIFICADO
B71: =[2]PATRON!G35 -> Datalogger de Temperatura y Humedad | H71: H12F-J164747 | M71: 46085 | P71: 318690
B72: Termómetro | H72: 230310997 | M72: 46055 | P72: 319239_A 319239_B
O76: =O1 -> CERTIFICADO N°: | R76: =R1 -> JD6576-25
B78: 7. RESULTADOS DE LA CALIBRACIÓN
...
