Workbook
Name Instrumento: '[1]R-LAB-127 DENSIDAD AIRE'!#REF!
Name Instrumento: '[1]R-LAB-127 DENSIDAD AIRE'!#REF!
Name Instrumento.: '[1]R-LAB-127 DENSIDAD AIRE'!#REF!
Name Instrumento.: '[1]R-LAB-127 DENSIDAD AIRE'!#REF!
Name N: #REF!
Name N: #REF!

Sheet INFORMACIÓN
A1: Datos del item | N1: En sitio ( instalaciones del cliente) | O1: En sitio ( instalaciones del cliente)
A2: Intrumento | B2: Marca | C2: Modelo | D2: Serie | E2: Ubicación | F2: Inventario | G2: Número de Certificado | H2: Fecha de Recepción | N2: Laboratorio BTMC | O2: Laboratorio BTMC
A3: TENSIOMETRO | B3: HILLROM | C3: 7670-01 | D3: 220907150040 | E3: CONSULTA EXTERNA | F3: 0401005309 | G3: JD1743-24 | H3: 45465
N4: BUEN ESTADO | O4: BUEN ESTADO
N5: REGULAR ESTADO | O5: REGULAR ESTADO
A6: Datos de calibración | D6: Datos del cliente | N6: MAL ESTADO | O6: MAL ESTADO
A7: Lugar de calibración: | B7: En sitio ( instalaciones del cliente) | D7: Solicitante: | E7: HOSPITAL DE ALTA COMPLEJIDAD DEL MAGDALENA CENTRO
A8: Estado Físico: | B8: BUEN ESTADO | D8: Nit: | E8: 901.532.463-8
A9: Fecha de calibración: | B9: =H3 -> 45465 | D9: Telefono: | E9: 3007835072
A10: Fecha de emisión: | B10: =H3 -> 45465 | D10: Dirección: | E10: CARRERA 15 ENTRE CALLE 18 y 19
A11: Temperatura mínima: | B11: 24.1 | D11: Ciudad: | E11: LA DORADA - CALDAS
A12: Temperatura máxima: | B12: 24.5
A13: Humedad Mínima: | B13: 60
A14: Humedad Máxima: | B14: 63
A15: Calibración realiza por: | B15: ING. GABRIEL DURÁN

Sheet Redondeo
C1: DATO 1
C2: Dato | D2: Dato redondeado | E2: =FIXED(C3,6) -> 0,593971 | F2: =RIGHT(E2,1) -> 1 | G2: =F2/1000000 -> 1e-06 | H2: =C3-G2 -> 0.59396981 | J2: =IF(E7=5,IF(AND(F3=0,F8=FALSE),L5,L6),L6) -> 0,5940
C3: =INCERTIDUMBRE!M5 -> 0.59397081 | D3: =IF(C3>=10,M37,IF(C3>=1,M29,IF(C3>=0.1,M21,IF(C3>=0.01,M13,IF(C3>=0.001,M5))))) -> 0,59 | E3: 6 decimal | F3: =F2+0 -> 1
E4: Extrae el ultimo digito | F4: extrael primer digito | G4: parte entera | H4: Parte decimal | I4: cantidad de decimales | J4: decimales en enteros | K4: restar ultimo numero | L4: Elimar ultimo digito | M4: Dato Final
E5: =RIGHT(H2,2) -> 93 | F5: =LEFT(E5,1) -> 9 | G5: =TRUNC(C3) -> 0 | H5: =FIXED(C3-G5,I5) -> 0,593970809556193 | I5: =ABS(G8-H8) -> 15 | J5: =RIGHT(C3,I5) -> 593970809556193 | K5: 5e-05 | L5: =(C3-K5) -> 0.59392081 | M5: =IF(E7=5,IF(AND(F3=0,F8=FALSE),L5,L6),L6) -> 0,5940
E6: =RIGHT(E5,1) -> 3 | F6: =F5+0 -> 9 | L6: =FIXED(C3,4) -> 0,5940
E7: =E6+0 -> 3 | F7: es impar? | G7: Largo dato original | H7: largo parte enetero y decimal
F8: =ISODD(F5) -> TRUE | G8: =LEN(C3) -> 17 | H8: =LEN(G5)+1 -> 2
C10: 4 Decimales
C11: =M5 -> 0,5940 | E11: =FIXED(C3,5) -> 0,59397 | F11: =RIGHT(E11,1) -> 7 | G11: =F11+0 -> 7
E12: Extrae el ultimo digito | F12: extrael primer digito | G12: parte entera | H12: Parte decimal | I12: cantidad de decimales | J12: decimales en enteros | K12: restar ultimo numero | L12: Elimar ultimo digito | M12: Dato Final
E13: =RIGHT(C11,2) -> 40 | F13: =LEFT(E13,1) -> 4 | G13: =TRUNC(C11) -> 0 | H13: =FIXED(C11-G13,I13) -> 0,5940 | I13: =ABS(G16-H16) -> 4 | J13: =RIGHT(C11,I13) -> 5940 | K13: 0.0005 | L13: =(C11-K13) -> 0.5935 | M13: =IF(E15=5,IF(AND(G11=0,F16=FALSE),L13,L14),L14) -> 0,594
E14: =RIGHT(E13,1) -> 0 | F14: =F13+0 -> 4 | L14: =FIXED(C11,3) -> 0,594
E15: =E14+0 -> 0 | F15: es impar? | G15: Largo dato original | H15: largo parte enetero y decimal
F16: =ISODD(F13) -> FALSE | G16: =LEN(C11) -> 6 | H16: =LEN(G13)+1 -> 2
C18: 3 Decimales
C19: =M13 -> 0,594 | E19: =FIXED(C11,4) -> 0,5940 | F19: =RIGHT(E19,1) -> 0 | G19: =F19+0 -> 0
E20: Extrae el ultimo digito | F20: extrael primer digito | G20: parte entera | H20: Parte decimal | I20: cantidad de decimales | J20: decimales en enteros | K20: restar ultimo numero | L20: Elimar ultimo digito | M20: Dato Final
E21: =RIGHT(C19,2) -> 94 | F21: =LEFT(E21,1) -> 9 | G21: =TRUNC(C19) -> 0 | H21: =FIXED(C19-G21,I21) -> 0,594 | I21: =ABS(G24-H24) -> 3 | J21: =RIGHT(C19,I21) -> 594 | K21: 0.005 | L21: =(C19-K21) -> 0.589 | M21: =IF(E23=5,IF(AND(G19=0,F24=FALSE),L21,L22),L22) -> 0,59
E22: =RIGHT(E21,1) -> 4 | F22: =F21+0 -> 9 | L22: =FIXED(C19,2) -> 0,59
E23: =E22+0 -> 4 | F23: es impar? | G23: Largo dato original | H23: largo parte enetero y decimal
F24: =ISODD(F21) -> TRUE | G24: =LEN(C19) -> 5 | H24: =LEN(G21)+1 -> 2
C26: 2 Decimales
C27: =M21 -> 0,59 | E27: =FIXED(C19,3) -> 0,594 | F27: =RIGHT(E27,1) -> 4 | G27: =F27+0 -> 4
E28: Extrae el ultimo digito | F28: extrael primer digito | G28: parte entera | H28: Parte decimal | I28: cantidad de decimales | J28: decimales en enteros | K28: restar ultimo numero | L28: Elimar ultimo digito | M28: Dato Final
E29: =RIGHT(C27,2) -> 59 | F29: =LEFT(E29,1) -> 5 | G29: =TRUNC(C27) -> 0 | H29: =FIXED(C27-G29,I29) -> 0,59 | I29: =ABS(G32-H32) -> 2 | J29: =RIGHT(C27,I29) -> 59 | K29: 0.05 | L29: =(C27-K29) -> 0.54 | M29: =IF(E31=5,IF(AND(G27=0,F32=FALSE),L29,L30),L30) -> 0,6
E30: =RIGHT(E29,1) -> 9 | F30: =F29+0 -> 5 | L30: =FIXED(C27,1) -> 0,6
E31: =E30+0 -> 9 | F31: es impar? | G31: Largo dato original | H31: largo parte enetero y decimal
F32: =ISODD(F29) -> TRUE | G32: =LEN(C27) -> 4 | H32: =LEN(G29)+1 -> 2
C34: 1 Decimales
C35: =M29 -> 0,6 | E35: =FIXED(C27,2) -> 0,59 | F35: =RIGHT(E35,1) -> 9 | G35: =F35+0 -> 9
E36: Extrae el ultimo digito | F36: extrael primer digito | G36: parte entera | H36: Parte decimal | I36: cantidad de decimales | J36: decimales en enteros | K36: restar ultimo numero | L36: Elimar ultimo digito | M36: Dato Final
E37: =RIGHT(C35,2) -> ,6 | F37: =RIGHT(G37,1) -> 0 | G37: =TRUNC(C35) -> 0 | H37: =FIXED(C35-G37,I37) -> 0,6 | I37: =ABS(G40-H40) -> 1 | J37: =RIGHT(C35,I37) -> 6 | K37: 0.5 | L37: =(C35-K37) -> 0.1 | M37: =IF(E39=5,IF(AND(G35=0,F40=FALSE),L37,L38),L38) -> 1
E38: =RIGHT(E37,1) -> 6 | F38: =F37+0 -> 0 | L38: =FIXED(C35,0) -> 1
E39: =E38+0 -> 6 | F39: es impar? | G39: Largo dato original | H39: largo parte enetero y decimal
F40: =ISODD(F37) -> FALSE | G40: =LEN(C35) -> 3 | H40: =LEN(G37)+1 -> 2
C41: DATO 2
C42: Dato | D42: Dato redondeado | E42: =FIXED(C43,6) -> 0,688782 | F42: =RIGHT(E42,1) -> 2 | G42: =F42/1000000 -> 2e-06 | H42: =C43-G42 -> 0.68878044 | J42: =IF(E47=5,IF(AND(F43=0,F48=FALSE),L45,L46),L46) -> 0,6888
C43: =INCERTIDUMBRE!M6 -> 0.68878244 | D43: =IF(C43>=10,M77,IF(C43>=1,M69,IF(C43>=0.1,M61,IF(C43>=0.01,M53,IF(C43>=0.001,M45))))) -> 0,69 | E43: 6 decimal | F43: =F42+0 -> 2
E44: Extrae el ultimo digito | F44: extrael primer digito | G44: parte entera | H44: Parte decimal | I44: cantidad de decimales | J44: decimales en enteros | K44: restar ultimo numero | L44: Elimar ultimo digito | M44: Dato Final
...

Sheet INCERTIDUMBRE
E3: correcciones debidas al Patrón, | H3: correcciones debidas al Instrumento | L3: INDCREDIUMBRE | N3: =INFORMACIÓN!W12 -> 0
B4: Lectura instrumento | C4: Promedio lecturas patrón | D4: δ(Pat)cal | E4: δ(Pat)der | F4: δ(Pat),int | G4: δ(Inst)res | H4: δ(Ins)hist | I4: u(rep) | J4: u(comb) | K4: Veff | L4: Factor de cobertura (k) | M4: Incertidumbre Expandida
B5: =MEDIDA!A8 -> 0 | C5: =(MEDIDA!F8+MEDIDA!G8)/2 -> 0 | D5: =PATRON!H$40/2 -> 0.055 | E5: =PATRON!H$42/SQRT(3) -> 0.28867513 | F5: 0 | G5: =PATRON!H$44/SQRT(12) -> 0.028867513 | H5: =ABS(MEDIDA!F8-MEDIDA!G8)/SQRT(12) -> 0 | I5: =STDEV(MEDIDA!B8:E8)/SQRT(4) -> 0 | J5: =SQRT(SUMSQ(D5:I5)) -> 0.29528235 | K5: =J5^4/(D5^4/$D$12+E5^4/$E$12+F5^4/$F$12+G5^4/$G$12+H5^4/$H$12+I5^4/$I$12) -> 218.63878 | L5: =TINV(0.0455,K5) -> 2.0115351 | M5: =J5*L5 -> 0.59397081 | N5: =Redondeo!D3 -> 0,59
B6: =MEDIDA!A9 -> 100 | C6: =(MEDIDA!F9+MEDIDA!G9)/2 -> 99.186917 | D6: =PATRON!H$40/2 -> 0.055 | E6: =PATRON!H$42/SQRT(3) -> 0.28867513 | F6: 0 | G6: =PATRON!H$44/SQRT(12) -> 0.028867513 | H6: =ABS(MEDIDA!F9-MEDIDA!G9)/SQRT(12) -> 0.10791669 | I6: =STDEV(MEDIDA!B9:E9)/SQRT(4) -> 0.12991908 | J6: =SQRT(SUMSQ(D6:I6)) -> 0.3401715 | K6: =J6^4/(D6^4/$D$12+E6^4/$E$12+F6^4/$F$12+G6^4/$G$12+H6^4/$H$12+I6^4/$I$12) -> 102.67398 | L6: =TINV(0.0455,K6) -> 2.0248094 | M6: =J6*L6 -> 0.68878244 | N6: =Redondeo!D43 -> 0,69
B7: =MEDIDA!A10 -> 300 | C7: =(MEDIDA!F10+MEDIDA!G10)/2 -> 299.34637 | D7: =PATRON!H$40/2 -> 0.055 | E7: =PATRON!H$42/SQRT(3) -> 0.28867513 | F7: 0 | G7: =PATRON!H$44/SQRT(12) -> 0.028867513 | H7: =ABS(MEDIDA!F10-MEDIDA!G10)/SQRT(12) -> 0.10143595 | I7: =STDEV(MEDIDA!B10:E10)/SQRT(4) -> 0.20380592 | J7: =SQRT(SUMSQ(D7:I7)) -> 0.37285087 | K7: =J7^4/(D7^4/$D$12+E7^4/$E$12+F7^4/$F$12+G7^4/$G$12+H7^4/$H$12+I7^4/$I$12) -> 31.660893 | L7: =TINV(0.0455,K7) -> 2.0839327 | M7: =J7*L7 -> 0.77699611 | N7: =Redondeo!D83 -> 0,78
B8: =MEDIDA!A11 -> 400 | C8: =(MEDIDA!F11+MEDIDA!G11)/2 -> 399.0318 | D8: =PATRON!H$40/2 -> 0.055 | E8: =PATRON!H$42/SQRT(3) -> 0.28867513 | F8: 0 | G8: =PATRON!H$44/SQRT(12) -> 0.028867513 | H8: =ABS(MEDIDA!F11-MEDIDA!G11)/SQRT(12) -> 0.068828645 | I8: =STDEV(MEDIDA!B11:E11)/SQRT(4) -> 0.093108996 | J8: =SQRT(SUMSQ(D8:I8)) -> 0.3171724 | K8: =J8^4/(D8^4/$D$12+E8^4/$E$12+F8^4/$F$12+G8^4/$G$12+H8^4/$H$12+I8^4/$I$12) -> 168.84766 | L8: =TINV(0.0455,K8) -> 2.0149926 | M8: =J8*L8 -> 0.63910003 | N8: =Redondeo!D124 -> 0,64
B9: =MEDIDA!A12 -> 500 | C9: =(MEDIDA!F12+MEDIDA!G12)/2 -> 499.12224 | D9: =PATRON!H$40/2 -> 0.055 | E9: =PATRON!H$42/SQRT(3) -> 0.28867513 | F9: 0 | G9: =PATRON!H$44/SQRT(12) -> 0.028867513 | H9: =ABS(MEDIDA!F12-MEDIDA!G12)/SQRT(12) -> 0.061212947 | I9: =STDEV(MEDIDA!B12:E12)/SQRT(4) -> 0.10602393 | J9: =SQRT(SUMSQ(D9:I9)) -> 0.3196557 | K9: =J9^4/(D9^4/$D$12+E9^4/$E$12+F9^4/$F$12+G9^4/$G$12+H9^4/$H$12+I9^4/$I$12) -> 135.6601 | L9: =TINV(0.0455,K9) -> 2.0186902 | M9: =J9*L9 -> 0.64528584 | N9: =Redondeo!D204 -> 0,65
B10: =MEDIDA!A13 -> 600 | C10: =(MEDIDA!F13+MEDIDA!G13)/2 -> 598.99169 | D10: =PATRON!H$40/2 -> 0.055 | E10: =PATRON!H$42/SQRT(3) -> 0.28867513 | F10: 0 | G10: =PATRON!H$44/SQRT(12) -> 0.028867513 | H10: =ABS(MEDIDA!F13-MEDIDA!G13)/SQRT(12) -> 0.0079721099 | I10: =STDEV(MEDIDA!B13:E13)/SQRT(4) -> 0.076407354 | J10: =SQRT(SUMSQ(D10:I10)) -> 0.30511195 | K10: =J10^4/(D10^4/$D$12+E10^4/$E$12+F10^4/$F$12+G10^4/$G$12+H10^4/$H$12+I10^4/$I$12) -> 187.85792 | L10: =TINV(0.0455,K10) -> 2.0134595 | M10: =J10*L10 -> 0.61433056 | N10: =Redondeo!D244 -> 0,61
B11: =MEDIDA!A14 -> 700 | C11: =(MEDIDA!F14+MEDIDA!G14)/2 -> 698.59271 | D11: =PATRON!H$40/2 -> 0.055 | E11: =PATRON!H$42/SQRT(3) -> 0.28867513 | F11: 0 | G11: =PATRON!H$44/SQRT(12) -> 0.028867513 | H11: =ABS(MEDIDA!F14-MEDIDA!G14)/SQRT(12) -> 0.038715254 | I11: =STDEV(MEDIDA!B14:E14)/SQRT(4) -> 0.12054091 | J11: =SQRT(SUMSQ(D11:I11)) -> 0.3212797 | K11: =J11^4/(D11^4/$D$12+E11^4/$E$12+F11^4/$F$12+G11^4/$G$12+H11^4/$H$12+I11^4/$I$12) -> 101.31959 | L11: =TINV(0.0455,K11) -> 2.025058 | M11: =J11*L11 -> 0.65061004 | N11: =Redondeo!D284 -> 0,65
D12: =0.5*(100%-D13)^-2 -> 200 | E12: =0.5*(100%-E13)^-2 -> 200 | F12: =0.5*(100%-F13)^-2 -> 200 | G12: =0.5*(100%-G13)^-2 -> 200 | H12: =0.5*(100%-H13)^-2 -> 200 | I12: 3
D13: 0.95 | E13: 0.95 | F13: 0.95 | G13: 0.95 | H13: 0.95

Sheet MEDIDA
E2: RESULTADOS DE CALIBRACIÓN DE PRESIÓN
B5: MEDIDOS
A6: Equipo bajo prueba | B6: 1 Lectura | D6: 2 Lectura | F6: Promedio | H6: Error | J6: Histerisis | L6: Promedio | M6: Error
B7: Subida | C7: Bajada | D7: Subida | E7: Bajada | F7: Subida | G7: Bajada | H7: Subida | I7: Bajada | J7: 1 Lectura | K7: 2 Lectura
A8: 0 | B8: 0 | C8: 0 | D8: 0 | E8: 0 | F8: =IF(INFORMACIÓN!$W$15=PATRON!$Q$13,AVERAGE(#REF!,#REF!),AVERAGE(MEDIDA!B8,MEDIDA!D8)) -> 0 | G8: =IF(INFORMACIÓN!W15=PATRON!Q13,AVERAGE(#REF!,#REF!),AVERAGE(MEDIDA!C8,MEDIDA!E8)) -> 0 | H8: =A8-F8 -> 0 | I8: =A8-G8 -> 0 | J8: 0 | K8: 0 | L8: =AVERAGE(F8:G8) -> 0 | M8: =AVERAGE(H8:I8) -> 0
A9: 100 | B9: =ROUND(98 + RAND() * (102 - 98), 1) -> 99 | C9: =B9+((RAND()*(0.6-0.1)+0.1)*RANDBETWEEN(-1,1)) -> 99.551028 | D9: =B9+((RAND()*(0.6-0.1)+0.1)*RANDBETWEEN(-1,1)) -> 99 | E9: =B9+((RAND()*(0.6-0.1)+0.1)*RANDBETWEEN(-1,1)) -> 99.19664 | F9: =AVERAGE(B9,D9) -> 99 | G9: =AVERAGE(C9,E9) -> 99.373834 | H9: =A9-F9 -> 1 | I9: =A9-G9 -> 0.62616564 | J9: =ABS(B9-C9) -> 0.55102845 | K9: =ABS(D9-E9) -> 0.19664028 | L9: =AVERAGE(F9:G9) -> 99.186917 | M9: =AVERAGE(H9:I9) -> 0.81308282
A10: 300 | B10: =G9 + (RAND() * 1.2 - 0.6)+200 -> 299.44665 | C10: =B10+((RAND()*(0.6-0.1)+0.1)*RANDBETWEEN(-1,1)) -> 299.85572 | D10: =B10+((RAND()*(0.6-0.1)+0.1)*RANDBETWEEN(-1,1)) -> 298.89471 | E10: =B10+((RAND()*(0.6-0.1)+0.1)*RANDBETWEEN(-1,1)) -> 299.18841 | F10: =AVERAGE(B10,D10) -> 299.17068 | G10: =AVERAGE(C10,E10) -> 299.52206 | H10: =A10-F10 -> 0.82931945 | I10: =A10-G10 -> 0.47793502 | J10: =ABS(B10-C10) -> 0.40906659 | K10: =ABS(D10-E10) -> 0.29370228 | L10: =AVERAGE(F10:G10) -> 299.34637 | M10: =AVERAGE(H10:I10) -> 0.65362723
A11: 400 | B11: =G10 + (RAND() * 1.2 - 0.6)+100 -> 399.28491 | C11: =B11+((RAND()*(0.6-0.1)+0.1)*RANDBETWEEN(-1,1)) -> 398.98783 | D11: =B11+((RAND()*(0.6-0.1)+0.1)*RANDBETWEEN(-1,1)) -> 399.01711 | E11: =B11+((RAND()*(0.6-0.1)+0.1)*RANDBETWEEN(-1,1)) -> 398.83734 | F11: =AVERAGE(B11,D11) -> 399.15101 | G11: =AVERAGE(C11,E11) -> 398.91258 | H11: =A11-F11 -> 0.8489895 | I11: =A11-G11 -> 1.0874189 | J11: =ABS(B11-C11) -> 0.29708757 | K11: =ABS(D11-E11) -> 0.17977127 | L11: =AVERAGE(F11:G11) -> 399.0318 | M11: =AVERAGE(H11:I11) -> 0.96820421
A12: 500 | B12: =G11 + (RAND() * 1.2 - 0.6)+100 -> 499.22826 | C12: =B12+((RAND()*(0.6-0.1)+0.1)*RANDBETWEEN(-1,1)) -> 499.22826 | D12: =B12+((RAND()*(0.6-0.1)+0.1)*RANDBETWEEN(-1,1)) -> 499.22826 | E12: =B12+((RAND()*(0.6-0.1)+0.1)*RANDBETWEEN(-1,1)) -> 498.80417 | F12: =AVERAGE(B12,D12) -> 499.22826 | G12: =AVERAGE(C12,E12) -> 499.01621 | H12: =A12-F12 -> 0.77173887 | I12: =A12-G12 -> 0.98378674 | J12: =ABS(B12-C12) -> 0 | K12: =ABS(D12-E12) -> 0.42409573 | L12: =AVERAGE(F12:G12) -> 499.12224 | M12: =AVERAGE(H12:I12) -> 0.8777628
A13: 600 | B13: =G12 + (RAND() * 1.2 - 0.6)+100 -> 599.12258 | C13: =B13+((RAND()*(0.6-0.1)+0.1)*RANDBETWEEN(-1,1)) -> 598.88841 | D13: =B13+((RAND()*(0.6-0.1)+0.1)*RANDBETWEEN(-1,1)) -> 598.83318 | E13: =B13+((RAND()*(0.6-0.1)+0.1)*RANDBETWEEN(-1,1)) -> 599.12258 | F13: =AVERAGE(B13,D13) -> 598.97788 | G13: =AVERAGE(C13,E13) -> 599.00549 | H13: =A13-F13 -> 1.0221216 | I13: =A13-G13 -> 0.9945054 | J13: =ABS(B13-C13) -> 0.23416939 | K13: =ABS(D13-E13) -> 0.28940179 | L13: =AVERAGE(F13:G13) -> 598.99169 | M13: =AVERAGE(H13:I13) -> 1.0083135
A14: 700 | B14: =G13 + (RAND() * 1.2 - 0.6)+100 -> 698.65977 | C14: =B14+((RAND()*(0.6-0.1)+0.1)*RANDBETWEEN(-1,1)) -> 698.24604 | D14: =B14+((RAND()*(0.6-0.1)+0.1)*RANDBETWEEN(-1,1)) -> 698.65977 | E14: =B14+((RAND()*(0.6-0.1)+0.1)*RANDBETWEEN(-1,1)) -> 698.80528 | F14: =AVERAGE(B14,D14) -> 698.65977 | G14: =AVERAGE(C14,E14) -> 698.52566 | H14: =A14-F14 -> 1.3402301 | I14: =A14-G14 -> 1.4743437 | J14: =ABS(B14-C14) -> 0.41373373 | K14: =ABS(D14-E14) -> 0.14550659 | L14: =AVERAGE(F14:G14) -> 698.59271 | M14: =AVERAGE(H14:I14) -> 1.4072869

Sheet PATRON
C1: SIMULADOR DE SIGNOS VITALES
B2: -9.505e-14 | C2: PSI
B3: 8.270408e-11 | C3: NOMINAL | D3: MEDIDO | E3: CORRECIÓN | F3: Correcion estimada | G3: Residuales | H3: Residualales al cuadrado | I3: Suma de residuales | J3: N-M-1 | K3: uiter
B4: 2.6982967e-08 | C4: 0 | D4: 0 | E4: =C4-D4 -> 0 | F4: =B$2*D4^6-B$3*D4^5+B$4*D4^4-B$5*D4^3+B$6*D4^2-B$7*D4+B$8 -> 2.8701166e-09 | G4: =E4-F4 -> -2.8701166e-09 | H4: =G4^2 -> 8.2375692e-18 | I4: =SUM(J4:J12) -> 0 | J4: =7-6-1 -> 0 | K4: 0
B5: 4.143528e-06 | C5: 50.037 | D5: 49.98 | E5: =C5-D5 -> 0.057 | F5: =B$2*D5^6+B$3*D5^5-B$4*D5^4+B$5*D5^3-B$6*D5^2+B$7*D5+B$8 -> 0.057000009 | G5: =E5-F5 -> -9.3928717e-09 | H5: =G5^2 -> 8.8226039e-17
B6: 0.00031474646 | C6: 100.03 | D6: 100.06 | E6: =C6-D6 -> -0.03 | F6: =B$2*D6^6+B$3*D6^5-B$4*D6^4+B$5*D6^3-B$6*D6^2+B$7*D6+B$8 -> -0.029999484 | G6: =E6-F6 -> -5.155885e-07 | H6: =G6^2 -> 2.658315e-13
B7: 0.0094033449 | C7: 150.03 | D7: 150.18 | E7: =C7-D7 -> -0.15 | F7: =B$2*D7^6+B$3*D7^5-B$4*D7^4+B$5*D7^3-B$6*D7^2+B$7*D7+B$8 -> -0.14999419 | G7: =E7-F7 -> -5.807119e-06 | H7: =G7^2 -> 3.3722631e-11
B8: 2.8701166e-09 | C8: 200.027 | D8: 200.38 | E8: =C8-D8 -> -0.353 | F8: =B$2*D8^6+B$3*D8^5-B$4*D8^4+B$5*D8^3-B$6*D8^2+B$7*D8+B$8 -> -0.35296748 | G8: =E8-F8 -> -3.252269e-05 | H8: =G8^2 -> 1.0577254e-09
C9: 250.02 | D9: 250.44 | E9: =C9-D9 -> -0.42 | F9: =B$2*D9^6+B$3*D9^5-B$4*D9^4+B$5*D9^3-B$6*D9^2+B$7*D9+B$8 -> -0.41987659 | G9: =E9-F9 -> -0.00012340758 | H9: =G9^2 -> 1.522943e-08
C10: 300.02 | D10: 300.54 | E10: =C10-D10 -> -0.52 | F10: =B$2*D10^6+B$3*D10^5-B$4*D10^4+B$5*D10^3-B$6*D10^2+B$7*D10+B$8 -> -0.51963252 | G10: =E10-F10 -> -0.00036748127 | H10: =G10^2 -> 1.3504248e-07
N11: Unidades | O11: x | P11: x | Q11: Tipo
N12: mmHg | O12: Si | P12: Buen estado | Q12: Digital
N13: PSI | O13: No | P13: Mal estado | Q13: Análogo
C33: EQUIPO PATRÓN
C34: Equipo patrón: | H34: Simulador de signos vitales
C35: Marca: | H35: BC Biomedical
C36: Modelo: | H36: NIBP-1020
C37: Serie: | H37: 73581403 Rev AH
C38: Fecha de Calibración: | H38: 44971
C39: No. Certificado: | H39: L4015
C40: Incertidumbre NIBP: | H40: 0.11
C41: Incertidumbre ECG: | H41: 0.48
C42: Deriva NIBP | H42: 0.5
C43: Deriva ECG | H43: 0
C44: Resolución NIBP | H44: 0.1
C45: Resolución ECG | H45: 1
C46: Factor de cobertura K: | H46: 2

Sheet CERTIFICADO 
O1: CERTIFICADO N°: | R1: =INFORMACIÓN!G3 -> JD1743-24
C3: 1. EQUIPO BAJO PRUEBA
C5: INSTRUMENTO: | I5: =INFORMACIÓN!A3 -> TENSIOMETRO
C6: MARCA: | I6: =INFORMACIÓN!B3 -> HILLROM
C7: MODELO: | I7: =INFORMACIÓN!C3 -> 7670-01
C8: SERIE: | I8: =INFORMACIÓN!D3 -> 220907150040
C9: CÓDIGO INTERNO: | I9: =INFORMACIÓN!F3 -> 0401005309
C10: UBICACIÓN: | I10: =INFORMACIÓN!E3 -> CONSULTA EXTERNA
C11: ESTADO FÍSICO: | I11: =INFORMACIÓN!B8 -> BUEN ESTADO
C12: FECHA DE RECEPCIÓN: | I12: =INFORMACIÓN!H3 -> 45465
C13: FECHA DE CALIBRACIÓN: | I13: =INFORMACIÓN!B9 -> 45465
C15: 2. DATOS DEL CLIENTE
C17: NOMBRE: | I17: =INFORMACIÓN!E7 -> HOSPITAL DE ALTA COMPLEJIDAD DEL MAGDALENA CENTRO
C18: NIT: | I18: =INFORMACIÓN!E8 -> 901.532.463-8
C19: TELÉFONO: | I19: =INFORMACIÓN!E9 -> 3007835072
C20: DIRECCIÓN: | I20: =INFORMACIÓN!E10 -> CARRERA 15 ENTRE CALLE 18 y 19
C21: CIUDAD: | I21: =INFORMACIÓN!E11 -> LA DORADA - CALDAS
C23: Este certificado expresa fielmente el resultado de las mediciones realizadas; no podrá ser reproducido total o parcialmente excepto cuando se haya obtenido permiso por escrito de BTM COLOMBIA ZOMAC S.A.S y se debe reproducir en su totalidad, para proporcionar seguridad de que el certificado no sea sacado de contexto. Los resultados que se encuentran en este certificado se refieren al momento y condiciones en que se realizaron las mediciones, BTM COLOMBIA ZOMAC S.A.S no se responsabiliza de los daños que puedan ser causados por el uso inadecuado de los equipos calibrados. El usuario es responsable de la calibración de sus instrumentos a intervalos apropiados. El laboratorio no se hace responsable por cómo la información suministrada por el cliente afecte los resultados de medición.
C31: REVISÓ Y AUTORIZÓ: | I31: CALIBRADO POR: | M31: =INFORMACIÓN!B15 -> ING. GABRIEL DURÁN
I32: FECHA DE EMISIÓN: | M32: =INFORMACIÓN!B10 -> 45465
I33: NÚMERO DE PÁGINAS: | M33: 3
C36: ING. JOHAN SEBASTIÁN PÉREZ
C37: DIRECTOR DE LABORATORIO
O38: =O1 -> CERTIFICADO N°: | R38: =R1 -> JD1743-24
B40: 3. CONDICIONES AMBIENTALES
B41: El laboratorio de metrología BTM COLOMBIA ZOMAC S.A.S registra las condiciones ambientales (Humedad y Temperatura) tomando los máximos y mínimos alcanzados durante el tiempo en que se ejecuta la calibración. A continuación se presenta el promedio y la variación resultante.
F45: TEMPERATURA AMBIENTE (°C) | K45: HUMEDAD RELATIVA (%HR)
F46: =AVERAGE(INFORMACIÓN!B11:B12) -> 24.3 | H46: ± | I46: =ABS(INFORMACIÓN!B11-INFORMACIÓN!B12) -> 0.4 | K46: =AVERAGE(INFORMACIÓN!B13:B14) -> 61.5 | M46: ± | N46: =ABS(INFORMACIÓN!B13-INFORMACIÓN!B14) -> 3
F48: La calibración fue realizada en: | K48: En sitio (instalaciones del cliente)
B50: 4. INCERTIDUMBRE DE MEDICIÓN
B51: La incertidumbre expandida de la medición reportada se establece como la incertidumbre estándar de medición multiplicada por el factor de cobertura “k” y la probabilidad de cobertura, la cual debe ser aproximada al 95% y no menor a este valor. La incertidumbre de medición ha sido estimada con un nivel de confianza del 95,45% empleando una distribución t de student. Cuando se hace declaración de cumplimiento, el laboratorio hace referencia a las especificaciones del fabricante, norma o requisitos declarados por el cliente. La regla de decisión aplicada en estos casos será |Error| +U ≤ EMP según la ASME B89 7.3.1, si cumple la anterior condición la medición se toma como conforme y registrará un pasa, en caso contrario se registrará falla. La probabilidad de dar una aceptación falsa o un rechazo falso no lo determina el laboratorio, sin embargo se puede calcular de acuerdo a la guía JCGM 106:2012 según su numeral 8.
B60: 5. PROCEDIMIENTO DE CALIBRACIÓN
B61: La calibración se ejecutó mediante el método de comparación directa con patrón de referencia de acuerdo con el procedimiento interno para tensiómetros manuales BTM-P-002.
B64: 6. TRAZABILIDAD
B65: El laboratorio BTM COLOMBIA ZOMAC S.A.S establece la trazabilidad metrológica de sus mediciones al sistema internacional de unidades (SI), por medio de una cadena documentada de calibraciones, las cuales se encuentran referenciadas a patrones de medidas primarios. Esta vinculación se logra a través del uso de patrones calibrados por institutos nacionales de metrología (INM) y por laboratorios acreditados por parte de un organismo de acreditación.
B70: PATRÓN | H70: SERIE | M70: CALIBRACIÓN | P70: CERTIFICADO
B71: Simulador de signos vitales | H71: 73581403 | M71: 46065 | P71: L5555
O76: =O1 -> CERTIFICADO N°: | R76: =R1 -> JD1743-24
B78: 7. RESULTADOS DE LA CALIBRACIÓN
B80: Calibración de presión | I80: Intervalo de medición (mmHg): | N80: 0 a 700 | P80: Resolución (mmHg): | S80: 0.5
...
