Workbook
Name Instrumento: '[1]R-LAB-127 DENSIDAD AIRE'!#REF!
Name Instrumento: '[1]R-LAB-127 DENSIDAD AIRE'!#REF!
Name Instrumento.: '[1]R-LAB-127 DENSIDAD AIRE'!#REF!
Name Instrumento.: '[1]R-LAB-127 DENSIDAD AIRE'!#REF!
Name N: #REF!
Name N: #REF!

Sheet INFORMACIÓN
A1: Datos del item | O1: En sitio ( instalaciones del cliente)
A2: Intrumento | B2: Marca | C2: Modelo | D2: Serie | E2: Ubicación | F2: Inventario | G2: Número de Certificado | H2: Fecha de Recepción | O2: Laboratorio BTMC
O4: BUEN ESTADO
O5: REGULAR ESTADO
A6: Datos de calibración | D6: Datos del cliente | O6: MAL ESTADO
A7: Lugar de calibración: | B7: En sitio ( instalaciones del cliente) | D7: Solicitante: | E7: HOSPITAL DE ALTA COMPLEJIDAD DEL MAGDALENA CENTRO
A8: Estado Físico: | B8: BUEN ESTADO | D8: Nit: | E8: 901.532.463-8
A9: Fecha de calibración: | B9: =H3 -> 0 | D9: Telefono: | E9: 3007835072
A10: Fecha de emisión: | B10: =H3 -> 0 | D10: Dirección: | E10: CARRERA 15 ENTRE CALLE 18 y 19
A11: Temperatura mínima: | B11: 24.1 | D11: Ciudad: | E11: LA DORADA - CALDAS
A12: Temperatura máxima: | B12: 24.5
A13: Humedad Mínima: | B13: 60
A14: Humedad Máxima: | B14: 63
A15: Calibración realiza por: | B15: ING. GABRIEL DURÁN

Sheet Redondeo
C1: DATO 1
C2: Dato | D2: Dato redondeado | E2: =FIXED(C3,6) -> #REF! | F2: =RIGHT(E2,1) -> #REF! | G2: =F2/1000000 -> #REF! | H2: =C3-G2 -> #REF! | J2: =IF(E7=5,IF(AND(F3=0,F8=FALSE),L5,L6),L6) -> #REF!
C3: =INCERTIDUMBRE!M5 -> #REF! | D3: =IF(C3>=10,M37,IF(C3>=1,M29,IF(C3>=0.1,M21,IF(C3>=0.01,M13,IF(C3>=0.001,M5))))) -> #REF! | E3: 6 decimal | F3: =F2+0 -> #REF!
E4: Extrae el ultimo digito | F4: extrael primer digito | G4: parte entera | H4: Parte decimal | I4: cantidad de decimales | J4: decimales en enteros | K4: restar ultimo numero | L4: Elimar ultimo digito | M4: Dato Final
E5: =RIGHT(H2,2) -> #REF! | F5: =LEFT(E5,1) -> #REF! | G5: =TRUNC(C3) -> #REF! | H5: =FIXED(C3-G5,I5) -> #REF! | I5: =ABS(G8-H8) -> #REF! | J5: =RIGHT(C3,I5) -> #REF! | K5: 5e-05 | L5: =(C3-K5) -> #REF! | M5: =IF(E7=5,IF(AND(F3=0,F8=FALSE),L5,L6),L6) -> #REF!
E6: =RIGHT(E5,1) -> #REF! | F6: =F5+0 -> #REF! | L6: =FIXED(C3,4) -> #REF!
E7: =E6+0 -> #REF! | F7: es impar? | G7: Largo dato original | H7: largo parte enetero y decimal
F8: =ISODD(F5) -> #REF! | G8: =LEN(C3) -> #REF! | H8: =LEN(G5)+1 -> #REF!
C10: 4 Decimales
C11: =M5 -> #REF! | E11: =FIXED(C3,5) -> #REF! | F11: =RIGHT(E11,1) -> #REF! | G11: =F11+0 -> #REF!
E12: Extrae el ultimo digito | F12: extrael primer digito | G12: parte entera | H12: Parte decimal | I12: cantidad de decimales | J12: decimales en enteros | K12: restar ultimo numero | L12: Elimar ultimo digito | M12: Dato Final
E13: =RIGHT(C11,2) -> #REF! | F13: =LEFT(E13,1) -> #REF! | G13: =TRUNC(C11) -> #REF! | H13: =FIXED(C11-G13,I13) -> #REF! | I13: =ABS(G16-H16) -> #REF! | J13: =RIGHT(C11,I13) -> #REF! | K13: 0.0005 | L13: =(C11-K13) -> #REF! | M13: =IF(E15=5,IF(AND(G11=0,F16=FALSE),L13,L14),L14) -> #REF!
E14: =RIGHT(E13,1) -> #REF! | F14: =F13+0 -> #REF! | L14: =FIXED(C11,3) -> #REF!
E15: =E14+0 -> #REF! | F15: es impar? | G15: Largo dato original | H15: largo parte enetero y decimal
F16: =ISODD(F13) -> #REF! | G16: =LEN(C11) -> #REF! | H16: =LEN(G13)+1 -> #REF!
C18: 3 Decimales
C19: =M13 -> #REF! | E19: =FIXED(C11,4) -> #REF! | F19: =RIGHT(E19,1) -> #REF! | G19: =F19+0 -> #REF!
E20: Extrae el ultimo digito | F20: extrael primer digito | G20: parte entera | H20: Parte decimal | I20: cantidad de decimales | J20: decimales en enteros | K20: restar ultimo numero | L20: Elimar ultimo digito | M20: Dato Final
E21: =RIGHT(C19,2) -> #REF! | F21: =LEFT(E21,1) -> #REF! | G21: =TRUNC(C19) -> #REF! | H21: =FIXED(C19-G21,I21) -> #REF! | I21: =ABS(G24-H24) -> #REF! | J21: =RIGHT(C19,I21) -> #REF! | K21: 0.005 | L21: =(C19-K21) -> #REF! | M21: =IF(E23=5,IF(AND(G19=0,F24=FALSE),L21,L22),L22) -> #REF!
E22: =RIGHT(E21,1) -> #REF! | F22: =F21+0 -> #REF! | L22: =FIXED(C19,2) -> #REF!
E23: =E22+0 -> #REF! | F23: es impar? | G23: Largo dato original | H23: largo parte enetero y decimal
F24: =ISODD(F21) -> #REF! | G24: =LEN(C19) -> #REF! | H24: =LEN(G21)+1 -> #REF!
C26: 2 Decimales
C27: =M21 -> #REF! | E27: =FIXED(C19,3) -> #REF! | F27: =RIGHT(E27,1) -> #REF! | G27: =F27+0 -> #REF!
E28: Extrae el ultimo digito | F28: extrael primer digito | G28: parte entera | H28: Parte decimal | I28: cantidad de decimales | J28: decimales en enteros | K28: restar ultimo numero | L28: Elimar ultimo digito | M28: Dato Final
E29: =RIGHT(C27,2) -> #REF! | F29: =LEFT(E29,1) -> #REF! | G29: =TRUNC(C27) -> #REF! | H29: =FIXED(C27-G29,I29) -> #REF! | I29: =ABS(G32-H32) -> #REF! | J29: =RIGHT(C27,I29) -> #REF! | K29: 0.05 | L29: =(C27-K29) -> #REF! | M29: =IF(E31=5,IF(AND(G27=0,F32=FALSE),L29,L30),L30) -> #REF!
E30: =RIGHT(E29,1) -> #REF! | F30: =F29+0 -> #REF! | L30: =FIXED(C27,1) -> #REF!
E31: =E30+0 -> #REF! | F31: es impar? | G31: Largo dato original | H31: largo parte enetero y decimal
F32: =ISODD(F29) -> #REF! | G32: =LEN(C27) -> #REF! | H32: =LEN(G29)+1 -> #REF!
C34: 1 Decimales
C35: =M29 -> #REF! | E35: =FIXED(C27,2) -> #REF! | F35: =RIGHT(E35,1) -> #REF! | G35: =F35+0 -> #REF!
E36: Extrae el ultimo digito | F36: extrael primer digito | G36: parte entera | H36: Parte decimal | I36: cantidad de decimales | J36: decimales en enteros | K36: restar ultimo numero | L36: Elimar ultimo digito | M36: Dato Final
E37: =RIGHT(C35,2) -> #REF! | F37: =RIGHT(G37,1) -> #REF! | G37: =TRUNC(C35) -> #REF! | H37: =FIXED(C35-G37,I37) -> #REF! | I37: =ABS(G40-H40) -> #REF! | J37: =RIGHT(C35,I37) -> #REF! | K37: 0.5 | L37: =(C35-K37) -> #REF! | M37: =IF(E39=5,IF(AND(G35=0,F40=FALSE),L37,L38),L38) -> #REF!
E38: =RIGHT(E37,1) -> #REF! | F38: =F37+0 -> #REF! | L38: =FIXED(C35,0) -> #REF!
E39: =E38+0 -> #REF! | F39: es impar? | G39: Largo dato original | H39: largo parte enetero y decimal
F40: =ISODD(F37) -> #REF! | G40: =LEN(C35) -> #REF! | H40: =LEN(G37)+1 -> #REF!
C41: DATO 2
C42: Dato | D42: Dato redondeado | E42: =FIXED(C43,6) -> #REF! | F42: =RIGHT(E42,1) -> #REF! | G42: =F42/1000000 -> #REF! | H42: =C43-G42 -> #REF! | J42: =IF(E47=5,IF(AND(F43=0,F48=FALSE),L45,L46),L46) -> #REF!
C43: =INCERTIDUMBRE!M6 -> #REF! | D43: =IF(C43>=10,M77,IF(C43>=1,M69,IF(C43>=0.1,M61,IF(C43>=0.01,M53,IF(C43>=0.001,M45))))) -> #REF! | E43: 6 decimal | F43: =F42+0 -> #REF!
E44: Extrae el ultimo digito | F44: extrael primer digito | G44: parte entera | H44: Parte decimal | I44: cantidad de decimales | J44: decimales en enteros | K44: restar ultimo numero | L44: Elimar ultimo digito | M44: Dato Final
...

Sheet INCERTIDUMBRE
E3: correcciones debidas al Patrón, | H3: correcciones debidas al Instrumento | L3: INDCREDIUMBRE | N3: =INFORMACIÓN!W12 -> 0
B4: Lectura instrumento | C4: Promedio lecturas patrón | D4: δ(Pat)cal | E4: δ(Pat)der | F4: δ(Pat),int | G4: δ(Inst)res | H4: δ(Ins)hist | I4: u(rep) | J4: u(comb) | K4: Veff | L4: Factor de cobertura (k) | M4: Incertidumbre Expandida
B5: =MEDIDA!A8 -> 0 | C5: =(MEDIDA!J8+MEDIDA!K8)/2 -> 0 | D5: =#REF!/2 -> #REF! | E5: =#REF!/SQRT(3) -> #REF! | F5: 0 | G5: =#REF!/SQRT(12) -> #REF! | H5: =ABS(MEDIDA!J8-MEDIDA!K8)/SQRT(12) -> 0 | I5: =STDEV(MEDIDA!F8:I8)/SQRT(4) -> #DIV/0! | J5: =SQRT(SUMSQ(D5:I5)) -> #REF! | K5: =J5^4/(D5^4/$D$12+E5^4/$E$12+F5^4/$F$12+G5^4/$G$12+H5^4/$H$12+I5^4/$I$12) -> #REF! | L5: =TINV(0.0455,K5) -> #REF! | M5: =J5*L5 -> #REF! | N5: =Redondeo!D3 -> #REF!
B6: =MEDIDA!A9 -> 0 | C6: =(MEDIDA!J9+MEDIDA!K9)/2 -> 0 | D6: =#REF!/2 -> #REF! | E6: =#REF!/SQRT(3) -> #REF! | F6: 0 | G6: =#REF!/SQRT(12) -> #REF! | H6: =ABS(MEDIDA!J9-MEDIDA!K9)/SQRT(12) -> 0 | I6: =STDEV(MEDIDA!F9:I9)/SQRT(4) -> #DIV/0! | J6: =SQRT(SUMSQ(D6:I6)) -> #REF! | K6: =J6^4/(D6^4/$D$12+E6^4/$E$12+F6^4/$F$12+G6^4/$G$12+H6^4/$H$12+I6^4/$I$12) -> #REF! | L6: =TINV(0.0455,K6) -> #REF! | M6: =J6*L6 -> #REF! | N6: =Redondeo!D43 -> #REF!
B7: =MEDIDA!A10 -> 0 | C7: =(MEDIDA!J10+MEDIDA!K10)/2 -> 0 | D7: =#REF!/2 -> #REF! | E7: =#REF!/SQRT(3) -> #REF! | F7: 0 | G7: =#REF!/SQRT(12) -> #REF! | H7: =ABS(MEDIDA!J10-MEDIDA!K10)/SQRT(12) -> 0 | I7: =STDEV(MEDIDA!F10:I10)/SQRT(4) -> #DIV/0! | J7: =SQRT(SUMSQ(D7:I7)) -> #REF! | K7: =J7^4/(D7^4/$D$12+E7^4/$E$12+F7^4/$F$12+G7^4/$G$12+H7^4/$H$12+I7^4/$I$12) -> #REF! | L7: =TINV(0.0455,K7) -> #REF! | M7: =J7*L7 -> #REF! | N7: =Redondeo!D83 -> #REF!
B8: =MEDIDA!A11 -> 0 | C8: =(MEDIDA!J11+MEDIDA!K11)/2 -> 0 | D8: =#REF!/2 -> #REF! | E8: =#REF!/SQRT(3) -> #REF! | F8: 0 | G8: =#REF!/SQRT(12) -> #REF! | H8: =ABS(MEDIDA!J11-MEDIDA!K11)/SQRT(12) -> 0 | I8: =STDEV(MEDIDA!F11:I11)/SQRT(4) -> #DIV/0! | J8: =SQRT(SUMSQ(D8:I8)) -> #REF! | K8: =J8^4/(D8^4/$D$12+E8^4/$E$12+F8^4/$F$12+G8^4/$G$12+H8^4/$H$12+I8^4/$I$12) -> #REF! | L8: =TINV(0.0455,K8) -> #REF! | M8: =J8*L8 -> #REF! | N8: =Redondeo!D124 -> #REF!
B9: =MEDIDA!A12 -> 0 | C9: =(MEDIDA!J12+MEDIDA!K12)/2 -> 0 | D9: =#REF!/2 -> #REF! | E9: =#REF!/SQRT(3) -> #REF! | F9: 0 | G9: =#REF!/SQRT(12) -> #REF! | H9: =ABS(MEDIDA!J12-MEDIDA!K12)/SQRT(12) -> 0 | I9: =STDEV(MEDIDA!F12:I12)/SQRT(4) -> #DIV/0! | J9: =SQRT(SUMSQ(D9:I9)) -> #REF! | K9: =J9^4/(D9^4/$D$12+E9^4/$E$12+F9^4/$F$12+G9^4/$G$12+H9^4/$H$12+I9^4/$I$12) -> #REF! | L9: =TINV(0.0455,K9) -> #REF! | M9: =J9*L9 -> #REF! | N9: =Redondeo!D204 -> #REF!
B10: =MEDIDA!A13 -> 0 | C10: =(MEDIDA!J13+MEDIDA!K13)/2 -> 0 | D10: =#REF!/2 -> #REF! | E10: =#REF!/SQRT(3) -> #REF! | F10: 0 | G10: =#REF!/SQRT(12) -> #REF! | H10: =ABS(MEDIDA!J13-MEDIDA!K13)/SQRT(12) -> 0 | I10: =STDEV(MEDIDA!F13:I13)/SQRT(4) -> #DIV/0! | J10: =SQRT(SUMSQ(D10:I10)) -> #REF! | K10: =J10^4/(D10^4/$D$12+E10^4/$E$12+F10^4/$F$12+G10^4/$G$12+H10^4/$H$12+I10^4/$I$12) -> #REF! | L10: =TINV(0.0455,K10) -> #REF! | M10: =J10*L10 -> #REF! | N10: =Redondeo!D244 -> #REF!
B11: =MEDIDA!A14 -> 0 | C11: =(MEDIDA!J14+MEDIDA!K14)/2 -> 0 | D11: =#REF!/2 -> #REF! | E11: =#REF!/SQRT(3) -> #REF! | F11: 0 | G11: =#REF!/SQRT(12) -> #REF! | H11: =ABS(MEDIDA!J14-MEDIDA!K14)/SQRT(12) -> 0 | I11: =STDEV(MEDIDA!F14:I14)/SQRT(4) -> #DIV/0! | J11: =SQRT(SUMSQ(D11:I11)) -> #REF! | K11: =J11^4/(D11^4/$D$12+E11^4/$E$12+F11^4/$F$12+G11^4/$G$12+H11^4/$H$12+I11^4/$I$12) -> #REF! | L11: =TINV(0.0455,K11) -> #REF! | M11: =J11*L11 -> #REF! | N11: =Redondeo!D284 -> #REF!
D12: =0.5*(100%-D13)^-2 -> 200 | E12: =0.5*(100%-E13)^-2 -> 200 | F12: =0.5*(100%-F13)^-2 -> 200 | G12: =0.5*(100%-G13)^-2 -> 200 | H12: =0.5*(100%-H13)^-2 -> 200 | I12: 3
D13: 0.95 | E13: 0.95 | F13: 0.95 | G13: 0.95 | H13: 0.95

Sheet MEDIDA
H3: Digital | K3: PASA
H4: Análogo | K4: FALLA
H5: No tiene

Sheet CERTIFICADO 
O1: CERTIFICADO N°: | R1: =INFORMACIÓN!G3 -> 0
C3: EQUIPO BAJO PRUEBA
C5: INSTRUMENTO: | I5: =INFORMACIÓN!A3 -> 0
C6: MARCA: | I6: =INFORMACIÓN!B3 -> 0
C7: MODELO: | I7: =INFORMACIÓN!C3 -> 0
C8: SERIE: | I8: =INFORMACIÓN!D3 -> 0
C9: CÓDIGO INTERNO: | I9: =INFORMACIÓN!F3 -> 0
C10: UBICACIÓN: | I10: =INFORMACIÓN!E3 -> 0
C11: ESTADO FÍSICO: | I11: =INFORMACIÓN!B8 -> BUEN ESTADO
C12: FECHA DE RECEPCIÓN: | I12: =INFORMACIÓN!H3 -> 0
C13: FECHA DE CALIBRACIÓN: | I13: =INFORMACIÓN!B9 -> 0
C15: DATOS DEL CLIENTE
C17: NOMBRE: | I17: =INFORMACIÓN!E7 -> HOSPITAL DE ALTA COMPLEJIDAD DEL MAGDALENA CENTRO
C18: NIT: | I18: =INFORMACIÓN!E8 -> 901.532.463-8
C19: TELÉFONO: | I19: =INFORMACIÓN!E9 -> 3007835072
C20: DIRECCIÓN: | I20: =INFORMACIÓN!E10 -> CARRERA 15 ENTRE CALLE 18 y 19
C21: CIUDAD: | I21: =INFORMACIÓN!E11 -> LA DORADA - CALDAS
C23: Este certificado expresa fielmente el resultado de las mediciones realizadas; no podrá ser reproducido total o parcialmente excepto cuando se haya obtenido permiso por escrito de BTM COLOMBIA ZOMAC S.A.S y se debe reproducir en su totalidad, para proporcionar seguridad de que el certificado no sea sacado de contexto. Los resultados que se encuentran en este certificado se refieren al momento y condiciones en que se realizaron las mediciones, BTM COLOMBIA ZOMAC S.A.S no se responsabiliza de los daños que puedan ser causados por el uso inadecuado de los equipos calibrados. El usuario es responsable de la calibración de sus instrumentos a intervalos apropiados. El laboratorio no se hace responsable por cómo la información suministrada por el cliente afecte los resultados de medición.
C31: REVISÓ Y AUTORIZÓ: | I31: VALIDADO POR: | M31: =INFORMACIÓN!B15 -> ING. GABRIEL DURÁN
I32: FECHA DE EMISIÓN: | M32: =INFORMACIÓN!B10 -> 0
I33: NÚMERO DE PÁGINAS: | M33: 9
C36: ING. JOHAN SEBASTIÁN PÉREZ
C37: DIRECTOR DE LABORATORIO
O38: =O1 -> CERTIFICADO N°: | R38: =R1 -> 0
B40: CONDICIONES AMBIENTALES
B41: El laboratorio de metrología BTM COLOMBIA ZOMAC S.A.S registra las condiciones ambientales (Humedad y Temperatura) tomando los máximos y mínimos alcanzados durante el tiempo en que se ejecuta la validación. A continuación se presenta el promedio y la variación resultante.
F45: TEMPERATURA AMBIENTE (°C) | K45: HUMEDAD RELATIVA (%HR)
F46: =AVERAGE(INFORMACIÓN!B11:B12) -> 24.3 | H46: ± | I46: =ABS(INFORMACIÓN!B11-INFORMACIÓN!B12) -> 0.4 | K46: =AVERAGE(INFORMACIÓN!B13:B14) -> 61.5 | M46: ± | N46: =ABS(INFORMACIÓN!B13-INFORMACIÓN!B14) -> 3
F48: La validación fue realizada en: | K48: En sitio (instalaciones del cliente)
B50: INCERTIDUMBRE DE MEDICIÓN
B51: La incertidumbre expandida de la medición reportada se establece como la incertidumbre estándar de medición multiplicada por el factor de cobertura “k” y la probabilidad de cobertura, la cual debe ser aproximada al 95% y no menor a este valor. La incertidumbre de medición ha sido estimada con un nivel de confianza del 95,45% empleando una distribución t de student. Cuando se hace declaración de cumplimiento, el laboratorio hace referencia a las especificaciones del fabricante, norma o requisitos declarados por el cliente. La regla de decisión aplicada en estos casos será |Error| +U ≤ EMP según la ASME B89 7.3.1, si cumple la anterior condición la medición se toma como conforme y registrará un pasa, en caso contrario se registrará falla. La probabilidad de dar una aceptación falsa o un rechazo falso no lo determina el laboratorio, sin embargo se puede calcular de acuerdo a la guía JCGM 106:2012 según su numeral 8.
B60: PROCEDIMIENTO DE VALIDACIÓN
B61: La validación se ejecutó mediante el método de comparación directa con patrón de referencia de acuerdo con el procedimiento interno para cavas BTM-P-040.
B64: TRAZABILIDAD
B65: El laboratorio BTM COLOMBIA ZOMAC S.A.S establece la trazabilidad metrológica de sus mediciones al sistema internacional de unidades (SI), por medio de una cadena documentada de calibraciones, las cuales se encuentran referenciadas a patrones de medidas primarios. Esta vinculación se logra a través del uso de patrones calibrados por institutos nacionales de metrología (INM) y por laboratorios acreditados por parte de un organismo de acreditación.
B70: PATRÓN | H70: SERIE | M70: VALIDEZ | P70: CERTIFICADO
B71: Datalogger de Temperatura 4 Sondas | H71: 230310997 | M71: 45970 | P71: 263916_A 263916_B 263917_A 263917_B 263918_A 263918_B 263919_A 263919_B
O74: =O1 -> CERTIFICADO N°: | R74: =R1 -> 0
B76: 1. OBJETIVO
B78: Probar y documentar que el procedimiento utilizado para el transporte de medicamentos y dispositivos médicos cumpla la temperatura de conservación definida y que esta temperatura se mantenga en el rango de 2 °C a 8 °C durante el tiempo de transporte, para que los medicamentos no pierdan sus propiedades originales.
...
