Workbook
Name Instrumento: '[1]R-LAB-127 DENSIDAD AIRE'!#REF!
Name Instrumento: '[1]R-LAB-127 DENSIDAD AIRE'!#REF!
Name Instrumento.: '[1]R-LAB-127 DENSIDAD AIRE'!#REF!
Name Instrumento.: '[1]R-LAB-127 DENSIDAD AIRE'!#REF!
Name N: #REF!
Name N: #REF!

Sheet INFORMACIÓN
A1: Datos del item | O1: En sitio ( instalaciones del cliente)
A2: Intrumento | B2: Marca | C2: Modelo | D2: Serie | E2: Ubicación | F2: Inventario | G2: Número de Certificado | H2: Fecha de Recepción | O2: Laboratorio BTMC
O4: BUEN ESTADO
O5: REGULAR ESTADO
A6: Datos de calibración | D6: Datos del cliente | O6: MAL ESTADO
A7: Lugar de calibración: | B7: En sitio ( instalaciones del cliente) | D7: Solicitante: | E7: HOSPITAL DE ALTA COMPLEJIDAD DEL MAGDALENA CENTRO
A8: Estado Físico: | B8: BUEN ESTADO | D8: Nit: | E8: 901.532.463-8
A9: Fecha de calibración: | B9: =H3 -> 0 | D9: Telefono: | E9: 3007835072
A10: Fecha de emisión: | B10: =H3 -> 0 | D10: Dirección: | E10: CARRERA 15 ENTRE CALLE 18 y 19
A11: Temperatura mínima: | B11: 24.1 | D11: Ciudad: | E11: LA DORADA - CALDAS
A12: Temperatura máxima: | B12: 24.5
A13: Humedad Mínima: | B13: 60
A14: Humedad Máxima: | B14: 63
A15: Calibración realiza por: | B15: ING. GABRIEL DURÁN

Sheet Redondeo
A1: DATO 1
A2: Dato | B2: Dato redondeado | C2: =FIXED(A3,6) -> #REF! | D2: =RIGHT(C2,1) -> #REF! | E2: =D2/1000000 -> #REF! | F2: =A3-E2 -> #REF! | H2: =IF(C7=5,IF(AND(D3=0,D8=FALSE),J5,J6),J6) -> #REF!
A3: =INCERTIDUMBRE!L5 -> #REF! | B3: =IF(A3>=10,K37,IF(A3>=1,K29,IF(A3>=0.1,K21,IF(A3>=0.01,K13,IF(A3>=0.001,K5))))) -> #REF! | C3: 6 decimal | D3: =D2+0 -> #REF!
C4: Extrae el ultimo digito | D4: extrael primer digito | E4: parte entera | F4: Parte decimal | G4: cantidad de decimales | H4: decimales en enteros | I4: restar ultimo numero | J4: Elimar ultimo digito | K4: Dato Final
C5: =RIGHT(F2,2) -> #REF! | D5: =LEFT(C5,1) -> #REF! | E5: =TRUNC(A3) -> #REF! | F5: =FIXED(A3-E5,G5) -> #REF! | G5: =ABS(E8-F8) -> #REF! | H5: =RIGHT(A3,G5) -> #REF! | I5: 5e-05 | J5: =(A3-I5) -> #REF! | K5: =IF(C7=5,IF(AND(D3=0,D8=FALSE),J5,J6),J6) -> #REF!
C6: =RIGHT(C5,1) -> #REF! | D6: =D5+0 -> #REF! | J6: =FIXED(A3,4) -> #REF!
C7: =C6+0 -> #REF! | D7: es impar? | E7: Largo dato original | F7: largo parte enetero y decimal
D8: =ISODD(D5) -> #REF! | E8: =LEN(A3) -> #REF! | F8: =LEN(E5)+1 -> #REF!
A10: 4 Decimales
A11: =K5 -> #REF! | C11: =FIXED(A3,5) -> #REF! | D11: =RIGHT(C11,1) -> #REF! | E11: =D11+0 -> #REF!
C12: Extrae el ultimo digito | D12: extrael primer digito | E12: parte entera | F12: Parte decimal | G12: cantidad de decimales | H12: decimales en enteros | I12: restar ultimo numero | J12: Elimar ultimo digito | K12: Dato Final
C13: =RIGHT(A11,2) -> #REF! | D13: =LEFT(C13,1) -> #REF! | E13: =TRUNC(A11) -> #REF! | F13: =FIXED(A11-E13,G13) -> #REF! | G13: =ABS(E16-F16) -> #REF! | H13: =RIGHT(A11,G13) -> #REF! | I13: 0.0005 | J13: =(A11-I13) -> #REF! | K13: =IF(C15=5,IF(AND(E11=0,D16=FALSE),J13,J14),J14) -> #REF!
C14: =RIGHT(C13,1) -> #REF! | D14: =D13+0 -> #REF! | J14: =FIXED(A11,3) -> #REF!
C15: =C14+0 -> #REF! | D15: es impar? | E15: Largo dato original | F15: largo parte enetero y decimal
D16: =ISODD(D13) -> #REF! | E16: =LEN(A11) -> #REF! | F16: =LEN(E13)+1 -> #REF!
A18: 3 Decimales
A19: =K13 -> #REF! | C19: =FIXED(A11,4) -> #REF! | D19: =RIGHT(C19,1) -> #REF! | E19: =D19+0 -> #REF!
C20: Extrae el ultimo digito | D20: extrael primer digito | E20: parte entera | F20: Parte decimal | G20: cantidad de decimales | H20: decimales en enteros | I20: restar ultimo numero | J20: Elimar ultimo digito | K20: Dato Final
C21: =RIGHT(A19,2) -> #REF! | D21: =LEFT(C21,1) -> #REF! | E21: =TRUNC(A19) -> #REF! | F21: =FIXED(A19-E21,G21) -> #REF! | G21: =ABS(E24-F24) -> #REF! | H21: =RIGHT(A19,G21) -> #REF! | I21: 0.005 | J21: =(A19-I21) -> #REF! | K21: =IF(C23=5,IF(AND(E19=0,D24=FALSE),J21,J22),J22) -> #REF!
C22: =RIGHT(C21,1) -> #REF! | D22: =D21+0 -> #REF! | J22: =FIXED(A19,2) -> #REF!
C23: =C22+0 -> #REF! | D23: es impar? | E23: Largo dato original | F23: largo parte enetero y decimal
D24: =ISODD(D21) -> #REF! | E24: =LEN(A19) -> #REF! | F24: =LEN(E21)+1 -> #REF!
A26: 2 Decimales
A27: =K21 -> #REF! | C27: =FIXED(A19,3) -> #REF! | D27: =RIGHT(C27,1) -> #REF! | E27: =D27+0 -> #REF!
C28: Extrae el ultimo digito | D28: extrael primer digito | E28: parte entera | F28: Parte decimal | G28: cantidad de decimales | H28: decimales en enteros | I28: restar ultimo numero | J28: Elimar ultimo digito | K28: Dato Final
C29: =RIGHT(A27,2) -> #REF! | D29: =LEFT(C29,1) -> #REF! | E29: =TRUNC(A27) -> #REF! | F29: =FIXED(A27-E29,G29) -> #REF! | G29: =ABS(E32-F32) -> #REF! | H29: =RIGHT(A27,G29) -> #REF! | I29: 0.05 | J29: =(A27-I29) -> #REF! | K29: =IF(C31=5,IF(AND(E27=0,D32=FALSE),J29,J30),J30) -> #REF!
C30: =RIGHT(C29,1) -> #REF! | D30: =D29+0 -> #REF! | J30: =FIXED(A27,1) -> #REF!
C31: =C30+0 -> #REF! | D31: es impar? | E31: Largo dato original | F31: largo parte enetero y decimal
D32: =ISODD(D29) -> #REF! | E32: =LEN(A27) -> #REF! | F32: =LEN(E29)+1 -> #REF!
A34: 1 Decimales
A35: =K29 -> #REF! | C35: =FIXED(A27,2) -> #REF! | D35: =RIGHT(C35,1) -> #REF! | E35: =D35+0 -> #REF!
C36: Extrae el ultimo digito | D36: extrael primer digito | E36: parte entera | F36: Parte decimal | G36: cantidad de decimales | H36: decimales en enteros | I36: restar ultimo numero | J36: Elimar ultimo digito | K36: Dato Final
C37: =RIGHT(A35,2) -> #REF! | D37: =RIGHT(E37,1) -> #REF! | E37: =TRUNC(A35) -> #REF! | F37: =FIXED(A35-E37,G37) -> #REF! | G37: =ABS(E40-F40) -> #REF! | H37: =RIGHT(A35,G37) -> #REF! | I37: 0.5 | J37: =(A35-I37) -> #REF! | K37: =IF(C39=5,IF(AND(E35=0,D40=FALSE),J37,J38),J38) -> #REF!
C38: =RIGHT(C37,1) -> #REF! | D38: =D37+0 -> #REF! | J38: =FIXED(A35,0) -> #REF!
C39: =C38+0 -> #REF! | D39: es impar? | E39: Largo dato original | F39: largo parte enetero y decimal
D40: =ISODD(D37) -> #REF! | E40: =LEN(A35) -> #REF! | F40: =LEN(E37)+1 -> #REF!
A41: DATO 2
A42: Dato | B42: Dato redondeado | C42: =FIXED(A43,6) -> #REF! | D42: =RIGHT(C42,1) -> #REF! | E42: =D42/1000000 -> #REF! | F42: =A43-E42 -> #REF! | H42: =IF(C47=5,IF(AND(D43=0,D48=FALSE),J45,J46),J46) -> #REF!
A43: =INCERTIDUMBRE!#REF! -> #REF! | B43: =IF(A43>=10,K77,IF(A43>=1,K69,IF(A43>=0.1,K61,IF(A43>=0.01,K53,IF(A43>=0.001,K45))))) -> #REF! | C43: 6 decimal | D43: =D42+0 -> #REF!
C44: Extrae el ultimo digito | D44: extrael primer digito | E44: parte entera | F44: Parte decimal | G44: cantidad de decimales | H44: decimales en enteros | I44: restar ultimo numero | J44: Elimar ultimo digito | K44: Dato Final
...

Sheet MEDIDA
R3: PIP
R4: Equipo bajo prueba (cmH2O) | T4: Medidas del equipo patrón
T5: Lectura 1 (cmH2O) | V5: Lectura 2 (cmH2O) | X5: Lectura 3 (cmH2O) | Z5: Lectura 4 (cmH2O) | AB5: Promedio (cmH2O) | AD5: Error (cmH2O)
R6: 5 | T6: =4.7 + (5.3 - 4.7) * RAND() -> 5.1009388 | V6: =T6+((RAND()*(0.1)*RANDBETWEEN(-1,1))) -> 5.1009388 | X6: =V6+((RAND()*(0.1)*RANDBETWEEN(-1,1))) -> 5.0691441 | Z6: =X6+((RAND()*(0.1)*RANDBETWEEN(-1,1))) -> 5.0044415 | AB6: =AVERAGE(T6:AA6) -> 5.0688658 | AD6: =AB6-R6 -> 0.068865788
R7: 10 | T7: =IF((T6 - R6) < 0, R7 - MIN(0.6, ABS(R6 - T6) + RAND()/2), R7 + MIN(0.6, ABS(R6 - T6) + RAND()/2)) -> 10.15508 | V7: =T7+((RAND()*(0.1)*RANDBETWEEN(-1,1))) -> 10.147548 | X7: =V7+((RAND()*(0.1)*RANDBETWEEN(-1,1))) -> 10.156245 | Z7: =X7+((RAND()*(0.1)*RANDBETWEEN(-1,1))) -> 10.156245 | AB7: =AVERAGE(T7:AA7) -> 10.153779 | AD7: =AB7-R7 -> 0.15377922
R8: 20 | T8: =IF((T7 - R7) < 0, R8 - MIN(1, ABS(R7 - T7) + RAND()), R8 + MIN(1, ABS(R7 - T7) + RAND())) -> 20.706721 | V8: =T8+((RAND()*(0.1)*RANDBETWEEN(-1,1))) -> 20.666526 | X8: =V8+((RAND()*(0.1)*RANDBETWEEN(-1,1))) -> 20.666526 | Z8: =X8+((RAND()*(0.1)*RANDBETWEEN(-1,1))) -> 20.666526 | AB8: =AVERAGE(T8:AA8) -> 20.676575 | AD8: =AB8-R8 -> 0.67657491
R9: 40 | T9: =IF((T8 - R8) < 0, R9 - MIN(1.5, ABS(R8 - T8) + RAND()*1.5), R9 + MIN(1.5, ABS(R8 - T8) + RAND()*1.5)) -> 41.305754 | V9: =T9+((RAND()*(0.1)*RANDBETWEEN(-1,1))) -> 41.341959 | X9: =V9+((RAND()*(0.1)*RANDBETWEEN(-1,1))) -> 41.274829 | Z9: =X9+((RAND()*(0.1)*RANDBETWEEN(-1,1))) -> 41.203788 | AB9: =AVERAGE(T9:AA9) -> 41.281583 | AD9: =AB9-R9 -> 1.2815827
B11: Oxígeno | R11: Frecuencia
B12: Equipo bajo prueba (%) | D12: Medidas del equipo patrón | R12: Equipo bajo prueba (bpm) | T12: Medidas del equipo patrón
D13: Lectura 1 (%) | F13: Lectura 2 (%) | H13: Lectura 3 (%) | J13: Lectura 4 (%) | L13: Promedio (%) | N13: Error (%) | T13: Lectura 1 (bpm) | V13: Lectura 2 (bpm) | X13: Lectura 3 (bpm) | Z13: Lectura 4 (bpm) | AB13: Promedio (bpm) | AD13: Error (bpm)
B14: 21 | D14: =20.8 + (21.5 - 20.8) * RAND() -> 21.316276 | F14: =D14+((RAND()*(0.4-0.1)+0.1)*RANDBETWEEN(-1,1)) -> 21.630948 | H14: =D14+((RAND()*(0.3-0.1)+0.1)*RANDBETWEEN(-1,1)) -> 21.100344 | J14: =D14+((RAND()*(0.3-0.1)+0.1)*RANDBETWEEN(-1,1)) -> 21.316276 | L14: =AVERAGE(D14:K14) -> 21.340961 | N14: =L14-B14 -> 0.34096066 | R14: 8 | T14: 8 | V14: =T14 -> 8 | X14: =V14 -> 8 | Z14: =X14 -> 8 | AB14: =AVERAGE(T14:AA14) -> 8 | AD14: =AB14-R14 -> 0
B15: 50 | D15: =IF((D14 - B14) < 0, B15 - MIN(1, ABS(B14 - D14) + RAND()/2), B15 - MIN(1, ABS(B14 - D14) + RAND()/2)) -> 49.523723 | F15: =D15+((RAND()*(0.4-0.1)+0.1)*RANDBETWEEN(-1,1)) -> 49.814221 | H15: =D15+((RAND()*(0.3-0.1)+0.1)*RANDBETWEEN(-1,1)) -> 49.523723 | J15: =D15+((RAND()*(0.3-0.1)+0.1)*RANDBETWEEN(-1,1)) -> 49.233434 | L15: =AVERAGE(D15:K15) -> 49.523776 | N15: =L15-B15 -> -0.47622446 | R15: 10 | T15: 10 | V15: =T15 -> 10 | X15: =V15 -> 10 | Z15: =X15 -> 10 | AB15: =AVERAGE(T15:AA15) -> 10 | AD15: =AB15-R15 -> 0
B16: 70 | D16: =IF((D15 - B15) < 0, B16 - MIN(1, ABS(B15 - D15) + RAND()/2), B16 - MIN(1, ABS(B15 - D15) + RAND()/2)) -> 69.511873 | F16: =D16+((RAND()*(0.4-0.1)+0.1)*RANDBETWEEN(-1,1)) -> 69.158779 | H16: =D16+((RAND()*(0.3-0.1)+0.1)*RANDBETWEEN(-1,1)) -> 69.24766 | J16: =D16+((RAND()*(0.3-0.1)+0.1)*RANDBETWEEN(-1,1)) -> 69.767784 | L16: =AVERAGE(D16:K16) -> 69.421524 | N16: =L16-B16 -> -0.57847619 | R16: 20 | T16: 20 | V16: =T16 -> 20 | X16: =V16 -> 20 | Z16: =X16 -> 20 | AB16: =AVERAGE(T16:AA16) -> 20 | AD16: =AB16-R16 -> 0
B17: 100 | D17: =IF((D16 - B16) < 0, B17 - MIN(1.5, ABS(B16 - D16) + RAND()/2), B17 - MIN(1.5, ABS(B16 - D16) + RAND()/2)) -> 99.05055 | F17: =D17+((RAND()*(0.4-0.1)+0.1)*RANDBETWEEN(-1,1)) -> 99.310435 | H17: =D17+((RAND()*(0.3-0.1)+0.1)*RANDBETWEEN(-1,1)) -> 98.905136 | J17: =D17+((RAND()*(0.3-0.1)+0.1)*RANDBETWEEN(-1,1)) -> 99.294007 | L17: =AVERAGE(D17:K17) -> 99.140032 | N17: =L17-B17 -> -0.85996818 | R17: 40 | T17: =39.8 + (40.1 - 39.8) * RAND() -> 39.970128 | V17: =T17 -> 39.970128 | X17: =V17 -> 39.970128 | Z17: =X17 -> 39.970128 | AB17: =AVERAGE(T17:AA17) -> 39.970128 | AD17: =AB17-R17 -> -0.029872196
B20: PEEP | R20: Tiempo
B21: Equipo bajo prueba (cmH2O) | D21: Medidas del equipo patrón | R21: Equipo bajo prueba (S) | T21: Medidas del equipo patrón
D22: Lectura 1 (cmH2O) | F22: Lectura 2 (cmH2O) | H22: Lectura 3 (cmH2O) | J22: Lectura 4 (cmH2O) | L22: Promedio (cmH2O) | N22: Error (cmH2O) | T22: Lectura 1 (S) | V22: Lectura 2 (S) | X22: Lectura 3 (S) | Z22: Lectura 4 (S) | AB22: Promedio (S) | AD22: Error (S)
B23: 2 | D23: =1.8 + (2.2 - 1.8) * RAND() -> 1.8848959 | F23: =D23+((RAND()*(0.1)*RANDBETWEEN(-1,1))) -> 1.8848959 | H23: =F23+((RAND()*(0.1)*RANDBETWEEN(-1,1))) -> 1.8339618 | J23: =H23+((RAND()*(0.1)*RANDBETWEEN(-1,1))) -> 1.8339618 | L23: =AVERAGE(D23:K23) -> 1.8594289 | N23: =L23-B23 -> -0.14057113 | R23: 1 | S23: 1 | T23: 1,00 | U23: =ROUND(0.96 + (1.04 - 0.96) * RAND(), 2) -> 0.97 | V23: =T23 -> 1,00 | W23: =U23+((RAND()*(0.01)+0.007)*(RANDBETWEEN(-1,1))) -> 0.9811102 | X23: =T23 -> 1,00 | Y23: =W23+((RAND()*(0.01)+0.007)*(RANDBETWEEN(-1,1))) -> 0.9811102 | Z23: =T23 -> 1,00 | AA23: =Y23+((RAND()*(0.01)+0.007)*(RANDBETWEEN(-1,1))) -> 0.9811102 | AB23: =T23 -> 1,00 | AC23: =AVERAGE(U23,W23,Y23,AA23) -> 0.97833265 | AD23: =AB23-R23 -> 0 | AE23: =S23-AC23 -> 0.021667353
B24: 6 | D24: =IF((D23 - B23) < 0, B24 - MIN(0.6, ABS(B23 - D23) + RAND()/2), B24 + MIN(0.6, ABS(B23 - D23) + RAND()/2)) -> 5.6206546 | F24: =D24+((RAND()*(0.1)*RANDBETWEEN(-1,1))) -> 5.6876167 | H24: =F24+((RAND()*(0.1)*RANDBETWEEN(-1,1))) -> 5.7383932 | J24: =H24+((RAND()*(0.1)*RANDBETWEEN(-1,1))) -> 5.7551561 | L24: =AVERAGE(D24:K24) -> 5.7004552 | N24: =L24-B24 -> -0.29954483 | R24: 1 | S24: 2 | T24: 1,00 | U24: =ROUND(IF((U23 - S23) < 0, S24 - MIN(0.1, ABS(S23 - U23) + RAND()/10), S24 + MIN(0.1, ABS(S23 - U23) + RAND()/10)), 2) -> 1.92 | V24: =T24 -> 1,00 | W24: =U24+((RAND()*(0.01)+0.007)*(RANDBETWEEN(-1,1))) -> 1.9307564 | X24: =T24 -> 1,00 | Y24: =W24+((RAND()*(0.01)+0.007)*(RANDBETWEEN(-1,1))) -> 1.9307564 | Z24: =T24 -> 1,00 | AA24: =Y24+((RAND()*(0.01)+0.007)*(RANDBETWEEN(-1,1))) -> 1.9228467 | AB24: =T24 -> 1,00 | AC24: =AVERAGE(U24,W24,Y24,AA24) -> 1.9260899 | AD24: =AB24-R24 -> 0 | AE24: =S24-AC24 -> 0.073910103
B25: 8 | D25: =IF((D24 - B24) < 0, B25 - MIN(1, ABS(B24 - D24) + RAND()), B25 + MIN(1, ABS(B24 - D24) + RAND())) -> 7 | F25: =D25+((RAND()*(0.1)*RANDBETWEEN(-1,1))) -> 7 | H25: =F25+((RAND()*(0.1)*RANDBETWEEN(-1,1))) -> 6.9741483 | J25: =H25+((RAND()*(0.1)*RANDBETWEEN(-1,1))) -> 6.9127085 | L25: =AVERAGE(D25:K25) -> 6.9717142 | N25: =L25-B25 -> -1.0282858 | R25: 1 | S25: 3 | T25: 1,00 | U25: =ROUND(IF((U24 - S24) < 0, S25 - MIN(0.15, ABS(S24 - U24) + RAND()/10), S25 + MIN(0.15, ABS(S24 - U24) + RAND()/10)), 2) -> 2.85 | V25: =T25 -> 1,00 | W25: =U25+((RAND()*(0.01)+0.007)*(RANDBETWEEN(-1,1))) -> 2.8371814 | X25: =T25 -> 1,00 | Y25: =W25+((RAND()*(0.01)+0.007)*(RANDBETWEEN(-1,1))) -> 2.8286215 | Z25: =T25 -> 1,00 | AA25: =Y25+((RAND()*(0.01)+0.007)*(RANDBETWEEN(-1,1))) -> 2.8420401 | AB25: =T25 -> 1,00 | AC25: =AVERAGE(U25,W25,Y25,AA25) -> 2.8394607 | AD25: =AB25-R25 -> 0 | AE25: =S25-AC25 -> 0.16053925
B26: 10 | D26: =IF((D25 - B25) < 0, B26 - MIN(1.5, ABS(B25 - D25) + RAND()*1.5), B26 + MIN(1.5, ABS(B25 - D25) + RAND()*1.5)) -> 8.5 | F26: =D26+((RAND()*(0.1)*RANDBETWEEN(-1,1))) -> 8.5148477 | H26: =F26+((RAND()*(0.1)*RANDBETWEEN(-1,1))) -> 8.5948992 | J26: =H26+((RAND()*(0.1)*RANDBETWEEN(-1,1))) -> 8.5948992 | L26: =AVERAGE(D26:K26) -> 8.5511615 | N26: =L26-B26 -> -1.4488385

Sheet PATRON
C2: Volumen
C3: Nominal | D3: Medido | E3: Corrección | F3: k | G3: Correcion estimada | H3: Residuales | I3: N-M-1 | J3: u interpolación
C4: 99.6 | D4: 106.2 | E4: =C4-D4 -> -6.6 | F4: 2 | G4: =J$13*D4-J$14 -> -6.6 | H4: =E4-G4 -> 0 | I4: =2-2-1 -> -1 | J4: 0
C5: 1000 | D5: 1042 | E5: =C5-D5 -> -42 | F5: 2 | G5: =J$13*D5-J$14 -> -42 | H5: =E5-G5 -> 0
J13: -0.037828596
J14: 2.5826031
B34: EQUIPO PATRÓN
B35: Equipo patrón: | G35: Analizador de flujo de gases
B36: Marca: | G36: TSI
B37: Modelo: | G37: 4070
B38: Serie: | G38: 40712037006
B39: Fecha de Calibración: | G39: 44970
B40: No. Certificado: | G40: L4012
B41: Incertidumbre Volumen: | G41: 5.5
B42: Incertidumbre presión: | G42: 0.11
B43: Deriva volumen | G43: 3
B44: Deriva presión | G44: 0.2
B45: Resolución volumen | G45: 0.1
B46: Resolución presión | G46: 0.1
B47: Factor de cobertura K: | G47: 2

Sheet INCERTIDUMBRE
B2: FUENTES DE INCERTIDUMBRE VOLUMEN
B3: Punto de calibración | C3: Cert de calibración | D3: Deriva | E3: Interpolación | F3: Resolución item | G3: Resolución patrón | H3: Repetibilidad | I3: Incertidumbre combinada | J3: Veff | K3: Factor de cobertura (k) | L3: Incertidumbre Expandida
B4: =MEDIDA!#REF! -> #REF! | C4: =PATRON!G$41/2 -> 2.75 | D4: =PATRON!G$43/SQRT(3) -> 1.7320508 | E4: 0 | F4: =1/SQRT(12) -> 0.28867513 | G4: =PATRON!G$45/SQRT(12) -> 0.028867513 | H4: =STDEVA(MEDIDA!#REF!)/SQRT(4) -> #REF! | I4: =SQRT(SUMSQ(C4:H4)) -> #REF! | J4: =I4^4/(C4^4/200+D4^4/200+E4^4/200+F4^4/200+G4^4/200+H4^4/3) -> #REF! | K4: =TINV(0.0455,J4) -> #REF! | L4: =I4*K4 -> #REF!
B5: =MEDIDA!#REF! -> #REF! | C5: =PATRON!G$41/2 -> 2.75 | D5: =PATRON!G$43/SQRT(3) -> 1.7320508 | E5: 0 | F5: =1/SQRT(12) -> 0.28867513 | G5: =PATRON!G$45/SQRT(12) -> 0.028867513 | H5: =STDEVA(MEDIDA!#REF!)/SQRT(4) -> #REF! | I5: =SQRT(SUMSQ(C5:H5)) -> #REF! | J5: =I5^4/(C5^4/200+D5^4/200+E5^4/200+F5^4/200+G5^4/200+H5^4/3) -> #REF! | K5: =TINV(0.0455,J5) -> #REF! | L5: =I5*K5 -> #REF!
B6: =MEDIDA!#REF! -> #REF! | C6: =PATRON!G$41/2 -> 2.75 | D6: =PATRON!G$43/SQRT(3) -> 1.7320508 | E6: 0 | F6: =1/SQRT(12) -> 0.28867513 | G6: =PATRON!G$45/SQRT(12) -> 0.028867513 | H6: =STDEVA(MEDIDA!#REF!)/SQRT(4) -> #REF! | I6: =SQRT(SUMSQ(C6:H6)) -> #REF! | J6: =I6^4/(C6^4/200+D6^4/200+E6^4/200+F6^4/200+G6^4/200+H6^4/3) -> #REF! | K6: =TINV(0.0455,J6) -> #REF! | L6: =I6*K6 -> #REF!
B7: =MEDIDA!#REF! -> #REF! | C7: =PATRON!G$41/2 -> 2.75 | D7: =PATRON!G$43/SQRT(3) -> 1.7320508 | E7: 0 | F7: =1/SQRT(12) -> 0.28867513 | G7: =PATRON!G$45/SQRT(12) -> 0.028867513 | H7: =STDEVA(MEDIDA!#REF!)/SQRT(4) -> #REF! | I7: =SQRT(SUMSQ(C7:H7)) -> #REF! | J7: =I7^4/(C7^4/200+D7^4/200+E7^4/200+F7^4/200+G7^4/200+H7^4/3) -> #REF! | K7: =TINV(0.0455,J7) -> #REF! | L7: =I7*K7 -> #REF!
B9: FUENTES DE INCERTIDUMBRE OXÍGENO
B10: Punto de calibración | C10: Cert de calibración | D10: Deriva | E10: Interpolación | F10: Resolución item | G10: Resolución patrón | H10: Repetibilidad | I10: Incertidumbre combinada | J10: Veff | K10: Factor de cobertura (k) | L10: Incertidumbre Expandida
B11: =MEDIDA!B14 -> 21 | C11: =0.083/2 -> 0.0415 | D11: =0.2/SQRT(3) -> 0.11547005 | E11: 0 | F11: =1/SQRT(12) -> 0.28867513 | G11: =0.1/SQRT(12) -> 0.028867513 | H11: =STDEVA(MEDIDA!D14:K14)/SQRT(4) -> 0.10924269 | I11: =SQRT(SUMSQ(C11:H11)) -> 0.33340098 | J11: =I11^4/(C11^4/200+D11^4/200+E11^4/200+F11^4/200+G11^4/200+H11^4/3) -> 148.68012 | K11: =TINV(0.0455,J11) -> 2.0170351 | L11: =I11*K11 -> 0.67248148
B12: =MEDIDA!B15 -> 50 | C12: =0.083/2 -> 0.0415 | D12: =0.2/SQRT(3) -> 0.11547005 | E12: 0 | F12: =1/SQRT(12) -> 0.28867513 | G12: =0.1/SQRT(12) -> 0.028867513 | H12: =STDEVA(MEDIDA!D15:K15)/SQRT(4) -> 0.11855265 | I12: =SQRT(SUMSQ(C12:H12)) -> 0.33656646 | J12: =I12^4/(C12^4/200+D12^4/200+E12^4/200+F12^4/200+G12^4/200+H12^4/3) -> 126.45212 | K12: =TINV(0.0455,J12) -> 2.0200381 | L12: =I12*K12 -> 0.67987707
B13: =MEDIDA!B16 -> 70 | C13: =0.083/2 -> 0.0415 | D13: =0.2/SQRT(3) -> 0.11547005 | E13: 0 | F13: =1/SQRT(12) -> 0.28867513 | G13: =0.1/SQRT(12) -> 0.028867513 | H13: =STDEVA(MEDIDA!D16:K16)/SQRT(4) -> 0.1376357 | I13: =SQRT(SUMSQ(C13:H13)) -> 0.34375258 | J13: =I13^4/(C13^4/200+D13^4/200+E13^4/200+F13^4/200+G13^4/200+H13^4/3) -> 89.940311 | K13: =TINV(0.0455,J13) -> 2.0284831 | L13: =I13*K13 -> 0.69729631
B14: =MEDIDA!B17 -> 100 | C14: =0.083/2 -> 0.0415 | D14: =0.2/SQRT(3) -> 0.11547005 | E14: 0 | F14: =1/SQRT(12) -> 0.28867513 | G14: =0.1/SQRT(12) -> 0.028867513 | H14: =STDEVA(MEDIDA!D17:K17)/SQRT(4) -> 0.098289064 | I14: =SQRT(SUMSQ(C14:H14)) -> 0.32997423 | J14: =I14^4/(C14^4/200+D14^4/200+E14^4/200+F14^4/200+G14^4/200+H14^4/3) -> 177.63883 | K14: =TINV(0.0455,J14) -> 2.0142251 | L14: =I14*K14 -> 0.66464235
B16: FUENTES DE INCERTIDUMBRE PEEP
B17: Punto de calibración | C17: Cert de calibración | D17: Deriva | E17: Interpolación | F17: Resolución item | G17: Resolución patrón | H17: Repetibilidad | I17: Incertidumbre combinada | J17: Veff | K17: Factor de cobertura (k) | L17: Incertidumbre Expandida
B18: =MEDIDA!B23 -> 2 | C18: =PATRON!G$42/2 -> 0.055 | D18: =PATRON!G$44/SQRT(3) -> 0.11547005 | E18: 0 | F18: =1/SQRT(12) -> 0.28867513 | G18: =PATRON!G$46/SQRT(12) -> 0.028867513 | H18: =STDEVA(MEDIDA!D23:K23)/SQRT(4) -> 0.014703408 | I18: =SQRT(SUMSQ(C18:H18)) -> 0.31739753 | J18: =I18^4/(C18^4/200+D18^4/200+E18^4/200+F18^4/200+G18^4/200+H18^4/3) -> 284.47167 | K18: =TINV(0.0455,J18) -> 2.0088434 | L18: =I18*K18 -> 0.63760192
B19: =MEDIDA!B24 -> 6 | C19: =PATRON!G$42/2 -> 0.055 | D19: =PATRON!G$44/SQRT(3) -> 0.11547005 | E19: 0 | F19: =1/SQRT(12) -> 0.28867513 | G19: =PATRON!G$46/SQRT(12) -> 0.028867513 | H19: =STDEVA(MEDIDA!D24:K24)/SQRT(4) -> 0.030227527 | I19: =SQRT(SUMSQ(C19:H19)) -> 0.31849443 | J19: =I19^4/(C19^4/200+D19^4/200+E19^4/200+F19^4/200+G19^4/200+H19^4/3) -> 286.31623 | K19: =TINV(0.0455,J19) -> 2.0087813 | L19: =I19*K19 -> 0.63978566
B20: =MEDIDA!B25 -> 8 | C20: =PATRON!G$42/2 -> 0.055 | D20: =PATRON!G$44/SQRT(3) -> 0.11547005 | E20: 0 | F20: =1/SQRT(12) -> 0.28867513 | G20: =PATRON!G$46/SQRT(12) -> 0.028867513 | H20: =STDEVA(MEDIDA!D25:K25)/SQRT(4) -> 0.020590794 | I20: =SQRT(SUMSQ(C20:H20)) -> 0.31772469 | J20: =I20^4/(C20^4/200+D20^4/200+E20^4/200+F20^4/200+G20^4/200+H20^4/3) -> 285.29181 | K20: =TINV(0.0455,J20) -> 2.0088122 | L20: =I20*K20 -> 0.63824925
B21: =MEDIDA!B26 -> 10 | C21: =PATRON!G$42/2 -> 0.055 | D21: =PATRON!G$44/SQRT(3) -> 0.11547005 | E21: 0 | F21: =1/SQRT(12) -> 0.28867513 | G21: =PATRON!G$46/SQRT(12) -> 0.028867513 | H21: =STDEVA(MEDIDA!D26:K26)/SQRT(4) -> 0.025433193 | I21: =SQRT(SUMSQ(C21:H21)) -> 0.31807522 | J21: =I21^4/(C21^4/200+D21^4/200+E21^4/200+F21^4/200+G21^4/200+H21^4/3) -> 285.91614 | K21: =TINV(0.0455,J21) -> 2.0088122 | L21: =I21*K21 -> 0.6389534
B23: FUENTES DE INCERTIDUMBRE PIP
B24: Punto de calibración | C24: Cert de calibración | D24: Deriva | E24: Interpolación | F24: Resolución item | G24: Resolución patrón | H24: Repetibilidad | I24: Incertidumbre combinada | J24: Veff | K24: Factor de cobertura (k) | L24: Incertidumbre Expandida
B25: =MEDIDA!R6 -> 5 | C25: =PATRON!G$42/2 -> 0.055 | D25: =PATRON!G$44/SQRT(3) -> 0.11547005 | E25: 0 | F25: =1/SQRT(12) -> 0.28867513 | G25: =PATRON!G$46/SQRT(12) -> 0.028867513 | H25: =STDEVA(MEDIDA!T6:AA6)/SQRT(4) -> 0.022744835 | I25: =SQRT(SUMSQ(C25:H25)) -> 0.31787156 | J25: =I25^4/(C25^4/200+D25^4/200+E25^4/200+F25^4/200+G25^4/200+H25^4/3) -> 285.5855 | K25: =TINV(0.0455,J25) -> 2.0088122 | L25: =I25*K25 -> 0.63854427
B26: =MEDIDA!R7 -> 10 | C26: =PATRON!G$42/2 -> 0.055 | D26: =PATRON!G$44/SQRT(3) -> 0.11547005 | E26: 0 | F26: =1/SQRT(12) -> 0.28867513 | G26: =PATRON!G$46/SQRT(12) -> 0.028867513 | H26: =STDEVA(MEDIDA!T7:AA7)/SQRT(4) -> 0.0020952301 | I26: =SQRT(SUMSQ(C26:H26)) -> 0.3170637 | J26: =I26^4/(C26^4/200+D26^4/200+E26^4/200+F26^4/200+G26^4/200+H26^4/3) -> 283.40048 | K26: =TINV(0.0455,J26) -> 2.0088748 | L26: =I26*K26 -> 0.63694126
B27: =MEDIDA!R8 -> 20 | C27: =PATRON!G$42/2 -> 0.055 | D27: =PATRON!G$44/SQRT(3) -> 0.11547005 | E27: 0 | F27: =1/SQRT(12) -> 0.28867513 | G27: =PATRON!G$46/SQRT(12) -> 0.028867513 | H27: =STDEVA(MEDIDA!T8:AA8)/SQRT(4) -> 0.01004881 | I27: =SQRT(SUMSQ(C27:H27)) -> 0.31721598 | J27: =I27^4/(C27^4/200+D27^4/200+E27^4/200+F27^4/200+G27^4/200+H27^4/3) -> 283.91831 | K27: =TINV(0.0455,J27) -> 2.0088748 | L27: =I27*K27 -> 0.63724718
B28: =MEDIDA!R9 -> 40 | C28: =PATRON!G$42/2 -> 0.055 | D28: =PATRON!G$44/SQRT(3) -> 0.11547005 | E28: 0 | F28: =1/SQRT(12) -> 0.28867513 | G28: =PATRON!G$46/SQRT(12) -> 0.028867513 | H28: =STDEVA(MEDIDA!T9:AA9)/SQRT(4) -> 0.029335909 | I28: =SQRT(SUMSQ(C28:H28)) -> 0.31841105 | J28: =I28^4/(C28^4/200+D28^4/200+E28^4/200+F28^4/200+G28^4/200+H28^4/3) -> 286.2667 | K28: =TINV(0.0455,J28) -> 2.0087813 | L28: =I28*K28 -> 0.63961816
B30: FUENTES DE INCERTIDUMBRE FRECUENCIA
B31: Punto de calibración | C31: Cert de calibración | D31: Deriva | E31: Interpolación | F31: Resolución item | G31: Resolución patrón | H31: Repetibilidad | I31: Incertidumbre combinada | J31: Veff | K31: Factor de cobertura (k) | L31: Incertidumbre Expandida
B32: =MEDIDA!R14 -> 8 | C32: 0 | D32: 0 | E32: 0 | F32: =1/SQRT(12) -> 0.28867513 | G32: =1/SQRT(12) -> 0.28867513 | H32: =STDEVA(MEDIDA!T14:AA14)/SQRT(4) -> 0 | I32: =SQRT(SUMSQ(C32:H32)) -> 0.40824829 | J32: =I32^4/(C32^4/200+D32^4/200+E32^4/200+F32^4/200+G32^4/200+H32^4/3) -> 400 | K32: =TINV(0.0455,J32) -> 2.0062716 | L32: =I32*K32 -> 0.81905697
B33: =MEDIDA!R15 -> 10 | C33: 0 | D33: 0 | E33: 0 | F33: =1/SQRT(12) -> 0.28867513 | G33: =1/SQRT(12) -> 0.28867513 | H33: =STDEVA(MEDIDA!T15:AA15)/SQRT(4) -> 0 | I33: =SQRT(SUMSQ(C33:H33)) -> 0.40824829 | J33: =I33^4/(C33^4/200+D33^4/200+E33^4/200+F33^4/200+G33^4/200+H33^4/3) -> 400 | K33: =TINV(0.0455,J33) -> 2.0062716 | L33: =I33*K33 -> 0.81905697
B34: =MEDIDA!R16 -> 20 | C34: 0 | D34: 0 | E34: 0 | F34: =1/SQRT(12) -> 0.28867513 | G34: =1/SQRT(12) -> 0.28867513 | H34: =STDEVA(MEDIDA!T16:AA16)/SQRT(4) -> 0 | I34: =SQRT(SUMSQ(C34:H34)) -> 0.40824829 | J34: =I34^4/(C34^4/200+D34^4/200+E34^4/200+F34^4/200+G34^4/200+H34^4/3) -> 400 | K34: =TINV(0.0455,J34) -> 2.0062716 | L34: =I34*K34 -> 0.81905697
B35: =MEDIDA!R17 -> 40 | C35: 0 | D35: 0 | E35: 0 | F35: =1/SQRT(12) -> 0.28867513 | G35: =1/SQRT(12) -> 0.28867513 | H35: =STDEVA(MEDIDA!T17:AA17)/SQRT(4) -> 0 | I35: =SQRT(SUMSQ(C35:H35)) -> 0.40824829 | J35: =I35^4/(C35^4/200+D35^4/200+E35^4/200+F35^4/200+G35^4/200+H35^4/3) -> 400 | K35: =TINV(0.0455,J35) -> 2.0062716 | L35: =I35*K35 -> 0.81905697
B37: FUENTES DE INCERTIDUMBRE TIEMPO
B38: Punto de calibración | C38: Cert de calibración | D38: Deriva | E38: Interpolación | F38: Resolución item | G38: Resolución patrón | H38: Repetibilidad | I38: Incertidumbre combinada | J38: Veff | K38: Factor de cobertura (k) | L38: Incertidumbre Expandida
B39: =MEDIDA!R23 -> 1 | C39: 0 | D39: 0 | E39: 0 | F39: =1/SQRT(12) -> 0.28867513 | G39: =0.01/SQRT(12) -> 0.0028867513 | H39: 0 | I39: =SQRT(SUMSQ(C39:H39)) -> 0.28868957 | J39: =I39^4/(C39^4/200+D39^4/200+E39^4/200+F39^4/200+G39^4/200+H39^4/3) -> 200.04 | K39: =TINV(0.0455,J39) -> 2.0125794 | L39: =I39*K39 -> 0.58101068
B40: =MEDIDA!R24 -> 1 | C40: 0 | D40: 0 | E40: 0 | F40: =1/SQRT(12) -> 0.28867513 | G40: =0.01/SQRT(12) -> 0.0028867513 | H40: 0 | I40: =SQRT(SUMSQ(C40:H40)) -> 0.28868957 | J40: =I40^4/(C40^4/200+D40^4/200+E40^4/200+F40^4/200+G40^4/200+H40^4/3) -> 200.04 | K40: =TINV(0.0455,J40) -> 2.0125794 | L40: =I40*K40 -> 0.58101068
B41: =MEDIDA!R25 -> 1 | C41: 0 | D41: 0 | E41: 0 | F41: =1/SQRT(12) -> 0.28867513 | G41: =0.01/SQRT(12) -> 0.0028867513 | H41: 0 | I41: =SQRT(SUMSQ(C41:H41)) -> 0.28868957 | J41: =I41^4/(C41^4/200+D41^4/200+E41^4/200+F41^4/200+G41^4/200+H41^4/3) -> 200.04 | K41: =TINV(0.0455,J41) -> 2.0125794 | L41: =I41*K41 -> 0.58101068

Sheet CERTIFICADO 
O1: CERTIFICADO N°: | R1: =INFORMACIÓN!G3 -> 0
C3: 1. EQUIPO BAJO PRUEBA
C5: INSTRUMENTO: | I5: =INFORMACIÓN!A3 -> 0
C6: MARCA: | I6: =INFORMACIÓN!B3 -> 0
C7: MODELO: | I7: =INFORMACIÓN!C3 -> 0
C8: SERIE: | I8: =INFORMACIÓN!D3 -> 0
C9: CÓDIGO INTERNO: | I9: =INFORMACIÓN!F3 -> 0
C10: UBICACIÓN: | I10: =INFORMACIÓN!E3 -> 0
C11: ESTADO FÍSICO: | I11: =INFORMACIÓN!B8 -> BUEN ESTADO
C12: FECHA DE RECEPCIÓN: | I12: =INFORMACIÓN!H3 -> 0
C13: FECHA DE CALIBRACIÓN: | I13: =INFORMACIÓN!B9 -> 0
C15: 2. DATOS DEL CLIENTE
C17: NOMBRE: | I17: =INFORMACIÓN!E7 -> HOSPITAL DE ALTA COMPLEJIDAD DEL MAGDALENA CENTRO
C18: NIT: | I18: =INFORMACIÓN!E8 -> 901.532.463-8
C19: TELÉFONO: | I19: =INFORMACIÓN!E9 -> 3007835072
C20: DIRECCIÓN: | I20: =INFORMACIÓN!E10 -> CARRERA 15 ENTRE CALLE 18 y 19
C21: CIUDAD: | I21: =INFORMACIÓN!E11 -> LA DORADA - CALDAS
C23: Este certificado expresa fielmente el resultado de las mediciones realizadas; no podrá ser reproducido total o parcialmente excepto cuando se haya obtenido permiso por escrito de BTM COLOMBIA ZOMAC S.A.S y se debe reproducir en su totalidad, para proporcionar seguridad de que el certificado no sea sacado de contexto. Los resultados que se encuentran en este certificado se refieren al momento y condiciones en que se realizaron las mediciones, BTM COLOMBIA ZOMAC S.A.S no se responsabiliza de los daños que puedan ser causados por el uso inadecuado de los equipos calibrados. El usuario es responsable de la calibración de sus instrumentos a intervalos apropiados. El laboratorio no se hace responsable por cómo la información suministrada por el cliente afecte los resultados de medición.
C31: REVISÓ Y AUTORIZÓ: | I31: CALIBRADO POR: | M31: =INFORMACIÓN!B15 -> ING. GABRIEL DURÁN
I32: FECHA DE EMISIÓN: | M32: =INFORMACIÓN!B10 -> 0
I33: NÚMERO DE PÁGINAS: | M33: 4
C36: ING. JOHAN SEBASTIÁN PÉREZ
C37: DIRECTOR DE LABORATORIO
O38: =O1 -> CERTIFICADO N°: | R38: =R1 -> 0
B40: 3. CONDICIONES AMBIENTALES
B41: El laboratorio de metrología BTM COLOMBIA ZOMAC S.A.S registra las condiciones ambientales (Humedad y Temperatura) tomando los máximos y mínimos alcanzados durante el tiempo en que se ejecuta la calibración. A continuación se presenta el promedio y la variación resultante.
F45: TEMPERATURA AMBIENTE (°C) | K45: HUMEDAD RELATIVA (%HR)
F46: =AVERAGE(INFORMACIÓN!B11:B12) -> 24.3 | H46: ± | I46: =ABS(INFORMACIÓN!B11-INFORMACIÓN!B12) -> 0.4 | K46: =AVERAGE(INFORMACIÓN!B13:B14) -> 61.5 | M46: ± | N46: =ABS(INFORMACIÓN!B13-INFORMACIÓN!B14) -> 3
F48: La calibración fue realizada en: | K48: En sitio (instalaciones del cliente)
B50: 4. INCERTIDUMBRE DE MEDICIÓN
B51: La incertidumbre expandida de la medición reportada se establece como la incertidumbre estándar de medición multiplicada por el factor de cobertura “k” y la probabilidad de cobertura, la cual debe ser aproximada al 95% y no menor a este valor. La incertidumbre de medición ha sido estimada con un nivel de confianza del 95,45% empleando una distribución t de student. Cuando se hace declaración de cumplimiento, el laboratorio hace referencia a las especificaciones del fabricante, norma o requisitos declarados por el cliente. La regla de decisión aplicada en estos casos será |Error| +U ≤ EMP según la ASME B89 7.3.1, si cumple la anterior condición la medición se toma como conforme y registrará un pasa, en caso contrario se registrará falla. La probabilidad de dar una aceptación falsa o un rechazo falso no lo determina el laboratorio, sin embargo se puede calcular de acuerdo a la guía JCGM 106:2012 según su numeral 8.
B60: 5. PROCEDIMIENTO DE CALIBRACIÓN
B61: La calibración se ejecutó mediante el método de comparación directa con patrón de referencia de acuerdo con el procedimiento interno para ventiladores mecánicos BTM-P-010.
B64: 6. TRAZABILIDAD
B65: El laboratorio BTM COLOMBIA ZOMAC S.A.S establece la trazabilidad metrológica de sus mediciones al sistema internacional de unidades (SI), por medio de una cadena documentada de calibraciones, las cuales se encuentran referenciadas a patrones de medidas primarios. Esta vinculación se logra a través del uso de patrones calibrados por institutos nacionales de metrología (INM) y por laboratorios acreditados por parte de un organismo de acreditación.
B70: PATRÓN | H70: SERIE | M70: CALIBRACIÓN | P70: CERTIFICADO
B71: Analizador de flujo de gases | H71: 40712037006 | M71: 46072 | P71: L5602
O76: =O1 -> CERTIFICADO N°: | R76: =R1 -> 0
B78: 7. RESULTADOS DE LA CALIBRACIÓN
B81: Calibración de oxígeno | I81: Intervalo de medición (%): | N81: 21 a 100 | P81: Resolución (%): | S81: 1
...
